<robot name = "robot">
    <link name="0">
        <inertial>
            <origin xyz="0 0 3.5182725904800365" rpy="0 0 0"/>
            <mass value="1" />
            <inertia ixx="100" ixy="0" ixz="0" iyy="100" iyz="0" izz="100" />
        </inertial>
        <visual>
            <origin xyz="0 0 3.5182725904800365" rpy="0 0 0"/>
            <geometry>
                <box size="0.47466231649907253 1.0179743418845857 1.0365451809600732" />
            </geometry>
            <material name="Blue">
                <color rgba="0 0 1.0 1.0"/>
            </material>
        </visual>
        <collision>
            <origin xyz="0 0 3.5182725904800365" rpy="0 0 0"/>
            <geometry>
                <box size="0.47466231649907253 1.0179743418845857 1.0365451809600732" />
            </geometry>
        </collision>
    </link>
    <joint name="0_1" type="revolute">
       <parent link="0"/>
       <child  link="1"/>
       <origin rpy="0 0 0" xyz="0.0 -0.5089871709422928 3.5182725904800365" />
     <axis xyz="0 1 0"/>
       <limit effort="0.0" lower="-3.14159" upper="3.14159" velocity="0.0"/>
    </joint>
    <link name="1">
        <inertial>
            <origin xyz="0.0 -0.5151706275372828 0.0" rpy="0 0 0"/>
            <mass value="1" />
            <inertia ixx="100" ixy="0" ixz="0" iyy="100" iyz="0" izz="100" />
        </inertial>
        <visual>
            <origin xyz="0.0 -0.5151706275372828 0.0" rpy="0 0 0"/>
            <geometry>
                <box size="0.6497873631180568 1.0303412550745656 1.0384639052989577" />
            </geometry>
            <material name="Green">
                <color rgba="0 1.0 0 1.0"/>
            </material>
        </visual>
        <collision>
            <origin xyz="0.0 -0.5151706275372828 0.0" rpy="0 0 0"/>
            <geometry>
                <box size="0.6497873631180568 1.0303412550745656 1.0384639052989577" />
            </geometry>
        </collision>
    </link>
    <joint name="1_2" type="revolute">
       <parent link="1"/>
       <child  link="2"/>
       <origin rpy="0 0 0" xyz="-0.3248936815590284 -0.5151706275372828 0.0" />
     <axis xyz="1 0 0"/>
       <limit effort="0.0" lower="-3.14159" upper="3.14159" velocity="0.0"/>
    </joint>
    <link name="2">
        <inertial>
            <origin xyz="-0.2931318689493989 0.0 0.0" rpy="0 0 0"/>
            <mass value="1" />
            <inertia ixx="100" ixy="0" ixz="0" iyy="100" iyz="0" izz="100" />
        </inertial>
        <visual>
            <origin xyz="-0.2931318689493989 0.0 0.0" rpy="0 0 0"/>
            <geometry>
                <box size="0.5862637378987978 0.7564271129867076 0.7000601771794719" />
            </geometry>
            <material name="Blue">
                <color rgba="0 0 1.0 1.0"/>
            </material>
        </visual>
        <collision>
            <origin xyz="-0.2931318689493989 0.0 0.0" rpy="0 0 0"/>
            <geometry>
                <box size="0.5862637378987978 0.7564271129867076 0.7000601771794719" />
            </geometry>
        </collision>
    </link>
    <joint name="2_3" type="revolute">
       <parent link="2"/>
       <child  link="3"/>
       <origin rpy="0 0 0" xyz="-0.2931318689493989 0.0 -0.35003008858973594" />
     <axis xyz="1 0 0"/>
       <limit effort="0.0" lower="-3.14159" upper="3.14159" velocity="0.0"/>
    </joint>
    <link name="3">
        <inertial>
            <origin xyz="0.0 0.0 -0.5520759771071505" rpy="0 0 0"/>
            <mass value="1" />
            <inertia ixx="100" ixy="0" ixz="0" iyy="100" iyz="0" izz="100" />
        </inertial>
        <visual>
            <origin xyz="0.0 0.0 -0.5520759771071505" rpy="0 0 0"/>
            <geometry>
                <box size="0.5044174737229238 0.8186288569217361 1.104151954214301" />
            </geometry>
            <material name="Blue">
                <color rgba="0 0 1.0 1.0"/>
            </material>
        </visual>
        <collision>
            <origin xyz="0.0 0.0 -0.5520759771071505" rpy="0 0 0"/>
            <geometry>
                <box size="0.5044174737229238 0.8186288569217361 1.104151954214301" />
            </geometry>
        </collision>
    </link>
    <joint name="3_4" type="revolute">
       <parent link="3"/>
       <child  link="4"/>
       <origin rpy="0 0 0" xyz="0.0 -0.4093144284608681 -0.5520759771071505" />
     <axis xyz="1 0 0"/>
       <limit effort="0.0" lower="-3.14159" upper="3.14159" velocity="0.0"/>
    </joint>
    <link name="4">
        <inertial>
            <origin xyz="0.0 -0.2933856753839196 0.0" rpy="0 0 0"/>
            <mass value="1" />
            <inertia ixx="100" ixy="0" ixz="0" iyy="100" iyz="0" izz="100" />
        </inertial>
        <visual>
            <origin xyz="0.0 -0.2933856753839196 0.0" rpy="0 0 0"/>
            <geometry>
                <box size="1.040272297751459 0.5867713507678392 0.6484207908202047" />
            </geometry>
            <material name="Blue">
                <color rgba="0 0 1.0 1.0"/>
            </material>
        </visual>
        <collision>
            <origin xyz="0.0 -0.2933856753839196 0.0" rpy="0 0 0"/>
            <geometry>
                <box size="1.040272297751459 0.5867713507678392 0.6484207908202047" />
            </geometry>
        </collision>
    </link>
    <joint name="2_5" type="revolute">
       <parent link="2"/>
       <child  link="5"/>
       <origin rpy="0 0 0" xyz="-0.2931318689493989 0.0 0.35003008858973594" />
     <axis xyz="1 0 0"/>
       <limit effort="0.0" lower="-3.14159" upper="3.14159" velocity="0.0"/>
    </joint>
    <link name="5">
        <inertial>
            <origin xyz="0.0 0.0 0.25286495345404236" rpy="0 0 0"/>
            <mass value="1" />
            <inertia ixx="100" ixy="0" ixz="0" iyy="100" iyz="0" izz="100" />
        </inertial>
        <visual>
            <origin xyz="0.0 0.0 0.25286495345404236" rpy="0 0 0"/>
            <geometry>
                <box size="0.39411199838732625 0.944320367408815 0.5057299069080847" />
            </geometry>
            <material name="Green">
                <color rgba="0 1.0 0 1.0"/>
            </material>
        </visual>
        <collision>
            <origin xyz="0.0 0.0 0.25286495345404236" rpy="0 0 0"/>
            <geometry>
                <box size="0.39411199838732625 0.944320367408815 0.5057299069080847" />
            </geometry>
        </collision>
    </link>
    <joint name="3_6" type="revolute">
       <parent link="3"/>
       <child  link="6"/>
       <origin rpy="0 0 0" xyz="0.0 0.0 -1.104151954214301" />
     <axis xyz="1 0 0"/>
       <limit effort="0.0" lower="-3.14159" upper="3.14159" velocity="0.0"/>
    </joint>
    <link name="6">
        <inertial>
            <origin xyz="0.0 0.0 -0.4146812052878358" rpy="0 0 0"/>
            <mass value="1" />
            <inertia ixx="100" ixy="0" ixz="0" iyy="100" iyz="0" izz="100" />
        </inertial>
        <visual>
            <origin xyz="0.0 0.0 -0.4146812052878358" rpy="0 0 0"/>
            <geometry>
                <box size="0.9042628642374283 1.1229918968287806 0.8293624105756716" />
            </geometry>
            <material name="Green">
                <color rgba="0 1.0 0 1.0"/>
            </material>
        </visual>
        <collision>
            <origin xyz="0.0 0.0 -0.4146812052878358" rpy="0 0 0"/>
            <geometry>
                <box size="0.9042628642374283 1.1229918968287806 0.8293624105756716" />
            </geometry>
        </collision>
    </link>
</robot>