<robot name = "robot">
    <link name="0">
        <inertial>
            <origin xyz="0 0 3.218188989933979" rpy="0 0 0"/>
            <mass value="1" />
            <inertia ixx="100" ixy="0" ixz="0" iyy="100" iyz="0" izz="100" />
        </inertial>
        <visual>
            <origin xyz="0 0 3.218188989933979" rpy="0 0 0"/>
            <geometry>
                <box size="0.5272318832823354 0.5625255729944305 0.43637797986795757" />
            </geometry>
            <material name="Green">
                <color rgba="0 1.0 0 1.0"/>
            </material>
        </visual>
        <collision>
            <origin xyz="0 0 3.218188989933979" rpy="0 0 0"/>
            <geometry>
                <box size="0.5272318832823354 0.5625255729944305 0.43637797986795757" />
            </geometry>
        </collision>
    </link>
    <joint name="0_1" type="revolute">
       <parent link="0"/>
       <child  link="1"/>
       <origin rpy="0 0 0" xyz="0.0 0.28126278649721526 3.218188989933979" />
     <axis xyz="0 1 0"/>
       <limit effort="0.0" lower="-3.14159" upper="3.14159" velocity="0.0"/>
    </joint>
    <link name="1">
        <inertial>
            <origin xyz="0.0 0.5361995666357319 0.0" rpy="0 0 0"/>
            <mass value="1" />
            <inertia ixx="100" ixy="0" ixz="0" iyy="100" iyz="0" izz="100" />
        </inertial>
        <visual>
            <origin xyz="0.0 0.5361995666357319 0.0" rpy="0 0 0"/>
            <geometry>
                <box size="0.6412731110749363 1.0723991332714637 0.752910982261664" />
            </geometry>
            <material name="Green">
                <color rgba="0 1.0 0 1.0"/>
            </material>
        </visual>
        <collision>
            <origin xyz="0.0 0.5361995666357319 0.0" rpy="0 0 0"/>
            <geometry>
                <box size="0.6412731110749363 1.0723991332714637 0.752910982261664" />
            </geometry>
        </collision>
    </link>
    <joint name="1_2" type="revolute">
       <parent link="1"/>
       <child  link="2"/>
       <origin rpy="0 0 0" xyz="-0.32063655553746817 0.5361995666357319 0.0" />
     <axis xyz="0 1 0"/>
       <limit effort="0.0" lower="-3.14159" upper="3.14159" velocity="0.0"/>
    </joint>
    <link name="2">
        <inertial>
            <origin xyz="-0.5473612817382667 0.0 0.0" rpy="0 0 0"/>
            <mass value="1" />
            <inertia ixx="100" ixy="0" ixz="0" iyy="100" iyz="0" izz="100" />
        </inertial>
        <visual>
            <origin xyz="-0.5473612817382667 0.0 0.0" rpy="0 0 0"/>
            <geometry>
                <box size="1.0947225634765334 1.0618209119071995 0.651143009202755" />
            </geometry>
            <material name="Blue">
                <color rgba="0 0 1.0 1.0"/>
            </material>
        </visual>
        <collision>
            <origin xyz="-0.5473612817382667 0.0 0.0" rpy="0 0 0"/>
            <geometry>
                <box size="1.0947225634765334 1.0618209119071995 0.651143009202755" />
            </geometry>
        </collision>
    </link>
    <joint name="2_3" type="revolute">
       <parent link="2"/>
       <child  link="3"/>
       <origin rpy="0 0 0" xyz="-0.5473612817382667 0.0 0.3255715046013775" />
     <axis xyz="0 1 0"/>
       <limit effort="0.0" lower="-3.14159" upper="3.14159" velocity="0.0"/>
    </joint>
    <link name="3">
        <inertial>
            <origin xyz="0.0 0.0 0.40066713234293755" rpy="0 0 0"/>
            <mass value="1" />
            <inertia ixx="100" ixy="0" ixz="0" iyy="100" iyz="0" izz="100" />
        </inertial>
        <visual>
            <origin xyz="0.0 0.0 0.40066713234293755" rpy="0 0 0"/>
            <geometry>
                <box size="0.5190287496626049 0.3810018153129163 0.8013342646858751" />
            </geometry>
            <material name="Green">
                <color rgba="0 1.0 0 1.0"/>
            </material>
        </visual>
        <collision>
            <origin xyz="0.0 0.0 0.40066713234293755" rpy="0 0 0"/>
            <geometry>
                <box size="0.5190287496626049 0.3810018153129163 0.8013342646858751" />
            </geometry>
        </collision>
    </link>
    <joint name="1_4" type="revolute">
       <parent link="1"/>
       <child  link="4"/>
       <origin rpy="0 0 0" xyz="0.0 0.5361995666357319 -0.376455491130832" />
     <axis xyz="0 1 0"/>
       <limit effort="0.0" lower="-3.14159" upper="3.14159" velocity="0.0"/>
    </joint>
    <link name="4">
        <inertial>
            <origin xyz="0.0 0.0 -0.5578286255867847" rpy="0 0 0"/>
            <mass value="1" />
            <inertia ixx="100" ixy="0" ixz="0" iyy="100" iyz="0" izz="100" />
        </inertial>
        <visual>
            <origin xyz="0.0 0.0 -0.5578286255867847" rpy="0 0 0"/>
            <geometry>
                <box size="0.9887484517299463 0.8672531377759505 1.1156572511735694" />
            </geometry>
            <material name="Green">
                <color rgba="0 1.0 0 1.0"/>
            </material>
        </visual>
        <collision>
            <origin xyz="0.0 0.0 -0.5578286255867847" rpy="0 0 0"/>
            <geometry>
                <box size="0.9887484517299463 0.8672531377759505 1.1156572511735694" />
            </geometry>
        </collision>
    </link>
    <joint name="2_5" type="revolute">
       <parent link="2"/>
       <child  link="5"/>
       <origin rpy="0 0 0" xyz="-0.5473612817382667 0.5309104559535998 0.0" />
     <axis xyz="0 1 0"/>
       <limit effort="0.0" lower="-3.14159" upper="3.14159" velocity="0.0"/>
    </joint>
    <link name="5">
        <inertial>
            <origin xyz="0.0 0.5399517500577466 0.0" rpy="0 0 0"/>
            <mass value="1" />
            <inertia ixx="100" ixy="0" ixz="0" iyy="100" iyz="0" izz="100" />
        </inertial>
        <visual>
            <origin xyz="0.0 0.5399517500577466 0.0" rpy="0 0 0"/>
            <geometry>
                <box size="0.8264988998092908 1.0799035001154933 0.6746358353048119" />
            </geometry>
            <material name="Blue">
                <color rgba="0 0 1.0 1.0"/>
            </material>
        </visual>
        <collision>
            <origin xyz="0.0 0.5399517500577466 0.0" rpy="0 0 0"/>
            <geometry>
                <box size="0.8264988998092908 1.0799035001154933 0.6746358353048119" />
            </geometry>
        </collision>
    </link>
    <joint name="4_6" type="revolute">
       <parent link="4"/>
       <child  link="6"/>
       <origin rpy="0 0 0" xyz="0.49437422586497315 0.0 -0.5578286255867847" />
     <axis xyz="1 0 0"/>
       <limit effort="0.0" lower="-3.14159" upper="3.14159" velocity="0.0"/>
    </joint>
    <link name="6">
        <inertial>
            <origin xyz="0.5145621040102824 0.0 0.0" rpy="0 0 0"/>
            <mass value="1" />
            <inertia ixx="100" ixy="0" ixz="0" iyy="100" iyz="0" izz="100" />
        </inertial>
        <visual>
            <origin xyz="0.5145621040102824 0.0 0.0" rpy="0 0 0"/>
            <geometry>
                <box size="1.0291242080205647 0.894521085239627 0.6647411210398976" />
            </geometry>
            <material name="Green">
                <color rgba="0 1.0 0 1.0"/>
            </material>
        </visual>
        <collision>
            <origin xyz="0.5145621040102824 0.0 0.0" rpy="0 0 0"/>
            <geometry>
                <box size="1.0291242080205647 0.894521085239627 0.6647411210398976" />
            </geometry>
        </collision>
    </link>
</robot>