<robot name = "robot">
    <link name="0">
        <inertial>
            <origin xyz="0 0 3.211595476721497" rpy="0 0 0"/>
            <mass value="1" />
            <inertia ixx="100" ixy="0" ixz="0" iyy="100" iyz="0" izz="100" />
        </inertial>
        <visual>
            <origin xyz="0 0 3.211595476721497" rpy="0 0 0"/>
            <geometry>
                <box size="1.0856070574297372 0.5320547753268617 0.4231909534429943" />
            </geometry>
            <material name="Blue">
                <color rgba="0 0 1.0 1.0"/>
            </material>
        </visual>
        <collision>
            <origin xyz="0 0 3.211595476721497" rpy="0 0 0"/>
            <geometry>
                <box size="1.0856070574297372 0.5320547753268617 0.4231909534429943" />
            </geometry>
        </collision>
    </link>
    <joint name="0_1" type="revolute">
       <parent link="0"/>
       <child  link="1"/>
       <origin rpy="0 0 0" xyz="-0.5428035287148686 0.0 3.211595476721497" />
     <axis xyz="0 1 0"/>
       <limit effort="0.0" lower="-3.14159" upper="3.14159" velocity="0.0"/>
    </joint>
    <link name="1">
        <inertial>
            <origin xyz="-0.4678128273424932 0.0 0.0" rpy="0 0 0"/>
            <mass value="1" />
            <inertia ixx="100" ixy="0" ixz="0" iyy="100" iyz="0" izz="100" />
        </inertial>
        <visual>
            <origin xyz="-0.4678128273424932 0.0 0.0" rpy="0 0 0"/>
            <geometry>
                <box size="0.9356256546849864 0.7916389679524598 0.7879004814783116" />
            </geometry>
            <material name="Blue">
                <color rgba="0 0 1.0 1.0"/>
            </material>
        </visual>
        <collision>
            <origin xyz="-0.4678128273424932 0.0 0.0" rpy="0 0 0"/>
            <geometry>
                <box size="0.9356256546849864 0.7916389679524598 0.7879004814783116" />
            </geometry>
        </collision>
    </link>
    <joint name="1_4" type="revolute">
       <parent link="1"/>
       <child  link="4"/>
       <origin rpy="0 0 0" xyz="-0.4678128273424932 0.3958194839762299 0.0" />
     <axis xyz="0 1 0"/>
       <limit effort="0.0" lower="-3.14159" upper="3.14159" velocity="0.0"/>
    </joint>
    <link name="4">
        <inertial>
            <origin xyz="0.0 0.21211077405373313 0.0" rpy="0 0 0"/>
            <mass value="1" />
            <inertia ixx="100" ixy="0" ixz="0" iyy="100" iyz="0" izz="100" />
        </inertial>
        <visual>
            <origin xyz="0.0 0.21211077405373313 0.0" rpy="0 0 0"/>
            <geometry>
                <box size="0.9561106787183907 0.42422154810746626 0.651333538926333" />
            </geometry>
            <material name="Blue">
                <color rgba="0 0 1.0 1.0"/>
            </material>
        </visual>
        <collision>
            <origin xyz="0.0 0.21211077405373313 0.0" rpy="0 0 0"/>
            <geometry>
                <box size="0.9561106787183907 0.42422154810746626 0.651333538926333" />
            </geometry>
        </collision>
    </link>
    <joint name="0_5" type="revolute">
       <parent link="0"/>
       <child  link="5"/>
       <origin rpy="0 0 0" xyz="0.0 -0.26602738766343087 3.211595476721497" />
     <axis xyz="1 0 0"/>
       <limit effort="0.0" lower="-3.14159" upper="3.14159" velocity="0.0"/>
    </joint>
    <link name="5">
        <inertial>
            <origin xyz="0.0 -0.5510162567317078 0.0" rpy="0 0 0"/>
            <mass value="1" />
            <inertia ixx="100" ixy="0" ixz="0" iyy="100" iyz="0" izz="100" />
        </inertial>
        <visual>
            <origin xyz="0.0 -0.5510162567317078 0.0" rpy="0 0 0"/>
            <geometry>
                <box size="0.5477760444908667 1.1020325134634157 1.083340582015758" />
            </geometry>
            <material name="Blue">
                <color rgba="0 0 1.0 1.0"/>
            </material>
        </visual>
        <collision>
            <origin xyz="0.0 -0.5510162567317078 0.0" rpy="0 0 0"/>
            <geometry>
                <box size="0.5477760444908667 1.1020325134634157 1.083340582015758" />
            </geometry>
        </collision>
    </link>
    <joint name="4_6" type="revolute">
       <parent link="4"/>
       <child  link="6"/>
       <origin rpy="0 0 0" xyz="-0.47805533935919536 0.21211077405373313 0.0" />
     <axis xyz="0 1 0"/>
       <limit effort="0.0" lower="-3.14159" upper="3.14159" velocity="0.0"/>
    </joint>
    <link name="6">
        <inertial>
            <origin xyz="-0.5426884366806339 0.0 0.0" rpy="0 0 0"/>
            <mass value="1" />
            <inertia ixx="100" ixy="0" ixz="0" iyy="100" iyz="0" izz="100" />
        </inertial>
        <visual>
            <origin xyz="-0.5426884366806339 0.0 0.0" rpy="0 0 0"/>
            <geometry>
                <box size="1.0853768733612679 0.5207555852681827 0.4993583240307854" />
            </geometry>
            <material name="Blue">
                <color rgba="0 0 1.0 1.0"/>
            </material>
        </visual>
        <collision>
            <origin xyz="-0.5426884366806339 0.0 0.0" rpy="0 0 0"/>
            <geometry>
                <box size="1.0853768733612679 0.5207555852681827 0.4993583240307854" />
            </geometry>
        </collision>
    </link>
    <joint name="5_8" type="revolute">
       <parent link="5"/>
       <child  link="8"/>
       <origin rpy="0 0 0" xyz="-0.27388802224543335 -0.5510162567317078 0.0" />
     <axis xyz="1 0 0"/>
       <limit effort="0.0" lower="-3.14159" upper="3.14159" velocity="0.0"/>
    </joint>
    <link name="8">
        <inertial>
            <origin xyz="-0.4101099977344004 0.0 0.0" rpy="0 0 0"/>
            <mass value="1" />
            <inertia ixx="100" ixy="0" ixz="0" iyy="100" iyz="0" izz="100" />
        </inertial>
        <visual>
            <origin xyz="-0.4101099977344004 0.0 0.0" rpy="0 0 0"/>
            <geometry>
                <box size="0.8202199954688008 0.6512782828574575 0.4530711499267635" />
            </geometry>
            <material name="Blue">
                <color rgba="0 0 1.0 1.0"/>
            </material>
        </visual>
        <collision>
            <origin xyz="-0.4101099977344004 0.0 0.0" rpy="0 0 0"/>
            <geometry>
                <box size="0.8202199954688008 0.6512782828574575 0.4530711499267635" />
            </geometry>
        </collision>
    </link>
    <joint name="0_9" type="revolute">
       <parent link="0"/>
       <child  link="9"/>
       <origin rpy="0 0 0" xyz="0.0 0.26602738766343087 3.211595476721497" />
     <axis xyz="0 1 0"/>
       <limit effort="0.0" lower="-3.14159" upper="3.14159" velocity="0.0"/>
    </joint>
    <link name="9">
        <inertial>
            <origin xyz="0.0 0.4372083233176476 0.0" rpy="0 0 0"/>
            <mass value="1" />
            <inertia ixx="100" ixy="0" ixz="0" iyy="100" iyz="0" izz="100" />
        </inertial>
        <visual>
            <origin xyz="0.0 0.4372083233176476 0.0" rpy="0 0 0"/>
            <geometry>
                <box size="0.6334201344582925 0.8744166466352952 0.559261834796822" />
            </geometry>
            <material name="Green">
                <color rgba="0 1.0 0 1.0"/>
            </material>
        </visual>
        <collision>
            <origin xyz="0.0 0.4372083233176476 0.0" rpy="0 0 0"/>
            <geometry>
                <box size="0.6334201344582925 0.8744166466352952 0.559261834796822" />
            </geometry>
        </collision>
    </link>
    <joint name="9_10" type="revolute">
       <parent link="9"/>
       <child  link="10"/>
       <origin rpy="0 0 0" xyz="0.0 0.4372083233176476 -0.279630917398411" />
     <axis xyz="1 0 0"/>
       <limit effort="0.0" lower="-3.14159" upper="3.14159" velocity="0.0"/>
    </joint>
    <link name="10">
        <inertial>
            <origin xyz="0.0 0.0 -0.43630923266997873" rpy="0 0 0"/>
            <mass value="1" />
            <inertia ixx="100" ixy="0" ixz="0" iyy="100" iyz="0" izz="100" />
        </inertial>
        <visual>
            <origin xyz="0.0 0.0 -0.43630923266997873" rpy="0 0 0"/>
            <geometry>
                <box size="0.8013487986276029 0.8863497483182796 0.8726184653399575" />
            </geometry>
            <material name="Blue">
                <color rgba="0 0 1.0 1.0"/>
            </material>
        </visual>
        <collision>
            <origin xyz="0.0 0.0 -0.43630923266997873" rpy="0 0 0"/>
            <geometry>
                <box size="0.8013487986276029 0.8863497483182796 0.8726184653399575" />
            </geometry>
        </collision>
    </link>
    <joint name="10_2" type="revolute">
       <parent link="10"/>
       <child  link="2"/>
       <origin rpy="0 0 0" xyz="0.40067439931380144 0.0 -0.43630923266997873" />
     <axis xyz="1 0 0"/>
       <limit effort="0.0" lower="-3.14159" upper="3.14159" velocity="0.0"/>
    </joint>
    <link name="2">
        <inertial>
            <origin xyz="0.2883806662046042 0.0 0.0" rpy="0 0 0"/>
            <mass value="1" />
            <inertia ixx="100" ixy="0" ixz="0" iyy="100" iyz="0" izz="100" />
        </inertial>
        <visual>
            <origin xyz="0.2883806662046042 0.0 0.0" rpy="0 0 0"/>
            <geometry>
                <box size="0.5767613324092083 0.6009442340840918 0.5829573034225852" />
            </geometry>
            <material name="Blue">
                <color rgba="0 0 1.0 1.0"/>
            </material>
        </visual>
        <collision>
            <origin xyz="0.2883806662046042 0.0 0.0" rpy="0 0 0"/>
            <geometry>
                <box size="0.5767613324092083 0.6009442340840918 0.5829573034225852" />
            </geometry>
        </collision>
    </link>
    <joint name="2_3" type="revolute">
       <parent link="2"/>
       <child  link="3"/>
       <origin rpy="0 0 0" xyz="0.2883806662046042 0.0 -0.2914786517112926" />
     <axis xyz="1 0 0"/>
       <limit effort="0.0" lower="-3.14159" upper="3.14159" velocity="0.0"/>
    </joint>
    <link name="3">
        <inertial>
            <origin xyz="0.0 0.0 -0.4068451850530702" rpy="0 0 0"/>
            <mass value="1" />
            <inertia ixx="100" ixy="0" ixz="0" iyy="100" iyz="0" izz="100" />
        </inertial>
        <visual>
            <origin xyz="0.0 0.0 -0.4068451850530702" rpy="0 0 0"/>
            <geometry>
                <box size="0.48264256023535923 0.3791620798372212 0.8136903701061404" />
            </geometry>
            <material name="Blue">
                <color rgba="0 0 1.0 1.0"/>
            </material>
        </visual>
        <collision>
            <origin xyz="0.0 0.0 -0.4068451850530702" rpy="0 0 0"/>
            <geometry>
                <box size="0.48264256023535923 0.3791620798372212 0.8136903701061404" />
            </geometry>
        </collision>
    </link>
    <joint name="8_7" type="revolute">
       <parent link="8"/>
       <child  link="7"/>
       <origin rpy="0 0 0" xyz="-0.4101099977344004 0.0 -0.22653557496338175" />
     <axis xyz="0 1 0"/>
       <limit effort="0.0" lower="-3.14159" upper="3.14159" velocity="0.0"/>
    </joint>
    <link name="7">
        <inertial>
            <origin xyz="0.0 0.0 -0.3450714167628669" rpy="0 0 0"/>
            <mass value="1" />
            <inertia ixx="100" ixy="0" ixz="0" iyy="100" iyz="0" izz="100" />
        </inertial>
        <visual>
            <origin xyz="0.0 0.0 -0.3450714167628669" rpy="0 0 0"/>
            <geometry>
                <box size="0.450375520615134 0.5625942836089385 0.6901428335257338" />
            </geometry>
            <material name="Green">
                <color rgba="0 1.0 0 1.0"/>
            </material>
        </visual>
        <collision>
            <origin xyz="0.0 0.0 -0.3450714167628669" rpy="0 0 0"/>
            <geometry>
                <box size="0.450375520615134 0.5625942836089385 0.6901428335257338" />
            </geometry>
        </collision>
    </link>
</robot>