<robot name = "robot">
    <link name="0">
        <inertial>
            <origin xyz="0 0 1.2344604115165523" rpy="0 0 0"/>
            <mass value="1" />
            <inertia ixx="100" ixy="0" ixz="0" iyy="100" iyz="0" izz="100" />
        </inertial>
        <visual>
            <origin xyz="0 0 1.2344604115165523" rpy="0 0 0"/>
            <geometry>
                <box size="0.8477835128310957 0.8990085930127647 0.4689208230331047" />
            </geometry>
            <material name="Blue">
                <color rgba="0 0 1.0 1.0"/>
            </material>
        </visual>
        <collision>
            <origin xyz="0 0 1.2344604115165523" rpy="0 0 0"/>
            <geometry>
                <box size="0.8477835128310957 0.8990085930127647 0.4689208230331047" />
            </geometry>
        </collision>
    </link>
    <joint name="0_1" type="revolute">
       <parent link="0"/>
       <child  link="1"/>
       <origin rpy="0 0 0" xyz="0.4238917564155478 0 1.2344604115165523" />
     <axis xyz="0 1 0"/>
       <limit effort="0.0" lower="-3.14159" upper="3.14159" velocity="0.0"/>
    </joint>
    <link name="1">
        <inertial>
            <origin xyz="0.0995330860695075 0 0" rpy="0 0 0"/>
            <mass value="1" />
            <inertia ixx="100" ixy="0" ixz="0" iyy="100" iyz="0" izz="100" />
        </inertial>
        <visual>
            <origin xyz="0.0995330860695075 0 0" rpy="0 0 0"/>
            <geometry>
                <box size="0.199066172139015 0.5059150223500399 0.6670897978966985" />
            </geometry>
            <material name="Blue">
                <color rgba="0 0 1.0 1.0"/>
            </material>
        </visual>
        <collision>
            <origin xyz="0.0995330860695075 0 0" rpy="0 0 0"/>
            <geometry>
                <box size="0.199066172139015 0.5059150223500399 0.6670897978966985" />
            </geometry>
        </collision>
    </link>
    <joint name="1_2" type="revolute">
       <parent link="1"/>
       <child  link="2"/>
       <origin rpy="0 0 0" xyz="0.199066172139015 0 0" />
     <axis xyz="0 1 0"/>
       <limit effort="0.0" lower="-3.14159" upper="3.14159" velocity="0.0"/>
    </joint>
    <link name="2">
        <inertial>
            <origin xyz="0.488858631261731 0 0" rpy="0 0 0"/>
            <mass value="1" />
            <inertia ixx="100" ixy="0" ixz="0" iyy="100" iyz="0" izz="100" />
        </inertial>
        <visual>
            <origin xyz="0.488858631261731 0 0" rpy="0 0 0"/>
            <geometry>
                <box size="0.977717262523462 0.12348470965742286 0.8436371922446059" />
            </geometry>
            <material name="Blue">
                <color rgba="0 0 1.0 1.0"/>
            </material>
        </visual>
        <collision>
            <origin xyz="0.488858631261731 0 0" rpy="0 0 0"/>
            <geometry>
                <box size="0.977717262523462 0.12348470965742286 0.8436371922446059" />
            </geometry>
        </collision>
    </link>
    <joint name="2_3" type="revolute">
       <parent link="2"/>
       <child  link="3"/>
       <origin rpy="0 0 0" xyz="0.977717262523462 0 0" />
     <axis xyz="0 1 0"/>
       <limit effort="0.0" lower="-3.14159" upper="3.14159" velocity="0.0"/>
    </joint>
    <link name="3">
        <inertial>
            <origin xyz="0.2543472436392204 0 0" rpy="0 0 0"/>
            <mass value="1" />
            <inertia ixx="100" ixy="0" ixz="0" iyy="100" iyz="0" izz="100" />
        </inertial>
        <visual>
            <origin xyz="0.2543472436392204 0 0" rpy="0 0 0"/>
            <geometry>
                <box size="0.5086944872784408 0.949440928052879 0.349997569265346" />
            </geometry>
            <material name="Blue">
                <color rgba="0 0 1.0 1.0"/>
            </material>
        </visual>
        <collision>
            <origin xyz="0.2543472436392204 0 0" rpy="0 0 0"/>
            <geometry>
                <box size="0.5086944872784408 0.949440928052879 0.349997569265346" />
            </geometry>
        </collision>
    </link>
    <joint name="3_4" type="revolute">
       <parent link="3"/>
       <child  link="4"/>
       <origin rpy="0 0 0" xyz="0.5086944872784408 0 0" />
     <axis xyz="0 1 0"/>
       <limit effort="0.0" lower="-3.14159" upper="3.14159" velocity="0.0"/>
    </joint>
    <link name="4">
        <inertial>
            <origin xyz="0.31357619690324656 0 0" rpy="0 0 0"/>
            <mass value="1" />
            <inertia ixx="100" ixy="0" ixz="0" iyy="100" iyz="0" izz="100" />
        </inertial>
        <visual>
            <origin xyz="0.31357619690324656 0 0" rpy="0 0 0"/>
            <geometry>
                <box size="0.6271523938064931 0.7002218427065944 0.6171277694448312" />
            </geometry>
            <material name="Green">
                <color rgba="0 1.0 0 1.0"/>
            </material>
        </visual>
        <collision>
            <origin xyz="0.31357619690324656 0 0" rpy="0 0 0"/>
            <geometry>
                <box size="0.6271523938064931 0.7002218427065944 0.6171277694448312" />
            </geometry>
        </collision>
    </link>
</robot>