<robot name = "robot">
    <link name="0">
        <inertial>
            <origin xyz="0 0 3.3806771703239766" rpy="0 0 0"/>
            <mass value="1" />
            <inertia ixx="100" ixy="0" ixz="0" iyy="100" iyz="0" izz="100" />
        </inertial>
        <visual>
            <origin xyz="0 0 3.3806771703239766" rpy="0 0 0"/>
            <geometry>
                <box size="1.086067816427028 0.9921634803573629 0.7613543406479528" />
            </geometry>
            <material name="Blue">
                <color rgba="0 0 1.0 1.0"/>
            </material>
        </visual>
        <collision>
            <origin xyz="0 0 3.3806771703239766" rpy="0 0 0"/>
            <geometry>
                <box size="1.086067816427028 0.9921634803573629 0.7613543406479528" />
            </geometry>
        </collision>
    </link>
    <joint name="0_1" type="revolute">
       <parent link="0"/>
       <child  link="1"/>
       <origin rpy="0 0 0" xyz="-0.543033908213514 0.0 3.3806771703239766" />
     <axis xyz="1 0 0"/>
       <limit effort="0.0" lower="-3.14159" upper="3.14159" velocity="0.0"/>
    </joint>
    <link name="1">
        <inertial>
            <origin xyz="-0.5435992315144611 0.0 0.0" rpy="0 0 0"/>
            <mass value="1" />
            <inertia ixx="100" ixy="0" ixz="0" iyy="100" iyz="0" izz="100" />
        </inertial>
        <visual>
            <origin xyz="-0.5435992315144611 0.0 0.0" rpy="0 0 0"/>
            <geometry>
                <box size="1.0871984630289222 0.5736994034563825 1.0097623206514978" />
            </geometry>
            <material name="Green">
                <color rgba="0 1.0 0 1.0"/>
            </material>
        </visual>
        <collision>
            <origin xyz="-0.5435992315144611 0.0 0.0" rpy="0 0 0"/>
            <geometry>
                <box size="1.0871984630289222 0.5736994034563825 1.0097623206514978" />
            </geometry>
        </collision>
    </link>
    <joint name="1_4" type="revolute">
       <parent link="1"/>
       <child  link="4"/>
       <origin rpy="0 0 0" xyz="-0.5435992315144611 0.0 0.5048811603257489" />
     <axis xyz="0 1 0"/>
       <limit effort="0.0" lower="-3.14159" upper="3.14159" velocity="0.0"/>
    </joint>
    <link name="4">
        <inertial>
            <origin xyz="0.0 0.0 0.4175368306289205" rpy="0 0 0"/>
            <mass value="1" />
            <inertia ixx="100" ixy="0" ixz="0" iyy="100" iyz="0" izz="100" />
        </inertial>
        <visual>
            <origin xyz="0.0 0.0 0.4175368306289205" rpy="0 0 0"/>
            <geometry>
                <box size="0.5526157614904191 0.6531409705634295 0.835073661257841" />
            </geometry>
            <material name="Blue">
                <color rgba="0 0 1.0 1.0"/>
            </material>
        </visual>
        <collision>
            <origin xyz="0.0 0.0 0.4175368306289205" rpy="0 0 0"/>
            <geometry>
                <box size="0.5526157614904191 0.6531409705634295 0.835073661257841" />
            </geometry>
        </collision>
    </link>
    <joint name="1_5" type="revolute">
       <parent link="1"/>
       <child  link="5"/>
       <origin rpy="0 0 0" xyz="-0.5435992315144611 0.28684970172819124 0.0" />
     <axis xyz="1 0 0"/>
       <limit effort="0.0" lower="-3.14159" upper="3.14159" velocity="0.0"/>
    </joint>
    <link name="5">
        <inertial>
            <origin xyz="0.0 0.4055531941047284 0.0" rpy="0 0 0"/>
            <mass value="1" />
            <inertia ixx="100" ixy="0" ixz="0" iyy="100" iyz="0" izz="100" />
        </inertial>
        <visual>
            <origin xyz="0.0 0.4055531941047284 0.0" rpy="0 0 0"/>
            <geometry>
                <box size="0.5680190195426984 0.8111063882094568 0.799990838901882" />
            </geometry>
            <material name="Blue">
                <color rgba="0 0 1.0 1.0"/>
            </material>
        </visual>
        <collision>
            <origin xyz="0.0 0.4055531941047284 0.0" rpy="0 0 0"/>
            <geometry>
                <box size="0.5680190195426984 0.8111063882094568 0.799990838901882" />
            </geometry>
        </collision>
    </link>
    <joint name="5_6" type="revolute">
       <parent link="5"/>
       <child  link="6"/>
       <origin rpy="0 0 0" xyz="-0.2840095097713492 0.4055531941047284 0.0" />
     <axis xyz="0 1 0"/>
       <limit effort="0.0" lower="-3.14159" upper="3.14159" velocity="0.0"/>
    </joint>
    <link name="6">
        <inertial>
            <origin xyz="-0.3562871518041737 0.0 0.0" rpy="0 0 0"/>
            <mass value="1" />
            <inertia ixx="100" ixy="0" ixz="0" iyy="100" iyz="0" izz="100" />
        </inertial>
        <visual>
            <origin xyz="-0.3562871518041737 0.0 0.0" rpy="0 0 0"/>
            <geometry>
                <box size="0.7125743036083474 0.4337251947005195 0.9126247498045169" />
            </geometry>
            <material name="Green">
                <color rgba="0 1.0 0 1.0"/>
            </material>
        </visual>
        <collision>
            <origin xyz="-0.3562871518041737 0.0 0.0" rpy="0 0 0"/>
            <geometry>
                <box size="0.7125743036083474 0.4337251947005195 0.9126247498045169" />
            </geometry>
        </collision>
    </link>
    <joint name="5_2" type="revolute">
       <parent link="5"/>
       <child  link="2"/>
       <origin rpy="0 0 0" xyz="0.0 0.4055531941047284 0.399995419450941" />
     <axis xyz="0 1 0"/>
       <limit effort="0.0" lower="-3.14159" upper="3.14159" velocity="0.0"/>
    </joint>
    <link name="2">
        <inertial>
            <origin xyz="0.0 0.0 0.3072149593595042" rpy="0 0 0"/>
            <mass value="1" />
            <inertia ixx="100" ixy="0" ixz="0" iyy="100" iyz="0" izz="100" />
        </inertial>
        <visual>
            <origin xyz="0.0 0.0 0.3072149593595042" rpy="0 0 0"/>
            <geometry>
                <box size="0.37653328718663825 0.4237810048995604 0.6144299187190084" />
            </geometry>
            <material name="Blue">
                <color rgba="0 0 1.0 1.0"/>
            </material>
        </visual>
        <collision>
            <origin xyz="0.0 0.0 0.3072149593595042" rpy="0 0 0"/>
            <geometry>
                <box size="0.37653328718663825 0.4237810048995604 0.6144299187190084" />
            </geometry>
        </collision>
    </link>
</robot>