<robot name = "robot">
    <link name="0">
        <inertial>
            <origin xyz="0 0 1.4804086716236626" rpy="0 0 0"/>
            <mass value="1" />
            <inertia ixx="100" ixy="0" ixz="0" iyy="100" iyz="0" izz="100" />
        </inertial>
        <visual>
            <origin xyz="0 0 1.4804086716236626" rpy="0 0 0"/>
            <geometry>
                <box size="0.5367997426281297 0.5851819746099385 0.9608173432473253" />
            </geometry>
            <material name="Blue">
                <color rgba="0 0 1.0 1.0"/>
            </material>
        </visual>
        <collision>
            <origin xyz="0 0 1.4804086716236626" rpy="0 0 0"/>
            <geometry>
                <box size="0.5367997426281297 0.5851819746099385 0.9608173432473253" />
            </geometry>
        </collision>
    </link>
    <joint name="0_1" type="revolute">
       <parent link="0"/>
       <child  link="1"/>
       <origin rpy="0 0 0" xyz="0.26839987131406484 0 1.4804086716236626" />
     <axis xyz="0 1 0"/>
       <limit effort="0.0" lower="-3.14159" upper="3.14159" velocity="0.0"/>
    </joint>
    <link name="1">
        <inertial>
            <origin xyz="0.03580691111988393 0 0" rpy="0 0 0"/>
            <mass value="1" />
            <inertia ixx="100" ixy="0" ixz="0" iyy="100" iyz="0" izz="100" />
        </inertial>
        <visual>
            <origin xyz="0.03580691111988393 0 0" rpy="0 0 0"/>
            <geometry>
                <box size="0.07161382223976787 0.00585468318834137 0.48011826698016646" />
            </geometry>
            <material name="Blue">
                <color rgba="0 0 1.0 1.0"/>
            </material>
        </visual>
        <collision>
            <origin xyz="0.03580691111988393 0 0" rpy="0 0 0"/>
            <geometry>
                <box size="0.07161382223976787 0.00585468318834137 0.48011826698016646" />
            </geometry>
        </collision>
    </link>
    <joint name="1_2" type="revolute">
       <parent link="1"/>
       <child  link="2"/>
       <origin rpy="0 0 0" xyz="0.07161382223976787 0 0" />
     <axis xyz="0 1 0"/>
       <limit effort="0.0" lower="-3.14159" upper="3.14159" velocity="0.0"/>
    </joint>
    <link name="2">
        <inertial>
            <origin xyz="0.18717155595759255 0 0" rpy="0 0 0"/>
            <mass value="1" />
            <inertia ixx="100" ixy="0" ixz="0" iyy="100" iyz="0" izz="100" />
        </inertial>
        <visual>
            <origin xyz="0.18717155595759255 0 0" rpy="0 0 0"/>
            <geometry>
                <box size="0.3743431119151851 0.8505187928600575 0.5187108761667947" />
            </geometry>
            <material name="Green">
                <color rgba="0 1.0 0 1.0"/>
            </material>
        </visual>
        <collision>
            <origin xyz="0.18717155595759255 0 0" rpy="0 0 0"/>
            <geometry>
                <box size="0.3743431119151851 0.8505187928600575 0.5187108761667947" />
            </geometry>
        </collision>
    </link>
    <joint name="2_3" type="revolute">
       <parent link="2"/>
       <child  link="3"/>
       <origin rpy="0 0 0" xyz="0.3743431119151851 0 0" />
     <axis xyz="0 1 0"/>
       <limit effort="0.0" lower="-3.14159" upper="3.14159" velocity="0.0"/>
    </joint>
    <link name="3">
        <inertial>
            <origin xyz="0.04512388584731841 0 0" rpy="0 0 0"/>
            <mass value="1" />
            <inertia ixx="100" ixy="0" ixz="0" iyy="100" iyz="0" izz="100" />
        </inertial>
        <visual>
            <origin xyz="0.04512388584731841 0 0" rpy="0 0 0"/>
            <geometry>
                <box size="0.09024777169463682 0.6767363230819874 0.4482552008424595" />
            </geometry>
            <material name="Green">
                <color rgba="0 1.0 0 1.0"/>
            </material>
        </visual>
        <collision>
            <origin xyz="0.04512388584731841 0 0" rpy="0 0 0"/>
            <geometry>
                <box size="0.09024777169463682 0.6767363230819874 0.4482552008424595" />
            </geometry>
        </collision>
    </link>
    <joint name="3_4" type="revolute">
       <parent link="3"/>
       <child  link="4"/>
       <origin rpy="0 0 0" xyz="0.09024777169463682 0 0" />
     <axis xyz="0 1 0"/>
       <limit effort="0.0" lower="-3.14159" upper="3.14159" velocity="0.0"/>
    </joint>
    <link name="4">
        <inertial>
            <origin xyz="0.4911700096935003 0 0" rpy="0 0 0"/>
            <mass value="1" />
            <inertia ixx="100" ixy="0" ixz="0" iyy="100" iyz="0" izz="100" />
        </inertial>
        <visual>
            <origin xyz="0.4911700096935003 0 0" rpy="0 0 0"/>
            <geometry>
                <box size="0.9823400193870006 0.4375947637662092 0.01689721278776668" />
            </geometry>
            <material name="Blue">
                <color rgba="0 0 1.0 1.0"/>
            </material>
        </visual>
        <collision>
            <origin xyz="0.4911700096935003 0 0" rpy="0 0 0"/>
            <geometry>
                <box size="0.9823400193870006 0.4375947637662092 0.01689721278776668" />
            </geometry>
        </collision>
    </link>
    <joint name="4_5" type="revolute">
       <parent link="4"/>
       <child  link="5"/>
       <origin rpy="0 0 0" xyz="0.9823400193870006 0 0" />
     <axis xyz="0 1 0"/>
       <limit effort="0.0" lower="-3.14159" upper="3.14159" velocity="0.0"/>
    </joint>
    <link name="5">
        <inertial>
            <origin xyz="0.02630469026688187 0 0" rpy="0 0 0"/>
            <mass value="1" />
            <inertia ixx="100" ixy="0" ixz="0" iyy="100" iyz="0" izz="100" />
        </inertial>
        <visual>
            <origin xyz="0.02630469026688187 0 0" rpy="0 0 0"/>
            <geometry>
                <box size="0.05260938053376374 0.3835415030019975 0.47266569709337247" />
            </geometry>
            <material name="Blue">
                <color rgba="0 0 1.0 1.0"/>
            </material>
        </visual>
        <collision>
            <origin xyz="0.02630469026688187 0 0" rpy="0 0 0"/>
            <geometry>
                <box size="0.05260938053376374 0.3835415030019975 0.47266569709337247" />
            </geometry>
        </collision>
    </link>
    <joint name="5_6" type="revolute">
       <parent link="5"/>
       <child  link="6"/>
       <origin rpy="0 0 0" xyz="0.05260938053376374 0 0" />
     <axis xyz="0 1 0"/>
       <limit effort="0.0" lower="-3.14159" upper="3.14159" velocity="0.0"/>
    </joint>
    <link name="6">
        <inertial>
            <origin xyz="0.4578121065536904 0 0" rpy="0 0 0"/>
            <mass value="1" />
            <inertia ixx="100" ixy="0" ixz="0" iyy="100" iyz="0" izz="100" />
        </inertial>
        <visual>
            <origin xyz="0.4578121065536904 0 0" rpy="0 0 0"/>
            <geometry>
                <box size="0.9156242131073808 0.036722784966805144 0.9961234125682681" />
            </geometry>
            <material name="Green">
                <color rgba="0 1.0 0 1.0"/>
            </material>
        </visual>
        <collision>
            <origin xyz="0.4578121065536904 0 0" rpy="0 0 0"/>
            <geometry>
                <box size="0.9156242131073808 0.036722784966805144 0.9961234125682681" />
            </geometry>
        </collision>
    </link>
    <joint name="6_7" type="revolute">
       <parent link="6"/>
       <child  link="7"/>
       <origin rpy="0 0 0" xyz="0.9156242131073808 0 0" />
     <axis xyz="0 1 0"/>
       <limit effort="0.0" lower="-3.14159" upper="3.14159" velocity="0.0"/>
    </joint>
    <link name="7">
        <inertial>
            <origin xyz="0.17262041320711052 0 0" rpy="0 0 0"/>
            <mass value="1" />
            <inertia ixx="100" ixy="0" ixz="0" iyy="100" iyz="0" izz="100" />
        </inertial>
        <visual>
            <origin xyz="0.17262041320711052 0 0" rpy="0 0 0"/>
            <geometry>
                <box size="0.34524082641422105 0.703119808382608 0.3898978674347502" />
            </geometry>
            <material name="Green">
                <color rgba="0 1.0 0 1.0"/>
            </material>
        </visual>
        <collision>
            <origin xyz="0.17262041320711052 0 0" rpy="0 0 0"/>
            <geometry>
                <box size="0.34524082641422105 0.703119808382608 0.3898978674347502" />
            </geometry>
        </collision>
    </link>
    <joint name="7_8" type="revolute">
       <parent link="7"/>
       <child  link="8"/>
       <origin rpy="0 0 0" xyz="0.34524082641422105 0 0" />
     <axis xyz="0 1 0"/>
       <limit effort="0.0" lower="-3.14159" upper="3.14159" velocity="0.0"/>
    </joint>
    <link name="8">
        <inertial>
            <origin xyz="0.10646922340291942 0 0" rpy="0 0 0"/>
            <mass value="1" />
            <inertia ixx="100" ixy="0" ixz="0" iyy="100" iyz="0" izz="100" />
        </inertial>
        <visual>
            <origin xyz="0.10646922340291942 0 0" rpy="0 0 0"/>
            <geometry>
                <box size="0.21293844680583884 0.28001571046472873 0.8462888452988548" />
            </geometry>
            <material name="Blue">
                <color rgba="0 0 1.0 1.0"/>
            </material>
        </visual>
        <collision>
            <origin xyz="0.10646922340291942 0 0" rpy="0 0 0"/>
            <geometry>
                <box size="0.21293844680583884 0.28001571046472873 0.8462888452988548" />
            </geometry>
        </collision>
    </link>
</robot>