<robot name = "robot">
    <link name="0">
        <inertial>
            <origin xyz="0 0 3.2761452073044284" rpy="0 0 0"/>
            <mass value="1" />
            <inertia ixx="100" ixy="0" ixz="0" iyy="100" iyz="0" izz="100" />
        </inertial>
        <visual>
            <origin xyz="0 0 3.2761452073044284" rpy="0 0 0"/>
            <geometry>
                <box size="0.6990998250981766 0.5905895167489935 0.5522904146088572" />
            </geometry>
            <material name="Green">
                <color rgba="0 1.0 0 1.0"/>
            </material>
        </visual>
        <collision>
            <origin xyz="0 0 3.2761452073044284" rpy="0 0 0"/>
            <geometry>
                <box size="0.6990998250981766 0.5905895167489935 0.5522904146088572" />
            </geometry>
        </collision>
    </link>
    <joint name="0_1" type="revolute">
       <parent link="0"/>
       <child  link="1"/>
       <origin rpy="0 0 0" xyz="0.0 0.0 3.0" />
     <axis xyz="1 0 0"/>
       <limit effort="0.0" lower="-3.14159" upper="3.14159" velocity="0.0"/>
    </joint>
    <link name="1">
        <inertial>
            <origin xyz="0.0 0.0 -0.24112320881818272" rpy="0 0 0"/>
            <mass value="1" />
            <inertia ixx="100" ixy="0" ixz="0" iyy="100" iyz="0" izz="100" />
        </inertial>
        <visual>
            <origin xyz="0.0 0.0 -0.24112320881818272" rpy="0 0 0"/>
            <geometry>
                <box size="0.8931450382022443 0.5621772656403661 0.48224641763636544" />
            </geometry>
            <material name="Blue">
                <color rgba="0 0 1.0 1.0"/>
            </material>
        </visual>
        <collision>
            <origin xyz="0.0 0.0 -0.24112320881818272" rpy="0 0 0"/>
            <geometry>
                <box size="0.8931450382022443 0.5621772656403661 0.48224641763636544" />
            </geometry>
        </collision>
    </link>
    <joint name="1_2" type="revolute">
       <parent link="1"/>
       <child  link="2"/>
       <origin rpy="0 0 0" xyz="0.0 0.0 -0.48224641763636544" />
     <axis xyz="0 1 0"/>
       <limit effort="0.0" lower="-3.14159" upper="3.14159" velocity="0.0"/>
    </joint>
    <link name="2">
        <inertial>
            <origin xyz="0.0 0.0 -0.3267266893754611" rpy="0 0 0"/>
            <mass value="1" />
            <inertia ixx="100" ixy="0" ixz="0" iyy="100" iyz="0" izz="100" />
        </inertial>
        <visual>
            <origin xyz="0.0 0.0 -0.3267266893754611" rpy="0 0 0"/>
            <geometry>
                <box size="0.5227232402625289 1.0818154592978573 0.6534533787509222" />
            </geometry>
            <material name="Blue">
                <color rgba="0 0 1.0 1.0"/>
            </material>
        </visual>
        <collision>
            <origin xyz="0.0 0.0 -0.3267266893754611" rpy="0 0 0"/>
            <geometry>
                <box size="0.5227232402625289 1.0818154592978573 0.6534533787509222" />
            </geometry>
        </collision>
    </link>
    <joint name="2_3" type="revolute">
       <parent link="2"/>
       <child  link="3"/>
       <origin rpy="0 0 0" xyz="-0.26136162013126446 0.0 -0.3267266893754611" />
     <axis xyz="0 1 0"/>
       <limit effort="0.0" lower="-3.14159" upper="3.14159" velocity="0.0"/>
    </joint>
    <link name="3">
        <inertial>
            <origin xyz="-0.38778813752750146 0.0 0.0" rpy="0 0 0"/>
            <mass value="1" />
            <inertia ixx="100" ixy="0" ixz="0" iyy="100" iyz="0" izz="100" />
        </inertial>
        <visual>
            <origin xyz="-0.38778813752750146 0.0 0.0" rpy="0 0 0"/>
            <geometry>
                <box size="0.7755762750550029 0.4076172734522081 0.5606631567169054" />
            </geometry>
            <material name="Blue">
                <color rgba="0 0 1.0 1.0"/>
            </material>
        </visual>
        <collision>
            <origin xyz="-0.38778813752750146 0.0 0.0" rpy="0 0 0"/>
            <geometry>
                <box size="0.7755762750550029 0.4076172734522081 0.5606631567169054" />
            </geometry>
        </collision>
    </link>
    <joint name="1_4" type="revolute">
       <parent link="1"/>
       <child  link="4"/>
       <origin rpy="0 0 0" xyz="-0.44657251910112217 0.0 -0.24112320881818272" />
     <axis xyz="1 0 0"/>
       <limit effort="0.0" lower="-3.14159" upper="3.14159" velocity="0.0"/>
    </joint>
    <link name="4">
        <inertial>
            <origin xyz="-0.3282680389701562 0.0 0.0" rpy="0 0 0"/>
            <mass value="1" />
            <inertia ixx="100" ixy="0" ixz="0" iyy="100" iyz="0" izz="100" />
        </inertial>
        <visual>
            <origin xyz="-0.3282680389701562 0.0 0.0" rpy="0 0 0"/>
            <geometry>
                <box size="0.6565360779403124 0.5210957463718944 0.42210407854187953" />
            </geometry>
            <material name="Green">
                <color rgba="0 1.0 0 1.0"/>
            </material>
        </visual>
        <collision>
            <origin xyz="-0.3282680389701562 0.0 0.0" rpy="0 0 0"/>
            <geometry>
                <box size="0.6565360779403124 0.5210957463718944 0.42210407854187953" />
            </geometry>
        </collision>
    </link>
    <joint name="1_5" type="revolute">
       <parent link="1"/>
       <child  link="5"/>
       <origin rpy="0 0 0" xyz="0.0 0.28108863282018304 -0.24112320881818272" />
     <axis xyz="1 0 0"/>
       <limit effort="0.0" lower="-3.14159" upper="3.14159" velocity="0.0"/>
    </joint>
    <link name="5">
        <inertial>
            <origin xyz="0.0 0.43789558088984604 0.0" rpy="0 0 0"/>
            <mass value="1" />
            <inertia ixx="100" ixy="0" ixz="0" iyy="100" iyz="0" izz="100" />
        </inertial>
        <visual>
            <origin xyz="0.0 0.43789558088984604 0.0" rpy="0 0 0"/>
            <geometry>
                <box size="1.0007612869075135 0.8757911617796921 0.4731483550165342" />
            </geometry>
            <material name="Blue">
                <color rgba="0 0 1.0 1.0"/>
            </material>
        </visual>
        <collision>
            <origin xyz="0.0 0.43789558088984604 0.0" rpy="0 0 0"/>
            <geometry>
                <box size="1.0007612869075135 0.8757911617796921 0.4731483550165342" />
            </geometry>
        </collision>
    </link>
    <joint name="5_6" type="revolute">
       <parent link="5"/>
       <child  link="6"/>
       <origin rpy="0 0 0" xyz="0.0 0.8757911617796921 0.0" />
     <axis xyz="0 1 0"/>
       <limit effort="0.0" lower="-3.14159" upper="3.14159" velocity="0.0"/>
    </joint>
    <link name="6">
        <inertial>
            <origin xyz="0.0 0.2701131206698691 0.0" rpy="0 0 0"/>
            <mass value="1" />
            <inertia ixx="100" ixy="0" ixz="0" iyy="100" iyz="0" izz="100" />
        </inertial>
        <visual>
            <origin xyz="0.0 0.2701131206698691 0.0" rpy="0 0 0"/>
            <geometry>
                <box size="0.6309074693656891 0.5402262413397382 0.7971430491867901" />
            </geometry>
            <material name="Green">
                <color rgba="0 1.0 0 1.0"/>
            </material>
        </visual>
        <collision>
            <origin xyz="0.0 0.2701131206698691 0.0" rpy="0 0 0"/>
            <geometry>
                <box size="0.6309074693656891 0.5402262413397382 0.7971430491867901" />
            </geometry>
        </collision>
    </link>
    <joint name="6_7" type="revolute">
       <parent link="6"/>
       <child  link="7"/>
       <origin rpy="0 0 0" xyz="0.0 0.5402262413397382 0.0" />
     <axis xyz="0 1 0"/>
       <limit effort="0.0" lower="-3.14159" upper="3.14159" velocity="0.0"/>
    </joint>
    <link name="7">
        <inertial>
            <origin xyz="0.0 0.23820140734177328 0.0" rpy="0 0 0"/>
            <mass value="1" />
            <inertia ixx="100" ixy="0" ixz="0" iyy="100" iyz="0" izz="100" />
        </inertial>
        <visual>
            <origin xyz="0.0 0.23820140734177328 0.0" rpy="0 0 0"/>
            <geometry>
                <box size="0.5304025904042957 0.47640281468354656 0.6038971066828922" />
            </geometry>
            <material name="Blue">
                <color rgba="0 0 1.0 1.0"/>
            </material>
        </visual>
        <collision>
            <origin xyz="0.0 0.23820140734177328 0.0" rpy="0 0 0"/>
            <geometry>
                <box size="0.5304025904042957 0.47640281468354656 0.6038971066828922" />
            </geometry>
        </collision>
    </link>
    <joint name="6_8" type="revolute">
       <parent link="6"/>
       <child  link="8"/>
       <origin rpy="0 0 0" xyz="0.0 0.2701131206698691 -0.39857152459339507" />
     <axis xyz="1 0 0"/>
       <limit effort="0.0" lower="-3.14159" upper="3.14159" velocity="0.0"/>
    </joint>
    <link name="8">
        <inertial>
            <origin xyz="0.0 0.0 -0.2784491758063462" rpy="0 0 0"/>
            <mass value="1" />
            <inertia ixx="100" ixy="0" ixz="0" iyy="100" iyz="0" izz="100" />
        </inertial>
        <visual>
            <origin xyz="0.0 0.0 -0.2784491758063462" rpy="0 0 0"/>
            <geometry>
                <box size="1.0344259498982025 0.9824502492366881 0.5568983516126924" />
            </geometry>
            <material name="Green">
                <color rgba="0 1.0 0 1.0"/>
            </material>
        </visual>
        <collision>
            <origin xyz="0.0 0.0 -0.2784491758063462" rpy="0 0 0"/>
            <geometry>
                <box size="1.0344259498982025 0.9824502492366881 0.5568983516126924" />
            </geometry>
        </collision>
    </link>
    <joint name="8_9" type="revolute">
       <parent link="8"/>
       <child  link="9"/>
       <origin rpy="0 0 0" xyz="-0.5172129749491012 0.0 -0.2784491758063462" />
     <axis xyz="1 0 0"/>
       <limit effort="0.0" lower="-3.14159" upper="3.14159" velocity="0.0"/>
    </joint>
    <link name="9">
        <inertial>
            <origin xyz="-0.3573066116932788 0.0 0.0" rpy="0 0 0"/>
            <mass value="1" />
            <inertia ixx="100" ixy="0" ixz="0" iyy="100" iyz="0" izz="100" />
        </inertial>
        <visual>
            <origin xyz="-0.3573066116932788 0.0 0.0" rpy="0 0 0"/>
            <geometry>
                <box size="0.7146132233865576 1.0163249901918354 0.8652088885597546" />
            </geometry>
            <material name="Green">
                <color rgba="0 1.0 0 1.0"/>
            </material>
        </visual>
        <collision>
            <origin xyz="-0.3573066116932788 0.0 0.0" rpy="0 0 0"/>
            <geometry>
                <box size="0.7146132233865576 1.0163249901918354 0.8652088885597546" />
            </geometry>
        </collision>
    </link>
    <joint name="5_10" type="revolute">
       <parent link="5"/>
       <child  link="10"/>
       <origin rpy="0 0 0" xyz="-0.5003806434537568 0.43789558088984604 0.0" />
     <axis xyz="0 1 0"/>
       <limit effort="0.0" lower="-3.14159" upper="3.14159" velocity="0.0"/>
    </joint>
    <link name="10">
        <inertial>
            <origin xyz="-0.29779020050077554 0.0 0.0" rpy="0 0 0"/>
            <mass value="1" />
            <inertia ixx="100" ixy="0" ixz="0" iyy="100" iyz="0" izz="100" />
        </inertial>
        <visual>
            <origin xyz="-0.29779020050077554 0.0 0.0" rpy="0 0 0"/>
            <geometry>
                <box size="0.5955804010015511 0.6098850371026088 0.4378174197534497" />
            </geometry>
            <material name="Blue">
                <color rgba="0 0 1.0 1.0"/>
            </material>
        </visual>
        <collision>
            <origin xyz="-0.29779020050077554 0.0 0.0" rpy="0 0 0"/>
            <geometry>
                <box size="0.5955804010015511 0.6098850371026088 0.4378174197534497" />
            </geometry>
        </collision>
    </link>
</robot>