<robot name = "robot">
    <link name="0">
        <inertial>
            <origin xyz="0 0 3.242358176304872" rpy="0 0 0"/>
            <mass value="1" />
            <inertia ixx="100" ixy="0" ixz="0" iyy="100" iyz="0" izz="100" />
        </inertial>
        <visual>
            <origin xyz="0 0 3.242358176304872" rpy="0 0 0"/>
            <geometry>
                <box size="0.7239717740684257 0.7272435038378634 0.48471635260974344" />
            </geometry>
            <material name="Green">
                <color rgba="0 1.0 0 1.0"/>
            </material>
        </visual>
        <collision>
            <origin xyz="0 0 3.242358176304872" rpy="0 0 0"/>
            <geometry>
                <box size="0.7239717740684257 0.7272435038378634 0.48471635260974344" />
            </geometry>
        </collision>
    </link>
    <joint name="0_1" type="revolute">
       <parent link="0"/>
       <child  link="1"/>
       <origin rpy="0 0 0" xyz="0.0 -0.3636217519189317 3.242358176304872" />
     <axis xyz="0 1 0"/>
       <limit effort="0.0" lower="-3.14159" upper="3.14159" velocity="0.0"/>
    </joint>
    <link name="1">
        <inertial>
            <origin xyz="0.0 -0.48431746068175185 0.0" rpy="0 0 0"/>
            <mass value="1" />
            <inertia ixx="100" ixy="0" ixz="0" iyy="100" iyz="0" izz="100" />
        </inertial>
        <visual>
            <origin xyz="0.0 -0.48431746068175185 0.0" rpy="0 0 0"/>
            <geometry>
                <box size="0.5036082248151748 0.9686349213635037 0.9834352825897347" />
            </geometry>
            <material name="Green">
                <color rgba="0 1.0 0 1.0"/>
            </material>
        </visual>
        <collision>
            <origin xyz="0.0 -0.48431746068175185 0.0" rpy="0 0 0"/>
            <geometry>
                <box size="0.5036082248151748 0.9686349213635037 0.9834352825897347" />
            </geometry>
        </collision>
    </link>
    <joint name="1_2" type="revolute">
       <parent link="1"/>
       <child  link="2"/>
       <origin rpy="0 0 0" xyz="-0.2518041124075874 -0.48431746068175185 0.0" />
     <axis xyz="1 0 0"/>
       <limit effort="0.0" lower="-3.14159" upper="3.14159" velocity="0.0"/>
    </joint>
    <link name="2">
        <inertial>
            <origin xyz="-0.33074210771150375 0.0 0.0" rpy="0 0 0"/>
            <mass value="1" />
            <inertia ixx="100" ixy="0" ixz="0" iyy="100" iyz="0" izz="100" />
        </inertial>
        <visual>
            <origin xyz="-0.33074210771150375 0.0 0.0" rpy="0 0 0"/>
            <geometry>
                <box size="0.6614842154230075 0.6064400240259858 1.0489282130673612" />
            </geometry>
            <material name="Green">
                <color rgba="0 1.0 0 1.0"/>
            </material>
        </visual>
        <collision>
            <origin xyz="-0.33074210771150375 0.0 0.0" rpy="0 0 0"/>
            <geometry>
                <box size="0.6614842154230075 0.6064400240259858 1.0489282130673612" />
            </geometry>
        </collision>
    </link>
    <joint name="1_3" type="revolute">
       <parent link="1"/>
       <child  link="3"/>
       <origin rpy="0 0 0" xyz="0.0 -0.9686349213635037 0.0" />
     <axis xyz="1 0 0"/>
       <limit effort="0.0" lower="-3.14159" upper="3.14159" velocity="0.0"/>
    </joint>
    <link name="3">
        <inertial>
            <origin xyz="0.0 -0.24343583959645754 0.0" rpy="0 0 0"/>
            <mass value="1" />
            <inertia ixx="100" ixy="0" ixz="0" iyy="100" iyz="0" izz="100" />
        </inertial>
        <visual>
            <origin xyz="0.0 -0.24343583959645754 0.0" rpy="0 0 0"/>
            <geometry>
                <box size="0.8011578945263259 0.4868716791929151 0.7340238519899318" />
            </geometry>
            <material name="Green">
                <color rgba="0 1.0 0 1.0"/>
            </material>
        </visual>
        <collision>
            <origin xyz="0.0 -0.24343583959645754 0.0" rpy="0 0 0"/>
            <geometry>
                <box size="0.8011578945263259 0.4868716791929151 0.7340238519899318" />
            </geometry>
        </collision>
    </link>
    <joint name="3_4" type="revolute">
       <parent link="3"/>
       <child  link="4"/>
       <origin rpy="0 0 0" xyz="0.0 -0.24343583959645754 0.3670119259949659" />
     <axis xyz="0 1 0"/>
       <limit effort="0.0" lower="-3.14159" upper="3.14159" velocity="0.0"/>
    </joint>
    <link name="4">
        <inertial>
            <origin xyz="0.0 0.0 0.46058397496384623" rpy="0 0 0"/>
            <mass value="1" />
            <inertia ixx="100" ixy="0" ixz="0" iyy="100" iyz="0" izz="100" />
        </inertial>
        <visual>
            <origin xyz="0.0 0.0 0.46058397496384623" rpy="0 0 0"/>
            <geometry>
                <box size="0.5024268328580643 0.398360038327304 0.9211679499276925" />
            </geometry>
            <material name="Green">
                <color rgba="0 1.0 0 1.0"/>
            </material>
        </visual>
        <collision>
            <origin xyz="0.0 0.0 0.46058397496384623" rpy="0 0 0"/>
            <geometry>
                <box size="0.5024268328580643 0.398360038327304 0.9211679499276925" />
            </geometry>
        </collision>
    </link>
    <joint name="4_5" type="revolute">
       <parent link="4"/>
       <child  link="5"/>
       <origin rpy="0 0 0" xyz="0.0 0.199180019163652 0.46058397496384623" />
     <axis xyz="1 0 0"/>
       <limit effort="0.0" lower="-3.14159" upper="3.14159" velocity="0.0"/>
    </joint>
    <link name="5">
        <inertial>
            <origin xyz="0.0 0.5086152102628714 0.0" rpy="0 0 0"/>
            <mass value="1" />
            <inertia ixx="100" ixy="0" ixz="0" iyy="100" iyz="0" izz="100" />
        </inertial>
        <visual>
            <origin xyz="0.0 0.5086152102628714 0.0" rpy="0 0 0"/>
            <geometry>
                <box size="0.5846811941811917 1.0172304205257428 0.50868540061244" />
            </geometry>
            <material name="Green">
                <color rgba="0 1.0 0 1.0"/>
            </material>
        </visual>
        <collision>
            <origin xyz="0.0 0.5086152102628714 0.0" rpy="0 0 0"/>
            <geometry>
                <box size="0.5846811941811917 1.0172304205257428 0.50868540061244" />
            </geometry>
        </collision>
    </link>
</robot>