<robot name = "robot">
    <link name="0">
        <inertial>
            <origin xyz="0 0 3.3778565575019854" rpy="0 0 0"/>
            <mass value="1" />
            <inertia ixx="100" ixy="0" ixz="0" iyy="100" iyz="0" izz="100" />
        </inertial>
        <visual>
            <origin xyz="0 0 3.3778565575019854" rpy="0 0 0"/>
            <geometry>
                <box size="0.6940254689290398 0.7084306985728183 0.7557131150039711" />
            </geometry>
            <material name="Green">
                <color rgba="0 1.0 0 1.0"/>
            </material>
        </visual>
        <collision>
            <origin xyz="0 0 3.3778565575019854" rpy="0 0 0"/>
            <geometry>
                <box size="0.6940254689290398 0.7084306985728183 0.7557131150039711" />
            </geometry>
        </collision>
    </link>
    <joint name="0_1" type="revolute">
       <parent link="0"/>
       <child  link="1"/>
       <origin rpy="0 0 0" xyz="0.3470127344645199 0.0 3.3778565575019854" />
     <axis xyz="1 0 0"/>
       <limit effort="0.0" lower="-3.14159" upper="3.14159" velocity="0.0"/>
    </joint>
    <link name="1">
        <inertial>
            <origin xyz="0.35633519235651495 0.0 0.0" rpy="0 0 0"/>
            <mass value="1" />
            <inertia ixx="100" ixy="0" ixz="0" iyy="100" iyz="0" izz="100" />
        </inertial>
        <visual>
            <origin xyz="0.35633519235651495 0.0 0.0" rpy="0 0 0"/>
            <geometry>
                <box size="0.7126703847130299 0.9059783779641906 0.9581909312291502" />
            </geometry>
            <material name="Green">
                <color rgba="0 1.0 0 1.0"/>
            </material>
        </visual>
        <collision>
            <origin xyz="0.35633519235651495 0.0 0.0" rpy="0 0 0"/>
            <geometry>
                <box size="0.7126703847130299 0.9059783779641906 0.9581909312291502" />
            </geometry>
        </collision>
    </link>
    <joint name="1_2" type="revolute">
       <parent link="1"/>
       <child  link="2"/>
       <origin rpy="0 0 0" xyz="0.35633519235651495 0.4529891889820953 0.0" />
     <axis xyz="0 1 0"/>
       <limit effort="0.0" lower="-3.14159" upper="3.14159" velocity="0.0"/>
    </joint>
    <link name="2">
        <inertial>
            <origin xyz="0.0 0.5091898194148177 0.0" rpy="0 0 0"/>
            <mass value="1" />
            <inertia ixx="100" ixy="0" ixz="0" iyy="100" iyz="0" izz="100" />
        </inertial>
        <visual>
            <origin xyz="0.0 0.5091898194148177 0.0" rpy="0 0 0"/>
            <geometry>
                <box size="0.9362804995057772 1.0183796388296353 0.6858450413496836" />
            </geometry>
            <material name="Green">
                <color rgba="0 1.0 0 1.0"/>
            </material>
        </visual>
        <collision>
            <origin xyz="0.0 0.5091898194148177 0.0" rpy="0 0 0"/>
            <geometry>
                <box size="0.9362804995057772 1.0183796388296353 0.6858450413496836" />
            </geometry>
        </collision>
    </link>
    <joint name="2_3" type="revolute">
       <parent link="2"/>
       <child  link="3"/>
       <origin rpy="0 0 0" xyz="0.4681402497528886 0.5091898194148177 0.0" />
     <axis xyz="0 1 0"/>
       <limit effort="0.0" lower="-3.14159" upper="3.14159" velocity="0.0"/>
    </joint>
    <link name="3">
        <inertial>
            <origin xyz="0.3898866766192148 0.0 0.0" rpy="0 0 0"/>
            <mass value="1" />
            <inertia ixx="100" ixy="0" ixz="0" iyy="100" iyz="0" izz="100" />
        </inertial>
        <visual>
            <origin xyz="0.3898866766192148 0.0 0.0" rpy="0 0 0"/>
            <geometry>
                <box size="0.7797733532384296 0.6406293157225538 1.0064982638690179" />
            </geometry>
            <material name="Blue">
                <color rgba="0 0 1.0 1.0"/>
            </material>
        </visual>
        <collision>
            <origin xyz="0.3898866766192148 0.0 0.0" rpy="0 0 0"/>
            <geometry>
                <box size="0.7797733532384296 0.6406293157225538 1.0064982638690179" />
            </geometry>
        </collision>
    </link>
    <joint name="3_4" type="revolute">
       <parent link="3"/>
       <child  link="4"/>
       <origin rpy="0 0 0" xyz="0.3898866766192148 0.0 -0.5032491319345089" />
     <axis xyz="1 0 0"/>
       <limit effort="0.0" lower="-3.14159" upper="3.14159" velocity="0.0"/>
    </joint>
    <link name="4">
        <inertial>
            <origin xyz="0.0 0.0 -0.45084909030739684" rpy="0 0 0"/>
            <mass value="1" />
            <inertia ixx="100" ixy="0" ixz="0" iyy="100" iyz="0" izz="100" />
        </inertial>
        <visual>
            <origin xyz="0.0 0.0 -0.45084909030739684" rpy="0 0 0"/>
            <geometry>
                <box size="0.8027056573130393 1.0625359589684118 0.9016981806147937" />
            </geometry>
            <material name="Green">
                <color rgba="0 1.0 0 1.0"/>
            </material>
        </visual>
        <collision>
            <origin xyz="0.0 0.0 -0.45084909030739684" rpy="0 0 0"/>
            <geometry>
                <box size="0.8027056573130393 1.0625359589684118 0.9016981806147937" />
            </geometry>
        </collision>
    </link>
    <joint name="3_5" type="revolute">
       <parent link="3"/>
       <child  link="5"/>
       <origin rpy="0 0 0" xyz="0.3898866766192148 -0.3203146578612769 0.0" />
     <axis xyz="1 0 0"/>
       <limit effort="0.0" lower="-3.14159" upper="3.14159" velocity="0.0"/>
    </joint>
    <link name="5">
        <inertial>
            <origin xyz="0.0 -0.3896934815027617 0.0" rpy="0 0 0"/>
            <mass value="1" />
            <inertia ixx="100" ixy="0" ixz="0" iyy="100" iyz="0" izz="100" />
        </inertial>
        <visual>
            <origin xyz="0.0 -0.3896934815027617 0.0" rpy="0 0 0"/>
            <geometry>
                <box size="0.6345736136476106 0.7793869630055233 0.6984104291214691" />
            </geometry>
            <material name="Green">
                <color rgba="0 1.0 0 1.0"/>
            </material>
        </visual>
        <collision>
            <origin xyz="0.0 -0.3896934815027617 0.0" rpy="0 0 0"/>
            <geometry>
                <box size="0.6345736136476106 0.7793869630055233 0.6984104291214691" />
            </geometry>
        </collision>
    </link>
    <joint name="3_8" type="revolute">
       <parent link="3"/>
       <child  link="8"/>
       <origin rpy="0 0 0" xyz="0.7797733532384296 0.0 0.0" />
     <axis xyz="1 0 0"/>
       <limit effort="0.0" lower="-3.14159" upper="3.14159" velocity="0.0"/>
    </joint>
    <link name="8">
        <inertial>
            <origin xyz="0.3190213258426957 0.0 0.0" rpy="0 0 0"/>
            <mass value="1" />
            <inertia ixx="100" ixy="0" ixz="0" iyy="100" iyz="0" izz="100" />
        </inertial>
        <visual>
            <origin xyz="0.3190213258426957 0.0 0.0" rpy="0 0 0"/>
            <geometry>
                <box size="0.6380426516853914 0.6474709800012357 0.6272197293862042" />
            </geometry>
            <material name="Green">
                <color rgba="0 1.0 0 1.0"/>
            </material>
        </visual>
        <collision>
            <origin xyz="0.3190213258426957 0.0 0.0" rpy="0 0 0"/>
            <geometry>
                <box size="0.6380426516853914 0.6474709800012357 0.6272197293862042" />
            </geometry>
        </collision>
    </link>
    <joint name="8_6" type="revolute">
       <parent link="8"/>
       <child  link="6"/>
       <origin rpy="0 0 0" xyz="0.6380426516853914 0.0 0.0" />
     <axis xyz="0 1 0"/>
       <limit effort="0.0" lower="-3.14159" upper="3.14159" velocity="0.0"/>
    </joint>
    <link name="6">
        <inertial>
            <origin xyz="0.5273639281719299 0.0 0.0" rpy="0 0 0"/>
            <mass value="1" />
            <inertia ixx="100" ixy="0" ixz="0" iyy="100" iyz="0" izz="100" />
        </inertial>
        <visual>
            <origin xyz="0.5273639281719299 0.0 0.0" rpy="0 0 0"/>
            <geometry>
                <box size="1.0547278563438598 0.9805387013461769 0.6993761847596922" />
            </geometry>
            <material name="Green">
                <color rgba="0 1.0 0 1.0"/>
            </material>
        </visual>
        <collision>
            <origin xyz="0.5273639281719299 0.0 0.0" rpy="0 0 0"/>
            <geometry>
                <box size="1.0547278563438598 0.9805387013461769 0.6993761847596922" />
            </geometry>
        </collision>
    </link>
    <joint name="3_7" type="revolute">
       <parent link="3"/>
       <child  link="7"/>
       <origin rpy="0 0 0" xyz="0.3898866766192148 0.3203146578612769 0.0" />
     <axis xyz="1 0 0"/>
       <limit effort="0.0" lower="-3.14159" upper="3.14159" velocity="0.0"/>
    </joint>
    <link name="7">
        <inertial>
            <origin xyz="0.0 0.40177670495868756 0.0" rpy="0 0 0"/>
            <mass value="1" />
            <inertia ixx="100" ixy="0" ixz="0" iyy="100" iyz="0" izz="100" />
        </inertial>
        <visual>
            <origin xyz="0.0 0.40177670495868756 0.0" rpy="0 0 0"/>
            <geometry>
                <box size="0.6321149557511341 0.8035534099173751 0.6349836362426984" />
            </geometry>
            <material name="Blue">
                <color rgba="0 0 1.0 1.0"/>
            </material>
        </visual>
        <collision>
            <origin xyz="0.0 0.40177670495868756 0.0" rpy="0 0 0"/>
            <geometry>
                <box size="0.6321149557511341 0.8035534099173751 0.6349836362426984" />
            </geometry>
        </collision>
    </link>
    <joint name="0_9" type="revolute">
       <parent link="0"/>
       <child  link="9"/>
       <origin rpy="0 0 0" xyz="0.0 0.0 3.755713115003971" />
     <axis xyz="1 0 0"/>
       <limit effort="0.0" lower="-3.14159" upper="3.14159" velocity="0.0"/>
    </joint>
    <link name="9">
        <inertial>
            <origin xyz="0.0 0.0 0.5158715577617058" rpy="0 0 0"/>
            <mass value="1" />
            <inertia ixx="100" ixy="0" ixz="0" iyy="100" iyz="0" izz="100" />
        </inertial>
        <visual>
            <origin xyz="0.0 0.0 0.5158715577617058" rpy="0 0 0"/>
            <geometry>
                <box size="0.46271702642140394 0.5622664676812573 1.0317431155234116" />
            </geometry>
            <material name="Green">
                <color rgba="0 1.0 0 1.0"/>
            </material>
        </visual>
        <collision>
            <origin xyz="0.0 0.0 0.5158715577617058" rpy="0 0 0"/>
            <geometry>
                <box size="0.46271702642140394 0.5622664676812573 1.0317431155234116" />
            </geometry>
        </collision>
    </link>
</robot>