<robot name = "robot">
    <link name="0">
        <inertial>
            <origin xyz="0 0 3.3371933314903233" rpy="0 0 0"/>
            <mass value="1" />
            <inertia ixx="100" ixy="0" ixz="0" iyy="100" iyz="0" izz="100" />
        </inertial>
        <visual>
            <origin xyz="0 0 3.3371933314903233" rpy="0 0 0"/>
            <geometry>
                <box size="0.5038537462701665 0.7347031756708593 0.674386662980647" />
            </geometry>
            <material name="Blue">
                <color rgba="0 0 1.0 1.0"/>
            </material>
        </visual>
        <collision>
            <origin xyz="0 0 3.3371933314903233" rpy="0 0 0"/>
            <geometry>
                <box size="0.5038537462701665 0.7347031756708593 0.674386662980647" />
            </geometry>
        </collision>
    </link>
    <joint name="0_1" type="revolute">
       <parent link="0"/>
       <child  link="1"/>
       <origin rpy="0 0 0" xyz="-0.2519268731350833 0.0 3.3371933314903233" />
     <axis xyz="0 1 0"/>
       <limit effort="0.0" lower="-3.14159" upper="3.14159" velocity="0.0"/>
    </joint>
    <link name="1">
        <inertial>
            <origin xyz="-0.35782876588663703 0.0 0.0" rpy="0 0 0"/>
            <mass value="1" />
            <inertia ixx="100" ixy="0" ixz="0" iyy="100" iyz="0" izz="100" />
        </inertial>
        <visual>
            <origin xyz="-0.35782876588663703 0.0 0.0" rpy="0 0 0"/>
            <geometry>
                <box size="0.7156575317732741 0.6444022169695887 0.6424147905851849" />
            </geometry>
            <material name="Green">
                <color rgba="0 1.0 0 1.0"/>
            </material>
        </visual>
        <collision>
            <origin xyz="-0.35782876588663703 0.0 0.0" rpy="0 0 0"/>
            <geometry>
                <box size="0.7156575317732741 0.6444022169695887 0.6424147905851849" />
            </geometry>
        </collision>
    </link>
    <joint name="0_5" type="revolute">
       <parent link="0"/>
       <child  link="5"/>
       <origin rpy="0 0 0" xyz="0.2519268731350833 0.0 3.3371933314903233" />
     <axis xyz="0 1 0"/>
       <limit effort="0.0" lower="-3.14159" upper="3.14159" velocity="0.0"/>
    </joint>
    <link name="5">
        <inertial>
            <origin xyz="0.33096183597123285 0.0 0.0" rpy="0 0 0"/>
            <mass value="1" />
            <inertia ixx="100" ixy="0" ixz="0" iyy="100" iyz="0" izz="100" />
        </inertial>
        <visual>
            <origin xyz="0.33096183597123285 0.0 0.0" rpy="0 0 0"/>
            <geometry>
                <box size="0.6619236719424657 0.8925792852484893 0.7689301324572035" />
            </geometry>
            <material name="Blue">
                <color rgba="0 0 1.0 1.0"/>
            </material>
        </visual>
        <collision>
            <origin xyz="0.33096183597123285 0.0 0.0" rpy="0 0 0"/>
            <geometry>
                <box size="0.6619236719424657 0.8925792852484893 0.7689301324572035" />
            </geometry>
        </collision>
    </link>
    <joint name="0_2" type="revolute">
       <parent link="0"/>
       <child  link="2"/>
       <origin rpy="0 0 0" xyz="0.0 0.36735158783542965 3.3371933314903233" />
     <axis xyz="1 0 0"/>
       <limit effort="0.0" lower="-3.14159" upper="3.14159" velocity="0.0"/>
    </joint>
    <link name="2">
        <inertial>
            <origin xyz="0.0 0.30823818945598325 0.0" rpy="0 0 0"/>
            <mass value="1" />
            <inertia ixx="100" ixy="0" ixz="0" iyy="100" iyz="0" izz="100" />
        </inertial>
        <visual>
            <origin xyz="0.0 0.30823818945598325 0.0" rpy="0 0 0"/>
            <geometry>
                <box size="0.4373496547461867 0.6164763789119665 0.4390019494525692" />
            </geometry>
            <material name="Blue">
                <color rgba="0 0 1.0 1.0"/>
            </material>
        </visual>
        <collision>
            <origin xyz="0.0 0.30823818945598325 0.0" rpy="0 0 0"/>
            <geometry>
                <box size="0.4373496547461867 0.6164763789119665 0.4390019494525692" />
            </geometry>
        </collision>
    </link>
    <joint name="5_3" type="revolute">
       <parent link="5"/>
       <child  link="3"/>
       <origin rpy="0 0 0" xyz="0.33096183597123285 -0.44628964262424464 0.0" />
     <axis xyz="0 1 0"/>
       <limit effort="0.0" lower="-3.14159" upper="3.14159" velocity="0.0"/>
    </joint>
    <link name="3">
        <inertial>
            <origin xyz="0.0 -0.453980312713662 0.0" rpy="0 0 0"/>
            <mass value="1" />
            <inertia ixx="100" ixy="0" ixz="0" iyy="100" iyz="0" izz="100" />
        </inertial>
        <visual>
            <origin xyz="0.0 -0.453980312713662 0.0" rpy="0 0 0"/>
            <geometry>
                <box size="1.0298502199797133 0.907960625427324 0.4607581496501688" />
            </geometry>
            <material name="Blue">
                <color rgba="0 0 1.0 1.0"/>
            </material>
        </visual>
        <collision>
            <origin xyz="0.0 -0.453980312713662 0.0" rpy="0 0 0"/>
            <geometry>
                <box size="1.0298502199797133 0.907960625427324 0.4607581496501688" />
            </geometry>
        </collision>
    </link>
    <joint name="5_4" type="revolute">
       <parent link="5"/>
       <child  link="4"/>
       <origin rpy="0 0 0" xyz="0.33096183597123285 0.0 -0.38446506622860177" />
     <axis xyz="0 1 0"/>
       <limit effort="0.0" lower="-3.14159" upper="3.14159" velocity="0.0"/>
    </joint>
    <link name="4">
        <inertial>
            <origin xyz="0.0 0.0 -0.4256123189450711" rpy="0 0 0"/>
            <mass value="1" />
            <inertia ixx="100" ixy="0" ixz="0" iyy="100" iyz="0" izz="100" />
        </inertial>
        <visual>
            <origin xyz="0.0 0.0 -0.4256123189450711" rpy="0 0 0"/>
            <geometry>
                <box size="0.5926256221034918 0.5229972958325815 0.8512246378901422" />
            </geometry>
            <material name="Blue">
                <color rgba="0 0 1.0 1.0"/>
            </material>
        </visual>
        <collision>
            <origin xyz="0.0 0.0 -0.4256123189450711" rpy="0 0 0"/>
            <geometry>
                <box size="0.5926256221034918 0.5229972958325815 0.8512246378901422" />
            </geometry>
        </collision>
    </link>
    <joint name="1_6" type="revolute">
       <parent link="1"/>
       <child  link="6"/>
       <origin rpy="0 0 0" xyz="-0.35782876588663703 0.0 -0.32120739529259246" />
     <axis xyz="0 1 0"/>
       <limit effort="0.0" lower="-3.14159" upper="3.14159" velocity="0.0"/>
    </joint>
    <link name="6">
        <inertial>
            <origin xyz="0.0 0.0 -0.19190331962151264" rpy="0 0 0"/>
            <mass value="1" />
            <inertia ixx="100" ixy="0" ixz="0" iyy="100" iyz="0" izz="100" />
        </inertial>
        <visual>
            <origin xyz="0.0 0.0 -0.19190331962151264" rpy="0 0 0"/>
            <geometry>
                <box size="0.6781138885383232 0.4429662636919602 0.38380663924302527" />
            </geometry>
            <material name="Green">
                <color rgba="0 1.0 0 1.0"/>
            </material>
        </visual>
        <collision>
            <origin xyz="0.0 0.0 -0.19190331962151264" rpy="0 0 0"/>
            <geometry>
                <box size="0.6781138885383232 0.4429662636919602 0.38380663924302527" />
            </geometry>
        </collision>
    </link>
    <joint name="2_7" type="revolute">
       <parent link="2"/>
       <child  link="7"/>
       <origin rpy="0 0 0" xyz="0.0 0.30823818945598325 0.2195009747262846" />
     <axis xyz="1 0 0"/>
       <limit effort="0.0" lower="-3.14159" upper="3.14159" velocity="0.0"/>
    </joint>
    <link name="7">
        <inertial>
            <origin xyz="0.0 0.0 0.5595622096142279" rpy="0 0 0"/>
            <mass value="1" />
            <inertia ixx="100" ixy="0" ixz="0" iyy="100" iyz="0" izz="100" />
        </inertial>
        <visual>
            <origin xyz="0.0 0.0 0.5595622096142279" rpy="0 0 0"/>
            <geometry>
                <box size="1.0467080292468403 0.43093938939462606 1.1191244192284557" />
            </geometry>
            <material name="Green">
                <color rgba="0 1.0 0 1.0"/>
            </material>
        </visual>
        <collision>
            <origin xyz="0.0 0.0 0.5595622096142279" rpy="0 0 0"/>
            <geometry>
                <box size="1.0467080292468403 0.43093938939462606 1.1191244192284557" />
            </geometry>
        </collision>
    </link>
</robot>