<robot name = "robot">
    <link name="0">
        <inertial>
            <origin xyz="0 0 3.4391578890644596" rpy="0 0 0"/>
            <mass value="1" />
            <inertia ixx="100" ixy="0" ixz="0" iyy="100" iyz="0" izz="100" />
        </inertial>
        <visual>
            <origin xyz="0 0 3.4391578890644596" rpy="0 0 0"/>
            <geometry>
                <box size="0.7933325818253657 1.0060418842335976 0.878315778128919" />
            </geometry>
            <material name="Green">
                <color rgba="0 1.0 0 1.0"/>
            </material>
        </visual>
        <collision>
            <origin xyz="0 0 3.4391578890644596" rpy="0 0 0"/>
            <geometry>
                <box size="0.7933325818253657 1.0060418842335976 0.878315778128919" />
            </geometry>
        </collision>
    </link>
    <joint name="0_1" type="revolute">
       <parent link="0"/>
       <child  link="1"/>
       <origin rpy="0 0 0" xyz="-0.39666629091268285 0.0 3.4391578890644596" />
     <axis xyz="1 0 0"/>
       <limit effort="0.0" lower="-3.14159" upper="3.14159" velocity="0.0"/>
    </joint>
    <link name="1">
        <inertial>
            <origin xyz="-0.22377504250683347 0.0 0.0" rpy="0 0 0"/>
            <mass value="1" />
            <inertia ixx="100" ixy="0" ixz="0" iyy="100" iyz="0" izz="100" />
        </inertial>
        <visual>
            <origin xyz="-0.22377504250683347 0.0 0.0" rpy="0 0 0"/>
            <geometry>
                <box size="0.44755008501366694 1.1189515534656338 0.5647689510346394" />
            </geometry>
            <material name="Blue">
                <color rgba="0 0 1.0 1.0"/>
            </material>
        </visual>
        <collision>
            <origin xyz="-0.22377504250683347 0.0 0.0" rpy="0 0 0"/>
            <geometry>
                <box size="0.44755008501366694 1.1189515534656338 0.5647689510346394" />
            </geometry>
        </collision>
    </link>
    <joint name="1_2" type="revolute">
       <parent link="1"/>
       <child  link="2"/>
       <origin rpy="0 0 0" xyz="-0.22377504250683347 0.5594757767328169 0.0" />
     <axis xyz="1 0 0"/>
       <limit effort="0.0" lower="-3.14159" upper="3.14159" velocity="0.0"/>
    </joint>
    <link name="2">
        <inertial>
            <origin xyz="0.0 0.320734378080819 0.0" rpy="0 0 0"/>
            <mass value="1" />
            <inertia ixx="100" ixy="0" ixz="0" iyy="100" iyz="0" izz="100" />
        </inertial>
        <visual>
            <origin xyz="0.0 0.320734378080819 0.0" rpy="0 0 0"/>
            <geometry>
                <box size="0.9804343988349367 0.641468756161638 0.7461946717700508" />
            </geometry>
            <material name="Green">
                <color rgba="0 1.0 0 1.0"/>
            </material>
        </visual>
        <collision>
            <origin xyz="0.0 0.320734378080819 0.0" rpy="0 0 0"/>
            <geometry>
                <box size="0.9804343988349367 0.641468756161638 0.7461946717700508" />
            </geometry>
        </collision>
    </link>
    <joint name="2_3" type="revolute">
       <parent link="2"/>
       <child  link="3"/>
       <origin rpy="0 0 0" xyz="0.0 0.320734378080819 0.3730973358850254" />
     <axis xyz="1 0 0"/>
       <limit effort="0.0" lower="-3.14159" upper="3.14159" velocity="0.0"/>
    </joint>
    <link name="3">
        <inertial>
            <origin xyz="0.0 0.0 0.3484484932929167" rpy="0 0 0"/>
            <mass value="1" />
            <inertia ixx="100" ixy="0" ixz="0" iyy="100" iyz="0" izz="100" />
        </inertial>
        <visual>
            <origin xyz="0.0 0.0 0.3484484932929167" rpy="0 0 0"/>
            <geometry>
                <box size="0.44087769679480615 0.6378711461086721 0.6968969865858334" />
            </geometry>
            <material name="Green">
                <color rgba="0 1.0 0 1.0"/>
            </material>
        </visual>
        <collision>
            <origin xyz="0.0 0.0 0.3484484932929167" rpy="0 0 0"/>
            <geometry>
                <box size="0.44087769679480615 0.6378711461086721 0.6968969865858334" />
            </geometry>
        </collision>
    </link>
    <joint name="1_5" type="revolute">
       <parent link="1"/>
       <child  link="5"/>
       <origin rpy="0 0 0" xyz="-0.22377504250683347 -0.5594757767328169 0.0" />
     <axis xyz="0 1 0"/>
       <limit effort="0.0" lower="-3.14159" upper="3.14159" velocity="0.0"/>
    </joint>
    <link name="5">
        <inertial>
            <origin xyz="0.0 -0.5479048874274012 0.0" rpy="0 0 0"/>
            <mass value="1" />
            <inertia ixx="100" ixy="0" ixz="0" iyy="100" iyz="0" izz="100" />
        </inertial>
        <visual>
            <origin xyz="0.0 -0.5479048874274012 0.0" rpy="0 0 0"/>
            <geometry>
                <box size="0.7628155903126536 1.0958097748548024 0.8694462257239661" />
            </geometry>
            <material name="Green">
                <color rgba="0 1.0 0 1.0"/>
            </material>
        </visual>
        <collision>
            <origin xyz="0.0 -0.5479048874274012 0.0" rpy="0 0 0"/>
            <geometry>
                <box size="0.7628155903126536 1.0958097748548024 0.8694462257239661" />
            </geometry>
        </collision>
    </link>
    <joint name="2_4" type="revolute">
       <parent link="2"/>
       <child  link="4"/>
       <origin rpy="0 0 0" xyz="0.49021719941746833 0.320734378080819 0.0" />
     <axis xyz="1 0 0"/>
       <limit effort="0.0" lower="-3.14159" upper="3.14159" velocity="0.0"/>
    </joint>
    <link name="4">
        <inertial>
            <origin xyz="0.28266222368812566 0.0 0.0" rpy="0 0 0"/>
            <mass value="1" />
            <inertia ixx="100" ixy="0" ixz="0" iyy="100" iyz="0" izz="100" />
        </inertial>
        <visual>
            <origin xyz="0.28266222368812566 0.0 0.0" rpy="0 0 0"/>
            <geometry>
                <box size="0.5653244473762513 0.7378289838651844 0.8923521919534099" />
            </geometry>
            <material name="Green">
                <color rgba="0 1.0 0 1.0"/>
            </material>
        </visual>
        <collision>
            <origin xyz="0.28266222368812566 0.0 0.0" rpy="0 0 0"/>
            <geometry>
                <box size="0.5653244473762513 0.7378289838651844 0.8923521919534099" />
            </geometry>
        </collision>
    </link>
    <joint name="3_6" type="revolute">
       <parent link="3"/>
       <child  link="6"/>
       <origin rpy="0 0 0" xyz="0.0 0.0 0.6968969865858334" />
     <axis xyz="1 0 0"/>
       <limit effort="0.0" lower="-3.14159" upper="3.14159" velocity="0.0"/>
    </joint>
    <link name="6">
        <inertial>
            <origin xyz="0.0 0.0 0.3734594163419318" rpy="0 0 0"/>
            <mass value="1" />
            <inertia ixx="100" ixy="0" ixz="0" iyy="100" iyz="0" izz="100" />
        </inertial>
        <visual>
            <origin xyz="0.0 0.0 0.3734594163419318" rpy="0 0 0"/>
            <geometry>
                <box size="0.7155723399391583 0.4352099513383171 0.7469188326838636" />
            </geometry>
            <material name="Blue">
                <color rgba="0 0 1.0 1.0"/>
            </material>
        </visual>
        <collision>
            <origin xyz="0.0 0.0 0.3734594163419318" rpy="0 0 0"/>
            <geometry>
                <box size="0.7155723399391583 0.4352099513383171 0.7469188326838636" />
            </geometry>
        </collision>
    </link>
    <joint name="3_7" type="revolute">
       <parent link="3"/>
       <child  link="7"/>
       <origin rpy="0 0 0" xyz="0.22043884839740308 0.0 0.3484484932929167" />
     <axis xyz="1 0 0"/>
       <limit effort="0.0" lower="-3.14159" upper="3.14159" velocity="0.0"/>
    </joint>
    <link name="7">
        <inertial>
            <origin xyz="0.38923668651055376 0.0 0.0" rpy="0 0 0"/>
            <mass value="1" />
            <inertia ixx="100" ixy="0" ixz="0" iyy="100" iyz="0" izz="100" />
        </inertial>
        <visual>
            <origin xyz="0.38923668651055376 0.0 0.0" rpy="0 0 0"/>
            <geometry>
                <box size="0.7784733730211075 0.5927485163607399 0.5486242537228255" />
            </geometry>
            <material name="Green">
                <color rgba="0 1.0 0 1.0"/>
            </material>
        </visual>
        <collision>
            <origin xyz="0.38923668651055376 0.0 0.0" rpy="0 0 0"/>
            <geometry>
                <box size="0.7784733730211075 0.5927485163607399 0.5486242537228255" />
            </geometry>
        </collision>
    </link>
</robot>