<robot name = "robot">
    <link name="0">
        <inertial>
            <origin xyz="0 0 3.4391578890644596" rpy="0 0 0"/>
            <mass value="1" />
            <inertia ixx="100" ixy="0" ixz="0" iyy="100" iyz="0" izz="100" />
        </inertial>
        <visual>
            <origin xyz="0 0 3.4391578890644596" rpy="0 0 0"/>
            <geometry>
                <box size="0.7933325818253657 1.0060418842335976 0.878315778128919" />
            </geometry>
            <material name="Green">
                <color rgba="0 1.0 0 1.0"/>
            </material>
        </visual>
        <collision>
            <origin xyz="0 0 3.4391578890644596" rpy="0 0 0"/>
            <geometry>
                <box size="0.7933325818253657 1.0060418842335976 0.878315778128919" />
            </geometry>
        </collision>
    </link>
    <joint name="0_1" type="revolute">
       <parent link="0"/>
       <child  link="1"/>
       <origin rpy="0 0 0" xyz="-0.39666629091268285 0.0 3.4391578890644596" />
     <axis xyz="1 0 0"/>
       <limit effort="0.0" lower="-3.14159" upper="3.14159" velocity="0.0"/>
    </joint>
    <link name="1">
        <inertial>
            <origin xyz="-0.22377504250683347 0.0 0.0" rpy="0 0 0"/>
            <mass value="1" />
            <inertia ixx="100" ixy="0" ixz="0" iyy="100" iyz="0" izz="100" />
        </inertial>
        <visual>
            <origin xyz="-0.22377504250683347 0.0 0.0" rpy="0 0 0"/>
            <geometry>
                <box size="0.44755008501366694 1.1189515534656338 0.5647689510346394" />
            </geometry>
            <material name="Blue">
                <color rgba="0 0 1.0 1.0"/>
            </material>
        </visual>
        <collision>
            <origin xyz="-0.22377504250683347 0.0 0.0" rpy="0 0 0"/>
            <geometry>
                <box size="0.44755008501366694 1.1189515534656338 0.5647689510346394" />
            </geometry>
        </collision>
    </link>
    <joint name="1_2" type="revolute">
       <parent link="1"/>
       <child  link="2"/>
       <origin rpy="0 0 0" xyz="-0.22377504250683347 0.5594757767328169 0.0" />
     <axis xyz="1 0 0"/>
       <limit effort="0.0" lower="-3.14159" upper="3.14159" velocity="0.0"/>
    </joint>
    <link name="2">
        <inertial>
            <origin xyz="0.0 0.320734378080819 0.0" rpy="0 0 0"/>
            <mass value="1" />
            <inertia ixx="100" ixy="0" ixz="0" iyy="100" iyz="0" izz="100" />
        </inertial>
        <visual>
            <origin xyz="0.0 0.320734378080819 0.0" rpy="0 0 0"/>
            <geometry>
                <box size="0.9804343988349367 0.641468756161638 0.7461946717700508" />
            </geometry>
            <material name="Green">
                <color rgba="0 1.0 0 1.0"/>
            </material>
        </visual>
        <collision>
            <origin xyz="0.0 0.320734378080819 0.0" rpy="0 0 0"/>
            <geometry>
                <box size="0.9804343988349367 0.641468756161638 0.7461946717700508" />
            </geometry>
        </collision>
    </link>
    <joint name="2_3" type="revolute">
       <parent link="2"/>
       <child  link="3"/>
       <origin rpy="0 0 0" xyz="0.0 0.320734378080819 0.3730973358850254" />
     <axis xyz="1 0 0"/>
       <limit effort="0.0" lower="-3.14159" upper="3.14159" velocity="0.0"/>
    </joint>
    <link name="3">
        <inertial>
            <origin xyz="0.0 0.0 0.3484484932929167" rpy="0 0 0"/>
            <mass value="1" />
            <inertia ixx="100" ixy="0" ixz="0" iyy="100" iyz="0" izz="100" />
        </inertial>
        <visual>
            <origin xyz="0.0 0.0 0.3484484932929167" rpy="0 0 0"/>
            <geometry>
                <box size="0.44087769679480615 0.6378711461086721 0.6968969865858334" />
            </geometry>
            <material name="Green">
                <color rgba="0 1.0 0 1.0"/>
            </material>
        </visual>
        <collision>
            <origin xyz="0.0 0.0 0.3484484932929167" rpy="0 0 0"/>
            <geometry>
                <box size="0.44087769679480615 0.6378711461086721 0.6968969865858334" />
            </geometry>
        </collision>
    </link>
    <joint name="3_4" type="revolute">
       <parent link="3"/>
       <child  link="4"/>
       <origin rpy="0 0 0" xyz="0.0 -0.31893557305433606 0.3484484932929167" />
     <axis xyz="1 0 0"/>
       <limit effort="0.0" lower="-3.14159" upper="3.14159" velocity="0.0"/>
    </joint>
    <link name="4">
        <inertial>
            <origin xyz="0.0 -0.2815413808371213 0.0" rpy="0 0 0"/>
            <mass value="1" />
            <inertia ixx="100" ixy="0" ixz="0" iyy="100" iyz="0" izz="100" />
        </inertial>
        <visual>
            <origin xyz="0.0 -0.2815413808371213 0.0" rpy="0 0 0"/>
            <geometry>
                <box size="1.0856127142887515 0.5630827616742426 0.4930794446097006" />
            </geometry>
            <material name="Green">
                <color rgba="0 1.0 0 1.0"/>
            </material>
        </visual>
        <collision>
            <origin xyz="0.0 -0.2815413808371213 0.0" rpy="0 0 0"/>
            <geometry>
                <box size="1.0856127142887515 0.5630827616742426 0.4930794446097006" />
            </geometry>
        </collision>
    </link>
    <joint name="1_5" type="revolute">
       <parent link="1"/>
       <child  link="5"/>
       <origin rpy="0 0 0" xyz="-0.22377504250683347 -0.5594757767328169 0.0" />
     <axis xyz="0 1 0"/>
       <limit effort="0.0" lower="-3.14159" upper="3.14159" velocity="0.0"/>
    </joint>
    <link name="5">
        <inertial>
            <origin xyz="0.0 -0.5479048874274012 0.0" rpy="0 0 0"/>
            <mass value="1" />
            <inertia ixx="100" ixy="0" ixz="0" iyy="100" iyz="0" izz="100" />
        </inertial>
        <visual>
            <origin xyz="0.0 -0.5479048874274012 0.0" rpy="0 0 0"/>
            <geometry>
                <box size="0.7628155903126536 1.0958097748548024 0.8694462257239661" />
            </geometry>
            <material name="Green">
                <color rgba="0 1.0 0 1.0"/>
            </material>
        </visual>
        <collision>
            <origin xyz="0.0 -0.5479048874274012 0.0" rpy="0 0 0"/>
            <geometry>
                <box size="0.7628155903126536 1.0958097748548024 0.8694462257239661" />
            </geometry>
        </collision>
    </link>
</robot>