<robot name = "robot">
    <link name="0">
        <inertial>
            <origin xyz="0 0 3.454508090642686" rpy="0 0 0"/>
            <mass value="1" />
            <inertia ixx="100" ixy="0" ixz="0" iyy="100" iyz="0" izz="100" />
        </inertial>
        <visual>
            <origin xyz="0 0 3.454508090642686" rpy="0 0 0"/>
            <geometry>
                <box size="0.5175446757326901 0.4821403207426148 0.9090161812853719" />
            </geometry>
            <material name="Blue">
                <color rgba="0 0 1.0 1.0"/>
            </material>
        </visual>
        <collision>
            <origin xyz="0 0 3.454508090642686" rpy="0 0 0"/>
            <geometry>
                <box size="0.5175446757326901 0.4821403207426148 0.9090161812853719" />
            </geometry>
        </collision>
    </link>
    <joint name="0_1" type="revolute">
       <parent link="0"/>
       <child  link="1"/>
       <origin rpy="0 0 0" xyz="0.0 -0.2410701603713074 3.454508090642686" />
     <axis xyz="1 0 0"/>
       <limit effort="0.0" lower="-3.14159" upper="3.14159" velocity="0.0"/>
    </joint>
    <link name="1">
        <inertial>
            <origin xyz="0.0 -0.4114331590836319 0.0" rpy="0 0 0"/>
            <mass value="1" />
            <inertia ixx="100" ixy="0" ixz="0" iyy="100" iyz="0" izz="100" />
        </inertial>
        <visual>
            <origin xyz="0.0 -0.4114331590836319 0.0" rpy="0 0 0"/>
            <geometry>
                <box size="0.5551785679035854 0.8228663181672639 0.9901163872168722" />
            </geometry>
            <material name="Green">
                <color rgba="0 1.0 0 1.0"/>
            </material>
        </visual>
        <collision>
            <origin xyz="0.0 -0.4114331590836319 0.0" rpy="0 0 0"/>
            <geometry>
                <box size="0.5551785679035854 0.8228663181672639 0.9901163872168722" />
            </geometry>
        </collision>
    </link>
    <joint name="1_2" type="revolute">
       <parent link="1"/>
       <child  link="2"/>
       <origin rpy="0 0 0" xyz="0.0 -0.8228663181672639 0.0" />
     <axis xyz="1 0 0"/>
       <limit effort="0.0" lower="-3.14159" upper="3.14159" velocity="0.0"/>
    </joint>
    <link name="2">
        <inertial>
            <origin xyz="0.0 -0.21286207209342684 0.0" rpy="0 0 0"/>
            <mass value="1" />
            <inertia ixx="100" ixy="0" ixz="0" iyy="100" iyz="0" izz="100" />
        </inertial>
        <visual>
            <origin xyz="0.0 -0.21286207209342684 0.0" rpy="0 0 0"/>
            <geometry>
                <box size="0.5657033247598031 0.42572414418685367 0.9081820027142713" />
            </geometry>
            <material name="Blue">
                <color rgba="0 0 1.0 1.0"/>
            </material>
        </visual>
        <collision>
            <origin xyz="0.0 -0.21286207209342684 0.0" rpy="0 0 0"/>
            <geometry>
                <box size="0.5657033247598031 0.42572414418685367 0.9081820027142713" />
            </geometry>
        </collision>
    </link>
    <joint name="1_3" type="revolute">
       <parent link="1"/>
       <child  link="3"/>
       <origin rpy="0 0 0" xyz="-0.2775892839517927 -0.4114331590836319 0.0" />
     <axis xyz="1 0 0"/>
       <limit effort="0.0" lower="-3.14159" upper="3.14159" velocity="0.0"/>
    </joint>
    <link name="3">
        <inertial>
            <origin xyz="-0.4995317854922807 0.0 0.0" rpy="0 0 0"/>
            <mass value="1" />
            <inertia ixx="100" ixy="0" ixz="0" iyy="100" iyz="0" izz="100" />
        </inertial>
        <visual>
            <origin xyz="-0.4995317854922807 0.0 0.0" rpy="0 0 0"/>
            <geometry>
                <box size="0.9990635709845614 0.3850939188748183 0.757001543635604" />
            </geometry>
            <material name="Green">
                <color rgba="0 1.0 0 1.0"/>
            </material>
        </visual>
        <collision>
            <origin xyz="-0.4995317854922807 0.0 0.0" rpy="0 0 0"/>
            <geometry>
                <box size="0.9990635709845614 0.3850939188748183 0.757001543635604" />
            </geometry>
        </collision>
    </link>
    <joint name="3_5" type="revolute">
       <parent link="3"/>
       <child  link="5"/>
       <origin rpy="0 0 0" xyz="-0.4995317854922807 0.0 0.378500771817802" />
     <axis xyz="1 0 0"/>
       <limit effort="0.0" lower="-3.14159" upper="3.14159" velocity="0.0"/>
    </joint>
    <link name="5">
        <inertial>
            <origin xyz="0.0 0.0 0.5214187000419287" rpy="0 0 0"/>
            <mass value="1" />
            <inertia ixx="100" ixy="0" ixz="0" iyy="100" iyz="0" izz="100" />
        </inertial>
        <visual>
            <origin xyz="0.0 0.0 0.5214187000419287" rpy="0 0 0"/>
            <geometry>
                <box size="0.9434355151431673 0.872207985077206 1.0428374000838574" />
            </geometry>
            <material name="Green">
                <color rgba="0 1.0 0 1.0"/>
            </material>
        </visual>
        <collision>
            <origin xyz="0.0 0.0 0.5214187000419287" rpy="0 0 0"/>
            <geometry>
                <box size="0.9434355151431673 0.872207985077206 1.0428374000838574" />
            </geometry>
        </collision>
    </link>
    <joint name="2_6" type="revolute">
       <parent link="2"/>
       <child  link="6"/>
       <origin rpy="0 0 0" xyz="0.28285166237990156 -0.21286207209342684 0.0" />
     <axis xyz="1 0 0"/>
       <limit effort="0.0" lower="-3.14159" upper="3.14159" velocity="0.0"/>
    </joint>
    <link name="6">
        <inertial>
            <origin xyz="0.5036418319739395 0.0 0.0" rpy="0 0 0"/>
            <mass value="1" />
            <inertia ixx="100" ixy="0" ixz="0" iyy="100" iyz="0" izz="100" />
        </inertial>
        <visual>
            <origin xyz="0.5036418319739395 0.0 0.0" rpy="0 0 0"/>
            <geometry>
                <box size="1.007283663947879 0.8377834147330623 0.4804490450890456" />
            </geometry>
            <material name="Green">
                <color rgba="0 1.0 0 1.0"/>
            </material>
        </visual>
        <collision>
            <origin xyz="0.5036418319739395 0.0 0.0" rpy="0 0 0"/>
            <geometry>
                <box size="1.007283663947879 0.8377834147330623 0.4804490450890456" />
            </geometry>
        </collision>
    </link>
    <joint name="3_7" type="revolute">
       <parent link="3"/>
       <child  link="7"/>
       <origin rpy="0 0 0" xyz="-0.4995317854922807 0.19254695943740915 0.0" />
     <axis xyz="1 0 0"/>
       <limit effort="0.0" lower="-3.14159" upper="3.14159" velocity="0.0"/>
    </joint>
    <link name="7">
        <inertial>
            <origin xyz="0.0 0.42736093068583597 0.0" rpy="0 0 0"/>
            <mass value="1" />
            <inertia ixx="100" ixy="0" ixz="0" iyy="100" iyz="0" izz="100" />
        </inertial>
        <visual>
            <origin xyz="0.0 0.42736093068583597 0.0" rpy="0 0 0"/>
            <geometry>
                <box size="0.7679024123447112 0.8547218613716719 0.3788672610254378" />
            </geometry>
            <material name="Green">
                <color rgba="0 1.0 0 1.0"/>
            </material>
        </visual>
        <collision>
            <origin xyz="0.0 0.42736093068583597 0.0" rpy="0 0 0"/>
            <geometry>
                <box size="0.7679024123447112 0.8547218613716719 0.3788672610254378" />
            </geometry>
        </collision>
    </link>
    <joint name="1_8" type="revolute">
       <parent link="1"/>
       <child  link="8"/>
       <origin rpy="0 0 0" xyz="0.0 -0.4114331590836319 0.4950581936084361" />
     <axis xyz="0 1 0"/>
       <limit effort="0.0" lower="-3.14159" upper="3.14159" velocity="0.0"/>
    </joint>
    <link name="8">
        <inertial>
            <origin xyz="0.0 0.0 0.2919965134011285" rpy="0 0 0"/>
            <mass value="1" />
            <inertia ixx="100" ixy="0" ixz="0" iyy="100" iyz="0" izz="100" />
        </inertial>
        <visual>
            <origin xyz="0.0 0.0 0.2919965134011285" rpy="0 0 0"/>
            <geometry>
                <box size="0.5059946307678822 0.6596156097360857 0.583993026802257" />
            </geometry>
            <material name="Blue">
                <color rgba="0 0 1.0 1.0"/>
            </material>
        </visual>
        <collision>
            <origin xyz="0.0 0.0 0.2919965134011285" rpy="0 0 0"/>
            <geometry>
                <box size="0.5059946307678822 0.6596156097360857 0.583993026802257" />
            </geometry>
        </collision>
    </link>
    <joint name="6_4" type="revolute">
       <parent link="6"/>
       <child  link="4"/>
       <origin rpy="0 0 0" xyz="0.5036418319739395 0.0 0.2402245225445228" />
     <axis xyz="0 1 0"/>
       <limit effort="0.0" lower="-3.14159" upper="3.14159" velocity="0.0"/>
    </joint>
    <link name="4">
        <inertial>
            <origin xyz="0.0 0.0 0.37362249141501547" rpy="0 0 0"/>
            <mass value="1" />
            <inertia ixx="100" ixy="0" ixz="0" iyy="100" iyz="0" izz="100" />
        </inertial>
        <visual>
            <origin xyz="0.0 0.0 0.37362249141501547" rpy="0 0 0"/>
            <geometry>
                <box size="0.49992976127619293 1.0605265082289361 0.7472449828300309" />
            </geometry>
            <material name="Blue">
                <color rgba="0 0 1.0 1.0"/>
            </material>
        </visual>
        <collision>
            <origin xyz="0.0 0.0 0.37362249141501547" rpy="0 0 0"/>
            <geometry>
                <box size="0.49992976127619293 1.0605265082289361 0.7472449828300309" />
            </geometry>
        </collision>
    </link>
    <joint name="5_9" type="revolute">
       <parent link="5"/>
       <child  link="9"/>
       <origin rpy="0 0 0" xyz="-0.47171775757158363 0.0 0.5214187000419287" />
     <axis xyz="0 1 0"/>
       <limit effort="0.0" lower="-3.14159" upper="3.14159" velocity="0.0"/>
    </joint>
    <link name="9">
        <inertial>
            <origin xyz="-0.18857239605639453 0.0 0.0" rpy="0 0 0"/>
            <mass value="1" />
            <inertia ixx="100" ixy="0" ixz="0" iyy="100" iyz="0" izz="100" />
        </inertial>
        <visual>
            <origin xyz="-0.18857239605639453 0.0 0.0" rpy="0 0 0"/>
            <geometry>
                <box size="0.37714479211278906 0.3868038197224432 0.5684682150766092" />
            </geometry>
            <material name="Blue">
                <color rgba="0 0 1.0 1.0"/>
            </material>
        </visual>
        <collision>
            <origin xyz="-0.18857239605639453 0.0 0.0" rpy="0 0 0"/>
            <geometry>
                <box size="0.37714479211278906 0.3868038197224432 0.5684682150766092" />
            </geometry>
        </collision>
    </link>
    <joint name="6_10" type="revolute">
       <parent link="6"/>
       <child  link="10"/>
       <origin rpy="0 0 0" xyz="1.007283663947879 0.0 0.0" />
     <axis xyz="0 1 0"/>
       <limit effort="0.0" lower="-3.14159" upper="3.14159" velocity="0.0"/>
    </joint>
    <link name="10">
        <inertial>
            <origin xyz="0.2524256860199238 0.0 0.0" rpy="0 0 0"/>
            <mass value="1" />
            <inertia ixx="100" ixy="0" ixz="0" iyy="100" iyz="0" izz="100" />
        </inertial>
        <visual>
            <origin xyz="0.2524256860199238 0.0 0.0" rpy="0 0 0"/>
            <geometry>
                <box size="0.5048513720398476 0.6275490375481773 0.8384290287146843" />
            </geometry>
            <material name="Blue">
                <color rgba="0 0 1.0 1.0"/>
            </material>
        </visual>
        <collision>
            <origin xyz="0.2524256860199238 0.0 0.0" rpy="0 0 0"/>
            <geometry>
                <box size="0.5048513720398476 0.6275490375481773 0.8384290287146843" />
            </geometry>
        </collision>
    </link>
    <joint name="4_11" type="revolute">
       <parent link="4"/>
       <child  link="11"/>
       <origin rpy="0 0 0" xyz="0.0 -0.5302632541144681 0.37362249141501547" />
     <axis xyz="1 0 0"/>
       <limit effort="0.0" lower="-3.14159" upper="3.14159" velocity="0.0"/>
    </joint>
    <link name="11">
        <inertial>
            <origin xyz="0.0 -0.3626383523585815 0.0" rpy="0 0 0"/>
            <mass value="1" />
            <inertia ixx="100" ixy="0" ixz="0" iyy="100" iyz="0" izz="100" />
        </inertial>
        <visual>
            <origin xyz="0.0 -0.3626383523585815 0.0" rpy="0 0 0"/>
            <geometry>
                <box size="0.7999650829311199 0.725276704717163 0.5752872089548084" />
            </geometry>
            <material name="Green">
                <color rgba="0 1.0 0 1.0"/>
            </material>
        </visual>
        <collision>
            <origin xyz="0.0 -0.3626383523585815 0.0" rpy="0 0 0"/>
            <geometry>
                <box size="0.7999650829311199 0.725276704717163 0.5752872089548084" />
            </geometry>
        </collision>
    </link>
    <joint name="11_12" type="revolute">
       <parent link="11"/>
       <child  link="12"/>
       <origin rpy="0 0 0" xyz="0.0 -0.3626383523585815 0.2876436044774042" />
     <axis xyz="1 0 0"/>
       <limit effort="0.0" lower="-3.14159" upper="3.14159" velocity="0.0"/>
    </joint>
    <link name="12">
        <inertial>
            <origin xyz="0.0 0.0 0.40530642028045244" rpy="0 0 0"/>
            <mass value="1" />
            <inertia ixx="100" ixy="0" ixz="0" iyy="100" iyz="0" izz="100" />
        </inertial>
        <visual>
            <origin xyz="0.0 0.0 0.40530642028045244" rpy="0 0 0"/>
            <geometry>
                <box size="0.4061942433505804 0.3962275882862463 0.8106128405609049" />
            </geometry>
            <material name="Green">
                <color rgba="0 1.0 0 1.0"/>
            </material>
        </visual>
        <collision>
            <origin xyz="0.0 0.0 0.40530642028045244" rpy="0 0 0"/>
            <geometry>
                <box size="0.4061942433505804 0.3962275882862463 0.8106128405609049" />
            </geometry>
        </collision>
    </link>
    <joint name="8_13" type="revolute">
       <parent link="8"/>
       <child  link="13"/>
       <origin rpy="0 0 0" xyz="0.0 0.32980780486804284 0.2919965134011285" />
     <axis xyz="0 1 0"/>
       <limit effort="0.0" lower="-3.14159" upper="3.14159" velocity="0.0"/>
    </joint>
    <link name="13">
        <inertial>
            <origin xyz="0.0 0.5165723285571148 0.0" rpy="0 0 0"/>
            <mass value="1" />
            <inertia ixx="100" ixy="0" ixz="0" iyy="100" iyz="0" izz="100" />
        </inertial>
        <visual>
            <origin xyz="0.0 0.5165723285571148 0.0" rpy="0 0 0"/>
            <geometry>
                <box size="0.519637523685044 1.0331446571142295 0.5610289043248493" />
            </geometry>
            <material name="Green">
                <color rgba="0 1.0 0 1.0"/>
            </material>
        </visual>
        <collision>
            <origin xyz="0.0 0.5165723285571148 0.0" rpy="0 0 0"/>
            <geometry>
                <box size="0.519637523685044 1.0331446571142295 0.5610289043248493" />
            </geometry>
        </collision>
    </link>
</robot>