<robot name = "robot">
    <link name="0">
        <inertial>
            <origin xyz="0 0 3.439264623734011" rpy="0 0 0"/>
            <mass value="1" />
            <inertia ixx="100" ixy="0" ixz="0" iyy="100" iyz="0" izz="100" />
        </inertial>
        <visual>
            <origin xyz="0 0 3.439264623734011" rpy="0 0 0"/>
            <geometry>
                <box size="0.8972312038567478 0.5285712105226472 0.8785292474680225" />
            </geometry>
            <material name="Green">
                <color rgba="0 1.0 0 1.0"/>
            </material>
        </visual>
        <collision>
            <origin xyz="0 0 3.439264623734011" rpy="0 0 0"/>
            <geometry>
                <box size="0.8972312038567478 0.5285712105226472 0.8785292474680225" />
            </geometry>
        </collision>
    </link>
    <joint name="0_1" type="revolute">
       <parent link="0"/>
       <child  link="1"/>
       <origin rpy="0 0 0" xyz="0.0 0.0 3.0" />
     <axis xyz="1 0 0"/>
       <limit effort="0.0" lower="-3.14159" upper="3.14159" velocity="0.0"/>
    </joint>
    <link name="1">
        <inertial>
            <origin xyz="0.0 0.0 -0.21184011840247863" rpy="0 0 0"/>
            <mass value="1" />
            <inertia ixx="100" ixy="0" ixz="0" iyy="100" iyz="0" izz="100" />
        </inertial>
        <visual>
            <origin xyz="0.0 0.0 -0.21184011840247863" rpy="0 0 0"/>
            <geometry>
                <box size="1.1065445378799996 0.7879955881663613 0.42368023680495726" />
            </geometry>
            <material name="Blue">
                <color rgba="0 0 1.0 1.0"/>
            </material>
        </visual>
        <collision>
            <origin xyz="0.0 0.0 -0.21184011840247863" rpy="0 0 0"/>
            <geometry>
                <box size="1.1065445378799996 0.7879955881663613 0.42368023680495726" />
            </geometry>
        </collision>
    </link>
    <joint name="1_3" type="revolute">
       <parent link="1"/>
       <child  link="3"/>
       <origin rpy="0 0 0" xyz="0.0 -0.39399779408318064 -0.21184011840247863" />
     <axis xyz="1 0 0"/>
       <limit effort="0.0" lower="-3.14159" upper="3.14159" velocity="0.0"/>
    </joint>
    <link name="3">
        <inertial>
            <origin xyz="0.0 -0.22397718530245506 0.0" rpy="0 0 0"/>
            <mass value="1" />
            <inertia ixx="100" ixy="0" ixz="0" iyy="100" iyz="0" izz="100" />
        </inertial>
        <visual>
            <origin xyz="0.0 -0.22397718530245506 0.0" rpy="0 0 0"/>
            <geometry>
                <box size="0.8260802821371047 0.4479543706049101 0.5915511604064815" />
            </geometry>
            <material name="Blue">
                <color rgba="0 0 1.0 1.0"/>
            </material>
        </visual>
        <collision>
            <origin xyz="0.0 -0.22397718530245506 0.0" rpy="0 0 0"/>
            <geometry>
                <box size="0.8260802821371047 0.4479543706049101 0.5915511604064815" />
            </geometry>
        </collision>
    </link>
    <joint name="3_7" type="revolute">
       <parent link="3"/>
       <child  link="7"/>
       <origin rpy="0 0 0" xyz="0.0 -0.4479543706049101 0.0" />
     <axis xyz="0 1 0"/>
       <limit effort="0.0" lower="-3.14159" upper="3.14159" velocity="0.0"/>
    </joint>
    <link name="7">
        <inertial>
            <origin xyz="0.0 -0.23044766708484882 0.0" rpy="0 0 0"/>
            <mass value="1" />
            <inertia ixx="100" ixy="0" ixz="0" iyy="100" iyz="0" izz="100" />
        </inertial>
        <visual>
            <origin xyz="0.0 -0.23044766708484882 0.0" rpy="0 0 0"/>
            <geometry>
                <box size="0.5047872926074527 0.46089533416969763 0.973410447015923" />
            </geometry>
            <material name="Green">
                <color rgba="0 1.0 0 1.0"/>
            </material>
        </visual>
        <collision>
            <origin xyz="0.0 -0.23044766708484882 0.0" rpy="0 0 0"/>
            <geometry>
                <box size="0.5047872926074527 0.46089533416969763 0.973410447015923" />
            </geometry>
        </collision>
    </link>
    <joint name="1_8" type="revolute">
       <parent link="1"/>
       <child  link="8"/>
       <origin rpy="0 0 0" xyz="-0.5532722689399998 0.0 -0.21184011840247863" />
     <axis xyz="0 1 0"/>
       <limit effort="0.0" lower="-3.14159" upper="3.14159" velocity="0.0"/>
    </joint>
    <link name="8">
        <inertial>
            <origin xyz="-0.3848951087380067 0.0 0.0" rpy="0 0 0"/>
            <mass value="1" />
            <inertia ixx="100" ixy="0" ixz="0" iyy="100" iyz="0" izz="100" />
        </inertial>
        <visual>
            <origin xyz="-0.3848951087380067 0.0 0.0" rpy="0 0 0"/>
            <geometry>
                <box size="0.7697902174760134 0.8704602729875885 0.7178765726950027" />
            </geometry>
            <material name="Blue">
                <color rgba="0 0 1.0 1.0"/>
            </material>
        </visual>
        <collision>
            <origin xyz="-0.3848951087380067 0.0 0.0" rpy="0 0 0"/>
            <geometry>
                <box size="0.7697902174760134 0.8704602729875885 0.7178765726950027" />
            </geometry>
        </collision>
    </link>
    <joint name="0_6" type="revolute">
       <parent link="0"/>
       <child  link="6"/>
       <origin rpy="0 0 0" xyz="0.0 -0.2642856052613236 3.439264623734011" />
     <axis xyz="0 1 0"/>
       <limit effort="0.0" lower="-3.14159" upper="3.14159" velocity="0.0"/>
    </joint>
    <link name="6">
        <inertial>
            <origin xyz="0.0 -0.18928042093375902 0.0" rpy="0 0 0"/>
            <mass value="1" />
            <inertia ixx="100" ixy="0" ixz="0" iyy="100" iyz="0" izz="100" />
        </inertial>
        <visual>
            <origin xyz="0.0 -0.18928042093375902 0.0" rpy="0 0 0"/>
            <geometry>
                <box size="0.6829910308637271 0.37856084186751804 0.4579483691223719" />
            </geometry>
            <material name="Blue">
                <color rgba="0 0 1.0 1.0"/>
            </material>
        </visual>
        <collision>
            <origin xyz="0.0 -0.18928042093375902 0.0" rpy="0 0 0"/>
            <geometry>
                <box size="0.6829910308637271 0.37856084186751804 0.4579483691223719" />
            </geometry>
        </collision>
    </link>
    <joint name="7_9" type="revolute">
       <parent link="7"/>
       <child  link="9"/>
       <origin rpy="0 0 0" xyz="0.0 -0.23044766708484882 -0.4867052235079615" />
     <axis xyz="1 0 0"/>
       <limit effort="0.0" lower="-3.14159" upper="3.14159" velocity="0.0"/>
    </joint>
    <link name="9">
        <inertial>
            <origin xyz="0.0 0.0 -0.23146536789783584" rpy="0 0 0"/>
            <mass value="1" />
            <inertia ixx="100" ixy="0" ixz="0" iyy="100" iyz="0" izz="100" />
        </inertial>
        <visual>
            <origin xyz="0.0 0.0 -0.23146536789783584" rpy="0 0 0"/>
            <geometry>
                <box size="0.8732618046128763 0.7162051596953306 0.4629307357956717" />
            </geometry>
            <material name="Green">
                <color rgba="0 1.0 0 1.0"/>
            </material>
        </visual>
        <collision>
            <origin xyz="0.0 0.0 -0.23146536789783584" rpy="0 0 0"/>
            <geometry>
                <box size="0.8732618046128763 0.7162051596953306 0.4629307357956717" />
            </geometry>
        </collision>
    </link>
    <joint name="7_2" type="revolute">
       <parent link="7"/>
       <child  link="2"/>
       <origin rpy="0 0 0" xyz="0.25239364630372635 -0.23044766708484882 0.0" />
     <axis xyz="1 0 0"/>
       <limit effort="0.0" lower="-3.14159" upper="3.14159" velocity="0.0"/>
    </joint>
    <link name="2">
        <inertial>
            <origin xyz="0.5598458719968414 0.0 0.0" rpy="0 0 0"/>
            <mass value="1" />
            <inertia ixx="100" ixy="0" ixz="0" iyy="100" iyz="0" izz="100" />
        </inertial>
        <visual>
            <origin xyz="0.5598458719968414 0.0 0.0" rpy="0 0 0"/>
            <geometry>
                <box size="1.1196917439936829 0.44466198665304846 0.6259154498101858" />
            </geometry>
            <material name="Green">
                <color rgba="0 1.0 0 1.0"/>
            </material>
        </visual>
        <collision>
            <origin xyz="0.5598458719968414 0.0 0.0" rpy="0 0 0"/>
            <geometry>
                <box size="1.1196917439936829 0.44466198665304846 0.6259154498101858" />
            </geometry>
        </collision>
    </link>
    <joint name="1_4" type="revolute">
       <parent link="1"/>
       <child  link="4"/>
       <origin rpy="0 0 0" xyz="0.0 0.39399779408318064 -0.21184011840247863" />
     <axis xyz="0 1 0"/>
       <limit effort="0.0" lower="-3.14159" upper="3.14159" velocity="0.0"/>
    </joint>
    <link name="4">
        <inertial>
            <origin xyz="0.0 0.4581161362391615 0.0" rpy="0 0 0"/>
            <mass value="1" />
            <inertia ixx="100" ixy="0" ixz="0" iyy="100" iyz="0" izz="100" />
        </inertial>
        <visual>
            <origin xyz="0.0 0.4581161362391615 0.0" rpy="0 0 0"/>
            <geometry>
                <box size="0.39430591489213895 0.916232272478323 0.8171879743772424" />
            </geometry>
            <material name="Green">
                <color rgba="0 1.0 0 1.0"/>
            </material>
        </visual>
        <collision>
            <origin xyz="0.0 0.4581161362391615 0.0" rpy="0 0 0"/>
            <geometry>
                <box size="0.39430591489213895 0.916232272478323 0.8171879743772424" />
            </geometry>
        </collision>
    </link>
    <joint name="2_5" type="revolute">
       <parent link="2"/>
       <child  link="5"/>
       <origin rpy="0 0 0" xyz="1.1196917439936829 0.0 0.0" />
     <axis xyz="1 0 0"/>
       <limit effort="0.0" lower="-3.14159" upper="3.14159" velocity="0.0"/>
    </joint>
    <link name="5">
        <inertial>
            <origin xyz="0.27607826586892914 0.0 0.0" rpy="0 0 0"/>
            <mass value="1" />
            <inertia ixx="100" ixy="0" ixz="0" iyy="100" iyz="0" izz="100" />
        </inertial>
        <visual>
            <origin xyz="0.27607826586892914 0.0 0.0" rpy="0 0 0"/>
            <geometry>
                <box size="0.5521565317378583 1.06892260437314 0.5514900296517582" />
            </geometry>
            <material name="Blue">
                <color rgba="0 0 1.0 1.0"/>
            </material>
        </visual>
        <collision>
            <origin xyz="0.27607826586892914 0.0 0.0" rpy="0 0 0"/>
            <geometry>
                <box size="0.5521565317378583 1.06892260437314 0.5514900296517582" />
            </geometry>
        </collision>
    </link>
</robot>