<robot name = "robot">
    <link name="0">
        <inertial>
            <origin xyz="0 0 3.415263842035316" rpy="0 0 0"/>
            <mass value="1" />
            <inertia ixx="100" ixy="0" ixz="0" iyy="100" iyz="0" izz="100" />
        </inertial>
        <visual>
            <origin xyz="0 0 3.415263842035316" rpy="0 0 0"/>
            <geometry>
                <box size="0.41482617301444324 0.8866361563623701 0.8305276840706324" />
            </geometry>
            <material name="Blue">
                <color rgba="0 0 1.0 1.0"/>
            </material>
        </visual>
        <collision>
            <origin xyz="0 0 3.415263842035316" rpy="0 0 0"/>
            <geometry>
                <box size="0.41482617301444324 0.8866361563623701 0.8305276840706324" />
            </geometry>
        </collision>
    </link>
    <joint name="0_1" type="revolute">
       <parent link="0"/>
       <child  link="1"/>
       <origin rpy="0 0 0" xyz="0.20741308650722162 0.0 3.415263842035316" />
     <axis xyz="1 0 0"/>
       <limit effort="0.0" lower="-3.14159" upper="3.14159" velocity="0.0"/>
    </joint>
    <link name="1">
        <inertial>
            <origin xyz="0.23730248600333514 0.0 0.0" rpy="0 0 0"/>
            <mass value="1" />
            <inertia ixx="100" ixy="0" ixz="0" iyy="100" iyz="0" izz="100" />
        </inertial>
        <visual>
            <origin xyz="0.23730248600333514 0.0 0.0" rpy="0 0 0"/>
            <geometry>
                <box size="0.4746049720066703 1.099295480699286 0.9846251981072134" />
            </geometry>
            <material name="Green">
                <color rgba="0 1.0 0 1.0"/>
            </material>
        </visual>
        <collision>
            <origin xyz="0.23730248600333514 0.0 0.0" rpy="0 0 0"/>
            <geometry>
                <box size="0.4746049720066703 1.099295480699286 0.9846251981072134" />
            </geometry>
        </collision>
    </link>
    <joint name="1_2" type="revolute">
       <parent link="1"/>
       <child  link="2"/>
       <origin rpy="0 0 0" xyz="0.23730248600333514 0.0 0.4923125990536067" />
     <axis xyz="0 1 0"/>
       <limit effort="0.0" lower="-3.14159" upper="3.14159" velocity="0.0"/>
    </joint>
    <link name="2">
        <inertial>
            <origin xyz="0.0 0.0 0.3806028739226074" rpy="0 0 0"/>
            <mass value="1" />
            <inertia ixx="100" ixy="0" ixz="0" iyy="100" iyz="0" izz="100" />
        </inertial>
        <visual>
            <origin xyz="0.0 0.0 0.3806028739226074" rpy="0 0 0"/>
            <geometry>
                <box size="0.667245550192858 1.034060742071965 0.7612057478452148" />
            </geometry>
            <material name="Blue">
                <color rgba="0 0 1.0 1.0"/>
            </material>
        </visual>
        <collision>
            <origin xyz="0.0 0.0 0.3806028739226074" rpy="0 0 0"/>
            <geometry>
                <box size="0.667245550192858 1.034060742071965 0.7612057478452148" />
            </geometry>
        </collision>
    </link>
    <joint name="2_3" type="revolute">
       <parent link="2"/>
       <child  link="3"/>
       <origin rpy="0 0 0" xyz="0.0 0.5170303710359825 0.3806028739226074" />
     <axis xyz="0 1 0"/>
       <limit effort="0.0" lower="-3.14159" upper="3.14159" velocity="0.0"/>
    </joint>
    <link name="3">
        <inertial>
            <origin xyz="0.0 0.35650698803829173 0.0" rpy="0 0 0"/>
            <mass value="1" />
            <inertia ixx="100" ixy="0" ixz="0" iyy="100" iyz="0" izz="100" />
        </inertial>
        <visual>
            <origin xyz="0.0 0.35650698803829173 0.0" rpy="0 0 0"/>
            <geometry>
                <box size="0.9335674502743095 0.7130139760765835 0.43383269975807426" />
            </geometry>
            <material name="Blue">
                <color rgba="0 0 1.0 1.0"/>
            </material>
        </visual>
        <collision>
            <origin xyz="0.0 0.35650698803829173 0.0" rpy="0 0 0"/>
            <geometry>
                <box size="0.9335674502743095 0.7130139760765835 0.43383269975807426" />
            </geometry>
        </collision>
    </link>
    <joint name="0_5" type="revolute">
       <parent link="0"/>
       <child  link="5"/>
       <origin rpy="0 0 0" xyz="-0.20741308650722162 0.0 3.415263842035316" />
     <axis xyz="0 1 0"/>
       <limit effort="0.0" lower="-3.14159" upper="3.14159" velocity="0.0"/>
    </joint>
    <link name="5">
        <inertial>
            <origin xyz="-0.36380655381822347 0.0 0.0" rpy="0 0 0"/>
            <mass value="1" />
            <inertia ixx="100" ixy="0" ixz="0" iyy="100" iyz="0" izz="100" />
        </inertial>
        <visual>
            <origin xyz="-0.36380655381822347 0.0 0.0" rpy="0 0 0"/>
            <geometry>
                <box size="0.7276131076364469 1.0805330313482306 0.8134132422278815" />
            </geometry>
            <material name="Blue">
                <color rgba="0 0 1.0 1.0"/>
            </material>
        </visual>
        <collision>
            <origin xyz="-0.36380655381822347 0.0 0.0" rpy="0 0 0"/>
            <geometry>
                <box size="0.7276131076364469 1.0805330313482306 0.8134132422278815" />
            </geometry>
        </collision>
    </link>
    <joint name="2_6" type="revolute">
       <parent link="2"/>
       <child  link="6"/>
       <origin rpy="0 0 0" xyz="-0.333622775096429 0.0 0.3806028739226074" />
     <axis xyz="0 1 0"/>
       <limit effort="0.0" lower="-3.14159" upper="3.14159" velocity="0.0"/>
    </joint>
    <link name="6">
        <inertial>
            <origin xyz="-0.31653210919504954 0.0 0.0" rpy="0 0 0"/>
            <mass value="1" />
            <inertia ixx="100" ixy="0" ixz="0" iyy="100" iyz="0" izz="100" />
        </inertial>
        <visual>
            <origin xyz="-0.31653210919504954 0.0 0.0" rpy="0 0 0"/>
            <geometry>
                <box size="0.6330642183900991 0.8457682822310177 0.7733185728173247" />
            </geometry>
            <material name="Blue">
                <color rgba="0 0 1.0 1.0"/>
            </material>
        </visual>
        <collision>
            <origin xyz="-0.31653210919504954 0.0 0.0" rpy="0 0 0"/>
            <geometry>
                <box size="0.6330642183900991 0.8457682822310177 0.7733185728173247" />
            </geometry>
        </collision>
    </link>
    <joint name="1_4" type="revolute">
       <parent link="1"/>
       <child  link="4"/>
       <origin rpy="0 0 0" xyz="0.23730248600333514 -0.549647740349643 0.0" />
     <axis xyz="0 1 0"/>
       <limit effort="0.0" lower="-3.14159" upper="3.14159" velocity="0.0"/>
    </joint>
    <link name="4">
        <inertial>
            <origin xyz="0.0 -0.29539056379461076 0.0" rpy="0 0 0"/>
            <mass value="1" />
            <inertia ixx="100" ixy="0" ixz="0" iyy="100" iyz="0" izz="100" />
        </inertial>
        <visual>
            <origin xyz="0.0 -0.29539056379461076 0.0" rpy="0 0 0"/>
            <geometry>
                <box size="0.6974833880474345 0.5907811275892215 0.4195471958143406" />
            </geometry>
            <material name="Green">
                <color rgba="0 1.0 0 1.0"/>
            </material>
        </visual>
        <collision>
            <origin xyz="0.0 -0.29539056379461076 0.0" rpy="0 0 0"/>
            <geometry>
                <box size="0.6974833880474345 0.5907811275892215 0.4195471958143406" />
            </geometry>
        </collision>
    </link>
    <joint name="6_7" type="revolute">
       <parent link="6"/>
       <child  link="7"/>
       <origin rpy="0 0 0" xyz="-0.31653210919504954 -0.42288414111550887 0.0" />
     <axis xyz="0 1 0"/>
       <limit effort="0.0" lower="-3.14159" upper="3.14159" velocity="0.0"/>
    </joint>
    <link name="7">
        <inertial>
            <origin xyz="0.0 -0.5488065972649847 0.0" rpy="0 0 0"/>
            <mass value="1" />
            <inertia ixx="100" ixy="0" ixz="0" iyy="100" iyz="0" izz="100" />
        </inertial>
        <visual>
            <origin xyz="0.0 -0.5488065972649847 0.0" rpy="0 0 0"/>
            <geometry>
                <box size="0.4354367926260788 1.0976131945299694 0.8443396890916761" />
            </geometry>
            <material name="Blue">
                <color rgba="0 0 1.0 1.0"/>
            </material>
        </visual>
        <collision>
            <origin xyz="0.0 -0.5488065972649847 0.0" rpy="0 0 0"/>
            <geometry>
                <box size="0.4354367926260788 1.0976131945299694 0.8443396890916761" />
            </geometry>
        </collision>
    </link>
</robot>