<robot name = "robot">
    <link name="0">
        <inertial>
            <origin xyz="0 0 3.4241566985249725" rpy="0 0 0"/>
            <mass value="1" />
            <inertia ixx="100" ixy="0" ixz="0" iyy="100" iyz="0" izz="100" />
        </inertial>
        <visual>
            <origin xyz="0 0 3.4241566985249725" rpy="0 0 0"/>
            <geometry>
                <box size="0.6729320094875598 0.9930314585981488 0.848313397049945" />
            </geometry>
            <material name="Blue">
                <color rgba="0 0 1.0 1.0"/>
            </material>
        </visual>
        <collision>
            <origin xyz="0 0 3.4241566985249725" rpy="0 0 0"/>
            <geometry>
                <box size="0.6729320094875598 0.9930314585981488 0.848313397049945" />
            </geometry>
        </collision>
    </link>
    <joint name="0_1" type="revolute">
       <parent link="0"/>
       <child  link="1"/>
       <origin rpy="0 0 0" xyz="0.0 0.0 3.0" />
     <axis xyz="1 0 0"/>
       <limit effort="0.0" lower="-3.14159" upper="3.14159" velocity="0.0"/>
    </joint>
    <link name="1">
        <inertial>
            <origin xyz="0.0 0.0 -0.4541210780167658" rpy="0 0 0"/>
            <mass value="1" />
            <inertia ixx="100" ixy="0" ixz="0" iyy="100" iyz="0" izz="100" />
        </inertial>
        <visual>
            <origin xyz="0.0 0.0 -0.4541210780167658" rpy="0 0 0"/>
            <geometry>
                <box size="0.9637179990247997 0.8529618729109333 0.9082421560335316" />
            </geometry>
            <material name="Green">
                <color rgba="0 1.0 0 1.0"/>
            </material>
        </visual>
        <collision>
            <origin xyz="0.0 0.0 -0.4541210780167658" rpy="0 0 0"/>
            <geometry>
                <box size="0.9637179990247997 0.8529618729109333 0.9082421560335316" />
            </geometry>
        </collision>
    </link>
    <joint name="1_2" type="revolute">
       <parent link="1"/>
       <child  link="2"/>
       <origin rpy="0 0 0" xyz="0.0 0.0 -0.9082421560335316" />
     <axis xyz="1 0 0"/>
       <limit effort="0.0" lower="-3.14159" upper="3.14159" velocity="0.0"/>
    </joint>
    <link name="2">
        <inertial>
            <origin xyz="0.0 0.0 -0.40066103756782034" rpy="0 0 0"/>
            <mass value="1" />
            <inertia ixx="100" ixy="0" ixz="0" iyy="100" iyz="0" izz="100" />
        </inertial>
        <visual>
            <origin xyz="0.0 0.0 -0.40066103756782034" rpy="0 0 0"/>
            <geometry>
                <box size="0.6884095967405734 0.8364932698401177 0.8013220751356407" />
            </geometry>
            <material name="Blue">
                <color rgba="0 0 1.0 1.0"/>
            </material>
        </visual>
        <collision>
            <origin xyz="0.0 0.0 -0.40066103756782034" rpy="0 0 0"/>
            <geometry>
                <box size="0.6884095967405734 0.8364932698401177 0.8013220751356407" />
            </geometry>
        </collision>
    </link>
    <joint name="1_3" type="revolute">
       <parent link="1"/>
       <child  link="3"/>
       <origin rpy="0 0 0" xyz="0.48185899951239985 0.0 -0.4541210780167658" />
     <axis xyz="0 1 0"/>
       <limit effort="0.0" lower="-3.14159" upper="3.14159" velocity="0.0"/>
    </joint>
    <link name="3">
        <inertial>
            <origin xyz="0.4920352330083408 0.0 0.0" rpy="0 0 0"/>
            <mass value="1" />
            <inertia ixx="100" ixy="0" ixz="0" iyy="100" iyz="0" izz="100" />
        </inertial>
        <visual>
            <origin xyz="0.4920352330083408 0.0 0.0" rpy="0 0 0"/>
            <geometry>
                <box size="0.9840704660166816 0.9800204514808428 1.0690112473673152" />
            </geometry>
            <material name="Blue">
                <color rgba="0 0 1.0 1.0"/>
            </material>
        </visual>
        <collision>
            <origin xyz="0.4920352330083408 0.0 0.0" rpy="0 0 0"/>
            <geometry>
                <box size="0.9840704660166816 0.9800204514808428 1.0690112473673152" />
            </geometry>
        </collision>
    </link>
    <joint name="1_7" type="revolute">
       <parent link="1"/>
       <child  link="7"/>
       <origin rpy="0 0 0" xyz="0.0 -0.42648093645546664 -0.4541210780167658" />
     <axis xyz="0 1 0"/>
       <limit effort="0.0" lower="-3.14159" upper="3.14159" velocity="0.0"/>
    </joint>
    <link name="7">
        <inertial>
            <origin xyz="0.0 -0.551679204814535 0.0" rpy="0 0 0"/>
            <mass value="1" />
            <inertia ixx="100" ixy="0" ixz="0" iyy="100" iyz="0" izz="100" />
        </inertial>
        <visual>
            <origin xyz="0.0 -0.551679204814535 0.0" rpy="0 0 0"/>
            <geometry>
                <box size="0.7204763881681749 1.10335840962907 0.42395194685433324" />
            </geometry>
            <material name="Blue">
                <color rgba="0 0 1.0 1.0"/>
            </material>
        </visual>
        <collision>
            <origin xyz="0.0 -0.551679204814535 0.0" rpy="0 0 0"/>
            <geometry>
                <box size="0.7204763881681749 1.10335840962907 0.42395194685433324" />
            </geometry>
        </collision>
    </link>
    <joint name="2_8" type="revolute">
       <parent link="2"/>
       <child  link="8"/>
       <origin rpy="0 0 0" xyz="0.0 0.41824663492005887 -0.40066103756782034" />
     <axis xyz="0 1 0"/>
       <limit effort="0.0" lower="-3.14159" upper="3.14159" velocity="0.0"/>
    </joint>
    <link name="8">
        <inertial>
            <origin xyz="0.0 0.42454333172362496 0.0" rpy="0 0 0"/>
            <mass value="1" />
            <inertia ixx="100" ixy="0" ixz="0" iyy="100" iyz="0" izz="100" />
        </inertial>
        <visual>
            <origin xyz="0.0 0.42454333172362496 0.0" rpy="0 0 0"/>
            <geometry>
                <box size="0.6891064156445819 0.8490866634472499 0.6362202402631856" />
            </geometry>
            <material name="Green">
                <color rgba="0 1.0 0 1.0"/>
            </material>
        </visual>
        <collision>
            <origin xyz="0.0 0.42454333172362496 0.0" rpy="0 0 0"/>
            <geometry>
                <box size="0.6891064156445819 0.8490866634472499 0.6362202402631856" />
            </geometry>
        </collision>
    </link>
    <joint name="8_9" type="revolute">
       <parent link="8"/>
       <child  link="9"/>
       <origin rpy="0 0 0" xyz="0.0 0.8490866634472499 0.0" />
     <axis xyz="0 1 0"/>
       <limit effort="0.0" lower="-3.14159" upper="3.14159" velocity="0.0"/>
    </joint>
    <link name="9">
        <inertial>
            <origin xyz="0.0 0.33102300301909493 0.0" rpy="0 0 0"/>
            <mass value="1" />
            <inertia ixx="100" ixy="0" ixz="0" iyy="100" iyz="0" izz="100" />
        </inertial>
        <visual>
            <origin xyz="0.0 0.33102300301909493 0.0" rpy="0 0 0"/>
            <geometry>
                <box size="0.6284304154254408 0.6620460060381899 1.0897454784353406" />
            </geometry>
            <material name="Green">
                <color rgba="0 1.0 0 1.0"/>
            </material>
        </visual>
        <collision>
            <origin xyz="0.0 0.33102300301909493 0.0" rpy="0 0 0"/>
            <geometry>
                <box size="0.6284304154254408 0.6620460060381899 1.0897454784353406" />
            </geometry>
        </collision>
    </link>
    <joint name="0_4" type="revolute">
       <parent link="0"/>
       <child  link="4"/>
       <origin rpy="0 0 0" xyz="-0.3364660047437799 0.0 3.4241566985249725" />
     <axis xyz="1 0 0"/>
       <limit effort="0.0" lower="-3.14159" upper="3.14159" velocity="0.0"/>
    </joint>
    <link name="4">
        <inertial>
            <origin xyz="-0.5578632349181952 0.0 0.0" rpy="0 0 0"/>
            <mass value="1" />
            <inertia ixx="100" ixy="0" ixz="0" iyy="100" iyz="0" izz="100" />
        </inertial>
        <visual>
            <origin xyz="-0.5578632349181952 0.0 0.0" rpy="0 0 0"/>
            <geometry>
                <box size="1.1157264698363905 0.5075001624730473 0.4550000386297028" />
            </geometry>
            <material name="Blue">
                <color rgba="0 0 1.0 1.0"/>
            </material>
        </visual>
        <collision>
            <origin xyz="-0.5578632349181952 0.0 0.0" rpy="0 0 0"/>
            <geometry>
                <box size="1.1157264698363905 0.5075001624730473 0.4550000386297028" />
            </geometry>
        </collision>
    </link>
    <joint name="1_5" type="revolute">
       <parent link="1"/>
       <child  link="5"/>
       <origin rpy="0 0 0" xyz="-0.48185899951239985 0.0 -0.4541210780167658" />
     <axis xyz="1 0 0"/>
       <limit effort="0.0" lower="-3.14159" upper="3.14159" velocity="0.0"/>
    </joint>
    <link name="5">
        <inertial>
            <origin xyz="-0.24102694787770249 0.0 0.0" rpy="0 0 0"/>
            <mass value="1" />
            <inertia ixx="100" ixy="0" ixz="0" iyy="100" iyz="0" izz="100" />
        </inertial>
        <visual>
            <origin xyz="-0.24102694787770249 0.0 0.0" rpy="0 0 0"/>
            <geometry>
                <box size="0.48205389575540497 0.4846983048096427 0.4810125720652507" />
            </geometry>
            <material name="Blue">
                <color rgba="0 0 1.0 1.0"/>
            </material>
        </visual>
        <collision>
            <origin xyz="-0.24102694787770249 0.0 0.0" rpy="0 0 0"/>
            <geometry>
                <box size="0.48205389575540497 0.4846983048096427 0.4810125720652507" />
            </geometry>
        </collision>
    </link>
    <joint name="2_6" type="revolute">
       <parent link="2"/>
       <child  link="6"/>
       <origin rpy="0 0 0" xyz="0.3442047983702867 0.0 -0.40066103756782034" />
     <axis xyz="0 1 0"/>
       <limit effort="0.0" lower="-3.14159" upper="3.14159" velocity="0.0"/>
    </joint>
    <link name="6">
        <inertial>
            <origin xyz="0.44188507750977357 0.0 0.0" rpy="0 0 0"/>
            <mass value="1" />
            <inertia ixx="100" ixy="0" ixz="0" iyy="100" iyz="0" izz="100" />
        </inertial>
        <visual>
            <origin xyz="0.44188507750977357 0.0 0.0" rpy="0 0 0"/>
            <geometry>
                <box size="0.8837701550195471 0.6420857037292812 0.5292775559317915" />
            </geometry>
            <material name="Blue">
                <color rgba="0 0 1.0 1.0"/>
            </material>
        </visual>
        <collision>
            <origin xyz="0.44188507750977357 0.0 0.0" rpy="0 0 0"/>
            <geometry>
                <box size="0.8837701550195471 0.6420857037292812 0.5292775559317915" />
            </geometry>
        </collision>
    </link>
    <joint name="4_11" type="revolute">
       <parent link="4"/>
       <child  link="11"/>
       <origin rpy="0 0 0" xyz="-0.5578632349181952 0.25375008123652365 0.0" />
     <axis xyz="1 0 0"/>
       <limit effort="0.0" lower="-3.14159" upper="3.14159" velocity="0.0"/>
    </joint>
    <link name="11">
        <inertial>
            <origin xyz="0.0 0.4053725129826419 0.0" rpy="0 0 0"/>
            <mass value="1" />
            <inertia ixx="100" ixy="0" ixz="0" iyy="100" iyz="0" izz="100" />
        </inertial>
        <visual>
            <origin xyz="0.0 0.4053725129826419 0.0" rpy="0 0 0"/>
            <geometry>
                <box size="0.44082534480013713 0.8107450259652837 0.6252500679044837" />
            </geometry>
            <material name="Green">
                <color rgba="0 1.0 0 1.0"/>
            </material>
        </visual>
        <collision>
            <origin xyz="0.0 0.4053725129826419 0.0" rpy="0 0 0"/>
            <geometry>
                <box size="0.44082534480013713 0.8107450259652837 0.6252500679044837" />
            </geometry>
        </collision>
    </link>
    <joint name="5_10" type="revolute">
       <parent link="5"/>
       <child  link="10"/>
       <origin rpy="0 0 0" xyz="-0.24102694787770249 0.0 -0.24050628603262536" />
     <axis xyz="0 1 0"/>
       <limit effort="0.0" lower="-3.14159" upper="3.14159" velocity="0.0"/>
    </joint>
    <link name="10">
        <inertial>
            <origin xyz="0.0 0.0 -0.47780189391440375" rpy="0 0 0"/>
            <mass value="1" />
            <inertia ixx="100" ixy="0" ixz="0" iyy="100" iyz="0" izz="100" />
        </inertial>
        <visual>
            <origin xyz="0.0 0.0 -0.47780189391440375" rpy="0 0 0"/>
            <geometry>
                <box size="0.40461950695017035 0.9300843290991572 0.9556037878288075" />
            </geometry>
            <material name="Green">
                <color rgba="0 1.0 0 1.0"/>
            </material>
        </visual>
        <collision>
            <origin xyz="0.0 0.0 -0.47780189391440375" rpy="0 0 0"/>
            <geometry>
                <box size="0.40461950695017035 0.9300843290991572 0.9556037878288075" />
            </geometry>
        </collision>
    </link>
    <joint name="3_12" type="revolute">
       <parent link="3"/>
       <child  link="12"/>
       <origin rpy="0 0 0" xyz="0.4920352330083408 -0.4900102257404214 0.0" />
     <axis xyz="0 1 0"/>
       <limit effort="0.0" lower="-3.14159" upper="3.14159" velocity="0.0"/>
    </joint>
    <link name="12">
        <inertial>
            <origin xyz="0.0 -0.4872388536349161 0.0" rpy="0 0 0"/>
            <mass value="1" />
            <inertia ixx="100" ixy="0" ixz="0" iyy="100" iyz="0" izz="100" />
        </inertial>
        <visual>
            <origin xyz="0.0 -0.4872388536349161 0.0" rpy="0 0 0"/>
            <geometry>
                <box size="0.8939853294613571 0.9744777072698322 1.0163395273873945" />
            </geometry>
            <material name="Blue">
                <color rgba="0 0 1.0 1.0"/>
            </material>
        </visual>
        <collision>
            <origin xyz="0.0 -0.4872388536349161 0.0" rpy="0 0 0"/>
            <geometry>
                <box size="0.8939853294613571 0.9744777072698322 1.0163395273873945" />
            </geometry>
        </collision>
    </link>
</robot>