<robot name = "robot">
    <link name="0">
        <inertial>
            <origin xyz="0 0 3.2976548029598405" rpy="0 0 0"/>
            <mass value="1" />
            <inertia ixx="100" ixy="0" ixz="0" iyy="100" iyz="0" izz="100" />
        </inertial>
        <visual>
            <origin xyz="0 0 3.2976548029598405" rpy="0 0 0"/>
            <geometry>
                <box size="1.0452870330013448 0.8246695325158966 0.5953096059196807" />
            </geometry>
            <material name="Blue">
                <color rgba="0 0 1.0 1.0"/>
            </material>
        </visual>
        <collision>
            <origin xyz="0 0 3.2976548029598405" rpy="0 0 0"/>
            <geometry>
                <box size="1.0452870330013448 0.8246695325158966 0.5953096059196807" />
            </geometry>
        </collision>
    </link>
    <joint name="0_1" type="revolute">
       <parent link="0"/>
       <child  link="1"/>
       <origin rpy="0 0 0" xyz="0.0 0.0 3.595309605919681" />
     <axis xyz="0 1 0"/>
       <limit effort="0.0" lower="-3.14159" upper="3.14159" velocity="0.0"/>
    </joint>
    <link name="1">
        <inertial>
            <origin xyz="0.0 0.0 0.3672161591896039" rpy="0 0 0"/>
            <mass value="1" />
            <inertia ixx="100" ixy="0" ixz="0" iyy="100" iyz="0" izz="100" />
        </inertial>
        <visual>
            <origin xyz="0.0 0.0 0.3672161591896039" rpy="0 0 0"/>
            <geometry>
                <box size="1.0039271759149955 0.5435388542527861 0.7344323183792077" />
            </geometry>
            <material name="Green">
                <color rgba="0 1.0 0 1.0"/>
            </material>
        </visual>
        <collision>
            <origin xyz="0.0 0.0 0.3672161591896039" rpy="0 0 0"/>
            <geometry>
                <box size="1.0039271759149955 0.5435388542527861 0.7344323183792077" />
            </geometry>
        </collision>
    </link>
    <joint name="1_2" type="revolute">
       <parent link="1"/>
       <child  link="2"/>
       <origin rpy="0 0 0" xyz="0.0 0.27176942712639307 0.3672161591896039" />
     <axis xyz="0 1 0"/>
       <limit effort="0.0" lower="-3.14159" upper="3.14159" velocity="0.0"/>
    </joint>
    <link name="2">
        <inertial>
            <origin xyz="0.0 0.2068075130848157 0.0" rpy="0 0 0"/>
            <mass value="1" />
            <inertia ixx="100" ixy="0" ixz="0" iyy="100" iyz="0" izz="100" />
        </inertial>
        <visual>
            <origin xyz="0.0 0.2068075130848157 0.0" rpy="0 0 0"/>
            <geometry>
                <box size="0.5477749437958954 0.4136150261696314 0.3970508936162447" />
            </geometry>
            <material name="Blue">
                <color rgba="0 0 1.0 1.0"/>
            </material>
        </visual>
        <collision>
            <origin xyz="0.0 0.2068075130848157 0.0" rpy="0 0 0"/>
            <geometry>
                <box size="0.5477749437958954 0.4136150261696314 0.3970508936162447" />
            </geometry>
        </collision>
    </link>
    <joint name="1_3" type="revolute">
       <parent link="1"/>
       <child  link="3"/>
       <origin rpy="0 0 0" xyz="0.0 -0.27176942712639307 0.3672161591896039" />
     <axis xyz="0 1 0"/>
       <limit effort="0.0" lower="-3.14159" upper="3.14159" velocity="0.0"/>
    </joint>
    <link name="3">
        <inertial>
            <origin xyz="0.0 -0.4671708799643705 0.0" rpy="0 0 0"/>
            <mass value="1" />
            <inertia ixx="100" ixy="0" ixz="0" iyy="100" iyz="0" izz="100" />
        </inertial>
        <visual>
            <origin xyz="0.0 -0.4671708799643705 0.0" rpy="0 0 0"/>
            <geometry>
                <box size="0.790114119240029 0.934341759928741 0.5105176246633811" />
            </geometry>
            <material name="Blue">
                <color rgba="0 0 1.0 1.0"/>
            </material>
        </visual>
        <collision>
            <origin xyz="0.0 -0.4671708799643705 0.0" rpy="0 0 0"/>
            <geometry>
                <box size="0.790114119240029 0.934341759928741 0.5105176246633811" />
            </geometry>
        </collision>
    </link>
    <joint name="3_4" type="revolute">
       <parent link="3"/>
       <child  link="4"/>
       <origin rpy="0 0 0" xyz="0.0 -0.934341759928741 0.0" />
     <axis xyz="1 0 0"/>
       <limit effort="0.0" lower="-3.14159" upper="3.14159" velocity="0.0"/>
    </joint>
    <link name="4">
        <inertial>
            <origin xyz="0.0 -0.45448542891600413 0.0" rpy="0 0 0"/>
            <mass value="1" />
            <inertia ixx="100" ixy="0" ixz="0" iyy="100" iyz="0" izz="100" />
        </inertial>
        <visual>
            <origin xyz="0.0 -0.45448542891600413 0.0" rpy="0 0 0"/>
            <geometry>
                <box size="0.5406463140769058 0.9089708578320083 0.7142075557908953" />
            </geometry>
            <material name="Blue">
                <color rgba="0 0 1.0 1.0"/>
            </material>
        </visual>
        <collision>
            <origin xyz="0.0 -0.45448542891600413 0.0" rpy="0 0 0"/>
            <geometry>
                <box size="0.5406463140769058 0.9089708578320083 0.7142075557908953" />
            </geometry>
        </collision>
    </link>
    <joint name="3_5" type="revolute">
       <parent link="3"/>
       <child  link="5"/>
       <origin rpy="0 0 0" xyz="0.3950570596200145 -0.4671708799643705 0.0" />
     <axis xyz="0 1 0"/>
       <limit effort="0.0" lower="-3.14159" upper="3.14159" velocity="0.0"/>
    </joint>
    <link name="5">
        <inertial>
            <origin xyz="0.3908910974113133 0.0 0.0" rpy="0 0 0"/>
            <mass value="1" />
            <inertia ixx="100" ixy="0" ixz="0" iyy="100" iyz="0" izz="100" />
        </inertial>
        <visual>
            <origin xyz="0.3908910974113133 0.0 0.0" rpy="0 0 0"/>
            <geometry>
                <box size="0.7817821948226266 0.535126089217007 0.6080679300194983" />
            </geometry>
            <material name="Green">
                <color rgba="0 1.0 0 1.0"/>
            </material>
        </visual>
        <collision>
            <origin xyz="0.3908910974113133 0.0 0.0" rpy="0 0 0"/>
            <geometry>
                <box size="0.7817821948226266 0.535126089217007 0.6080679300194983" />
            </geometry>
        </collision>
    </link>
    <joint name="1_6" type="revolute">
       <parent link="1"/>
       <child  link="6"/>
       <origin rpy="0 0 0" xyz="0.5019635879574977 0.0 0.3672161591896039" />
     <axis xyz="0 1 0"/>
       <limit effort="0.0" lower="-3.14159" upper="3.14159" velocity="0.0"/>
    </joint>
    <link name="6">
        <inertial>
            <origin xyz="0.22525049258087138 0.0 0.0" rpy="0 0 0"/>
            <mass value="1" />
            <inertia ixx="100" ixy="0" ixz="0" iyy="100" iyz="0" izz="100" />
        </inertial>
        <visual>
            <origin xyz="0.22525049258087138 0.0 0.0" rpy="0 0 0"/>
            <geometry>
                <box size="0.45050098516174275 0.7134818045518554 0.5516694910981064" />
            </geometry>
            <material name="Green">
                <color rgba="0 1.0 0 1.0"/>
            </material>
        </visual>
        <collision>
            <origin xyz="0.22525049258087138 0.0 0.0" rpy="0 0 0"/>
            <geometry>
                <box size="0.45050098516174275 0.7134818045518554 0.5516694910981064" />
            </geometry>
        </collision>
    </link>
</robot>