<robot name = "robot">
    <link name="0">
        <inertial>
            <origin xyz="0 0 3.2976548029598405" rpy="0 0 0"/>
            <mass value="1" />
            <inertia ixx="100" ixy="0" ixz="0" iyy="100" iyz="0" izz="100" />
        </inertial>
        <visual>
            <origin xyz="0 0 3.2976548029598405" rpy="0 0 0"/>
            <geometry>
                <box size="1.0452870330013448 0.8246695325158966 0.5953096059196807" />
            </geometry>
            <material name="Blue">
                <color rgba="0 0 1.0 1.0"/>
            </material>
        </visual>
        <collision>
            <origin xyz="0 0 3.2976548029598405" rpy="0 0 0"/>
            <geometry>
                <box size="1.0452870330013448 0.8246695325158966 0.5953096059196807" />
            </geometry>
        </collision>
    </link>
    <joint name="0_1" type="revolute">
       <parent link="0"/>
       <child  link="1"/>
       <origin rpy="0 0 0" xyz="0.0 0.0 3.595309605919681" />
     <axis xyz="0 1 0"/>
       <limit effort="0.0" lower="-3.14159" upper="3.14159" velocity="0.0"/>
    </joint>
    <link name="1">
        <inertial>
            <origin xyz="0.0 0.0 0.3672161591896039" rpy="0 0 0"/>
            <mass value="1" />
            <inertia ixx="100" ixy="0" ixz="0" iyy="100" iyz="0" izz="100" />
        </inertial>
        <visual>
            <origin xyz="0.0 0.0 0.3672161591896039" rpy="0 0 0"/>
            <geometry>
                <box size="1.0039271759149955 0.5435388542527861 0.7344323183792077" />
            </geometry>
            <material name="Green">
                <color rgba="0 1.0 0 1.0"/>
            </material>
        </visual>
        <collision>
            <origin xyz="0.0 0.0 0.3672161591896039" rpy="0 0 0"/>
            <geometry>
                <box size="1.0039271759149955 0.5435388542527861 0.7344323183792077" />
            </geometry>
        </collision>
    </link>
    <joint name="1_2" type="revolute">
       <parent link="1"/>
       <child  link="2"/>
       <origin rpy="0 0 0" xyz="0.0 0.27176942712639307 0.3672161591896039" />
     <axis xyz="0 1 0"/>
       <limit effort="0.0" lower="-3.14159" upper="3.14159" velocity="0.0"/>
    </joint>
    <link name="2">
        <inertial>
            <origin xyz="0.0 0.2068075130848157 0.0" rpy="0 0 0"/>
            <mass value="1" />
            <inertia ixx="100" ixy="0" ixz="0" iyy="100" iyz="0" izz="100" />
        </inertial>
        <visual>
            <origin xyz="0.0 0.2068075130848157 0.0" rpy="0 0 0"/>
            <geometry>
                <box size="0.5477749437958954 0.4136150261696314 0.3970508936162447" />
            </geometry>
            <material name="Blue">
                <color rgba="0 0 1.0 1.0"/>
            </material>
        </visual>
        <collision>
            <origin xyz="0.0 0.2068075130848157 0.0" rpy="0 0 0"/>
            <geometry>
                <box size="0.5477749437958954 0.4136150261696314 0.3970508936162447" />
            </geometry>
        </collision>
    </link>
    <joint name="1_6" type="revolute">
       <parent link="1"/>
       <child  link="6"/>
       <origin rpy="0 0 0" xyz="0.5019635879574977 0.0 0.3672161591896039" />
     <axis xyz="0 1 0"/>
       <limit effort="0.0" lower="-3.14159" upper="3.14159" velocity="0.0"/>
    </joint>
    <link name="6">
        <inertial>
            <origin xyz="0.22525049258087138 0.0 0.0" rpy="0 0 0"/>
            <mass value="1" />
            <inertia ixx="100" ixy="0" ixz="0" iyy="100" iyz="0" izz="100" />
        </inertial>
        <visual>
            <origin xyz="0.22525049258087138 0.0 0.0" rpy="0 0 0"/>
            <geometry>
                <box size="0.45050098516174275 0.7134818045518554 0.5516694910981064" />
            </geometry>
            <material name="Green">
                <color rgba="0 1.0 0 1.0"/>
            </material>
        </visual>
        <collision>
            <origin xyz="0.22525049258087138 0.0 0.0" rpy="0 0 0"/>
            <geometry>
                <box size="0.45050098516174275 0.7134818045518554 0.5516694910981064" />
            </geometry>
        </collision>
    </link>
    <joint name="0_3" type="revolute">
       <parent link="0"/>
       <child  link="3"/>
       <origin rpy="0 0 0" xyz="0.5226435165006724 0.0 3.2976548029598405" />
     <axis xyz="0 1 0"/>
       <limit effort="0.0" lower="-3.14159" upper="3.14159" velocity="0.0"/>
    </joint>
    <link name="3">
        <inertial>
            <origin xyz="0.483659450381014 0.0 0.0" rpy="0 0 0"/>
            <mass value="1" />
            <inertia ixx="100" ixy="0" ixz="0" iyy="100" iyz="0" izz="100" />
        </inertial>
        <visual>
            <origin xyz="0.483659450381014 0.0 0.0" rpy="0 0 0"/>
            <geometry>
                <box size="0.967318900762028 0.6574080265835249 0.690536717322622" />
            </geometry>
            <material name="Blue">
                <color rgba="0 0 1.0 1.0"/>
            </material>
        </visual>
        <collision>
            <origin xyz="0.483659450381014 0.0 0.0" rpy="0 0 0"/>
            <geometry>
                <box size="0.967318900762028 0.6574080265835249 0.690536717322622" />
            </geometry>
        </collision>
    </link>
    <joint name="2_5" type="revolute">
       <parent link="2"/>
       <child  link="5"/>
       <origin rpy="0 0 0" xyz="0.0 0.4136150261696314 0.0" />
     <axis xyz="1 0 0"/>
       <limit effort="0.0" lower="-3.14159" upper="3.14159" velocity="0.0"/>
    </joint>
    <link name="5">
        <inertial>
            <origin xyz="0.0 0.2459661356733392 0.0" rpy="0 0 0"/>
            <mass value="1" />
            <inertia ixx="100" ixy="0" ixz="0" iyy="100" iyz="0" izz="100" />
        </inertial>
        <visual>
            <origin xyz="0.0 0.2459661356733392 0.0" rpy="0 0 0"/>
            <geometry>
                <box size="0.8516033294484961 0.4919322713466784 0.4704319957883234" />
            </geometry>
            <material name="Blue">
                <color rgba="0 0 1.0 1.0"/>
            </material>
        </visual>
        <collision>
            <origin xyz="0.0 0.2459661356733392 0.0" rpy="0 0 0"/>
            <geometry>
                <box size="0.8516033294484961 0.4919322713466784 0.4704319957883234" />
            </geometry>
        </collision>
    </link>
    <joint name="5_4" type="revolute">
       <parent link="5"/>
       <child  link="4"/>
       <origin rpy="0 0 0" xyz="0.0 0.4919322713466784 0.0" />
     <axis xyz="1 0 0"/>
       <limit effort="0.0" lower="-3.14159" upper="3.14159" velocity="0.0"/>
    </joint>
    <link name="4">
        <inertial>
            <origin xyz="0.0 0.5198797670608083 0.0" rpy="0 0 0"/>
            <mass value="1" />
            <inertia ixx="100" ixy="0" ixz="0" iyy="100" iyz="0" izz="100" />
        </inertial>
        <visual>
            <origin xyz="0.0 0.5198797670608083 0.0" rpy="0 0 0"/>
            <geometry>
                <box size="0.6034415292467554 1.0397595341216166 0.51887547094258" />
            </geometry>
            <material name="Blue">
                <color rgba="0 0 1.0 1.0"/>
            </material>
        </visual>
        <collision>
            <origin xyz="0.0 0.5198797670608083 0.0" rpy="0 0 0"/>
            <geometry>
                <box size="0.6034415292467554 1.0397595341216166 0.51887547094258" />
            </geometry>
        </collision>
    </link>
    <joint name="1_7" type="revolute">
       <parent link="1"/>
       <child  link="7"/>
       <origin rpy="0 0 0" xyz="0.0 0.0 0.7344323183792077" />
     <axis xyz="1 0 0"/>
       <limit effort="0.0" lower="-3.14159" upper="3.14159" velocity="0.0"/>
    </joint>
    <link name="7">
        <inertial>
            <origin xyz="0.0 0.0 0.3344309842271737" rpy="0 0 0"/>
            <mass value="1" />
            <inertia ixx="100" ixy="0" ixz="0" iyy="100" iyz="0" izz="100" />
        </inertial>
        <visual>
            <origin xyz="0.0 0.0 0.3344309842271737" rpy="0 0 0"/>
            <geometry>
                <box size="1.0725951964716922 0.7893088801468882 0.6688619684543474" />
            </geometry>
            <material name="Green">
                <color rgba="0 1.0 0 1.0"/>
            </material>
        </visual>
        <collision>
            <origin xyz="0.0 0.0 0.3344309842271737" rpy="0 0 0"/>
            <geometry>
                <box size="1.0725951964716922 0.7893088801468882 0.6688619684543474" />
            </geometry>
        </collision>
    </link>
    <joint name="4_8" type="revolute">
       <parent link="4"/>
       <child  link="8"/>
       <origin rpy="0 0 0" xyz="0.0 0.5198797670608083 0.25943773547129" />
     <axis xyz="1 0 0"/>
       <limit effort="0.0" lower="-3.14159" upper="3.14159" velocity="0.0"/>
    </joint>
    <link name="8">
        <inertial>
            <origin xyz="0.0 0.0 0.541260457690798" rpy="0 0 0"/>
            <mass value="1" />
            <inertia ixx="100" ixy="0" ixz="0" iyy="100" iyz="0" izz="100" />
        </inertial>
        <visual>
            <origin xyz="0.0 0.0 0.541260457690798" rpy="0 0 0"/>
            <geometry>
                <box size="0.5675172310658885 0.43613591875989866 1.082520915381596" />
            </geometry>
            <material name="Green">
                <color rgba="0 1.0 0 1.0"/>
            </material>
        </visual>
        <collision>
            <origin xyz="0.0 0.0 0.541260457690798" rpy="0 0 0"/>
            <geometry>
                <box size="0.5675172310658885 0.43613591875989866 1.082520915381596" />
            </geometry>
        </collision>
    </link>
</robot>