<robot name = "robot">
    <link name="0">
        <inertial>
            <origin xyz="0 0 3.538650795595198" rpy="0 0 0"/>
            <mass value="1" />
            <inertia ixx="100" ixy="0" ixz="0" iyy="100" iyz="0" izz="100" />
        </inertial>
        <visual>
            <origin xyz="0 0 3.538650795595198" rpy="0 0 0"/>
            <geometry>
                <box size="0.4204835252498347 0.7693889022111183 1.0773015911903956" />
            </geometry>
            <material name="Blue">
                <color rgba="0 0 1.0 1.0"/>
            </material>
        </visual>
        <collision>
            <origin xyz="0 0 3.538650795595198" rpy="0 0 0"/>
            <geometry>
                <box size="0.4204835252498347 0.7693889022111183 1.0773015911903956" />
            </geometry>
        </collision>
    </link>
    <joint name="0_1" type="revolute">
       <parent link="0"/>
       <child  link="1"/>
       <origin rpy="0 0 0" xyz="0.0 -0.38469445110555917 3.538650795595198" />
     <axis xyz="0 1 0"/>
       <limit effort="0.0" lower="-3.14159" upper="3.14159" velocity="0.0"/>
    </joint>
    <link name="1">
        <inertial>
            <origin xyz="0.0 -0.49243446794955975 0.0" rpy="0 0 0"/>
            <mass value="1" />
            <inertia ixx="100" ixy="0" ixz="0" iyy="100" iyz="0" izz="100" />
        </inertial>
        <visual>
            <origin xyz="0.0 -0.49243446794955975 0.0" rpy="0 0 0"/>
            <geometry>
                <box size="0.41991938725045486 0.9848689358991195 1.0129042970961553" />
            </geometry>
            <material name="Green">
                <color rgba="0 1.0 0 1.0"/>
            </material>
        </visual>
        <collision>
            <origin xyz="0.0 -0.49243446794955975 0.0" rpy="0 0 0"/>
            <geometry>
                <box size="0.41991938725045486 0.9848689358991195 1.0129042970961553" />
            </geometry>
        </collision>
    </link>
    <joint name="1_3" type="revolute">
       <parent link="1"/>
       <child  link="3"/>
       <origin rpy="0 0 0" xyz="0.0 -0.9848689358991195 0.0" />
     <axis xyz="1 0 0"/>
       <limit effort="0.0" lower="-3.14159" upper="3.14159" velocity="0.0"/>
    </joint>
    <link name="3">
        <inertial>
            <origin xyz="0.0 -0.3670120073691493 0.0" rpy="0 0 0"/>
            <mass value="1" />
            <inertia ixx="100" ixy="0" ixz="0" iyy="100" iyz="0" izz="100" />
        </inertial>
        <visual>
            <origin xyz="0.0 -0.3670120073691493 0.0" rpy="0 0 0"/>
            <geometry>
                <box size="0.7390578057690914 0.7340240147382986 1.0519977783197794" />
            </geometry>
            <material name="Green">
                <color rgba="0 1.0 0 1.0"/>
            </material>
        </visual>
        <collision>
            <origin xyz="0.0 -0.3670120073691493 0.0" rpy="0 0 0"/>
            <geometry>
                <box size="0.7390578057690914 0.7340240147382986 1.0519977783197794" />
            </geometry>
        </collision>
    </link>
    <joint name="1_4" type="revolute">
       <parent link="1"/>
       <child  link="4"/>
       <origin rpy="0 0 0" xyz="0.20995969362522743 -0.49243446794955975 0.0" />
     <axis xyz="1 0 0"/>
       <limit effort="0.0" lower="-3.14159" upper="3.14159" velocity="0.0"/>
    </joint>
    <link name="4">
        <inertial>
            <origin xyz="0.3706710639116183 0.0 0.0" rpy="0 0 0"/>
            <mass value="1" />
            <inertia ixx="100" ixy="0" ixz="0" iyy="100" iyz="0" izz="100" />
        </inertial>
        <visual>
            <origin xyz="0.3706710639116183 0.0 0.0" rpy="0 0 0"/>
            <geometry>
                <box size="0.7413421278232366 0.732419022686744 0.4045564186260885" />
            </geometry>
            <material name="Green">
                <color rgba="0 1.0 0 1.0"/>
            </material>
        </visual>
        <collision>
            <origin xyz="0.3706710639116183 0.0 0.0" rpy="0 0 0"/>
            <geometry>
                <box size="0.7413421278232366 0.732419022686744 0.4045564186260885" />
            </geometry>
        </collision>
    </link>
    <joint name="1_5" type="revolute">
       <parent link="1"/>
       <child  link="5"/>
       <origin rpy="0 0 0" xyz="0.0 -0.49243446794955975 -0.5064521485480776" />
     <axis xyz="0 1 0"/>
       <limit effort="0.0" lower="-3.14159" upper="3.14159" velocity="0.0"/>
    </joint>
    <link name="5">
        <inertial>
            <origin xyz="0.0 0.0 -0.2313625691458765" rpy="0 0 0"/>
            <mass value="1" />
            <inertia ixx="100" ixy="0" ixz="0" iyy="100" iyz="0" izz="100" />
        </inertial>
        <visual>
            <origin xyz="0.0 0.0 -0.2313625691458765" rpy="0 0 0"/>
            <geometry>
                <box size="1.0227843025083483 0.6567920258373945 0.462725138291753" />
            </geometry>
            <material name="Blue">
                <color rgba="0 0 1.0 1.0"/>
            </material>
        </visual>
        <collision>
            <origin xyz="0.0 0.0 -0.2313625691458765" rpy="0 0 0"/>
            <geometry>
                <box size="1.0227843025083483 0.6567920258373945 0.462725138291753" />
            </geometry>
        </collision>
    </link>
    <joint name="1_6" type="revolute">
       <parent link="1"/>
       <child  link="6"/>
       <origin rpy="0 0 0" xyz="-0.20995969362522743 -0.49243446794955975 0.0" />
     <axis xyz="0 1 0"/>
       <limit effort="0.0" lower="-3.14159" upper="3.14159" velocity="0.0"/>
    </joint>
    <link name="6">
        <inertial>
            <origin xyz="-0.3628157542609791 0.0 0.0" rpy="0 0 0"/>
            <mass value="1" />
            <inertia ixx="100" ixy="0" ixz="0" iyy="100" iyz="0" izz="100" />
        </inertial>
        <visual>
            <origin xyz="-0.3628157542609791 0.0 0.0" rpy="0 0 0"/>
            <geometry>
                <box size="0.7256315085219582 0.8121586323409665 0.5449047423778276" />
            </geometry>
            <material name="Green">
                <color rgba="0 1.0 0 1.0"/>
            </material>
        </visual>
        <collision>
            <origin xyz="-0.3628157542609791 0.0 0.0" rpy="0 0 0"/>
            <geometry>
                <box size="0.7256315085219582 0.8121586323409665 0.5449047423778276" />
            </geometry>
        </collision>
    </link>
    <joint name="6_7" type="revolute">
       <parent link="6"/>
       <child  link="7"/>
       <origin rpy="0 0 0" xyz="-0.3628157542609791 -0.40607931617048326 0.0" />
     <axis xyz="0 1 0"/>
       <limit effort="0.0" lower="-3.14159" upper="3.14159" velocity="0.0"/>
    </joint>
    <link name="7">
        <inertial>
            <origin xyz="0.0 -0.21969112872967486 0.0" rpy="0 0 0"/>
            <mass value="1" />
            <inertia ixx="100" ixy="0" ixz="0" iyy="100" iyz="0" izz="100" />
        </inertial>
        <visual>
            <origin xyz="0.0 -0.21969112872967486 0.0" rpy="0 0 0"/>
            <geometry>
                <box size="0.393393157199713 0.4393822574593497 0.919962943561726" />
            </geometry>
            <material name="Green">
                <color rgba="0 1.0 0 1.0"/>
            </material>
        </visual>
        <collision>
            <origin xyz="0.0 -0.21969112872967486 0.0" rpy="0 0 0"/>
            <geometry>
                <box size="0.393393157199713 0.4393822574593497 0.919962943561726" />
            </geometry>
        </collision>
    </link>
    <joint name="0_8" type="revolute">
       <parent link="0"/>
       <child  link="8"/>
       <origin rpy="0 0 0" xyz="-0.21024176262491734 0.0 3.538650795595198" />
     <axis xyz="0 1 0"/>
       <limit effort="0.0" lower="-3.14159" upper="3.14159" velocity="0.0"/>
    </joint>
    <link name="8">
        <inertial>
            <origin xyz="-0.4912511245956853 0.0 0.0" rpy="0 0 0"/>
            <mass value="1" />
            <inertia ixx="100" ixy="0" ixz="0" iyy="100" iyz="0" izz="100" />
        </inertial>
        <visual>
            <origin xyz="-0.4912511245956853 0.0 0.0" rpy="0 0 0"/>
            <geometry>
                <box size="0.9825022491913706 0.8355742031837604 0.37833675369160435" />
            </geometry>
            <material name="Blue">
                <color rgba="0 0 1.0 1.0"/>
            </material>
        </visual>
        <collision>
            <origin xyz="-0.4912511245956853 0.0 0.0" rpy="0 0 0"/>
            <geometry>
                <box size="0.9825022491913706 0.8355742031837604 0.37833675369160435" />
            </geometry>
        </collision>
    </link>
    <joint name="6_2" type="revolute">
       <parent link="6"/>
       <child  link="2"/>
       <origin rpy="0 0 0" xyz="-0.7256315085219582 0.0 0.0" />
     <axis xyz="0 1 0"/>
       <limit effort="0.0" lower="-3.14159" upper="3.14159" velocity="0.0"/>
    </joint>
    <link name="2">
        <inertial>
            <origin xyz="-0.2935230043930655 0.0 0.0" rpy="0 0 0"/>
            <mass value="1" />
            <inertia ixx="100" ixy="0" ixz="0" iyy="100" iyz="0" izz="100" />
        </inertial>
        <visual>
            <origin xyz="-0.2935230043930655 0.0 0.0" rpy="0 0 0"/>
            <geometry>
                <box size="0.587046008786131 0.685020027983906 1.0866578732418315" />
            </geometry>
            <material name="Green">
                <color rgba="0 1.0 0 1.0"/>
            </material>
        </visual>
        <collision>
            <origin xyz="-0.2935230043930655 0.0 0.0" rpy="0 0 0"/>
            <geometry>
                <box size="0.587046008786131 0.685020027983906 1.0866578732418315" />
            </geometry>
        </collision>
    </link>
    <joint name="0_9" type="revolute">
       <parent link="0"/>
       <child  link="9"/>
       <origin rpy="0 0 0" xyz="0.0 0.0 3.0" />
     <axis xyz="0 1 0"/>
       <limit effort="0.0" lower="-3.14159" upper="3.14159" velocity="0.0"/>
    </joint>
    <link name="9">
        <inertial>
            <origin xyz="0.0 0.0 -0.5585069225554818" rpy="0 0 0"/>
            <mass value="1" />
            <inertia ixx="100" ixy="0" ixz="0" iyy="100" iyz="0" izz="100" />
        </inertial>
        <visual>
            <origin xyz="0.0 0.0 -0.5585069225554818" rpy="0 0 0"/>
            <geometry>
                <box size="0.662542233435499 0.7772623854223786 1.1170138451109637" />
            </geometry>
            <material name="Blue">
                <color rgba="0 0 1.0 1.0"/>
            </material>
        </visual>
        <collision>
            <origin xyz="0.0 0.0 -0.5585069225554818" rpy="0 0 0"/>
            <geometry>
                <box size="0.662542233435499 0.7772623854223786 1.1170138451109637" />
            </geometry>
        </collision>
    </link>
    <joint name="9_10" type="revolute">
       <parent link="9"/>
       <child  link="10"/>
       <origin rpy="0 0 0" xyz="0.0 0.3886311927111893 -0.5585069225554818" />
     <axis xyz="0 1 0"/>
       <limit effort="0.0" lower="-3.14159" upper="3.14159" velocity="0.0"/>
    </joint>
    <link name="10">
        <inertial>
            <origin xyz="0.0 0.2961885771766414 0.0" rpy="0 0 0"/>
            <mass value="1" />
            <inertia ixx="100" ixy="0" ixz="0" iyy="100" iyz="0" izz="100" />
        </inertial>
        <visual>
            <origin xyz="0.0 0.2961885771766414 0.0" rpy="0 0 0"/>
            <geometry>
                <box size="0.43200718621140083 0.5923771543532828 0.9260614703759779" />
            </geometry>
            <material name="Blue">
                <color rgba="0 0 1.0 1.0"/>
            </material>
        </visual>
        <collision>
            <origin xyz="0.0 0.2961885771766414 0.0" rpy="0 0 0"/>
            <geometry>
                <box size="0.43200718621140083 0.5923771543532828 0.9260614703759779" />
            </geometry>
        </collision>
    </link>
</robot>