<robot name = "robot">
    <link name="0">
        <inertial>
            <origin xyz="0 0 3.465475031978208" rpy="0 0 0"/>
            <mass value="1" />
            <inertia ixx="100" ixy="0" ixz="0" iyy="100" iyz="0" izz="100" />
        </inertial>
        <visual>
            <origin xyz="0 0 3.465475031978208" rpy="0 0 0"/>
            <geometry>
                <box size="0.5566394177057365 0.37963254714511074 0.9309500639564168" />
            </geometry>
            <material name="Blue">
                <color rgba="0 0 1.0 1.0"/>
            </material>
        </visual>
        <collision>
            <origin xyz="0 0 3.465475031978208" rpy="0 0 0"/>
            <geometry>
                <box size="0.5566394177057365 0.37963254714511074 0.9309500639564168" />
            </geometry>
        </collision>
    </link>
    <joint name="0_1" type="revolute">
       <parent link="0"/>
       <child  link="1"/>
       <origin rpy="0 0 0" xyz="-0.2783197088528683 0.0 3.465475031978208" />
     <axis xyz="1 0 0"/>
       <limit effort="0.0" lower="-3.14159" upper="3.14159" velocity="0.0"/>
    </joint>
    <link name="1">
        <inertial>
            <origin xyz="-0.528387172334843 0.0 0.0" rpy="0 0 0"/>
            <mass value="1" />
            <inertia ixx="100" ixy="0" ixz="0" iyy="100" iyz="0" izz="100" />
        </inertial>
        <visual>
            <origin xyz="-0.528387172334843 0.0 0.0" rpy="0 0 0"/>
            <geometry>
                <box size="1.056774344669686 0.9018253637181126 0.44793822567017194" />
            </geometry>
            <material name="Blue">
                <color rgba="0 0 1.0 1.0"/>
            </material>
        </visual>
        <collision>
            <origin xyz="-0.528387172334843 0.0 0.0" rpy="0 0 0"/>
            <geometry>
                <box size="1.056774344669686 0.9018253637181126 0.44793822567017194" />
            </geometry>
        </collision>
    </link>
    <joint name="0_2" type="revolute">
       <parent link="0"/>
       <child  link="2"/>
       <origin rpy="0 0 0" xyz="0.0 0.18981627357255537 3.465475031978208" />
     <axis xyz="1 0 0"/>
       <limit effort="0.0" lower="-3.14159" upper="3.14159" velocity="0.0"/>
    </joint>
    <link name="2">
        <inertial>
            <origin xyz="0.0 0.23518722662720004 0.0" rpy="0 0 0"/>
            <mass value="1" />
            <inertia ixx="100" ixy="0" ixz="0" iyy="100" iyz="0" izz="100" />
        </inertial>
        <visual>
            <origin xyz="0.0 0.23518722662720004 0.0" rpy="0 0 0"/>
            <geometry>
                <box size="0.5460246248753539 0.4703744532544001 1.0950235116549214" />
            </geometry>
            <material name="Green">
                <color rgba="0 1.0 0 1.0"/>
            </material>
        </visual>
        <collision>
            <origin xyz="0.0 0.23518722662720004 0.0" rpy="0 0 0"/>
            <geometry>
                <box size="0.5460246248753539 0.4703744532544001 1.0950235116549214" />
            </geometry>
        </collision>
    </link>
    <joint name="0_3" type="revolute">
       <parent link="0"/>
       <child  link="3"/>
       <origin rpy="0 0 0" xyz="0.0 -0.18981627357255537 3.465475031978208" />
     <axis xyz="1 0 0"/>
       <limit effort="0.0" lower="-3.14159" upper="3.14159" velocity="0.0"/>
    </joint>
    <link name="3">
        <inertial>
            <origin xyz="0.0 -0.3595946656903862 0.0" rpy="0 0 0"/>
            <mass value="1" />
            <inertia ixx="100" ixy="0" ixz="0" iyy="100" iyz="0" izz="100" />
        </inertial>
        <visual>
            <origin xyz="0.0 -0.3595946656903862 0.0" rpy="0 0 0"/>
            <geometry>
                <box size="0.4357922590677997 0.7191893313807723 0.4343916373848756" />
            </geometry>
            <material name="Green">
                <color rgba="0 1.0 0 1.0"/>
            </material>
        </visual>
        <collision>
            <origin xyz="0.0 -0.3595946656903862 0.0" rpy="0 0 0"/>
            <geometry>
                <box size="0.4357922590677997 0.7191893313807723 0.4343916373848756" />
            </geometry>
        </collision>
    </link>
    <joint name="3_4" type="revolute">
       <parent link="3"/>
       <child  link="4"/>
       <origin rpy="0 0 0" xyz="0.0 -0.3595946656903862 -0.2171958186924378" />
     <axis xyz="0 1 0"/>
       <limit effort="0.0" lower="-3.14159" upper="3.14159" velocity="0.0"/>
    </joint>
    <link name="4">
        <inertial>
            <origin xyz="0.0 0.0 -0.5582767650552891" rpy="0 0 0"/>
            <mass value="1" />
            <inertia ixx="100" ixy="0" ixz="0" iyy="100" iyz="0" izz="100" />
        </inertial>
        <visual>
            <origin xyz="0.0 0.0 -0.5582767650552891" rpy="0 0 0"/>
            <geometry>
                <box size="0.4278196992526035 0.6467279647534833 1.1165535301105782" />
            </geometry>
            <material name="Blue">
                <color rgba="0 0 1.0 1.0"/>
            </material>
        </visual>
        <collision>
            <origin xyz="0.0 0.0 -0.5582767650552891" rpy="0 0 0"/>
            <geometry>
                <box size="0.4278196992526035 0.6467279647534833 1.1165535301105782" />
            </geometry>
        </collision>
    </link>
    <joint name="1_5" type="revolute">
       <parent link="1"/>
       <child  link="5"/>
       <origin rpy="0 0 0" xyz="-0.528387172334843 -0.4509126818590563 0.0" />
     <axis xyz="0 1 0"/>
       <limit effort="0.0" lower="-3.14159" upper="3.14159" velocity="0.0"/>
    </joint>
    <link name="5">
        <inertial>
            <origin xyz="0.0 -0.34804913017674044 0.0" rpy="0 0 0"/>
            <mass value="1" />
            <inertia ixx="100" ixy="0" ixz="0" iyy="100" iyz="0" izz="100" />
        </inertial>
        <visual>
            <origin xyz="0.0 -0.34804913017674044 0.0" rpy="0 0 0"/>
            <geometry>
                <box size="1.0385800835624281 0.6960982603534809 0.7919196083925629" />
            </geometry>
            <material name="Blue">
                <color rgba="0 0 1.0 1.0"/>
            </material>
        </visual>
        <collision>
            <origin xyz="0.0 -0.34804913017674044 0.0" rpy="0 0 0"/>
            <geometry>
                <box size="1.0385800835624281 0.6960982603534809 0.7919196083925629" />
            </geometry>
        </collision>
    </link>
    <joint name="1_6" type="revolute">
       <parent link="1"/>
       <child  link="6"/>
       <origin rpy="0 0 0" xyz="-0.528387172334843 0.0 -0.22396911283508597" />
     <axis xyz="1 0 0"/>
       <limit effort="0.0" lower="-3.14159" upper="3.14159" velocity="0.0"/>
    </joint>
    <link name="6">
        <inertial>
            <origin xyz="0.0 0.0 -0.22059770792857925" rpy="0 0 0"/>
            <mass value="1" />
            <inertia ixx="100" ixy="0" ixz="0" iyy="100" iyz="0" izz="100" />
        </inertial>
        <visual>
            <origin xyz="0.0 0.0 -0.22059770792857925" rpy="0 0 0"/>
            <geometry>
                <box size="0.8326909456502929 0.8434251233321373 0.4411954158571585" />
            </geometry>
            <material name="Green">
                <color rgba="0 1.0 0 1.0"/>
            </material>
        </visual>
        <collision>
            <origin xyz="0.0 0.0 -0.22059770792857925" rpy="0 0 0"/>
            <geometry>
                <box size="0.8326909456502929 0.8434251233321373 0.4411954158571585" />
            </geometry>
        </collision>
    </link>
    <joint name="4_7" type="revolute">
       <parent link="4"/>
       <child  link="7"/>
       <origin rpy="0 0 0" xyz="0.0 0.0 -1.1165535301105782" />
     <axis xyz="1 0 0"/>
       <limit effort="0.0" lower="-3.14159" upper="3.14159" velocity="0.0"/>
    </joint>
    <link name="7">
        <inertial>
            <origin xyz="0.0 0.0 -0.5198763939645601" rpy="0 0 0"/>
            <mass value="1" />
            <inertia ixx="100" ixy="0" ixz="0" iyy="100" iyz="0" izz="100" />
        </inertial>
        <visual>
            <origin xyz="0.0 0.0 -0.5198763939645601" rpy="0 0 0"/>
            <geometry>
                <box size="0.5595375139546748 0.8695958479189627 1.0397527879291202" />
            </geometry>
            <material name="Blue">
                <color rgba="0 0 1.0 1.0"/>
            </material>
        </visual>
        <collision>
            <origin xyz="0.0 0.0 -0.5198763939645601" rpy="0 0 0"/>
            <geometry>
                <box size="0.5595375139546748 0.8695958479189627 1.0397527879291202" />
            </geometry>
        </collision>
    </link>
    <joint name="1_8" type="revolute">
       <parent link="1"/>
       <child  link="8"/>
       <origin rpy="0 0 0" xyz="-1.056774344669686 0.0 0.0" />
     <axis xyz="1 0 0"/>
       <limit effort="0.0" lower="-3.14159" upper="3.14159" velocity="0.0"/>
    </joint>
    <link name="8">
        <inertial>
            <origin xyz="-0.4754840415977315 0.0 0.0" rpy="0 0 0"/>
            <mass value="1" />
            <inertia ixx="100" ixy="0" ixz="0" iyy="100" iyz="0" izz="100" />
        </inertial>
        <visual>
            <origin xyz="-0.4754840415977315 0.0 0.0" rpy="0 0 0"/>
            <geometry>
                <box size="0.950968083195463 0.7982694919387564 0.6791941731094494" />
            </geometry>
            <material name="Blue">
                <color rgba="0 0 1.0 1.0"/>
            </material>
        </visual>
        <collision>
            <origin xyz="-0.4754840415977315 0.0 0.0" rpy="0 0 0"/>
            <geometry>
                <box size="0.950968083195463 0.7982694919387564 0.6791941731094494" />
            </geometry>
        </collision>
    </link>
</robot>