<robot name = "robot">
    <link name="0">
        <inertial>
            <origin xyz="0 0 3.312223326911969" rpy="0 0 0"/>
            <mass value="1" />
            <inertia ixx="100" ixy="0" ixz="0" iyy="100" iyz="0" izz="100" />
        </inertial>
        <visual>
            <origin xyz="0 0 3.312223326911969" rpy="0 0 0"/>
            <geometry>
                <box size="0.5653528306206398 0.43164431629994404 0.6244466538239382" />
            </geometry>
            <material name="Blue">
                <color rgba="0 0 1.0 1.0"/>
            </material>
        </visual>
        <collision>
            <origin xyz="0 0 3.312223326911969" rpy="0 0 0"/>
            <geometry>
                <box size="0.5653528306206398 0.43164431629994404 0.6244466538239382" />
            </geometry>
        </collision>
    </link>
    <joint name="0_1" type="revolute">
       <parent link="0"/>
       <child  link="1"/>
       <origin rpy="0 0 0" xyz="0.2826764153103199 0.0 3.312223326911969" />
     <axis xyz="1 0 0"/>
       <limit effort="0.0" lower="-3.14159" upper="3.14159" velocity="0.0"/>
    </joint>
    <link name="1">
        <inertial>
            <origin xyz="0.4168541966449603 0.0 0.0" rpy="0 0 0"/>
            <mass value="1" />
            <inertia ixx="100" ixy="0" ixz="0" iyy="100" iyz="0" izz="100" />
        </inertial>
        <visual>
            <origin xyz="0.4168541966449603 0.0 0.0" rpy="0 0 0"/>
            <geometry>
                <box size="0.8337083932899206 0.9153343272091412 0.6344616559844283" />
            </geometry>
            <material name="Blue">
                <color rgba="0 0 1.0 1.0"/>
            </material>
        </visual>
        <collision>
            <origin xyz="0.4168541966449603 0.0 0.0" rpy="0 0 0"/>
            <geometry>
                <box size="0.8337083932899206 0.9153343272091412 0.6344616559844283" />
            </geometry>
        </collision>
    </link>
    <joint name="1_2" type="revolute">
       <parent link="1"/>
       <child  link="2"/>
       <origin rpy="0 0 0" xyz="0.4168541966449603 0.0 -0.31723082799221414" />
     <axis xyz="0 1 0"/>
       <limit effort="0.0" lower="-3.14159" upper="3.14159" velocity="0.0"/>
    </joint>
    <link name="2">
        <inertial>
            <origin xyz="0.0 0.0 -0.5032598933643717" rpy="0 0 0"/>
            <mass value="1" />
            <inertia ixx="100" ixy="0" ixz="0" iyy="100" iyz="0" izz="100" />
        </inertial>
        <visual>
            <origin xyz="0.0 0.0 -0.5032598933643717" rpy="0 0 0"/>
            <geometry>
                <box size="1.0866930070584733 0.9790147191063793 1.0065197867287434" />
            </geometry>
            <material name="Green">
                <color rgba="0 1.0 0 1.0"/>
            </material>
        </visual>
        <collision>
            <origin xyz="0.0 0.0 -0.5032598933643717" rpy="0 0 0"/>
            <geometry>
                <box size="1.0866930070584733 0.9790147191063793 1.0065197867287434" />
            </geometry>
        </collision>
    </link>
    <joint name="2_3" type="revolute">
       <parent link="2"/>
       <child  link="3"/>
       <origin rpy="0 0 0" xyz="0.0 -0.48950735955318964 -0.5032598933643717" />
     <axis xyz="0 1 0"/>
       <limit effort="0.0" lower="-3.14159" upper="3.14159" velocity="0.0"/>
    </joint>
    <link name="3">
        <inertial>
            <origin xyz="0.0 -0.4099172016725088 0.0" rpy="0 0 0"/>
            <mass value="1" />
            <inertia ixx="100" ixy="0" ixz="0" iyy="100" iyz="0" izz="100" />
        </inertial>
        <visual>
            <origin xyz="0.0 -0.4099172016725088 0.0" rpy="0 0 0"/>
            <geometry>
                <box size="0.60623257434275 0.8198344033450176 1.0617058794709293" />
            </geometry>
            <material name="Blue">
                <color rgba="0 0 1.0 1.0"/>
            </material>
        </visual>
        <collision>
            <origin xyz="0.0 -0.4099172016725088 0.0" rpy="0 0 0"/>
            <geometry>
                <box size="0.60623257434275 0.8198344033450176 1.0617058794709293" />
            </geometry>
        </collision>
    </link>
    <joint name="2_4" type="revolute">
       <parent link="2"/>
       <child  link="4"/>
       <origin rpy="0 0 0" xyz="0.5433465035292366 0.0 -0.5032598933643717" />
     <axis xyz="0 1 0"/>
       <limit effort="0.0" lower="-3.14159" upper="3.14159" velocity="0.0"/>
    </joint>
    <link name="4">
        <inertial>
            <origin xyz="0.4573850807884462 0.0 0.0" rpy="0 0 0"/>
            <mass value="1" />
            <inertia ixx="100" ixy="0" ixz="0" iyy="100" iyz="0" izz="100" />
        </inertial>
        <visual>
            <origin xyz="0.4573850807884462 0.0 0.0" rpy="0 0 0"/>
            <geometry>
                <box size="0.9147701615768924 0.5061866283826171 0.44949377891462616" />
            </geometry>
            <material name="Blue">
                <color rgba="0 0 1.0 1.0"/>
            </material>
        </visual>
        <collision>
            <origin xyz="0.4573850807884462 0.0 0.0" rpy="0 0 0"/>
            <geometry>
                <box size="0.9147701615768924 0.5061866283826171 0.44949377891462616" />
            </geometry>
        </collision>
    </link>
    <joint name="4_5" type="revolute">
       <parent link="4"/>
       <child  link="5"/>
       <origin rpy="0 0 0" xyz="0.4573850807884462 0.0 -0.22474688945731308" />
     <axis xyz="1 0 0"/>
       <limit effort="0.0" lower="-3.14159" upper="3.14159" velocity="0.0"/>
    </joint>
    <link name="5">
        <inertial>
            <origin xyz="0.0 0.0 -0.30119831525248963" rpy="0 0 0"/>
            <mass value="1" />
            <inertia ixx="100" ixy="0" ixz="0" iyy="100" iyz="0" izz="100" />
        </inertial>
        <visual>
            <origin xyz="0.0 0.0 -0.30119831525248963" rpy="0 0 0"/>
            <geometry>
                <box size="0.7004473832078411 0.6755235309449543 0.6023966305049793" />
            </geometry>
            <material name="Blue">
                <color rgba="0 0 1.0 1.0"/>
            </material>
        </visual>
        <collision>
            <origin xyz="0.0 0.0 -0.30119831525248963" rpy="0 0 0"/>
            <geometry>
                <box size="0.7004473832078411 0.6755235309449543 0.6023966305049793" />
            </geometry>
        </collision>
    </link>
    <joint name="2_6" type="revolute">
       <parent link="2"/>
       <child  link="6"/>
       <origin rpy="0 0 0" xyz="0.0 0.0 -1.0065197867287434" />
     <axis xyz="0 1 0"/>
       <limit effort="0.0" lower="-3.14159" upper="3.14159" velocity="0.0"/>
    </joint>
    <link name="6">
        <inertial>
            <origin xyz="0.0 0.0 -0.2741984145251459" rpy="0 0 0"/>
            <mass value="1" />
            <inertia ixx="100" ixy="0" ixz="0" iyy="100" iyz="0" izz="100" />
        </inertial>
        <visual>
            <origin xyz="0.0 0.0 -0.2741984145251459" rpy="0 0 0"/>
            <geometry>
                <box size="1.0482467547876764 0.5759444421425376 0.5483968290502917" />
            </geometry>
            <material name="Blue">
                <color rgba="0 0 1.0 1.0"/>
            </material>
        </visual>
        <collision>
            <origin xyz="0.0 0.0 -0.2741984145251459" rpy="0 0 0"/>
            <geometry>
                <box size="1.0482467547876764 0.5759444421425376 0.5483968290502917" />
            </geometry>
        </collision>
    </link>
    <joint name="6_7" type="revolute">
       <parent link="6"/>
       <child  link="7"/>
       <origin rpy="0 0 0" xyz="0.0 0.0 -0.5483968290502917" />
     <axis xyz="0 1 0"/>
       <limit effort="0.0" lower="-3.14159" upper="3.14159" velocity="0.0"/>
    </joint>
    <link name="7">
        <inertial>
            <origin xyz="0.0 0.0 -0.3286748404303962" rpy="0 0 0"/>
            <mass value="1" />
            <inertia ixx="100" ixy="0" ixz="0" iyy="100" iyz="0" izz="100" />
        </inertial>
        <visual>
            <origin xyz="0.0 0.0 -0.3286748404303962" rpy="0 0 0"/>
            <geometry>
                <box size="0.817101355470374 0.7323062444665868 0.6573496808607924" />
            </geometry>
            <material name="Green">
                <color rgba="0 1.0 0 1.0"/>
            </material>
        </visual>
        <collision>
            <origin xyz="0.0 0.0 -0.3286748404303962" rpy="0 0 0"/>
            <geometry>
                <box size="0.817101355470374 0.7323062444665868 0.6573496808607924" />
            </geometry>
        </collision>
    </link>
    <joint name="4_8" type="revolute">
       <parent link="4"/>
       <child  link="8"/>
       <origin rpy="0 0 0" xyz="0.9147701615768924 0.0 0.0" />
     <axis xyz="0 1 0"/>
       <limit effort="0.0" lower="-3.14159" upper="3.14159" velocity="0.0"/>
    </joint>
    <link name="8">
        <inertial>
            <origin xyz="0.4808058050449789 0.0 0.0" rpy="0 0 0"/>
            <mass value="1" />
            <inertia ixx="100" ixy="0" ixz="0" iyy="100" iyz="0" izz="100" />
        </inertial>
        <visual>
            <origin xyz="0.4808058050449789 0.0 0.0" rpy="0 0 0"/>
            <geometry>
                <box size="0.9616116100899578 0.8553761171671539 0.8388956575035363" />
            </geometry>
            <material name="Blue">
                <color rgba="0 0 1.0 1.0"/>
            </material>
        </visual>
        <collision>
            <origin xyz="0.4808058050449789 0.0 0.0" rpy="0 0 0"/>
            <geometry>
                <box size="0.9616116100899578 0.8553761171671539 0.8388956575035363" />
            </geometry>
        </collision>
    </link>
    <joint name="5_9" type="revolute">
       <parent link="5"/>
       <child  link="9"/>
       <origin rpy="0 0 0" xyz="0.0 -0.33776176547247716 -0.30119831525248963" />
     <axis xyz="0 1 0"/>
       <limit effort="0.0" lower="-3.14159" upper="3.14159" velocity="0.0"/>
    </joint>
    <link name="9">
        <inertial>
            <origin xyz="0.0 -0.5225117892638111 0.0" rpy="0 0 0"/>
            <mass value="1" />
            <inertia ixx="100" ixy="0" ixz="0" iyy="100" iyz="0" izz="100" />
        </inertial>
        <visual>
            <origin xyz="0.0 -0.5225117892638111 0.0" rpy="0 0 0"/>
            <geometry>
                <box size="0.8468489321647842 1.0450235785276223 0.789462259743505" />
            </geometry>
            <material name="Green">
                <color rgba="0 1.0 0 1.0"/>
            </material>
        </visual>
        <collision>
            <origin xyz="0.0 -0.5225117892638111 0.0" rpy="0 0 0"/>
            <geometry>
                <box size="0.8468489321647842 1.0450235785276223 0.789462259743505" />
            </geometry>
        </collision>
    </link>
    <joint name="3_10" type="revolute">
       <parent link="3"/>
       <child  link="10"/>
       <origin rpy="0 0 0" xyz="-0.303116287171375 -0.4099172016725088 0.0" />
     <axis xyz="1 0 0"/>
       <limit effort="0.0" lower="-3.14159" upper="3.14159" velocity="0.0"/>
    </joint>
    <link name="10">
        <inertial>
            <origin xyz="-0.29715836759840786 0.0 0.0" rpy="0 0 0"/>
            <mass value="1" />
            <inertia ixx="100" ixy="0" ixz="0" iyy="100" iyz="0" izz="100" />
        </inertial>
        <visual>
            <origin xyz="-0.29715836759840786 0.0 0.0" rpy="0 0 0"/>
            <geometry>
                <box size="0.5943167351968157 0.7398451571004465 0.5133936401377304" />
            </geometry>
            <material name="Blue">
                <color rgba="0 0 1.0 1.0"/>
            </material>
        </visual>
        <collision>
            <origin xyz="-0.29715836759840786 0.0 0.0" rpy="0 0 0"/>
            <geometry>
                <box size="0.5943167351968157 0.7398451571004465 0.5133936401377304" />
            </geometry>
        </collision>
    </link>
</robot>