<robot name = "robot">
    <link name="0">
        <inertial>
            <origin xyz="0 0 3.4578875962618976" rpy="0 0 0"/>
            <mass value="1" />
            <inertia ixx="100" ixy="0" ixz="0" iyy="100" iyz="0" izz="100" />
        </inertial>
        <visual>
            <origin xyz="0 0 3.4578875962618976" rpy="0 0 0"/>
            <geometry>
                <box size="1.1155668287264104 0.87882933272206 0.915775192523795" />
            </geometry>
            <material name="Green">
                <color rgba="0 1.0 0 1.0"/>
            </material>
        </visual>
        <collision>
            <origin xyz="0 0 3.4578875962618976" rpy="0 0 0"/>
            <geometry>
                <box size="1.1155668287264104 0.87882933272206 0.915775192523795" />
            </geometry>
        </collision>
    </link>
    <joint name="0_1" type="revolute">
       <parent link="0"/>
       <child  link="1"/>
       <origin rpy="0 0 0" xyz="0.0 0.43941466636103 3.4578875962618976" />
     <axis xyz="0 1 0"/>
       <limit effort="0.0" lower="-3.14159" upper="3.14159" velocity="0.0"/>
    </joint>
    <link name="1">
        <inertial>
            <origin xyz="0.0 0.3296822513716466 0.0" rpy="0 0 0"/>
            <mass value="1" />
            <inertia ixx="100" ixy="0" ixz="0" iyy="100" iyz="0" izz="100" />
        </inertial>
        <visual>
            <origin xyz="0.0 0.3296822513716466 0.0" rpy="0 0 0"/>
            <geometry>
                <box size="0.7675454016501639 0.6593645027432932 0.9344943276273628" />
            </geometry>
            <material name="Green">
                <color rgba="0 1.0 0 1.0"/>
            </material>
        </visual>
        <collision>
            <origin xyz="0.0 0.3296822513716466 0.0" rpy="0 0 0"/>
            <geometry>
                <box size="0.7675454016501639 0.6593645027432932 0.9344943276273628" />
            </geometry>
        </collision>
    </link>
    <joint name="1_2" type="revolute">
       <parent link="1"/>
       <child  link="2"/>
       <origin rpy="0 0 0" xyz="-0.38377270082508197 0.3296822513716466 0.0" />
     <axis xyz="1 0 0"/>
       <limit effort="0.0" lower="-3.14159" upper="3.14159" velocity="0.0"/>
    </joint>
    <link name="2">
        <inertial>
            <origin xyz="-0.3791259074998719 0.0 0.0" rpy="0 0 0"/>
            <mass value="1" />
            <inertia ixx="100" ixy="0" ixz="0" iyy="100" iyz="0" izz="100" />
        </inertial>
        <visual>
            <origin xyz="-0.3791259074998719 0.0 0.0" rpy="0 0 0"/>
            <geometry>
                <box size="0.7582518149997438 0.5361197297467473 0.7707380204750551" />
            </geometry>
            <material name="Green">
                <color rgba="0 1.0 0 1.0"/>
            </material>
        </visual>
        <collision>
            <origin xyz="-0.3791259074998719 0.0 0.0" rpy="0 0 0"/>
            <geometry>
                <box size="0.7582518149997438 0.5361197297467473 0.7707380204750551" />
            </geometry>
        </collision>
    </link>
    <joint name="2_3" type="revolute">
       <parent link="2"/>
       <child  link="3"/>
       <origin rpy="0 0 0" xyz="-0.7582518149997438 0.0 0.0" />
     <axis xyz="1 0 0"/>
       <limit effort="0.0" lower="-3.14159" upper="3.14159" velocity="0.0"/>
    </joint>
    <link name="3">
        <inertial>
            <origin xyz="-0.368476846887153 0.0 0.0" rpy="0 0 0"/>
            <mass value="1" />
            <inertia ixx="100" ixy="0" ixz="0" iyy="100" iyz="0" izz="100" />
        </inertial>
        <visual>
            <origin xyz="-0.368476846887153 0.0 0.0" rpy="0 0 0"/>
            <geometry>
                <box size="0.736953693774306 0.8157020013233242 0.41564814949335305" />
            </geometry>
            <material name="Blue">
                <color rgba="0 0 1.0 1.0"/>
            </material>
        </visual>
        <collision>
            <origin xyz="-0.368476846887153 0.0 0.0" rpy="0 0 0"/>
            <geometry>
                <box size="0.736953693774306 0.8157020013233242 0.41564814949335305" />
            </geometry>
        </collision>
    </link>
    <joint name="3_4" type="revolute">
       <parent link="3"/>
       <child  link="4"/>
       <origin rpy="0 0 0" xyz="-0.368476846887153 -0.4078510006616621 0.0" />
     <axis xyz="1 0 0"/>
       <limit effort="0.0" lower="-3.14159" upper="3.14159" velocity="0.0"/>
    </joint>
    <link name="4">
        <inertial>
            <origin xyz="0.0 -0.42406497825623135 0.0" rpy="0 0 0"/>
            <mass value="1" />
            <inertia ixx="100" ixy="0" ixz="0" iyy="100" iyz="0" izz="100" />
        </inertial>
        <visual>
            <origin xyz="0.0 -0.42406497825623135 0.0" rpy="0 0 0"/>
            <geometry>
                <box size="0.45675777426831093 0.8481299565124627 0.5937116902287326" />
            </geometry>
            <material name="Green">
                <color rgba="0 1.0 0 1.0"/>
            </material>
        </visual>
        <collision>
            <origin xyz="0.0 -0.42406497825623135 0.0" rpy="0 0 0"/>
            <geometry>
                <box size="0.45675777426831093 0.8481299565124627 0.5937116902287326" />
            </geometry>
        </collision>
    </link>
    <joint name="4_5" type="revolute">
       <parent link="4"/>
       <child  link="5"/>
       <origin rpy="0 0 0" xyz="0.0 -0.42406497825623135 -0.2968558451143663" />
     <axis xyz="1 0 0"/>
       <limit effort="0.0" lower="-3.14159" upper="3.14159" velocity="0.0"/>
    </joint>
    <link name="5">
        <inertial>
            <origin xyz="0.0 0.0 -0.3513976287719473" rpy="0 0 0"/>
            <mass value="1" />
            <inertia ixx="100" ixy="0" ixz="0" iyy="100" iyz="0" izz="100" />
        </inertial>
        <visual>
            <origin xyz="0.0 0.0 -0.3513976287719473" rpy="0 0 0"/>
            <geometry>
                <box size="0.4403213475576929 0.7853566542348559 0.7027952575438946" />
            </geometry>
            <material name="Green">
                <color rgba="0 1.0 0 1.0"/>
            </material>
        </visual>
        <collision>
            <origin xyz="0.0 0.0 -0.3513976287719473" rpy="0 0 0"/>
            <geometry>
                <box size="0.4403213475576929 0.7853566542348559 0.7027952575438946" />
            </geometry>
        </collision>
    </link>
    <joint name="3_8" type="revolute">
       <parent link="3"/>
       <child  link="8"/>
       <origin rpy="0 0 0" xyz="-0.736953693774306 0.0 0.0" />
     <axis xyz="1 0 0"/>
       <limit effort="0.0" lower="-3.14159" upper="3.14159" velocity="0.0"/>
    </joint>
    <link name="8">
        <inertial>
            <origin xyz="-0.28290442406391936 0.0 0.0" rpy="0 0 0"/>
            <mass value="1" />
            <inertia ixx="100" ixy="0" ixz="0" iyy="100" iyz="0" izz="100" />
        </inertial>
        <visual>
            <origin xyz="-0.28290442406391936 0.0 0.0" rpy="0 0 0"/>
            <geometry>
                <box size="0.5658088481278387 0.4678275159053362 0.6221471863371607" />
            </geometry>
            <material name="Blue">
                <color rgba="0 0 1.0 1.0"/>
            </material>
        </visual>
        <collision>
            <origin xyz="-0.28290442406391936 0.0 0.0" rpy="0 0 0"/>
            <geometry>
                <box size="0.5658088481278387 0.4678275159053362 0.6221471863371607" />
            </geometry>
        </collision>
    </link>
    <joint name="2_9" type="revolute">
       <parent link="2"/>
       <child  link="9"/>
       <origin rpy="0 0 0" xyz="-0.3791259074998719 0.26805986487337363 0.0" />
     <axis xyz="1 0 0"/>
       <limit effort="0.0" lower="-3.14159" upper="3.14159" velocity="0.0"/>
    </joint>
    <link name="9">
        <inertial>
            <origin xyz="0.0 0.2523599252550253 0.0" rpy="0 0 0"/>
            <mass value="1" />
            <inertia ixx="100" ixy="0" ixz="0" iyy="100" iyz="0" izz="100" />
        </inertial>
        <visual>
            <origin xyz="0.0 0.2523599252550253 0.0" rpy="0 0 0"/>
            <geometry>
                <box size="0.5430475255235092 0.5047198505100506 0.807806531467766" />
            </geometry>
            <material name="Green">
                <color rgba="0 1.0 0 1.0"/>
            </material>
        </visual>
        <collision>
            <origin xyz="0.0 0.2523599252550253 0.0" rpy="0 0 0"/>
            <geometry>
                <box size="0.5430475255235092 0.5047198505100506 0.807806531467766" />
            </geometry>
        </collision>
    </link>
    <joint name="5_6" type="revolute">
       <parent link="5"/>
       <child  link="6"/>
       <origin rpy="0 0 0" xyz="0.0 -0.39267832711742795 -0.3513976287719473" />
     <axis xyz="0 1 0"/>
       <limit effort="0.0" lower="-3.14159" upper="3.14159" velocity="0.0"/>
    </joint>
    <link name="6">
        <inertial>
            <origin xyz="0.0 -0.4045025062228457 0.0" rpy="0 0 0"/>
            <mass value="1" />
            <inertia ixx="100" ixy="0" ixz="0" iyy="100" iyz="0" izz="100" />
        </inertial>
        <visual>
            <origin xyz="0.0 -0.4045025062228457 0.0" rpy="0 0 0"/>
            <geometry>
                <box size="0.8140788129120142 0.8090050124456915 0.5703327593734079" />
            </geometry>
            <material name="Blue">
                <color rgba="0 0 1.0 1.0"/>
            </material>
        </visual>
        <collision>
            <origin xyz="0.0 -0.4045025062228457 0.0" rpy="0 0 0"/>
            <geometry>
                <box size="0.8140788129120142 0.8090050124456915 0.5703327593734079" />
            </geometry>
        </collision>
    </link>
    <joint name="4_10" type="revolute">
       <parent link="4"/>
       <child  link="10"/>
       <origin rpy="0 0 0" xyz="0.22837888713415547 -0.42406497825623135 0.0" />
     <axis xyz="0 1 0"/>
       <limit effort="0.0" lower="-3.14159" upper="3.14159" velocity="0.0"/>
    </joint>
    <link name="10">
        <inertial>
            <origin xyz="0.3152377381722388 0.0 0.0" rpy="0 0 0"/>
            <mass value="1" />
            <inertia ixx="100" ixy="0" ixz="0" iyy="100" iyz="0" izz="100" />
        </inertial>
        <visual>
            <origin xyz="0.3152377381722388 0.0 0.0" rpy="0 0 0"/>
            <geometry>
                <box size="0.6304754763444776 0.3924519861501634 1.0988685146905686" />
            </geometry>
            <material name="Blue">
                <color rgba="0 0 1.0 1.0"/>
            </material>
        </visual>
        <collision>
            <origin xyz="0.3152377381722388 0.0 0.0" rpy="0 0 0"/>
            <geometry>
                <box size="0.6304754763444776 0.3924519861501634 1.0988685146905686" />
            </geometry>
        </collision>
    </link>
    <joint name="8_11" type="revolute">
       <parent link="8"/>
       <child  link="11"/>
       <origin rpy="0 0 0" xyz="-0.28290442406391936 -0.2339137579526681 0.0" />
     <axis xyz="0 1 0"/>
       <limit effort="0.0" lower="-3.14159" upper="3.14159" velocity="0.0"/>
    </joint>
    <link name="11">
        <inertial>
            <origin xyz="0.0 -0.31631240112733355 0.0" rpy="0 0 0"/>
            <mass value="1" />
            <inertia ixx="100" ixy="0" ixz="0" iyy="100" iyz="0" izz="100" />
        </inertial>
        <visual>
            <origin xyz="0.0 -0.31631240112733355 0.0" rpy="0 0 0"/>
            <geometry>
                <box size="0.42542084155363125 0.6326248022546671 0.972876781568982" />
            </geometry>
            <material name="Green">
                <color rgba="0 1.0 0 1.0"/>
            </material>
        </visual>
        <collision>
            <origin xyz="0.0 -0.31631240112733355 0.0" rpy="0 0 0"/>
            <geometry>
                <box size="0.42542084155363125 0.6326248022546671 0.972876781568982" />
            </geometry>
        </collision>
    </link>
    <joint name="9_7" type="revolute">
       <parent link="9"/>
       <child  link="7"/>
       <origin rpy="0 0 0" xyz="0.0 0.5047198505100506 0.0" />
     <axis xyz="1 0 0"/>
       <limit effort="0.0" lower="-3.14159" upper="3.14159" velocity="0.0"/>
    </joint>
    <link name="7">
        <inertial>
            <origin xyz="0.0 0.3204478604062163 0.0" rpy="0 0 0"/>
            <mass value="1" />
            <inertia ixx="100" ixy="0" ixz="0" iyy="100" iyz="0" izz="100" />
        </inertial>
        <visual>
            <origin xyz="0.0 0.3204478604062163 0.0" rpy="0 0 0"/>
            <geometry>
                <box size="1.0026892014951867 0.6408957208124326 0.6702423525828999" />
            </geometry>
            <material name="Blue">
                <color rgba="0 0 1.0 1.0"/>
            </material>
        </visual>
        <collision>
            <origin xyz="0.0 0.3204478604062163 0.0" rpy="0 0 0"/>
            <geometry>
                <box size="1.0026892014951867 0.6408957208124326 0.6702423525828999" />
            </geometry>
        </collision>
    </link>
    <joint name="7_13" type="revolute">
       <parent link="7"/>
       <child  link="13"/>
       <origin rpy="0 0 0" xyz="-0.5013446007475933 0.3204478604062163 0.0" />
     <axis xyz="0 1 0"/>
       <limit effort="0.0" lower="-3.14159" upper="3.14159" velocity="0.0"/>
    </joint>
    <link name="13">
        <inertial>
            <origin xyz="-0.5410253676519929 0.0 0.0" rpy="0 0 0"/>
            <mass value="1" />
            <inertia ixx="100" ixy="0" ixz="0" iyy="100" iyz="0" izz="100" />
        </inertial>
        <visual>
            <origin xyz="-0.5410253676519929 0.0 0.0" rpy="0 0 0"/>
            <geometry>
                <box size="1.0820507353039859 0.6769102222214366 0.6080840700835821" />
            </geometry>
            <material name="Green">
                <color rgba="0 1.0 0 1.0"/>
            </material>
        </visual>
        <collision>
            <origin xyz="-0.5410253676519929 0.0 0.0" rpy="0 0 0"/>
            <geometry>
                <box size="1.0820507353039859 0.6769102222214366 0.6080840700835821" />
            </geometry>
        </collision>
    </link>
</robot>