<robot name = "robot">
    <link name="0">
        <inertial>
            <origin xyz="0 0 3.3809379610349235" rpy="0 0 0"/>
            <mass value="1" />
            <inertia ixx="100" ixy="0" ixz="0" iyy="100" iyz="0" izz="100" />
        </inertial>
        <visual>
            <origin xyz="0 0 3.3809379610349235" rpy="0 0 0"/>
            <geometry>
                <box size="1.0008377822621566 0.819683990498332 0.7618759220698472" />
            </geometry>
            <material name="Blue">
                <color rgba="0 0 1.0 1.0"/>
            </material>
        </visual>
        <collision>
            <origin xyz="0 0 3.3809379610349235" rpy="0 0 0"/>
            <geometry>
                <box size="1.0008377822621566 0.819683990498332 0.7618759220698472" />
            </geometry>
        </collision>
    </link>
    <joint name="0_1" type="revolute">
       <parent link="0"/>
       <child  link="1"/>
       <origin rpy="0 0 0" xyz="0.0 0.409841995249166 3.3809379610349235" />
     <axis xyz="1 0 0"/>
       <limit effort="0.0" lower="-3.14159" upper="3.14159" velocity="0.0"/>
    </joint>
    <link name="1">
        <inertial>
            <origin xyz="0.0 0.4877769874184344 0.0" rpy="0 0 0"/>
            <mass value="1" />
            <inertia ixx="100" ixy="0" ixz="0" iyy="100" iyz="0" izz="100" />
        </inertial>
        <visual>
            <origin xyz="0.0 0.4877769874184344 0.0" rpy="0 0 0"/>
            <geometry>
                <box size="0.5758259801763935 0.9755539748368688 1.074680198450133" />
            </geometry>
            <material name="Blue">
                <color rgba="0 0 1.0 1.0"/>
            </material>
        </visual>
        <collision>
            <origin xyz="0.0 0.4877769874184344 0.0" rpy="0 0 0"/>
            <geometry>
                <box size="0.5758259801763935 0.9755539748368688 1.074680198450133" />
            </geometry>
        </collision>
    </link>
    <joint name="1_3" type="revolute">
       <parent link="1"/>
       <child  link="3"/>
       <origin rpy="0 0 0" xyz="0.0 0.4877769874184344 0.5373400992250665" />
     <axis xyz="0 1 0"/>
       <limit effort="0.0" lower="-3.14159" upper="3.14159" velocity="0.0"/>
    </joint>
    <link name="3">
        <inertial>
            <origin xyz="0.0 0.0 0.3466492899007748" rpy="0 0 0"/>
            <mass value="1" />
            <inertia ixx="100" ixy="0" ixz="0" iyy="100" iyz="0" izz="100" />
        </inertial>
        <visual>
            <origin xyz="0.0 0.0 0.3466492899007748" rpy="0 0 0"/>
            <geometry>
                <box size="1.0713445990089951 0.5173302487002085 0.6932985798015496" />
            </geometry>
            <material name="Blue">
                <color rgba="0 0 1.0 1.0"/>
            </material>
        </visual>
        <collision>
            <origin xyz="0.0 0.0 0.3466492899007748" rpy="0 0 0"/>
            <geometry>
                <box size="1.0713445990089951 0.5173302487002085 0.6932985798015496" />
            </geometry>
        </collision>
    </link>
    <joint name="1_2" type="revolute">
       <parent link="1"/>
       <child  link="2"/>
       <origin rpy="0 0 0" xyz="-0.28791299008819676 0.4877769874184344 0.0" />
     <axis xyz="0 1 0"/>
       <limit effort="0.0" lower="-3.14159" upper="3.14159" velocity="0.0"/>
    </joint>
    <link name="2">
        <inertial>
            <origin xyz="-0.20724051480835637 0.0 0.0" rpy="0 0 0"/>
            <mass value="1" />
            <inertia ixx="100" ixy="0" ixz="0" iyy="100" iyz="0" izz="100" />
        </inertial>
        <visual>
            <origin xyz="-0.20724051480835637 0.0 0.0" rpy="0 0 0"/>
            <geometry>
                <box size="0.41448102961671274 0.8650298238609719 0.4513547236104279" />
            </geometry>
            <material name="Green">
                <color rgba="0 1.0 0 1.0"/>
            </material>
        </visual>
        <collision>
            <origin xyz="-0.20724051480835637 0.0 0.0" rpy="0 0 0"/>
            <geometry>
                <box size="0.41448102961671274 0.8650298238609719 0.4513547236104279" />
            </geometry>
        </collision>
    </link>
</robot>