<robot name = "robot">
    <link name="0">
        <inertial>
            <origin xyz="0 0 3.5426505801880945" rpy="0 0 0"/>
            <mass value="1" />
            <inertia ixx="100" ixy="0" ixz="0" iyy="100" iyz="0" izz="100" />
        </inertial>
        <visual>
            <origin xyz="0 0 3.5426505801880945" rpy="0 0 0"/>
            <geometry>
                <box size="0.954358110368301 0.7562821080969444 1.0853011603761893" />
            </geometry>
            <material name="Green">
                <color rgba="0 1.0 0 1.0"/>
            </material>
        </visual>
        <collision>
            <origin xyz="0 0 3.5426505801880945" rpy="0 0 0"/>
            <geometry>
                <box size="0.954358110368301 0.7562821080969444 1.0853011603761893" />
            </geometry>
        </collision>
    </link>
    <joint name="0_1" type="revolute">
       <parent link="0"/>
       <child  link="1"/>
       <origin rpy="0 0 0" xyz="-0.4771790551841505 0.0 3.5426505801880945" />
     <axis xyz="0 1 0"/>
       <limit effort="0.0" lower="-3.14159" upper="3.14159" velocity="0.0"/>
    </joint>
    <link name="1">
        <inertial>
            <origin xyz="-0.283784186289199 0.0 0.0" rpy="0 0 0"/>
            <mass value="1" />
            <inertia ixx="100" ixy="0" ixz="0" iyy="100" iyz="0" izz="100" />
        </inertial>
        <visual>
            <origin xyz="-0.283784186289199 0.0 0.0" rpy="0 0 0"/>
            <geometry>
                <box size="0.567568372578398 0.6085392482024758 0.5458649379148568" />
            </geometry>
            <material name="Blue">
                <color rgba="0 0 1.0 1.0"/>
            </material>
        </visual>
        <collision>
            <origin xyz="-0.283784186289199 0.0 0.0" rpy="0 0 0"/>
            <geometry>
                <box size="0.567568372578398 0.6085392482024758 0.5458649379148568" />
            </geometry>
        </collision>
    </link>
    <joint name="1_2" type="revolute">
       <parent link="1"/>
       <child  link="2"/>
       <origin rpy="0 0 0" xyz="-0.567568372578398 0.0 0.0" />
     <axis xyz="1 0 0"/>
       <limit effort="0.0" lower="-3.14159" upper="3.14159" velocity="0.0"/>
    </joint>
    <link name="2">
        <inertial>
            <origin xyz="-0.27859090637849865 0.0 0.0" rpy="0 0 0"/>
            <mass value="1" />
            <inertia ixx="100" ixy="0" ixz="0" iyy="100" iyz="0" izz="100" />
        </inertial>
        <visual>
            <origin xyz="-0.27859090637849865 0.0 0.0" rpy="0 0 0"/>
            <geometry>
                <box size="0.5571818127569973 0.4482810643473352 0.6561408374932427" />
            </geometry>
            <material name="Green">
                <color rgba="0 1.0 0 1.0"/>
            </material>
        </visual>
        <collision>
            <origin xyz="-0.27859090637849865 0.0 0.0" rpy="0 0 0"/>
            <geometry>
                <box size="0.5571818127569973 0.4482810643473352 0.6561408374932427" />
            </geometry>
        </collision>
    </link>
    <joint name="1_3" type="revolute">
       <parent link="1"/>
       <child  link="3"/>
       <origin rpy="0 0 0" xyz="-0.283784186289199 0.0 0.2729324689574284" />
     <axis xyz="0 1 0"/>
       <limit effort="0.0" lower="-3.14159" upper="3.14159" velocity="0.0"/>
    </joint>
    <link name="3">
        <inertial>
            <origin xyz="0.0 0.0 0.3485480711053966" rpy="0 0 0"/>
            <mass value="1" />
            <inertia ixx="100" ixy="0" ixz="0" iyy="100" iyz="0" izz="100" />
        </inertial>
        <visual>
            <origin xyz="0.0 0.0 0.3485480711053966" rpy="0 0 0"/>
            <geometry>
                <box size="0.48181227453573683 1.00933480244487 0.6970961422107932" />
            </geometry>
            <material name="Blue">
                <color rgba="0 0 1.0 1.0"/>
            </material>
        </visual>
        <collision>
            <origin xyz="0.0 0.0 0.3485480711053966" rpy="0 0 0"/>
            <geometry>
                <box size="0.48181227453573683 1.00933480244487 0.6970961422107932" />
            </geometry>
        </collision>
    </link>
    <joint name="3_4" type="revolute">
       <parent link="3"/>
       <child  link="4"/>
       <origin rpy="0 0 0" xyz="0.0 0.504667401222435 0.3485480711053966" />
     <axis xyz="1 0 0"/>
       <limit effort="0.0" lower="-3.14159" upper="3.14159" velocity="0.0"/>
    </joint>
    <link name="4">
        <inertial>
            <origin xyz="0.0 0.23010344789376147 0.0" rpy="0 0 0"/>
            <mass value="1" />
            <inertia ixx="100" ixy="0" ixz="0" iyy="100" iyz="0" izz="100" />
        </inertial>
        <visual>
            <origin xyz="0.0 0.23010344789376147 0.0" rpy="0 0 0"/>
            <geometry>
                <box size="0.538177821795955 0.46020689578752294 0.7067288677466883" />
            </geometry>
            <material name="Green">
                <color rgba="0 1.0 0 1.0"/>
            </material>
        </visual>
        <collision>
            <origin xyz="0.0 0.23010344789376147 0.0" rpy="0 0 0"/>
            <geometry>
                <box size="0.538177821795955 0.46020689578752294 0.7067288677466883" />
            </geometry>
        </collision>
    </link>
    <joint name="2_5" type="revolute">
       <parent link="2"/>
       <child  link="5"/>
       <origin rpy="0 0 0" xyz="-0.27859090637849865 -0.2241405321736676 0.0" />
     <axis xyz="1 0 0"/>
       <limit effort="0.0" lower="-3.14159" upper="3.14159" velocity="0.0"/>
    </joint>
    <link name="5">
        <inertial>
            <origin xyz="0.0 -0.36838892604997764 0.0" rpy="0 0 0"/>
            <mass value="1" />
            <inertia ixx="100" ixy="0" ixz="0" iyy="100" iyz="0" izz="100" />
        </inertial>
        <visual>
            <origin xyz="0.0 -0.36838892604997764 0.0" rpy="0 0 0"/>
            <geometry>
                <box size="0.5265345779502631 0.7367778520999553 0.8942740200847992" />
            </geometry>
            <material name="Green">
                <color rgba="0 1.0 0 1.0"/>
            </material>
        </visual>
        <collision>
            <origin xyz="0.0 -0.36838892604997764 0.0" rpy="0 0 0"/>
            <geometry>
                <box size="0.5265345779502631 0.7367778520999553 0.8942740200847992" />
            </geometry>
        </collision>
    </link>
    <joint name="2_6" type="revolute">
       <parent link="2"/>
       <child  link="6"/>
       <origin rpy="0 0 0" xyz="-0.27859090637849865 0.0 0.32807041874662135" />
     <axis xyz="1 0 0"/>
       <limit effort="0.0" lower="-3.14159" upper="3.14159" velocity="0.0"/>
    </joint>
    <link name="6">
        <inertial>
            <origin xyz="0.0 0.0 0.3292074152675299" rpy="0 0 0"/>
            <mass value="1" />
            <inertia ixx="100" ixy="0" ixz="0" iyy="100" iyz="0" izz="100" />
        </inertial>
        <visual>
            <origin xyz="0.0 0.0 0.3292074152675299" rpy="0 0 0"/>
            <geometry>
                <box size="0.4791514397841846 0.38318188747125775 0.6584148305350598" />
            </geometry>
            <material name="Green">
                <color rgba="0 1.0 0 1.0"/>
            </material>
        </visual>
        <collision>
            <origin xyz="0.0 0.0 0.3292074152675299" rpy="0 0 0"/>
            <geometry>
                <box size="0.4791514397841846 0.38318188747125775 0.6584148305350598" />
            </geometry>
        </collision>
    </link>
    <joint name="1_7" type="revolute">
       <parent link="1"/>
       <child  link="7"/>
       <origin rpy="0 0 0" xyz="-0.283784186289199 0.0 -0.2729324689574284" />
     <axis xyz="0 1 0"/>
       <limit effort="0.0" lower="-3.14159" upper="3.14159" velocity="0.0"/>
    </joint>
    <link name="7">
        <inertial>
            <origin xyz="0.0 0.0 -0.2212170735942014" rpy="0 0 0"/>
            <mass value="1" />
            <inertia ixx="100" ixy="0" ixz="0" iyy="100" iyz="0" izz="100" />
        </inertial>
        <visual>
            <origin xyz="0.0 0.0 -0.2212170735942014" rpy="0 0 0"/>
            <geometry>
                <box size="0.4818336562399801 0.9363872079623661 0.4424341471884028" />
            </geometry>
            <material name="Green">
                <color rgba="0 1.0 0 1.0"/>
            </material>
        </visual>
        <collision>
            <origin xyz="0.0 0.0 -0.2212170735942014" rpy="0 0 0"/>
            <geometry>
                <box size="0.4818336562399801 0.9363872079623661 0.4424341471884028" />
            </geometry>
        </collision>
    </link>
    <joint name="7_8" type="revolute">
       <parent link="7"/>
       <child  link="8"/>
       <origin rpy="0 0 0" xyz="0.0 -0.46819360398118304 -0.2212170735942014" />
     <axis xyz="0 1 0"/>
       <limit effort="0.0" lower="-3.14159" upper="3.14159" velocity="0.0"/>
    </joint>
    <link name="8">
        <inertial>
            <origin xyz="0.0 -0.24403575701677094 0.0" rpy="0 0 0"/>
            <mass value="1" />
            <inertia ixx="100" ixy="0" ixz="0" iyy="100" iyz="0" izz="100" />
        </inertial>
        <visual>
            <origin xyz="0.0 -0.24403575701677094 0.0" rpy="0 0 0"/>
            <geometry>
                <box size="0.42449943917954247 0.4880715140335419 0.9176871568393479" />
            </geometry>
            <material name="Blue">
                <color rgba="0 0 1.0 1.0"/>
            </material>
        </visual>
        <collision>
            <origin xyz="0.0 -0.24403575701677094 0.0" rpy="0 0 0"/>
            <geometry>
                <box size="0.42449943917954247 0.4880715140335419 0.9176871568393479" />
            </geometry>
        </collision>
    </link>
    <joint name="1_9" type="revolute">
       <parent link="1"/>
       <child  link="9"/>
       <origin rpy="0 0 0" xyz="-0.283784186289199 0.3042696241012379 0.0" />
     <axis xyz="0 1 0"/>
       <limit effort="0.0" lower="-3.14159" upper="3.14159" velocity="0.0"/>
    </joint>
    <link name="9">
        <inertial>
            <origin xyz="0.0 0.524885095842268 0.0" rpy="0 0 0"/>
            <mass value="1" />
            <inertia ixx="100" ixy="0" ixz="0" iyy="100" iyz="0" izz="100" />
        </inertial>
        <visual>
            <origin xyz="0.0 0.524885095842268 0.0" rpy="0 0 0"/>
            <geometry>
                <box size="0.4253495147083901 1.049770191684536 0.41105403399059937" />
            </geometry>
            <material name="Green">
                <color rgba="0 1.0 0 1.0"/>
            </material>
        </visual>
        <collision>
            <origin xyz="0.0 0.524885095842268 0.0" rpy="0 0 0"/>
            <geometry>
                <box size="0.4253495147083901 1.049770191684536 0.41105403399059937" />
            </geometry>
        </collision>
    </link>
</robot>