<robot name = "robot">
    <link name="0">
        <inertial>
            <origin xyz="0 0 3.207704153878636" rpy="0 0 0"/>
            <mass value="1" />
            <inertia ixx="100" ixy="0" ixz="0" iyy="100" iyz="0" izz="100" />
        </inertial>
        <visual>
            <origin xyz="0 0 3.207704153878636" rpy="0 0 0"/>
            <geometry>
                <box size="0.5084778452189425 0.8188137698007316 0.41540830775727267" />
            </geometry>
            <material name="Green">
                <color rgba="0 1.0 0 1.0"/>
            </material>
        </visual>
        <collision>
            <origin xyz="0 0 3.207704153878636" rpy="0 0 0"/>
            <geometry>
                <box size="0.5084778452189425 0.8188137698007316 0.41540830775727267" />
            </geometry>
        </collision>
    </link>
    <joint name="0_1" type="revolute">
       <parent link="0"/>
       <child  link="1"/>
       <origin rpy="0 0 0" xyz="0.0 0.4094068849003658 3.207704153878636" />
     <axis xyz="1 0 0"/>
       <limit effort="0.0" lower="-3.14159" upper="3.14159" velocity="0.0"/>
    </joint>
    <link name="1">
        <inertial>
            <origin xyz="0.0 0.3531199440603477 0.0" rpy="0 0 0"/>
            <mass value="1" />
            <inertia ixx="100" ixy="0" ixz="0" iyy="100" iyz="0" izz="100" />
        </inertial>
        <visual>
            <origin xyz="0.0 0.3531199440603477 0.0" rpy="0 0 0"/>
            <geometry>
                <box size="0.7301759101808706 0.7062398881206954 0.47705977657927473" />
            </geometry>
            <material name="Green">
                <color rgba="0 1.0 0 1.0"/>
            </material>
        </visual>
        <collision>
            <origin xyz="0.0 0.3531199440603477 0.0" rpy="0 0 0"/>
            <geometry>
                <box size="0.7301759101808706 0.7062398881206954 0.47705977657927473" />
            </geometry>
        </collision>
    </link>
    <joint name="1_2" type="revolute">
       <parent link="1"/>
       <child  link="2"/>
       <origin rpy="0 0 0" xyz="0.0 0.3531199440603477 -0.23852988828963737" />
     <axis xyz="1 0 0"/>
       <limit effort="0.0" lower="-3.14159" upper="3.14159" velocity="0.0"/>
    </joint>
    <link name="2">
        <inertial>
            <origin xyz="0.0 0.0 -0.3166028299776702" rpy="0 0 0"/>
            <mass value="1" />
            <inertia ixx="100" ixy="0" ixz="0" iyy="100" iyz="0" izz="100" />
        </inertial>
        <visual>
            <origin xyz="0.0 0.0 -0.3166028299776702" rpy="0 0 0"/>
            <geometry>
                <box size="0.8369892893728861 1.097938297753112 0.6332056599553404" />
            </geometry>
            <material name="Green">
                <color rgba="0 1.0 0 1.0"/>
            </material>
        </visual>
        <collision>
            <origin xyz="0.0 0.0 -0.3166028299776702" rpy="0 0 0"/>
            <geometry>
                <box size="0.8369892893728861 1.097938297753112 0.6332056599553404" />
            </geometry>
        </collision>
    </link>
    <joint name="2_3" type="revolute">
       <parent link="2"/>
       <child  link="3"/>
       <origin rpy="0 0 0" xyz="0.0 0.548969148876556 -0.3166028299776702" />
     <axis xyz="1 0 0"/>
       <limit effort="0.0" lower="-3.14159" upper="3.14159" velocity="0.0"/>
    </joint>
    <link name="3">
        <inertial>
            <origin xyz="0.0 0.2568053905614432 0.0" rpy="0 0 0"/>
            <mass value="1" />
            <inertia ixx="100" ixy="0" ixz="0" iyy="100" iyz="0" izz="100" />
        </inertial>
        <visual>
            <origin xyz="0.0 0.2568053905614432 0.0" rpy="0 0 0"/>
            <geometry>
                <box size="0.3993187191468951 0.5136107811228864 0.9467640632912855" />
            </geometry>
            <material name="Green">
                <color rgba="0 1.0 0 1.0"/>
            </material>
        </visual>
        <collision>
            <origin xyz="0.0 0.2568053905614432 0.0" rpy="0 0 0"/>
            <geometry>
                <box size="0.3993187191468951 0.5136107811228864 0.9467640632912855" />
            </geometry>
        </collision>
    </link>
    <joint name="1_4" type="revolute">
       <parent link="1"/>
       <child  link="4"/>
       <origin rpy="0 0 0" xyz="0.0 0.3531199440603477 0.23852988828963737" />
     <axis xyz="0 1 0"/>
       <limit effort="0.0" lower="-3.14159" upper="3.14159" velocity="0.0"/>
    </joint>
    <link name="4">
        <inertial>
            <origin xyz="0.0 0.0 0.3301213053527546" rpy="0 0 0"/>
            <mass value="1" />
            <inertia ixx="100" ixy="0" ixz="0" iyy="100" iyz="0" izz="100" />
        </inertial>
        <visual>
            <origin xyz="0.0 0.0 0.3301213053527546" rpy="0 0 0"/>
            <geometry>
                <box size="1.0492439065147652 0.5918233734393732 0.6602426107055092" />
            </geometry>
            <material name="Blue">
                <color rgba="0 0 1.0 1.0"/>
            </material>
        </visual>
        <collision>
            <origin xyz="0.0 0.0 0.3301213053527546" rpy="0 0 0"/>
            <geometry>
                <box size="1.0492439065147652 0.5918233734393732 0.6602426107055092" />
            </geometry>
        </collision>
    </link>
    <joint name="3_5" type="revolute">
       <parent link="3"/>
       <child  link="5"/>
       <origin rpy="0 0 0" xyz="0.19965935957344755 0.2568053905614432 0.0" />
     <axis xyz="0 1 0"/>
       <limit effort="0.0" lower="-3.14159" upper="3.14159" velocity="0.0"/>
    </joint>
    <link name="5">
        <inertial>
            <origin xyz="0.4405140162275599 0.0 0.0" rpy="0 0 0"/>
            <mass value="1" />
            <inertia ixx="100" ixy="0" ixz="0" iyy="100" iyz="0" izz="100" />
        </inertial>
        <visual>
            <origin xyz="0.4405140162275599 0.0 0.0" rpy="0 0 0"/>
            <geometry>
                <box size="0.8810280324551198 0.4343257816322231 0.39954299572585494" />
            </geometry>
            <material name="Blue">
                <color rgba="0 0 1.0 1.0"/>
            </material>
        </visual>
        <collision>
            <origin xyz="0.4405140162275599 0.0 0.0" rpy="0 0 0"/>
            <geometry>
                <box size="0.8810280324551198 0.4343257816322231 0.39954299572585494" />
            </geometry>
        </collision>
    </link>
    <joint name="0_6" type="revolute">
       <parent link="0"/>
       <child  link="6"/>
       <origin rpy="0 0 0" xyz="0.25423892260947123 0.0 3.207704153878636" />
     <axis xyz="0 1 0"/>
       <limit effort="0.0" lower="-3.14159" upper="3.14159" velocity="0.0"/>
    </joint>
    <link name="6">
        <inertial>
            <origin xyz="0.5543426942084269 0.0 0.0" rpy="0 0 0"/>
            <mass value="1" />
            <inertia ixx="100" ixy="0" ixz="0" iyy="100" iyz="0" izz="100" />
        </inertial>
        <visual>
            <origin xyz="0.5543426942084269 0.0 0.0" rpy="0 0 0"/>
            <geometry>
                <box size="1.1086853884168537 0.6248852302259468 0.3897116021651963" />
            </geometry>
            <material name="Green">
                <color rgba="0 1.0 0 1.0"/>
            </material>
        </visual>
        <collision>
            <origin xyz="0.5543426942084269 0.0 0.0" rpy="0 0 0"/>
            <geometry>
                <box size="1.1086853884168537 0.6248852302259468 0.3897116021651963" />
            </geometry>
        </collision>
    </link>
    <joint name="5_7" type="revolute">
       <parent link="5"/>
       <child  link="7"/>
       <origin rpy="0 0 0" xyz="0.4405140162275599 -0.21716289081611154 0.0" />
     <axis xyz="1 0 0"/>
       <limit effort="0.0" lower="-3.14159" upper="3.14159" velocity="0.0"/>
    </joint>
    <link name="7">
        <inertial>
            <origin xyz="0.0 -0.2956240624464382 0.0" rpy="0 0 0"/>
            <mass value="1" />
            <inertia ixx="100" ixy="0" ixz="0" iyy="100" iyz="0" izz="100" />
        </inertial>
        <visual>
            <origin xyz="0.0 -0.2956240624464382 0.0" rpy="0 0 0"/>
            <geometry>
                <box size="0.44317204224743145 0.5912481248928764 0.8503169465279502" />
            </geometry>
            <material name="Blue">
                <color rgba="0 0 1.0 1.0"/>
            </material>
        </visual>
        <collision>
            <origin xyz="0.0 -0.2956240624464382 0.0" rpy="0 0 0"/>
            <geometry>
                <box size="0.44317204224743145 0.5912481248928764 0.8503169465279502" />
            </geometry>
        </collision>
    </link>
</robot>