<robot name = "robot">
    <link name="0">
        <inertial>
            <origin xyz="0 0 3.247134370312449" rpy="0 0 0"/>
            <mass value="1" />
            <inertia ixx="100" ixy="0" ixz="0" iyy="100" iyz="0" izz="100" />
        </inertial>
        <visual>
            <origin xyz="0 0 3.247134370312449" rpy="0 0 0"/>
            <geometry>
                <box size="0.9835609054240878 1.0795281021885166 0.49426874062489845" />
            </geometry>
            <material name="Green">
                <color rgba="0 1.0 0 1.0"/>
            </material>
        </visual>
        <collision>
            <origin xyz="0 0 3.247134370312449" rpy="0 0 0"/>
            <geometry>
                <box size="0.9835609054240878 1.0795281021885166 0.49426874062489845" />
            </geometry>
        </collision>
    </link>
    <joint name="0_1" type="revolute">
       <parent link="0"/>
       <child  link="1"/>
       <origin rpy="0 0 0" xyz="0.0 0.0 3.0" />
     <axis xyz="1 0 0"/>
       <limit effort="0.0" lower="-3.14159" upper="3.14159" velocity="0.0"/>
    </joint>
    <link name="1">
        <inertial>
            <origin xyz="0.0 0.0 -0.47264411368172293" rpy="0 0 0"/>
            <mass value="1" />
            <inertia ixx="100" ixy="0" ixz="0" iyy="100" iyz="0" izz="100" />
        </inertial>
        <visual>
            <origin xyz="0.0 0.0 -0.47264411368172293" rpy="0 0 0"/>
            <geometry>
                <box size="0.9235861834850613 0.7164838272762479 0.9452882273634459" />
            </geometry>
            <material name="Green">
                <color rgba="0 1.0 0 1.0"/>
            </material>
        </visual>
        <collision>
            <origin xyz="0.0 0.0 -0.47264411368172293" rpy="0 0 0"/>
            <geometry>
                <box size="0.9235861834850613 0.7164838272762479 0.9452882273634459" />
            </geometry>
        </collision>
    </link>
    <joint name="1_3" type="revolute">
       <parent link="1"/>
       <child  link="3"/>
       <origin rpy="0 0 0" xyz="-0.46179309174253064 0.0 -0.47264411368172293" />
     <axis xyz="1 0 0"/>
       <limit effort="0.0" lower="-3.14159" upper="3.14159" velocity="0.0"/>
    </joint>
    <link name="3">
        <inertial>
            <origin xyz="-0.4714436067444866 0.0 0.0" rpy="0 0 0"/>
            <mass value="1" />
            <inertia ixx="100" ixy="0" ixz="0" iyy="100" iyz="0" izz="100" />
        </inertial>
        <visual>
            <origin xyz="-0.4714436067444866 0.0 0.0" rpy="0 0 0"/>
            <geometry>
                <box size="0.9428872134889732 0.9839783461938681 0.9244238218325419" />
            </geometry>
            <material name="Green">
                <color rgba="0 1.0 0 1.0"/>
            </material>
        </visual>
        <collision>
            <origin xyz="-0.4714436067444866 0.0 0.0" rpy="0 0 0"/>
            <geometry>
                <box size="0.9428872134889732 0.9839783461938681 0.9244238218325419" />
            </geometry>
        </collision>
    </link>
    <joint name="3_4" type="revolute">
       <parent link="3"/>
       <child  link="4"/>
       <origin rpy="0 0 0" xyz="-0.9428872134889732 0.0 0.0" />
     <axis xyz="0 1 0"/>
       <limit effort="0.0" lower="-3.14159" upper="3.14159" velocity="0.0"/>
    </joint>
    <link name="4">
        <inertial>
            <origin xyz="-0.5503946098971522 0.0 0.0" rpy="0 0 0"/>
            <mass value="1" />
            <inertia ixx="100" ixy="0" ixz="0" iyy="100" iyz="0" izz="100" />
        </inertial>
        <visual>
            <origin xyz="-0.5503946098971522 0.0 0.0" rpy="0 0 0"/>
            <geometry>
                <box size="1.1007892197943043 0.6062882633067623 0.6291674745865142" />
            </geometry>
            <material name="Blue">
                <color rgba="0 0 1.0 1.0"/>
            </material>
        </visual>
        <collision>
            <origin xyz="-0.5503946098971522 0.0 0.0" rpy="0 0 0"/>
            <geometry>
                <box size="1.1007892197943043 0.6062882633067623 0.6291674745865142" />
            </geometry>
        </collision>
    </link>
    <joint name="3_6" type="revolute">
       <parent link="3"/>
       <child  link="6"/>
       <origin rpy="0 0 0" xyz="-0.4714436067444866 -0.4919891730969341 0.0" />
     <axis xyz="1 0 0"/>
       <limit effort="0.0" lower="-3.14159" upper="3.14159" velocity="0.0"/>
    </joint>
    <link name="6">
        <inertial>
            <origin xyz="0.0 -0.43995818501975487 0.0" rpy="0 0 0"/>
            <mass value="1" />
            <inertia ixx="100" ixy="0" ixz="0" iyy="100" iyz="0" izz="100" />
        </inertial>
        <visual>
            <origin xyz="0.0 -0.43995818501975487 0.0" rpy="0 0 0"/>
            <geometry>
                <box size="0.7227257868514767 0.8799163700395097 0.7320933408084367" />
            </geometry>
            <material name="Green">
                <color rgba="0 1.0 0 1.0"/>
            </material>
        </visual>
        <collision>
            <origin xyz="0.0 -0.43995818501975487 0.0" rpy="0 0 0"/>
            <geometry>
                <box size="0.7227257868514767 0.8799163700395097 0.7320933408084367" />
            </geometry>
        </collision>
    </link>
    <joint name="4_7" type="revolute">
       <parent link="4"/>
       <child  link="7"/>
       <origin rpy="0 0 0" xyz="-0.5503946098971522 0.0 0.3145837372932571" />
     <axis xyz="1 0 0"/>
       <limit effort="0.0" lower="-3.14159" upper="3.14159" velocity="0.0"/>
    </joint>
    <link name="7">
        <inertial>
            <origin xyz="0.0 0.0 0.47229343919174005" rpy="0 0 0"/>
            <mass value="1" />
            <inertia ixx="100" ixy="0" ixz="0" iyy="100" iyz="0" izz="100" />
        </inertial>
        <visual>
            <origin xyz="0.0 0.0 0.47229343919174005" rpy="0 0 0"/>
            <geometry>
                <box size="1.0803522878838119 0.7921530574118636 0.9445868783834801" />
            </geometry>
            <material name="Green">
                <color rgba="0 1.0 0 1.0"/>
            </material>
        </visual>
        <collision>
            <origin xyz="0.0 0.0 0.47229343919174005" rpy="0 0 0"/>
            <geometry>
                <box size="1.0803522878838119 0.7921530574118636 0.9445868783834801" />
            </geometry>
        </collision>
    </link>
    <joint name="0_2" type="revolute">
       <parent link="0"/>
       <child  link="2"/>
       <origin rpy="0 0 0" xyz="0.0 0.0 3.4942687406248982" />
     <axis xyz="1 0 0"/>
       <limit effort="0.0" lower="-3.14159" upper="3.14159" velocity="0.0"/>
    </joint>
    <link name="2">
        <inertial>
            <origin xyz="0.0 0.0 0.3270200436726805" rpy="0 0 0"/>
            <mass value="1" />
            <inertia ixx="100" ixy="0" ixz="0" iyy="100" iyz="0" izz="100" />
        </inertial>
        <visual>
            <origin xyz="0.0 0.0 0.3270200436726805" rpy="0 0 0"/>
            <geometry>
                <box size="0.5612828744482742 0.7566669496216679 0.654040087345361" />
            </geometry>
            <material name="Blue">
                <color rgba="0 0 1.0 1.0"/>
            </material>
        </visual>
        <collision>
            <origin xyz="0.0 0.0 0.3270200436726805" rpy="0 0 0"/>
            <geometry>
                <box size="0.5612828744482742 0.7566669496216679 0.654040087345361" />
            </geometry>
        </collision>
    </link>
</robot>