<robot name = "robot">
    <link name="0">
        <inertial>
            <origin xyz="0 0 3.223753385666342" rpy="0 0 0"/>
            <mass value="1" />
            <inertia ixx="100" ixy="0" ixz="0" iyy="100" iyz="0" izz="100" />
        </inertial>
        <visual>
            <origin xyz="0 0 3.223753385666342" rpy="0 0 0"/>
            <geometry>
                <box size="0.8027671525585378 1.0353593993667323 0.44750677133268324" />
            </geometry>
            <material name="Green">
                <color rgba="0 1.0 0 1.0"/>
            </material>
        </visual>
        <collision>
            <origin xyz="0 0 3.223753385666342" rpy="0 0 0"/>
            <geometry>
                <box size="0.8027671525585378 1.0353593993667323 0.44750677133268324" />
            </geometry>
        </collision>
    </link>
    <joint name="0_1" type="revolute">
       <parent link="0"/>
       <child  link="1"/>
       <origin rpy="0 0 0" xyz="0.0 0.0 3.0" />
     <axis xyz="1 0 0"/>
       <limit effort="0.0" lower="-3.14159" upper="3.14159" velocity="0.0"/>
    </joint>
    <link name="1">
        <inertial>
            <origin xyz="0.0 0.0 -0.4308908153614761" rpy="0 0 0"/>
            <mass value="1" />
            <inertia ixx="100" ixy="0" ixz="0" iyy="100" iyz="0" izz="100" />
        </inertial>
        <visual>
            <origin xyz="0.0 0.0 -0.4308908153614761" rpy="0 0 0"/>
            <geometry>
                <box size="0.4086456169108873 1.1002886684397164 0.8617816307229522" />
            </geometry>
            <material name="Blue">
                <color rgba="0 0 1.0 1.0"/>
            </material>
        </visual>
        <collision>
            <origin xyz="0.0 0.0 -0.4308908153614761" rpy="0 0 0"/>
            <geometry>
                <box size="0.4086456169108873 1.1002886684397164 0.8617816307229522" />
            </geometry>
        </collision>
    </link>
    <joint name="1_2" type="revolute">
       <parent link="1"/>
       <child  link="2"/>
       <origin rpy="0 0 0" xyz="-0.20432280845544365 0.0 -0.4308908153614761" />
     <axis xyz="1 0 0"/>
       <limit effort="0.0" lower="-3.14159" upper="3.14159" velocity="0.0"/>
    </joint>
    <link name="2">
        <inertial>
            <origin xyz="-0.48635743952879396 0.0 0.0" rpy="0 0 0"/>
            <mass value="1" />
            <inertia ixx="100" ixy="0" ixz="0" iyy="100" iyz="0" izz="100" />
        </inertial>
        <visual>
            <origin xyz="-0.48635743952879396 0.0 0.0" rpy="0 0 0"/>
            <geometry>
                <box size="0.9727148790575879 0.43598091571129793 0.8500438322869462" />
            </geometry>
            <material name="Green">
                <color rgba="0 1.0 0 1.0"/>
            </material>
        </visual>
        <collision>
            <origin xyz="-0.48635743952879396 0.0 0.0" rpy="0 0 0"/>
            <geometry>
                <box size="0.9727148790575879 0.43598091571129793 0.8500438322869462" />
            </geometry>
        </collision>
    </link>
    <joint name="2_5" type="revolute">
       <parent link="2"/>
       <child  link="5"/>
       <origin rpy="0 0 0" xyz="-0.9727148790575879 0.0 0.0" />
     <axis xyz="0 1 0"/>
       <limit effort="0.0" lower="-3.14159" upper="3.14159" velocity="0.0"/>
    </joint>
    <link name="5">
        <inertial>
            <origin xyz="-0.31014439508776326 0.0 0.0" rpy="0 0 0"/>
            <mass value="1" />
            <inertia ixx="100" ixy="0" ixz="0" iyy="100" iyz="0" izz="100" />
        </inertial>
        <visual>
            <origin xyz="-0.31014439508776326 0.0 0.0" rpy="0 0 0"/>
            <geometry>
                <box size="0.6202887901755265 0.9668392261854564 0.8153519888110492" />
            </geometry>
            <material name="Blue">
                <color rgba="0 0 1.0 1.0"/>
            </material>
        </visual>
        <collision>
            <origin xyz="-0.31014439508776326 0.0 0.0" rpy="0 0 0"/>
            <geometry>
                <box size="0.6202887901755265 0.9668392261854564 0.8153519888110492" />
            </geometry>
        </collision>
    </link>
    <joint name="2_7" type="revolute">
       <parent link="2"/>
       <child  link="7"/>
       <origin rpy="0 0 0" xyz="-0.48635743952879396 -0.21799045785564897 0.0" />
     <axis xyz="1 0 0"/>
       <limit effort="0.0" lower="-3.14159" upper="3.14159" velocity="0.0"/>
    </joint>
    <link name="7">
        <inertial>
            <origin xyz="0.0 -0.5244469131263013 0.0" rpy="0 0 0"/>
            <mass value="1" />
            <inertia ixx="100" ixy="0" ixz="0" iyy="100" iyz="0" izz="100" />
        </inertial>
        <visual>
            <origin xyz="0.0 -0.5244469131263013 0.0" rpy="0 0 0"/>
            <geometry>
                <box size="0.5702674540251922 1.0488938262526026 0.5126810489484268" />
            </geometry>
            <material name="Green">
                <color rgba="0 1.0 0 1.0"/>
            </material>
        </visual>
        <collision>
            <origin xyz="0.0 -0.5244469131263013 0.0" rpy="0 0 0"/>
            <geometry>
                <box size="0.5702674540251922 1.0488938262526026 0.5126810489484268" />
            </geometry>
        </collision>
    </link>
    <joint name="1_8" type="revolute">
       <parent link="1"/>
       <child  link="8"/>
       <origin rpy="0 0 0" xyz="0.0 0.5501443342198582 -0.4308908153614761" />
     <axis xyz="1 0 0"/>
       <limit effort="0.0" lower="-3.14159" upper="3.14159" velocity="0.0"/>
    </joint>
    <link name="8">
        <inertial>
            <origin xyz="0.0 0.2939686165639518 0.0" rpy="0 0 0"/>
            <mass value="1" />
            <inertia ixx="100" ixy="0" ixz="0" iyy="100" iyz="0" izz="100" />
        </inertial>
        <visual>
            <origin xyz="0.0 0.2939686165639518 0.0" rpy="0 0 0"/>
            <geometry>
                <box size="0.3894539055722509 0.5879372331279036 0.8273095963929187" />
            </geometry>
            <material name="Blue">
                <color rgba="0 0 1.0 1.0"/>
            </material>
        </visual>
        <collision>
            <origin xyz="0.0 0.2939686165639518 0.0" rpy="0 0 0"/>
            <geometry>
                <box size="0.3894539055722509 0.5879372331279036 0.8273095963929187" />
            </geometry>
        </collision>
    </link>
    <joint name="7_3" type="revolute">
       <parent link="7"/>
       <child  link="3"/>
       <origin rpy="0 0 0" xyz="0.0 -0.5244469131263013 0.2563405244742134" />
     <axis xyz="0 1 0"/>
       <limit effort="0.0" lower="-3.14159" upper="3.14159" velocity="0.0"/>
    </joint>
    <link name="3">
        <inertial>
            <origin xyz="0.0 0.0 0.38500769273476126" rpy="0 0 0"/>
            <mass value="1" />
            <inertia ixx="100" ixy="0" ixz="0" iyy="100" iyz="0" izz="100" />
        </inertial>
        <visual>
            <origin xyz="0.0 0.0 0.38500769273476126" rpy="0 0 0"/>
            <geometry>
                <box size="0.868062087347353 0.37845772052913706 0.7700153854695225" />
            </geometry>
            <material name="Green">
                <color rgba="0 1.0 0 1.0"/>
            </material>
        </visual>
        <collision>
            <origin xyz="0.0 0.0 0.38500769273476126" rpy="0 0 0"/>
            <geometry>
                <box size="0.868062087347353 0.37845772052913706 0.7700153854695225" />
            </geometry>
        </collision>
    </link>
    <joint name="8_4" type="revolute">
       <parent link="8"/>
       <child  link="4"/>
       <origin rpy="0 0 0" xyz="0.19472695278612545 0.2939686165639518 0.0" />
     <axis xyz="1 0 0"/>
       <limit effort="0.0" lower="-3.14159" upper="3.14159" velocity="0.0"/>
    </joint>
    <link name="4">
        <inertial>
            <origin xyz="0.267461259632421 0.0 0.0" rpy="0 0 0"/>
            <mass value="1" />
            <inertia ixx="100" ixy="0" ixz="0" iyy="100" iyz="0" izz="100" />
        </inertial>
        <visual>
            <origin xyz="0.267461259632421 0.0 0.0" rpy="0 0 0"/>
            <geometry>
                <box size="0.534922519264842 0.47471457171462045 0.5422069658968336" />
            </geometry>
            <material name="Green">
                <color rgba="0 1.0 0 1.0"/>
            </material>
        </visual>
        <collision>
            <origin xyz="0.267461259632421 0.0 0.0" rpy="0 0 0"/>
            <geometry>
                <box size="0.534922519264842 0.47471457171462045 0.5422069658968336" />
            </geometry>
        </collision>
    </link>
    <joint name="1_6" type="revolute">
       <parent link="1"/>
       <child  link="6"/>
       <origin rpy="0 0 0" xyz="0.0 0.0 -0.8617816307229522" />
     <axis xyz="1 0 0"/>
       <limit effort="0.0" lower="-3.14159" upper="3.14159" velocity="0.0"/>
    </joint>
    <link name="6">
        <inertial>
            <origin xyz="0.0 0.0 -0.4126034037812531" rpy="0 0 0"/>
            <mass value="1" />
            <inertia ixx="100" ixy="0" ixz="0" iyy="100" iyz="0" izz="100" />
        </inertial>
        <visual>
            <origin xyz="0.0 0.0 -0.4126034037812531" rpy="0 0 0"/>
            <geometry>
                <box size="0.6868082487663846 0.5946792594718403 0.8252068075625062" />
            </geometry>
            <material name="Blue">
                <color rgba="0 0 1.0 1.0"/>
            </material>
        </visual>
        <collision>
            <origin xyz="0.0 0.0 -0.4126034037812531" rpy="0 0 0"/>
            <geometry>
                <box size="0.6868082487663846 0.5946792594718403 0.8252068075625062" />
            </geometry>
        </collision>
    </link>
</robot>