<robot name = "robot">
    <link name="0">
        <inertial>
            <origin xyz="0 0 3.3268172307480026" rpy="0 0 0"/>
            <mass value="1" />
            <inertia ixx="100" ixy="0" ixz="0" iyy="100" iyz="0" izz="100" />
        </inertial>
        <visual>
            <origin xyz="0 0 3.3268172307480026" rpy="0 0 0"/>
            <geometry>
                <box size="0.757766098004436 1.0958273114738475 0.6536344614960055" />
            </geometry>
            <material name="Blue">
                <color rgba="0 0 1.0 1.0"/>
            </material>
        </visual>
        <collision>
            <origin xyz="0 0 3.3268172307480026" rpy="0 0 0"/>
            <geometry>
                <box size="0.757766098004436 1.0958273114738475 0.6536344614960055" />
            </geometry>
        </collision>
    </link>
    <joint name="0_1" type="revolute">
       <parent link="0"/>
       <child  link="1"/>
       <origin rpy="0 0 0" xyz="-0.378883049002218 0.0 3.3268172307480026" />
     <axis xyz="0 1 0"/>
       <limit effort="0.0" lower="-3.14159" upper="3.14159" velocity="0.0"/>
    </joint>
    <link name="1">
        <inertial>
            <origin xyz="-0.48459049644341123 0.0 0.0" rpy="0 0 0"/>
            <mass value="1" />
            <inertia ixx="100" ixy="0" ixz="0" iyy="100" iyz="0" izz="100" />
        </inertial>
        <visual>
            <origin xyz="-0.48459049644341123 0.0 0.0" rpy="0 0 0"/>
            <geometry>
                <box size="0.9691809928868225 0.7096275935691286 1.103060892599503" />
            </geometry>
            <material name="Green">
                <color rgba="0 1.0 0 1.0"/>
            </material>
        </visual>
        <collision>
            <origin xyz="-0.48459049644341123 0.0 0.0" rpy="0 0 0"/>
            <geometry>
                <box size="0.9691809928868225 0.7096275935691286 1.103060892599503" />
            </geometry>
        </collision>
    </link>
    <joint name="1_2" type="revolute">
       <parent link="1"/>
       <child  link="2"/>
       <origin rpy="0 0 0" xyz="-0.48459049644341123 0.0 0.5515304462997515" />
     <axis xyz="0 1 0"/>
       <limit effort="0.0" lower="-3.14159" upper="3.14159" velocity="0.0"/>
    </joint>
    <link name="2">
        <inertial>
            <origin xyz="0.0 0.0 0.47097244989518505" rpy="0 0 0"/>
            <mass value="1" />
            <inertia ixx="100" ixy="0" ixz="0" iyy="100" iyz="0" izz="100" />
        </inertial>
        <visual>
            <origin xyz="0.0 0.0 0.47097244989518505" rpy="0 0 0"/>
            <geometry>
                <box size="0.4150595427195557 0.5597496627930745 0.9419448997903701" />
            </geometry>
            <material name="Blue">
                <color rgba="0 0 1.0 1.0"/>
            </material>
        </visual>
        <collision>
            <origin xyz="0.0 0.0 0.47097244989518505" rpy="0 0 0"/>
            <geometry>
                <box size="0.4150595427195557 0.5597496627930745 0.9419448997903701" />
            </geometry>
        </collision>
    </link>
    <joint name="2_3" type="revolute">
       <parent link="2"/>
       <child  link="3"/>
       <origin rpy="0 0 0" xyz="-0.20752977135977785 0.0 0.47097244989518505" />
     <axis xyz="1 0 0"/>
       <limit effort="0.0" lower="-3.14159" upper="3.14159" velocity="0.0"/>
    </joint>
    <link name="3">
        <inertial>
            <origin xyz="-0.4559918350344085 0.0 0.0" rpy="0 0 0"/>
            <mass value="1" />
            <inertia ixx="100" ixy="0" ixz="0" iyy="100" iyz="0" izz="100" />
        </inertial>
        <visual>
            <origin xyz="-0.4559918350344085 0.0 0.0" rpy="0 0 0"/>
            <geometry>
                <box size="0.911983670068817 0.47103853317996974 0.4667384984154217" />
            </geometry>
            <material name="Green">
                <color rgba="0 1.0 0 1.0"/>
            </material>
        </visual>
        <collision>
            <origin xyz="-0.4559918350344085 0.0 0.0" rpy="0 0 0"/>
            <geometry>
                <box size="0.911983670068817 0.47103853317996974 0.4667384984154217" />
            </geometry>
        </collision>
    </link>
    <joint name="1_4" type="revolute">
       <parent link="1"/>
       <child  link="4"/>
       <origin rpy="0 0 0" xyz="-0.48459049644341123 -0.3548137967845643 0.0" />
     <axis xyz="1 0 0"/>
       <limit effort="0.0" lower="-3.14159" upper="3.14159" velocity="0.0"/>
    </joint>
    <link name="4">
        <inertial>
            <origin xyz="0.0 -0.3127556639920394 0.0" rpy="0 0 0"/>
            <mass value="1" />
            <inertia ixx="100" ixy="0" ixz="0" iyy="100" iyz="0" izz="100" />
        </inertial>
        <visual>
            <origin xyz="0.0 -0.3127556639920394 0.0" rpy="0 0 0"/>
            <geometry>
                <box size="0.8225482551810301 0.6255113279840788 0.7091276054254981" />
            </geometry>
            <material name="Blue">
                <color rgba="0 0 1.0 1.0"/>
            </material>
        </visual>
        <collision>
            <origin xyz="0.0 -0.3127556639920394 0.0" rpy="0 0 0"/>
            <geometry>
                <box size="0.8225482551810301 0.6255113279840788 0.7091276054254981" />
            </geometry>
        </collision>
    </link>
    <joint name="2_5" type="revolute">
       <parent link="2"/>
       <child  link="5"/>
       <origin rpy="0 0 0" xyz="0.0 0.27987483139653724 0.47097244989518505" />
     <axis xyz="0 1 0"/>
       <limit effort="0.0" lower="-3.14159" upper="3.14159" velocity="0.0"/>
    </joint>
    <link name="5">
        <inertial>
            <origin xyz="0.0 0.21003606369988118 0.0" rpy="0 0 0"/>
            <mass value="1" />
            <inertia ixx="100" ixy="0" ixz="0" iyy="100" iyz="0" izz="100" />
        </inertial>
        <visual>
            <origin xyz="0.0 0.21003606369988118 0.0" rpy="0 0 0"/>
            <geometry>
                <box size="0.9827356740842639 0.42007212739976235 0.712307668422417" />
            </geometry>
            <material name="Blue">
                <color rgba="0 0 1.0 1.0"/>
            </material>
        </visual>
        <collision>
            <origin xyz="0.0 0.21003606369988118 0.0" rpy="0 0 0"/>
            <geometry>
                <box size="0.9827356740842639 0.42007212739976235 0.712307668422417" />
            </geometry>
        </collision>
    </link>
    <joint name="5_6" type="revolute">
       <parent link="5"/>
       <child  link="6"/>
       <origin rpy="0 0 0" xyz="0.0 0.42007212739976235 0.0" />
     <axis xyz="0 1 0"/>
       <limit effort="0.0" lower="-3.14159" upper="3.14159" velocity="0.0"/>
    </joint>
    <link name="6">
        <inertial>
            <origin xyz="0.0 0.490416538255257 0.0" rpy="0 0 0"/>
            <mass value="1" />
            <inertia ixx="100" ixy="0" ixz="0" iyy="100" iyz="0" izz="100" />
        </inertial>
        <visual>
            <origin xyz="0.0 0.490416538255257 0.0" rpy="0 0 0"/>
            <geometry>
                <box size="0.4388028463126617 0.980833076510514 0.5026875567285616" />
            </geometry>
            <material name="Green">
                <color rgba="0 1.0 0 1.0"/>
            </material>
        </visual>
        <collision>
            <origin xyz="0.0 0.490416538255257 0.0" rpy="0 0 0"/>
            <geometry>
                <box size="0.4388028463126617 0.980833076510514 0.5026875567285616" />
            </geometry>
        </collision>
    </link>
    <joint name="1_7" type="revolute">
       <parent link="1"/>
       <child  link="7"/>
       <origin rpy="0 0 0" xyz="-0.48459049644341123 0.0 -0.5515304462997515" />
     <axis xyz="0 1 0"/>
       <limit effort="0.0" lower="-3.14159" upper="3.14159" velocity="0.0"/>
    </joint>
    <link name="7">
        <inertial>
            <origin xyz="0.0 0.0 -0.4067689932071843" rpy="0 0 0"/>
            <mass value="1" />
            <inertia ixx="100" ixy="0" ixz="0" iyy="100" iyz="0" izz="100" />
        </inertial>
        <visual>
            <origin xyz="0.0 0.0 -0.4067689932071843" rpy="0 0 0"/>
            <geometry>
                <box size="1.0156087599312233 0.5028362663369438 0.8135379864143686" />
            </geometry>
            <material name="Green">
                <color rgba="0 1.0 0 1.0"/>
            </material>
        </visual>
        <collision>
            <origin xyz="0.0 0.0 -0.4067689932071843" rpy="0 0 0"/>
            <geometry>
                <box size="1.0156087599312233 0.5028362663369438 0.8135379864143686" />
            </geometry>
        </collision>
    </link>
    <joint name="6_8" type="revolute">
       <parent link="6"/>
       <child  link="8"/>
       <origin rpy="0 0 0" xyz="0.0 0.490416538255257 0.2513437783642808" />
     <axis xyz="1 0 0"/>
       <limit effort="0.0" lower="-3.14159" upper="3.14159" velocity="0.0"/>
    </joint>
    <link name="8">
        <inertial>
            <origin xyz="0.0 0.0 0.4283810775582083" rpy="0 0 0"/>
            <mass value="1" />
            <inertia ixx="100" ixy="0" ixz="0" iyy="100" iyz="0" izz="100" />
        </inertial>
        <visual>
            <origin xyz="0.0 0.0 0.4283810775582083" rpy="0 0 0"/>
            <geometry>
                <box size="0.7956859423576139 0.7865446478198856 0.8567621551164166" />
            </geometry>
            <material name="Blue">
                <color rgba="0 0 1.0 1.0"/>
            </material>
        </visual>
        <collision>
            <origin xyz="0.0 0.0 0.4283810775582083" rpy="0 0 0"/>
            <geometry>
                <box size="0.7956859423576139 0.7865446478198856 0.8567621551164166" />
            </geometry>
        </collision>
    </link>
    <joint name="3_9" type="revolute">
       <parent link="3"/>
       <child  link="9"/>
       <origin rpy="0 0 0" xyz="-0.4559918350344085 -0.23551926658998487 0.0" />
     <axis xyz="0 1 0"/>
       <limit effort="0.0" lower="-3.14159" upper="3.14159" velocity="0.0"/>
    </joint>
    <link name="9">
        <inertial>
            <origin xyz="0.0 -0.4790182479856928 0.0" rpy="0 0 0"/>
            <mass value="1" />
            <inertia ixx="100" ixy="0" ixz="0" iyy="100" iyz="0" izz="100" />
        </inertial>
        <visual>
            <origin xyz="0.0 -0.4790182479856928 0.0" rpy="0 0 0"/>
            <geometry>
                <box size="0.641089095523471 0.9580364959713856 0.8284524856749625" />
            </geometry>
            <material name="Green">
                <color rgba="0 1.0 0 1.0"/>
            </material>
        </visual>
        <collision>
            <origin xyz="0.0 -0.4790182479856928 0.0" rpy="0 0 0"/>
            <geometry>
                <box size="0.641089095523471 0.9580364959713856 0.8284524856749625" />
            </geometry>
        </collision>
    </link>
    <joint name="9_10" type="revolute">
       <parent link="9"/>
       <child  link="10"/>
       <origin rpy="0 0 0" xyz="0.0 -0.4790182479856928 0.4142262428374813" />
     <axis xyz="0 1 0"/>
       <limit effort="0.0" lower="-3.14159" upper="3.14159" velocity="0.0"/>
    </joint>
    <link name="10">
        <inertial>
            <origin xyz="0.0 0.0 0.31733150006491145" rpy="0 0 0"/>
            <mass value="1" />
            <inertia ixx="100" ixy="0" ixz="0" iyy="100" iyz="0" izz="100" />
        </inertial>
        <visual>
            <origin xyz="0.0 0.0 0.31733150006491145" rpy="0 0 0"/>
            <geometry>
                <box size="0.5819424002345259 0.37951275343532476 0.6346630001298229" />
            </geometry>
            <material name="Blue">
                <color rgba="0 0 1.0 1.0"/>
            </material>
        </visual>
        <collision>
            <origin xyz="0.0 0.0 0.31733150006491145" rpy="0 0 0"/>
            <geometry>
                <box size="0.5819424002345259 0.37951275343532476 0.6346630001298229" />
            </geometry>
        </collision>
    </link>
    <joint name="9_11" type="revolute">
       <parent link="9"/>
       <child  link="11"/>
       <origin rpy="0 0 0" xyz="0.0 -0.9580364959713856 0.0" />
     <axis xyz="1 0 0"/>
       <limit effort="0.0" lower="-3.14159" upper="3.14159" velocity="0.0"/>
    </joint>
    <link name="11">
        <inertial>
            <origin xyz="0.0 -0.26011337916766364 0.0" rpy="0 0 0"/>
            <mass value="1" />
            <inertia ixx="100" ixy="0" ixz="0" iyy="100" iyz="0" izz="100" />
        </inertial>
        <visual>
            <origin xyz="0.0 -0.26011337916766364 0.0" rpy="0 0 0"/>
            <geometry>
                <box size="0.48601668880233384 0.5202267583353273 1.1154315608802823" />
            </geometry>
            <material name="Green">
                <color rgba="0 1.0 0 1.0"/>
            </material>
        </visual>
        <collision>
            <origin xyz="0.0 -0.26011337916766364 0.0" rpy="0 0 0"/>
            <geometry>
                <box size="0.48601668880233384 0.5202267583353273 1.1154315608802823" />
            </geometry>
        </collision>
    </link>
</robot>