<robot name = "robot">
    <link name="0">
        <inertial>
            <origin xyz="0 0 3.4659364270455497" rpy="0 0 0"/>
            <mass value="1" />
            <inertia ixx="100" ixy="0" ixz="0" iyy="100" iyz="0" izz="100" />
        </inertial>
        <visual>
            <origin xyz="0 0 3.4659364270455497" rpy="0 0 0"/>
            <geometry>
                <box size="0.8613079512759554 0.5002600314785551 0.9318728540910992" />
            </geometry>
            <material name="Green">
                <color rgba="0 1.0 0 1.0"/>
            </material>
        </visual>
        <collision>
            <origin xyz="0 0 3.4659364270455497" rpy="0 0 0"/>
            <geometry>
                <box size="0.8613079512759554 0.5002600314785551 0.9318728540910992" />
            </geometry>
        </collision>
    </link>
    <joint name="0_1" type="revolute">
       <parent link="0"/>
       <child  link="1"/>
       <origin rpy="0 0 0" xyz="0.0 0.0 3.0" />
     <axis xyz="0 1 0"/>
       <limit effort="0.0" lower="-3.14159" upper="3.14159" velocity="0.0"/>
    </joint>
    <link name="1">
        <inertial>
            <origin xyz="0.0 0.0 -0.5506300514483047" rpy="0 0 0"/>
            <mass value="1" />
            <inertia ixx="100" ixy="0" ixz="0" iyy="100" iyz="0" izz="100" />
        </inertial>
        <visual>
            <origin xyz="0.0 0.0 -0.5506300514483047" rpy="0 0 0"/>
            <geometry>
                <box size="0.7570408625058644 0.7059802231396035 1.1012601028966094" />
            </geometry>
            <material name="Green">
                <color rgba="0 1.0 0 1.0"/>
            </material>
        </visual>
        <collision>
            <origin xyz="0.0 0.0 -0.5506300514483047" rpy="0 0 0"/>
            <geometry>
                <box size="0.7570408625058644 0.7059802231396035 1.1012601028966094" />
            </geometry>
        </collision>
    </link>
    <joint name="1_3" type="revolute">
       <parent link="1"/>
       <child  link="3"/>
       <origin rpy="0 0 0" xyz="0.0 -0.35299011156980176 -0.5506300514483047" />
     <axis xyz="0 1 0"/>
       <limit effort="0.0" lower="-3.14159" upper="3.14159" velocity="0.0"/>
    </joint>
    <link name="3">
        <inertial>
            <origin xyz="0.0 -0.4256609533608922 0.0" rpy="0 0 0"/>
            <mass value="1" />
            <inertia ixx="100" ixy="0" ixz="0" iyy="100" iyz="0" izz="100" />
        </inertial>
        <visual>
            <origin xyz="0.0 -0.4256609533608922 0.0" rpy="0 0 0"/>
            <geometry>
                <box size="0.40649117533318213 0.8513219067217844 0.5527578319472721" />
            </geometry>
            <material name="Blue">
                <color rgba="0 0 1.0 1.0"/>
            </material>
        </visual>
        <collision>
            <origin xyz="0.0 -0.4256609533608922 0.0" rpy="0 0 0"/>
            <geometry>
                <box size="0.40649117533318213 0.8513219067217844 0.5527578319472721" />
            </geometry>
        </collision>
    </link>
    <joint name="1_4" type="revolute">
       <parent link="1"/>
       <child  link="4"/>
       <origin rpy="0 0 0" xyz="-0.3785204312529322 0.0 -0.5506300514483047" />
     <axis xyz="0 1 0"/>
       <limit effort="0.0" lower="-3.14159" upper="3.14159" velocity="0.0"/>
    </joint>
    <link name="4">
        <inertial>
            <origin xyz="-0.21533812783793332 0.0 0.0" rpy="0 0 0"/>
            <mass value="1" />
            <inertia ixx="100" ixy="0" ixz="0" iyy="100" iyz="0" izz="100" />
        </inertial>
        <visual>
            <origin xyz="-0.21533812783793332 0.0 0.0" rpy="0 0 0"/>
            <geometry>
                <box size="0.43067625567586665 0.5877766511032206 0.7753319909710186" />
            </geometry>
            <material name="Blue">
                <color rgba="0 0 1.0 1.0"/>
            </material>
        </visual>
        <collision>
            <origin xyz="-0.21533812783793332 0.0 0.0" rpy="0 0 0"/>
            <geometry>
                <box size="0.43067625567586665 0.5877766511032206 0.7753319909710186" />
            </geometry>
        </collision>
    </link>
    <joint name="3_5" type="revolute">
       <parent link="3"/>
       <child  link="5"/>
       <origin rpy="0 0 0" xyz="0.0 -0.4256609533608922 0.27637891597363606" />
     <axis xyz="1 0 0"/>
       <limit effort="0.0" lower="-3.14159" upper="3.14159" velocity="0.0"/>
    </joint>
    <link name="5">
        <inertial>
            <origin xyz="0.0 0.0 0.21984293376369643" rpy="0 0 0"/>
            <mass value="1" />
            <inertia ixx="100" ixy="0" ixz="0" iyy="100" iyz="0" izz="100" />
        </inertial>
        <visual>
            <origin xyz="0.0 0.0 0.21984293376369643" rpy="0 0 0"/>
            <geometry>
                <box size="1.0965235211000244 0.5351103075931731 0.43968586752739286" />
            </geometry>
            <material name="Blue">
                <color rgba="0 0 1.0 1.0"/>
            </material>
        </visual>
        <collision>
            <origin xyz="0.0 0.0 0.21984293376369643" rpy="0 0 0"/>
            <geometry>
                <box size="1.0965235211000244 0.5351103075931731 0.43968586752739286" />
            </geometry>
        </collision>
    </link>
    <joint name="3_8" type="revolute">
       <parent link="3"/>
       <child  link="8"/>
       <origin rpy="0 0 0" xyz="-0.20324558766659107 -0.4256609533608922 0.0" />
     <axis xyz="1 0 0"/>
       <limit effort="0.0" lower="-3.14159" upper="3.14159" velocity="0.0"/>
    </joint>
    <link name="8">
        <inertial>
            <origin xyz="-0.2814179348000724 0.0 0.0" rpy="0 0 0"/>
            <mass value="1" />
            <inertia ixx="100" ixy="0" ixz="0" iyy="100" iyz="0" izz="100" />
        </inertial>
        <visual>
            <origin xyz="-0.2814179348000724 0.0 0.0" rpy="0 0 0"/>
            <geometry>
                <box size="0.5628358696001448 0.4557440988873166 0.38470919871818227" />
            </geometry>
            <material name="Green">
                <color rgba="0 1.0 0 1.0"/>
            </material>
        </visual>
        <collision>
            <origin xyz="-0.2814179348000724 0.0 0.0" rpy="0 0 0"/>
            <geometry>
                <box size="0.5628358696001448 0.4557440988873166 0.38470919871818227" />
            </geometry>
        </collision>
    </link>
    <joint name="5_9" type="revolute">
       <parent link="5"/>
       <child  link="9"/>
       <origin rpy="0 0 0" xyz="-0.5482617605500122 0.0 0.21984293376369643" />
     <axis xyz="0 1 0"/>
       <limit effort="0.0" lower="-3.14159" upper="3.14159" velocity="0.0"/>
    </joint>
    <link name="9">
        <inertial>
            <origin xyz="-0.22185315916701095 0.0 0.0" rpy="0 0 0"/>
            <mass value="1" />
            <inertia ixx="100" ixy="0" ixz="0" iyy="100" iyz="0" izz="100" />
        </inertial>
        <visual>
            <origin xyz="-0.22185315916701095 0.0 0.0" rpy="0 0 0"/>
            <geometry>
                <box size="0.4437063183340219 0.4416965212957149 0.42705734755377117" />
            </geometry>
            <material name="Blue">
                <color rgba="0 0 1.0 1.0"/>
            </material>
        </visual>
        <collision>
            <origin xyz="-0.22185315916701095 0.0 0.0" rpy="0 0 0"/>
            <geometry>
                <box size="0.4437063183340219 0.4416965212957149 0.42705734755377117" />
            </geometry>
        </collision>
    </link>
    <joint name="3_10" type="revolute">
       <parent link="3"/>
       <child  link="10"/>
       <origin rpy="0 0 0" xyz="0.0 -0.4256609533608922 -0.27637891597363606" />
     <axis xyz="1 0 0"/>
       <limit effort="0.0" lower="-3.14159" upper="3.14159" velocity="0.0"/>
    </joint>
    <link name="10">
        <inertial>
            <origin xyz="0.0 0.0 -0.5617501120046045" rpy="0 0 0"/>
            <mass value="1" />
            <inertia ixx="100" ixy="0" ixz="0" iyy="100" iyz="0" izz="100" />
        </inertial>
        <visual>
            <origin xyz="0.0 0.0 -0.5617501120046045" rpy="0 0 0"/>
            <geometry>
                <box size="1.0441004213733915 0.48282311916358733 1.123500224009209" />
            </geometry>
            <material name="Blue">
                <color rgba="0 0 1.0 1.0"/>
            </material>
        </visual>
        <collision>
            <origin xyz="0.0 0.0 -0.5617501120046045" rpy="0 0 0"/>
            <geometry>
                <box size="1.0441004213733915 0.48282311916358733 1.123500224009209" />
            </geometry>
        </collision>
    </link>
    <joint name="8_11" type="revolute">
       <parent link="8"/>
       <child  link="11"/>
       <origin rpy="0 0 0" xyz="-0.5628358696001448 0.0 0.0" />
     <axis xyz="0 1 0"/>
       <limit effort="0.0" lower="-3.14159" upper="3.14159" velocity="0.0"/>
    </joint>
    <link name="11">
        <inertial>
            <origin xyz="-0.33441164789229105 0.0 0.0" rpy="0 0 0"/>
            <mass value="1" />
            <inertia ixx="100" ixy="0" ixz="0" iyy="100" iyz="0" izz="100" />
        </inertial>
        <visual>
            <origin xyz="-0.33441164789229105 0.0 0.0" rpy="0 0 0"/>
            <geometry>
                <box size="0.6688232957845821 0.42987118557039283 0.5336112419943634" />
            </geometry>
            <material name="Blue">
                <color rgba="0 0 1.0 1.0"/>
            </material>
        </visual>
        <collision>
            <origin xyz="-0.33441164789229105 0.0 0.0" rpy="0 0 0"/>
            <geometry>
                <box size="0.6688232957845821 0.42987118557039283 0.5336112419943634" />
            </geometry>
        </collision>
    </link>
    <joint name="10_2" type="revolute">
       <parent link="10"/>
       <child  link="2"/>
       <origin rpy="0 0 0" xyz="0.5220502106866958 0.0 -0.5617501120046045" />
     <axis xyz="0 1 0"/>
       <limit effort="0.0" lower="-3.14159" upper="3.14159" velocity="0.0"/>
    </joint>
    <link name="2">
        <inertial>
            <origin xyz="0.37290606461150894 0.0 0.0" rpy="0 0 0"/>
            <mass value="1" />
            <inertia ixx="100" ixy="0" ixz="0" iyy="100" iyz="0" izz="100" />
        </inertial>
        <visual>
            <origin xyz="0.37290606461150894 0.0 0.0" rpy="0 0 0"/>
            <geometry>
                <box size="0.7458121292230179 1.1093367713694486 0.7183534816715144" />
            </geometry>
            <material name="Blue">
                <color rgba="0 0 1.0 1.0"/>
            </material>
        </visual>
        <collision>
            <origin xyz="0.37290606461150894 0.0 0.0" rpy="0 0 0"/>
            <geometry>
                <box size="0.7458121292230179 1.1093367713694486 0.7183534816715144" />
            </geometry>
        </collision>
    </link>
    <joint name="0_14" type="revolute">
       <parent link="0"/>
       <child  link="14"/>
       <origin rpy="0 0 0" xyz="0.0 0.25013001573927757 3.4659364270455497" />
     <axis xyz="0 1 0"/>
       <limit effort="0.0" lower="-3.14159" upper="3.14159" velocity="0.0"/>
    </joint>
    <link name="14">
        <inertial>
            <origin xyz="0.0 0.2788476172005194 0.0" rpy="0 0 0"/>
            <mass value="1" />
            <inertia ixx="100" ixy="0" ixz="0" iyy="100" iyz="0" izz="100" />
        </inertial>
        <visual>
            <origin xyz="0.0 0.2788476172005194 0.0" rpy="0 0 0"/>
            <geometry>
                <box size="0.8318275299629692 0.5576952344010389 0.6555324628980796" />
            </geometry>
            <material name="Green">
                <color rgba="0 1.0 0 1.0"/>
            </material>
        </visual>
        <collision>
            <origin xyz="0.0 0.2788476172005194 0.0" rpy="0 0 0"/>
            <geometry>
                <box size="0.8318275299629692 0.5576952344010389 0.6555324628980796" />
            </geometry>
        </collision>
    </link>
    <joint name="11_7" type="revolute">
       <parent link="11"/>
       <child  link="7"/>
       <origin rpy="0 0 0" xyz="-0.6688232957845821 0.0 0.0" />
     <axis xyz="0 1 0"/>
       <limit effort="0.0" lower="-3.14159" upper="3.14159" velocity="0.0"/>
    </joint>
    <link name="7">
        <inertial>
            <origin xyz="-0.4339339698475225 0.0 0.0" rpy="0 0 0"/>
            <mass value="1" />
            <inertia ixx="100" ixy="0" ixz="0" iyy="100" iyz="0" izz="100" />
        </inertial>
        <visual>
            <origin xyz="-0.4339339698475225 0.0 0.0" rpy="0 0 0"/>
            <geometry>
                <box size="0.867867939695045 0.7876682084095392 0.6796687547452105" />
            </geometry>
            <material name="Green">
                <color rgba="0 1.0 0 1.0"/>
            </material>
        </visual>
        <collision>
            <origin xyz="-0.4339339698475225 0.0 0.0" rpy="0 0 0"/>
            <geometry>
                <box size="0.867867939695045 0.7876682084095392 0.6796687547452105" />
            </geometry>
        </collision>
    </link>
    <joint name="3_6" type="revolute">
       <parent link="3"/>
       <child  link="6"/>
       <origin rpy="0 0 0" xyz="0.20324558766659107 -0.4256609533608922 0.0" />
     <axis xyz="0 1 0"/>
       <limit effort="0.0" lower="-3.14159" upper="3.14159" velocity="0.0"/>
    </joint>
    <link name="6">
        <inertial>
            <origin xyz="0.2819849707852004 0.0 0.0" rpy="0 0 0"/>
            <mass value="1" />
            <inertia ixx="100" ixy="0" ixz="0" iyy="100" iyz="0" izz="100" />
        </inertial>
        <visual>
            <origin xyz="0.2819849707852004 0.0 0.0" rpy="0 0 0"/>
            <geometry>
                <box size="0.5639699415704008 0.5920353592843406 0.5168627709019046" />
            </geometry>
            <material name="Blue">
                <color rgba="0 0 1.0 1.0"/>
            </material>
        </visual>
        <collision>
            <origin xyz="0.2819849707852004 0.0 0.0" rpy="0 0 0"/>
            <geometry>
                <box size="0.5639699415704008 0.5920353592843406 0.5168627709019046" />
            </geometry>
        </collision>
    </link>
    <joint name="3_12" type="revolute">
       <parent link="3"/>
       <child  link="12"/>
       <origin rpy="0 0 0" xyz="0.0 -0.8513219067217844 0.0" />
     <axis xyz="1 0 0"/>
       <limit effort="0.0" lower="-3.14159" upper="3.14159" velocity="0.0"/>
    </joint>
    <link name="12">
        <inertial>
            <origin xyz="0.0 -0.3622186265238581 0.0" rpy="0 0 0"/>
            <mass value="1" />
            <inertia ixx="100" ixy="0" ixz="0" iyy="100" iyz="0" izz="100" />
        </inertial>
        <visual>
            <origin xyz="0.0 -0.3622186265238581 0.0" rpy="0 0 0"/>
            <geometry>
                <box size="0.9166778120544364 0.7244372530477162 0.9849791483574553" />
            </geometry>
            <material name="Blue">
                <color rgba="0 0 1.0 1.0"/>
            </material>
        </visual>
        <collision>
            <origin xyz="0.0 -0.3622186265238581 0.0" rpy="0 0 0"/>
            <geometry>
                <box size="0.9166778120544364 0.7244372530477162 0.9849791483574553" />
            </geometry>
        </collision>
    </link>
</robot>