<robot name = "robot">
    <link name="0">
        <inertial>
            <origin xyz="0 0 3.209691452694646" rpy="0 0 0"/>
            <mass value="1" />
            <inertia ixx="100" ixy="0" ixz="0" iyy="100" iyz="0" izz="100" />
        </inertial>
        <visual>
            <origin xyz="0 0 3.209691452694646" rpy="0 0 0"/>
            <geometry>
                <box size="0.8242389667300648 0.8367782154029616 0.4193829053892918" />
            </geometry>
            <material name="Green">
                <color rgba="0 1.0 0 1.0"/>
            </material>
        </visual>
        <collision>
            <origin xyz="0 0 3.209691452694646" rpy="0 0 0"/>
            <geometry>
                <box size="0.8242389667300648 0.8367782154029616 0.4193829053892918" />
            </geometry>
        </collision>
    </link>
    <joint name="0_1" type="revolute">
       <parent link="0"/>
       <child  link="1"/>
       <origin rpy="0 0 0" xyz="0.0 0.0 3.419382905389292" />
     <axis xyz="0 1 0"/>
       <limit effort="0.0" lower="-3.14159" upper="3.14159" velocity="0.0"/>
    </joint>
    <link name="1">
        <inertial>
            <origin xyz="0.0 0.0 0.3105960388690428" rpy="0 0 0"/>
            <mass value="1" />
            <inertia ixx="100" ixy="0" ixz="0" iyy="100" iyz="0" izz="100" />
        </inertial>
        <visual>
            <origin xyz="0.0 0.0 0.3105960388690428" rpy="0 0 0"/>
            <geometry>
                <box size="0.9396944362349566 0.3804892269958978 0.6211920777380856" />
            </geometry>
            <material name="Green">
                <color rgba="0 1.0 0 1.0"/>
            </material>
        </visual>
        <collision>
            <origin xyz="0.0 0.0 0.3105960388690428" rpy="0 0 0"/>
            <geometry>
                <box size="0.9396944362349566 0.3804892269958978 0.6211920777380856" />
            </geometry>
        </collision>
    </link>
    <joint name="1_2" type="revolute">
       <parent link="1"/>
       <child  link="2"/>
       <origin rpy="0 0 0" xyz="0.0 -0.1902446134979489 0.3105960388690428" />
     <axis xyz="0 1 0"/>
       <limit effort="0.0" lower="-3.14159" upper="3.14159" velocity="0.0"/>
    </joint>
    <link name="2">
        <inertial>
            <origin xyz="0.0 -0.30786989044666996 0.0" rpy="0 0 0"/>
            <mass value="1" />
            <inertia ixx="100" ixy="0" ixz="0" iyy="100" iyz="0" izz="100" />
        </inertial>
        <visual>
            <origin xyz="0.0 -0.30786989044666996 0.0" rpy="0 0 0"/>
            <geometry>
                <box size="1.0346126425719877 0.6157397808933399 0.46721607866413384" />
            </geometry>
            <material name="Green">
                <color rgba="0 1.0 0 1.0"/>
            </material>
        </visual>
        <collision>
            <origin xyz="0.0 -0.30786989044666996 0.0" rpy="0 0 0"/>
            <geometry>
                <box size="1.0346126425719877 0.6157397808933399 0.46721607866413384" />
            </geometry>
        </collision>
    </link>
    <joint name="2_3" type="revolute">
       <parent link="2"/>
       <child  link="3"/>
       <origin rpy="0 0 0" xyz="0.0 -0.6157397808933399 0.0" />
     <axis xyz="1 0 0"/>
       <limit effort="0.0" lower="-3.14159" upper="3.14159" velocity="0.0"/>
    </joint>
    <link name="3">
        <inertial>
            <origin xyz="0.0 -0.27538346462002616 0.0" rpy="0 0 0"/>
            <mass value="1" />
            <inertia ixx="100" ixy="0" ixz="0" iyy="100" iyz="0" izz="100" />
        </inertial>
        <visual>
            <origin xyz="0.0 -0.27538346462002616 0.0" rpy="0 0 0"/>
            <geometry>
                <box size="1.1024856215495706 0.5507669292400523 1.0131856452019952" />
            </geometry>
            <material name="Blue">
                <color rgba="0 0 1.0 1.0"/>
            </material>
        </visual>
        <collision>
            <origin xyz="0.0 -0.27538346462002616 0.0" rpy="0 0 0"/>
            <geometry>
                <box size="1.1024856215495706 0.5507669292400523 1.0131856452019952" />
            </geometry>
        </collision>
    </link>
    <joint name="3_4" type="revolute">
       <parent link="3"/>
       <child  link="4"/>
       <origin rpy="0 0 0" xyz="0.0 -0.27538346462002616 0.5065928226009976" />
     <axis xyz="0 1 0"/>
       <limit effort="0.0" lower="-3.14159" upper="3.14159" velocity="0.0"/>
    </joint>
    <link name="4">
        <inertial>
            <origin xyz="0.0 0.0 0.39281018058475886" rpy="0 0 0"/>
            <mass value="1" />
            <inertia ixx="100" ixy="0" ixz="0" iyy="100" iyz="0" izz="100" />
        </inertial>
        <visual>
            <origin xyz="0.0 0.0 0.39281018058475886" rpy="0 0 0"/>
            <geometry>
                <box size="0.7035696799794025 0.4145348908009544 0.7856203611695177" />
            </geometry>
            <material name="Blue">
                <color rgba="0 0 1.0 1.0"/>
            </material>
        </visual>
        <collision>
            <origin xyz="0.0 0.0 0.39281018058475886" rpy="0 0 0"/>
            <geometry>
                <box size="0.7035696799794025 0.4145348908009544 0.7856203611695177" />
            </geometry>
        </collision>
    </link>
    <joint name="3_5" type="revolute">
       <parent link="3"/>
       <child  link="5"/>
       <origin rpy="0 0 0" xyz="0.0 -0.5507669292400523 0.0" />
     <axis xyz="1 0 0"/>
       <limit effort="0.0" lower="-3.14159" upper="3.14159" velocity="0.0"/>
    </joint>
    <link name="5">
        <inertial>
            <origin xyz="0.0 -0.5337736430717295 0.0" rpy="0 0 0"/>
            <mass value="1" />
            <inertia ixx="100" ixy="0" ixz="0" iyy="100" iyz="0" izz="100" />
        </inertial>
        <visual>
            <origin xyz="0.0 -0.5337736430717295 0.0" rpy="0 0 0"/>
            <geometry>
                <box size="0.7389112579000459 1.067547286143459 1.041541095326364" />
            </geometry>
            <material name="Green">
                <color rgba="0 1.0 0 1.0"/>
            </material>
        </visual>
        <collision>
            <origin xyz="0.0 -0.5337736430717295 0.0" rpy="0 0 0"/>
            <geometry>
                <box size="0.7389112579000459 1.067547286143459 1.041541095326364" />
            </geometry>
        </collision>
    </link>
</robot>