<robot name = "robot">
    <link name="0">
        <inertial>
            <origin xyz="0 0 3.363235628529791" rpy="0 0 0"/>
            <mass value="1" />
            <inertia ixx="100" ixy="0" ixz="0" iyy="100" iyz="0" izz="100" />
        </inertial>
        <visual>
            <origin xyz="0 0 3.363235628529791" rpy="0 0 0"/>
            <geometry>
                <box size="0.7440538511201689 0.9225684083175782 0.7264712570595819" />
            </geometry>
            <material name="Blue">
                <color rgba="0 0 1.0 1.0"/>
            </material>
        </visual>
        <collision>
            <origin xyz="0 0 3.363235628529791" rpy="0 0 0"/>
            <geometry>
                <box size="0.7440538511201689 0.9225684083175782 0.7264712570595819" />
            </geometry>
        </collision>
    </link>
    <joint name="0_1" type="revolute">
       <parent link="0"/>
       <child  link="1"/>
       <origin rpy="0 0 0" xyz="0.0 0.0 3.0" />
     <axis xyz="0 1 0"/>
       <limit effort="0.0" lower="-3.14159" upper="3.14159" velocity="0.0"/>
    </joint>
    <link name="1">
        <inertial>
            <origin xyz="0.0 0.0 -0.5566437938225666" rpy="0 0 0"/>
            <mass value="1" />
            <inertia ixx="100" ixy="0" ixz="0" iyy="100" iyz="0" izz="100" />
        </inertial>
        <visual>
            <origin xyz="0.0 0.0 -0.5566437938225666" rpy="0 0 0"/>
            <geometry>
                <box size="0.9437086953577472 0.6149646285582588 1.1132875876451331" />
            </geometry>
            <material name="Blue">
                <color rgba="0 0 1.0 1.0"/>
            </material>
        </visual>
        <collision>
            <origin xyz="0.0 0.0 -0.5566437938225666" rpy="0 0 0"/>
            <geometry>
                <box size="0.9437086953577472 0.6149646285582588 1.1132875876451331" />
            </geometry>
        </collision>
    </link>
    <joint name="1_2" type="revolute">
       <parent link="1"/>
       <child  link="2"/>
       <origin rpy="0 0 0" xyz="-0.4718543476788736 0.0 -0.5566437938225666" />
     <axis xyz="0 1 0"/>
       <limit effort="0.0" lower="-3.14159" upper="3.14159" velocity="0.0"/>
    </joint>
    <link name="2">
        <inertial>
            <origin xyz="-0.38396105087479937 0.0 0.0" rpy="0 0 0"/>
            <mass value="1" />
            <inertia ixx="100" ixy="0" ixz="0" iyy="100" iyz="0" izz="100" />
        </inertial>
        <visual>
            <origin xyz="-0.38396105087479937 0.0 0.0" rpy="0 0 0"/>
            <geometry>
                <box size="0.7679221017495987 0.9411685927953996 0.7228933379252217" />
            </geometry>
            <material name="Blue">
                <color rgba="0 0 1.0 1.0"/>
            </material>
        </visual>
        <collision>
            <origin xyz="-0.38396105087479937 0.0 0.0" rpy="0 0 0"/>
            <geometry>
                <box size="0.7679221017495987 0.9411685927953996 0.7228933379252217" />
            </geometry>
        </collision>
    </link>
    <joint name="2_3" type="revolute">
       <parent link="2"/>
       <child  link="3"/>
       <origin rpy="0 0 0" xyz="-0.38396105087479937 0.0 0.36144666896261085" />
     <axis xyz="1 0 0"/>
       <limit effort="0.0" lower="-3.14159" upper="3.14159" velocity="0.0"/>
    </joint>
    <link name="3">
        <inertial>
            <origin xyz="0.0 0.0 0.39913666200935716" rpy="0 0 0"/>
            <mass value="1" />
            <inertia ixx="100" ixy="0" ixz="0" iyy="100" iyz="0" izz="100" />
        </inertial>
        <visual>
            <origin xyz="0.0 0.0 0.39913666200935716" rpy="0 0 0"/>
            <geometry>
                <box size="0.45350146005542075 0.6266334719545271 0.7982733240187143" />
            </geometry>
            <material name="Green">
                <color rgba="0 1.0 0 1.0"/>
            </material>
        </visual>
        <collision>
            <origin xyz="0.0 0.0 0.39913666200935716" rpy="0 0 0"/>
            <geometry>
                <box size="0.45350146005542075 0.6266334719545271 0.7982733240187143" />
            </geometry>
        </collision>
    </link>
    <joint name="2_4" type="revolute">
       <parent link="2"/>
       <child  link="4"/>
       <origin rpy="0 0 0" xyz="-0.7679221017495987 0.0 0.0" />
     <axis xyz="0 1 0"/>
       <limit effort="0.0" lower="-3.14159" upper="3.14159" velocity="0.0"/>
    </joint>
    <link name="4">
        <inertial>
            <origin xyz="-0.39769874645102204 0.0 0.0" rpy="0 0 0"/>
            <mass value="1" />
            <inertia ixx="100" ixy="0" ixz="0" iyy="100" iyz="0" izz="100" />
        </inertial>
        <visual>
            <origin xyz="-0.39769874645102204 0.0 0.0" rpy="0 0 0"/>
            <geometry>
                <box size="0.7953974929020441 0.8787973386130652 0.6393222226623066" />
            </geometry>
            <material name="Blue">
                <color rgba="0 0 1.0 1.0"/>
            </material>
        </visual>
        <collision>
            <origin xyz="-0.39769874645102204 0.0 0.0" rpy="0 0 0"/>
            <geometry>
                <box size="0.7953974929020441 0.8787973386130652 0.6393222226623066" />
            </geometry>
        </collision>
    </link>
    <joint name="1_5" type="revolute">
       <parent link="1"/>
       <child  link="5"/>
       <origin rpy="0 0 0" xyz="0.4718543476788736 0.0 -0.5566437938225666" />
     <axis xyz="1 0 0"/>
       <limit effort="0.0" lower="-3.14159" upper="3.14159" velocity="0.0"/>
    </joint>
    <link name="5">
        <inertial>
            <origin xyz="0.4903869034170786 0.0 0.0" rpy="0 0 0"/>
            <mass value="1" />
            <inertia ixx="100" ixy="0" ixz="0" iyy="100" iyz="0" izz="100" />
        </inertial>
        <visual>
            <origin xyz="0.4903869034170786 0.0 0.0" rpy="0 0 0"/>
            <geometry>
                <box size="0.9807738068341572 0.6401511470009928 0.5352699282221859" />
            </geometry>
            <material name="Green">
                <color rgba="0 1.0 0 1.0"/>
            </material>
        </visual>
        <collision>
            <origin xyz="0.4903869034170786 0.0 0.0" rpy="0 0 0"/>
            <geometry>
                <box size="0.9807738068341572 0.6401511470009928 0.5352699282221859" />
            </geometry>
        </collision>
    </link>
    <joint name="3_6" type="revolute">
       <parent link="3"/>
       <child  link="6"/>
       <origin rpy="0 0 0" xyz="0.0 -0.31331673597726356 0.39913666200935716" />
     <axis xyz="0 1 0"/>
       <limit effort="0.0" lower="-3.14159" upper="3.14159" velocity="0.0"/>
    </joint>
    <link name="6">
        <inertial>
            <origin xyz="0.0 -0.25597285725393926 0.0" rpy="0 0 0"/>
            <mass value="1" />
            <inertia ixx="100" ixy="0" ixz="0" iyy="100" iyz="0" izz="100" />
        </inertial>
        <visual>
            <origin xyz="0.0 -0.25597285725393926 0.0" rpy="0 0 0"/>
            <geometry>
                <box size="0.49731706392800457 0.5119457145078785 0.7809694345981698" />
            </geometry>
            <material name="Blue">
                <color rgba="0 0 1.0 1.0"/>
            </material>
        </visual>
        <collision>
            <origin xyz="0.0 -0.25597285725393926 0.0" rpy="0 0 0"/>
            <geometry>
                <box size="0.49731706392800457 0.5119457145078785 0.7809694345981698" />
            </geometry>
        </collision>
    </link>
    <joint name="1_8" type="revolute">
       <parent link="1"/>
       <child  link="8"/>
       <origin rpy="0 0 0" xyz="0.0 0.0 -1.1132875876451331" />
     <axis xyz="0 1 0"/>
       <limit effort="0.0" lower="-3.14159" upper="3.14159" velocity="0.0"/>
    </joint>
    <link name="8">
        <inertial>
            <origin xyz="0.0 0.0 -0.45859319758358014" rpy="0 0 0"/>
            <mass value="1" />
            <inertia ixx="100" ixy="0" ixz="0" iyy="100" iyz="0" izz="100" />
        </inertial>
        <visual>
            <origin xyz="0.0 0.0 -0.45859319758358014" rpy="0 0 0"/>
            <geometry>
                <box size="0.5374629062465845 0.9443970369878585 0.9171863951671603" />
            </geometry>
            <material name="Green">
                <color rgba="0 1.0 0 1.0"/>
            </material>
        </visual>
        <collision>
            <origin xyz="0.0 0.0 -0.45859319758358014" rpy="0 0 0"/>
            <geometry>
                <box size="0.5374629062465845 0.9443970369878585 0.9171863951671603" />
            </geometry>
        </collision>
    </link>
    <joint name="4_9" type="revolute">
       <parent link="4"/>
       <child  link="9"/>
       <origin rpy="0 0 0" xyz="-0.39769874645102204 0.4393986693065326 0.0" />
     <axis xyz="1 0 0"/>
       <limit effort="0.0" lower="-3.14159" upper="3.14159" velocity="0.0"/>
    </joint>
    <link name="9">
        <inertial>
            <origin xyz="0.0 0.33870767703969346 0.0" rpy="0 0 0"/>
            <mass value="1" />
            <inertia ixx="100" ixy="0" ixz="0" iyy="100" iyz="0" izz="100" />
        </inertial>
        <visual>
            <origin xyz="0.0 0.33870767703969346 0.0" rpy="0 0 0"/>
            <geometry>
                <box size="0.7941778583707038 0.6774153540793869 0.9440601982667525" />
            </geometry>
            <material name="Green">
                <color rgba="0 1.0 0 1.0"/>
            </material>
        </visual>
        <collision>
            <origin xyz="0.0 0.33870767703969346 0.0" rpy="0 0 0"/>
            <geometry>
                <box size="0.7941778583707038 0.6774153540793869 0.9440601982667525" />
            </geometry>
        </collision>
    </link>
    <joint name="4_10" type="revolute">
       <parent link="4"/>
       <child  link="10"/>
       <origin rpy="0 0 0" xyz="-0.7953974929020441 0.0 0.0" />
     <axis xyz="0 1 0"/>
       <limit effort="0.0" lower="-3.14159" upper="3.14159" velocity="0.0"/>
    </joint>
    <link name="10">
        <inertial>
            <origin xyz="-0.37182943125635076 0.0 0.0" rpy="0 0 0"/>
            <mass value="1" />
            <inertia ixx="100" ixy="0" ixz="0" iyy="100" iyz="0" izz="100" />
        </inertial>
        <visual>
            <origin xyz="-0.37182943125635076 0.0 0.0" rpy="0 0 0"/>
            <geometry>
                <box size="0.7436588625127015 1.0175268723883442 0.688933519323074" />
            </geometry>
            <material name="Blue">
                <color rgba="0 0 1.0 1.0"/>
            </material>
        </visual>
        <collision>
            <origin xyz="-0.37182943125635076 0.0 0.0" rpy="0 0 0"/>
            <geometry>
                <box size="0.7436588625127015 1.0175268723883442 0.688933519323074" />
            </geometry>
        </collision>
    </link>
    <joint name="10_11" type="revolute">
       <parent link="10"/>
       <child  link="11"/>
       <origin rpy="0 0 0" xyz="-0.37182943125635076 0.0 -0.344466759661537" />
     <axis xyz="0 1 0"/>
       <limit effort="0.0" lower="-3.14159" upper="3.14159" velocity="0.0"/>
    </joint>
    <link name="11">
        <inertial>
            <origin xyz="0.0 0.0 -0.20009603252398384" rpy="0 0 0"/>
            <mass value="1" />
            <inertia ixx="100" ixy="0" ixz="0" iyy="100" iyz="0" izz="100" />
        </inertial>
        <visual>
            <origin xyz="0.0 0.0 -0.20009603252398384" rpy="0 0 0"/>
            <geometry>
                <box size="0.6150358512359959 1.060380048973484 0.40019206504796767" />
            </geometry>
            <material name="Green">
                <color rgba="0 1.0 0 1.0"/>
            </material>
        </visual>
        <collision>
            <origin xyz="0.0 0.0 -0.20009603252398384" rpy="0 0 0"/>
            <geometry>
                <box size="0.6150358512359959 1.060380048973484 0.40019206504796767" />
            </geometry>
        </collision>
    </link>
    <joint name="5_7" type="revolute">
       <parent link="5"/>
       <child  link="7"/>
       <origin rpy="0 0 0" xyz="0.4903869034170786 -0.3200755735004964 0.0" />
     <axis xyz="0 1 0"/>
       <limit effort="0.0" lower="-3.14159" upper="3.14159" velocity="0.0"/>
    </joint>
    <link name="7">
        <inertial>
            <origin xyz="0.0 -0.5485429832176268 0.0" rpy="0 0 0"/>
            <mass value="1" />
            <inertia ixx="100" ixy="0" ixz="0" iyy="100" iyz="0" izz="100" />
        </inertial>
        <visual>
            <origin xyz="0.0 -0.5485429832176268 0.0" rpy="0 0 0"/>
            <geometry>
                <box size="1.0669251605748942 1.0970859664352537 0.6715726694494312" />
            </geometry>
            <material name="Blue">
                <color rgba="0 0 1.0 1.0"/>
            </material>
        </visual>
        <collision>
            <origin xyz="0.0 -0.5485429832176268 0.0" rpy="0 0 0"/>
            <geometry>
                <box size="1.0669251605748942 1.0970859664352537 0.6715726694494312" />
            </geometry>
        </collision>
    </link>
</robot>