<robot name = "robot">
    <link name="0">
        <inertial>
            <origin xyz="0 0 3.206256782208091" rpy="0 0 0"/>
            <mass value="1" />
            <inertia ixx="100" ixy="0" ixz="0" iyy="100" iyz="0" izz="100" />
        </inertial>
        <visual>
            <origin xyz="0 0 3.206256782208091" rpy="0 0 0"/>
            <geometry>
                <box size="1.0790337747783898 0.6533504257166012 0.412513564416182" />
            </geometry>
            <material name="Green">
                <color rgba="0 1.0 0 1.0"/>
            </material>
        </visual>
        <collision>
            <origin xyz="0 0 3.206256782208091" rpy="0 0 0"/>
            <geometry>
                <box size="1.0790337747783898 0.6533504257166012 0.412513564416182" />
            </geometry>
        </collision>
    </link>
    <joint name="0_1" type="revolute">
       <parent link="0"/>
       <child  link="1"/>
       <origin rpy="0 0 0" xyz="0.5395168873891949 0.0 3.206256782208091" />
     <axis xyz="0 1 0"/>
       <limit effort="0.0" lower="-3.14159" upper="3.14159" velocity="0.0"/>
    </joint>
    <link name="1">
        <inertial>
            <origin xyz="0.5556587404449868 0.0 0.0" rpy="0 0 0"/>
            <mass value="1" />
            <inertia ixx="100" ixy="0" ixz="0" iyy="100" iyz="0" izz="100" />
        </inertial>
        <visual>
            <origin xyz="0.5556587404449868 0.0 0.0" rpy="0 0 0"/>
            <geometry>
                <box size="1.1113174808899735 1.0447659091472143 0.9445115962172459" />
            </geometry>
            <material name="Green">
                <color rgba="0 1.0 0 1.0"/>
            </material>
        </visual>
        <collision>
            <origin xyz="0.5556587404449868 0.0 0.0" rpy="0 0 0"/>
            <geometry>
                <box size="1.1113174808899735 1.0447659091472143 0.9445115962172459" />
            </geometry>
        </collision>
    </link>
    <joint name="1_2" type="revolute">
       <parent link="1"/>
       <child  link="2"/>
       <origin rpy="0 0 0" xyz="0.5556587404449868 -0.5223829545736072 0.0" />
     <axis xyz="0 1 0"/>
       <limit effort="0.0" lower="-3.14159" upper="3.14159" velocity="0.0"/>
    </joint>
    <link name="2">
        <inertial>
            <origin xyz="0.0 -0.4008192889074305 0.0" rpy="0 0 0"/>
            <mass value="1" />
            <inertia ixx="100" ixy="0" ixz="0" iyy="100" iyz="0" izz="100" />
        </inertial>
        <visual>
            <origin xyz="0.0 -0.4008192889074305 0.0" rpy="0 0 0"/>
            <geometry>
                <box size="0.8297470962399978 0.801638577814861 0.6130218069916206" />
            </geometry>
            <material name="Blue">
                <color rgba="0 0 1.0 1.0"/>
            </material>
        </visual>
        <collision>
            <origin xyz="0.0 -0.4008192889074305 0.0" rpy="0 0 0"/>
            <geometry>
                <box size="0.8297470962399978 0.801638577814861 0.6130218069916206" />
            </geometry>
        </collision>
    </link>
    <joint name="1_3" type="revolute">
       <parent link="1"/>
       <child  link="3"/>
       <origin rpy="0 0 0" xyz="0.5556587404449868 0.5223829545736072 0.0" />
     <axis xyz="1 0 0"/>
       <limit effort="0.0" lower="-3.14159" upper="3.14159" velocity="0.0"/>
    </joint>
    <link name="3">
        <inertial>
            <origin xyz="0.0 0.5311663886603887 0.0" rpy="0 0 0"/>
            <mass value="1" />
            <inertia ixx="100" ixy="0" ixz="0" iyy="100" iyz="0" izz="100" />
        </inertial>
        <visual>
            <origin xyz="0.0 0.5311663886603887 0.0" rpy="0 0 0"/>
            <geometry>
                <box size="0.5367377106770934 1.0623327773207774 0.7216143846414214" />
            </geometry>
            <material name="Blue">
                <color rgba="0 0 1.0 1.0"/>
            </material>
        </visual>
        <collision>
            <origin xyz="0.0 0.5311663886603887 0.0" rpy="0 0 0"/>
            <geometry>
                <box size="0.5367377106770934 1.0623327773207774 0.7216143846414214" />
            </geometry>
        </collision>
    </link>
    <joint name="3_5" type="revolute">
       <parent link="3"/>
       <child  link="5"/>
       <origin rpy="0 0 0" xyz="-0.2683688553385467 0.5311663886603887 0.0" />
     <axis xyz="0 1 0"/>
       <limit effort="0.0" lower="-3.14159" upper="3.14159" velocity="0.0"/>
    </joint>
    <link name="5">
        <inertial>
            <origin xyz="-0.46314973623325106 0.0 0.0" rpy="0 0 0"/>
            <mass value="1" />
            <inertia ixx="100" ixy="0" ixz="0" iyy="100" iyz="0" izz="100" />
        </inertial>
        <visual>
            <origin xyz="-0.46314973623325106 0.0 0.0" rpy="0 0 0"/>
            <geometry>
                <box size="0.9262994724665021 0.9541335221574351 1.055861889377643" />
            </geometry>
            <material name="Blue">
                <color rgba="0 0 1.0 1.0"/>
            </material>
        </visual>
        <collision>
            <origin xyz="-0.46314973623325106 0.0 0.0" rpy="0 0 0"/>
            <geometry>
                <box size="0.9262994724665021 0.9541335221574351 1.055861889377643" />
            </geometry>
        </collision>
    </link>
    <joint name="5_6" type="revolute">
       <parent link="5"/>
       <child  link="6"/>
       <origin rpy="0 0 0" xyz="-0.46314973623325106 0.0 -0.5279309446888215" />
     <axis xyz="0 1 0"/>
       <limit effort="0.0" lower="-3.14159" upper="3.14159" velocity="0.0"/>
    </joint>
    <link name="6">
        <inertial>
            <origin xyz="0.0 0.0 -0.2979418295044191" rpy="0 0 0"/>
            <mass value="1" />
            <inertia ixx="100" ixy="0" ixz="0" iyy="100" iyz="0" izz="100" />
        </inertial>
        <visual>
            <origin xyz="0.0 0.0 -0.2979418295044191" rpy="0 0 0"/>
            <geometry>
                <box size="0.38100203298907465 1.0697630311735404 0.5958836590088382" />
            </geometry>
            <material name="Green">
                <color rgba="0 1.0 0 1.0"/>
            </material>
        </visual>
        <collision>
            <origin xyz="0.0 0.0 -0.2979418295044191" rpy="0 0 0"/>
            <geometry>
                <box size="0.38100203298907465 1.0697630311735404 0.5958836590088382" />
            </geometry>
        </collision>
    </link>
    <joint name="3_7" type="revolute">
       <parent link="3"/>
       <child  link="7"/>
       <origin rpy="0 0 0" xyz="0.0 1.0623327773207774 0.0" />
     <axis xyz="1 0 0"/>
       <limit effort="0.0" lower="-3.14159" upper="3.14159" velocity="0.0"/>
    </joint>
    <link name="7">
        <inertial>
            <origin xyz="0.0 0.4159526209251839 0.0" rpy="0 0 0"/>
            <mass value="1" />
            <inertia ixx="100" ixy="0" ixz="0" iyy="100" iyz="0" izz="100" />
        </inertial>
        <visual>
            <origin xyz="0.0 0.4159526209251839 0.0" rpy="0 0 0"/>
            <geometry>
                <box size="0.6512826405179255 0.8319052418503678 0.40113579206516403" />
            </geometry>
            <material name="Blue">
                <color rgba="0 0 1.0 1.0"/>
            </material>
        </visual>
        <collision>
            <origin xyz="0.0 0.4159526209251839 0.0" rpy="0 0 0"/>
            <geometry>
                <box size="0.6512826405179255 0.8319052418503678 0.40113579206516403" />
            </geometry>
        </collision>
    </link>
    <joint name="0_8" type="revolute">
       <parent link="0"/>
       <child  link="8"/>
       <origin rpy="0 0 0" xyz="-0.5395168873891949 0.0 3.206256782208091" />
     <axis xyz="0 1 0"/>
       <limit effort="0.0" lower="-3.14159" upper="3.14159" velocity="0.0"/>
    </joint>
    <link name="8">
        <inertial>
            <origin xyz="-0.32380825623183945 0.0 0.0" rpy="0 0 0"/>
            <mass value="1" />
            <inertia ixx="100" ixy="0" ixz="0" iyy="100" iyz="0" izz="100" />
        </inertial>
        <visual>
            <origin xyz="-0.32380825623183945 0.0 0.0" rpy="0 0 0"/>
            <geometry>
                <box size="0.6476165124636789 0.5817023270706441 1.0685556101537788" />
            </geometry>
            <material name="Blue">
                <color rgba="0 0 1.0 1.0"/>
            </material>
        </visual>
        <collision>
            <origin xyz="-0.32380825623183945 0.0 0.0" rpy="0 0 0"/>
            <geometry>
                <box size="0.6476165124636789 0.5817023270706441 1.0685556101537788" />
            </geometry>
        </collision>
    </link>
    <joint name="2_4" type="revolute">
       <parent link="2"/>
       <child  link="4"/>
       <origin rpy="0 0 0" xyz="0.0 -0.4008192889074305 -0.3065109034958103" />
     <axis xyz="1 0 0"/>
       <limit effort="0.0" lower="-3.14159" upper="3.14159" velocity="0.0"/>
    </joint>
    <link name="4">
        <inertial>
            <origin xyz="0.0 0.0 -0.3924860664523248" rpy="0 0 0"/>
            <mass value="1" />
            <inertia ixx="100" ixy="0" ixz="0" iyy="100" iyz="0" izz="100" />
        </inertial>
        <visual>
            <origin xyz="0.0 0.0 -0.3924860664523248" rpy="0 0 0"/>
            <geometry>
                <box size="0.635650506379343 0.4556493982799912 0.7849721329046496" />
            </geometry>
            <material name="Blue">
                <color rgba="0 0 1.0 1.0"/>
            </material>
        </visual>
        <collision>
            <origin xyz="0.0 0.0 -0.3924860664523248" rpy="0 0 0"/>
            <geometry>
                <box size="0.635650506379343 0.4556493982799912 0.7849721329046496" />
            </geometry>
        </collision>
    </link>
    <joint name="2_9" type="revolute">
       <parent link="2"/>
       <child  link="9"/>
       <origin rpy="0 0 0" xyz="-0.4148735481199989 -0.4008192889074305 0.0" />
     <axis xyz="1 0 0"/>
       <limit effort="0.0" lower="-3.14159" upper="3.14159" velocity="0.0"/>
    </joint>
    <link name="9">
        <inertial>
            <origin xyz="-0.3788027473546441 0.0 0.0" rpy="0 0 0"/>
            <mass value="1" />
            <inertia ixx="100" ixy="0" ixz="0" iyy="100" iyz="0" izz="100" />
        </inertial>
        <visual>
            <origin xyz="-0.3788027473546441 0.0 0.0" rpy="0 0 0"/>
            <geometry>
                <box size="0.7576054947092882 0.5346652166428234 0.6743518565134312" />
            </geometry>
            <material name="Blue">
                <color rgba="0 0 1.0 1.0"/>
            </material>
        </visual>
        <collision>
            <origin xyz="-0.3788027473546441 0.0 0.0" rpy="0 0 0"/>
            <geometry>
                <box size="0.7576054947092882 0.5346652166428234 0.6743518565134312" />
            </geometry>
        </collision>
    </link>
</robot>