<robot name = "robot">
    <link name="0">
        <inertial>
            <origin xyz="0 0 3.445756284929505" rpy="0 0 0"/>
            <mass value="1" />
            <inertia ixx="100" ixy="0" ixz="0" iyy="100" iyz="0" izz="100" />
        </inertial>
        <visual>
            <origin xyz="0 0 3.445756284929505" rpy="0 0 0"/>
            <geometry>
                <box size="0.6534652082118745 0.9499432879546187 0.8915125698590104" />
            </geometry>
            <material name="Green">
                <color rgba="0 1.0 0 1.0"/>
            </material>
        </visual>
        <collision>
            <origin xyz="0 0 3.445756284929505" rpy="0 0 0"/>
            <geometry>
                <box size="0.6534652082118745 0.9499432879546187 0.8915125698590104" />
            </geometry>
        </collision>
    </link>
    <joint name="0_1" type="revolute">
       <parent link="0"/>
       <child  link="1"/>
       <origin rpy="0 0 0" xyz="-0.32673260410593724 0.0 3.445756284929505" />
     <axis xyz="0 1 0"/>
       <limit effort="0.0" lower="-3.14159" upper="3.14159" velocity="0.0"/>
    </joint>
    <link name="1">
        <inertial>
            <origin xyz="-0.393096105728283 0.0 0.0" rpy="0 0 0"/>
            <mass value="1" />
            <inertia ixx="100" ixy="0" ixz="0" iyy="100" iyz="0" izz="100" />
        </inertial>
        <visual>
            <origin xyz="-0.393096105728283 0.0 0.0" rpy="0 0 0"/>
            <geometry>
                <box size="0.786192211456566 0.7825144802375772 0.9297243758849619" />
            </geometry>
            <material name="Green">
                <color rgba="0 1.0 0 1.0"/>
            </material>
        </visual>
        <collision>
            <origin xyz="-0.393096105728283 0.0 0.0" rpy="0 0 0"/>
            <geometry>
                <box size="0.786192211456566 0.7825144802375772 0.9297243758849619" />
            </geometry>
        </collision>
    </link>
    <joint name="1_2" type="revolute">
       <parent link="1"/>
       <child  link="2"/>
       <origin rpy="0 0 0" xyz="-0.393096105728283 0.0 -0.46486218794248096" />
     <axis xyz="1 0 0"/>
       <limit effort="0.0" lower="-3.14159" upper="3.14159" velocity="0.0"/>
    </joint>
    <link name="2">
        <inertial>
            <origin xyz="0.0 0.0 -0.4050892015737976" rpy="0 0 0"/>
            <mass value="1" />
            <inertia ixx="100" ixy="0" ixz="0" iyy="100" iyz="0" izz="100" />
        </inertial>
        <visual>
            <origin xyz="0.0 0.0 -0.4050892015737976" rpy="0 0 0"/>
            <geometry>
                <box size="0.9699612545677861 0.8699779113924468 0.8101784031475951" />
            </geometry>
            <material name="Green">
                <color rgba="0 1.0 0 1.0"/>
            </material>
        </visual>
        <collision>
            <origin xyz="0.0 0.0 -0.4050892015737976" rpy="0 0 0"/>
            <geometry>
                <box size="0.9699612545677861 0.8699779113924468 0.8101784031475951" />
            </geometry>
        </collision>
    </link>
    <joint name="1_3" type="revolute">
       <parent link="1"/>
       <child  link="3"/>
       <origin rpy="0 0 0" xyz="-0.786192211456566 0.0 0.0" />
     <axis xyz="1 0 0"/>
       <limit effort="0.0" lower="-3.14159" upper="3.14159" velocity="0.0"/>
    </joint>
    <link name="3">
        <inertial>
            <origin xyz="-0.5353086732806396 0.0 0.0" rpy="0 0 0"/>
            <mass value="1" />
            <inertia ixx="100" ixy="0" ixz="0" iyy="100" iyz="0" izz="100" />
        </inertial>
        <visual>
            <origin xyz="-0.5353086732806396 0.0 0.0" rpy="0 0 0"/>
            <geometry>
                <box size="1.0706173465612792 0.38522831080178 0.735316069162604" />
            </geometry>
            <material name="Green">
                <color rgba="0 1.0 0 1.0"/>
            </material>
        </visual>
        <collision>
            <origin xyz="-0.5353086732806396 0.0 0.0" rpy="0 0 0"/>
            <geometry>
                <box size="1.0706173465612792 0.38522831080178 0.735316069162604" />
            </geometry>
        </collision>
    </link>
    <joint name="1_4" type="revolute">
       <parent link="1"/>
       <child  link="4"/>
       <origin rpy="0 0 0" xyz="-0.393096105728283 0.0 0.46486218794248096" />
     <axis xyz="0 1 0"/>
       <limit effort="0.0" lower="-3.14159" upper="3.14159" velocity="0.0"/>
    </joint>
    <link name="4">
        <inertial>
            <origin xyz="0.0 0.0 0.3758974852151629" rpy="0 0 0"/>
            <mass value="1" />
            <inertia ixx="100" ixy="0" ixz="0" iyy="100" iyz="0" izz="100" />
        </inertial>
        <visual>
            <origin xyz="0.0 0.0 0.3758974852151629" rpy="0 0 0"/>
            <geometry>
                <box size="1.0299895709264277 0.7083592165142025 0.7517949704303258" />
            </geometry>
            <material name="Green">
                <color rgba="0 1.0 0 1.0"/>
            </material>
        </visual>
        <collision>
            <origin xyz="0.0 0.0 0.3758974852151629" rpy="0 0 0"/>
            <geometry>
                <box size="1.0299895709264277 0.7083592165142025 0.7517949704303258" />
            </geometry>
        </collision>
    </link>
    <joint name="4_5" type="revolute">
       <parent link="4"/>
       <child  link="5"/>
       <origin rpy="0 0 0" xyz="0.0 0.0 0.7517949704303258" />
     <axis xyz="1 0 0"/>
       <limit effort="0.0" lower="-3.14159" upper="3.14159" velocity="0.0"/>
    </joint>
    <link name="5">
        <inertial>
            <origin xyz="0.0 0.0 0.3960499422939277" rpy="0 0 0"/>
            <mass value="1" />
            <inertia ixx="100" ixy="0" ixz="0" iyy="100" iyz="0" izz="100" />
        </inertial>
        <visual>
            <origin xyz="0.0 0.0 0.3960499422939277" rpy="0 0 0"/>
            <geometry>
                <box size="0.6137842024996324 0.5011065885171152 0.7920998845878554" />
            </geometry>
            <material name="Green">
                <color rgba="0 1.0 0 1.0"/>
            </material>
        </visual>
        <collision>
            <origin xyz="0.0 0.0 0.3960499422939277" rpy="0 0 0"/>
            <geometry>
                <box size="0.6137842024996324 0.5011065885171152 0.7920998845878554" />
            </geometry>
        </collision>
    </link>
    <joint name="5_6" type="revolute">
       <parent link="5"/>
       <child  link="6"/>
       <origin rpy="0 0 0" xyz="0.0 -0.2505532942585576 0.3960499422939277" />
     <axis xyz="0 1 0"/>
       <limit effort="0.0" lower="-3.14159" upper="3.14159" velocity="0.0"/>
    </joint>
    <link name="6">
        <inertial>
            <origin xyz="0.0 -0.4827943532301408 0.0" rpy="0 0 0"/>
            <mass value="1" />
            <inertia ixx="100" ixy="0" ixz="0" iyy="100" iyz="0" izz="100" />
        </inertial>
        <visual>
            <origin xyz="0.0 -0.4827943532301408 0.0" rpy="0 0 0"/>
            <geometry>
                <box size="1.1155375014582267 0.9655887064602816 0.7435350526925901" />
            </geometry>
            <material name="Blue">
                <color rgba="0 0 1.0 1.0"/>
            </material>
        </visual>
        <collision>
            <origin xyz="0.0 -0.4827943532301408 0.0" rpy="0 0 0"/>
            <geometry>
                <box size="1.1155375014582267 0.9655887064602816 0.7435350526925901" />
            </geometry>
        </collision>
    </link>
    <joint name="5_7" type="revolute">
       <parent link="5"/>
       <child  link="7"/>
       <origin rpy="0 0 0" xyz="0.0 0.0 0.7920998845878554" />
     <axis xyz="0 1 0"/>
       <limit effort="0.0" lower="-3.14159" upper="3.14159" velocity="0.0"/>
    </joint>
    <link name="7">
        <inertial>
            <origin xyz="0.0 0.0 0.3569367570908938" rpy="0 0 0"/>
            <mass value="1" />
            <inertia ixx="100" ixy="0" ixz="0" iyy="100" iyz="0" izz="100" />
        </inertial>
        <visual>
            <origin xyz="0.0 0.0 0.3569367570908938" rpy="0 0 0"/>
            <geometry>
                <box size="0.4031082541267275 0.954946545480302 0.7138735141817876" />
            </geometry>
            <material name="Green">
                <color rgba="0 1.0 0 1.0"/>
            </material>
        </visual>
        <collision>
            <origin xyz="0.0 0.0 0.3569367570908938" rpy="0 0 0"/>
            <geometry>
                <box size="0.4031082541267275 0.954946545480302 0.7138735141817876" />
            </geometry>
        </collision>
    </link>
</robot>