<robot name = "robot">
    <link name="0">
        <inertial>
            <origin xyz="0 0 3.353954503378012" rpy="0 0 0"/>
            <mass value="1" />
            <inertia ixx="100" ixy="0" ixz="0" iyy="100" iyz="0" izz="100" />
        </inertial>
        <visual>
            <origin xyz="0 0 3.353954503378012" rpy="0 0 0"/>
            <geometry>
                <box size="0.6052395419719595 0.4648285118231671 0.7079090067560239" />
            </geometry>
            <material name="Blue">
                <color rgba="0 0 1.0 1.0"/>
            </material>
        </visual>
        <collision>
            <origin xyz="0 0 3.353954503378012" rpy="0 0 0"/>
            <geometry>
                <box size="0.6052395419719595 0.4648285118231671 0.7079090067560239" />
            </geometry>
        </collision>
    </link>
    <joint name="0_1" type="revolute">
       <parent link="0"/>
       <child  link="1"/>
       <origin rpy="0 0 0" xyz="0.0 0.0 3.707909006756024" />
     <axis xyz="1 0 0"/>
       <limit effort="0.0" lower="-3.14159" upper="3.14159" velocity="0.0"/>
    </joint>
    <link name="1">
        <inertial>
            <origin xyz="0.0 0.0 0.2725550493113381" rpy="0 0 0"/>
            <mass value="1" />
            <inertia ixx="100" ixy="0" ixz="0" iyy="100" iyz="0" izz="100" />
        </inertial>
        <visual>
            <origin xyz="0.0 0.0 0.2725550493113381" rpy="0 0 0"/>
            <geometry>
                <box size="0.5085479873596521 0.781435427714489 0.5451100986226762" />
            </geometry>
            <material name="Green">
                <color rgba="0 1.0 0 1.0"/>
            </material>
        </visual>
        <collision>
            <origin xyz="0.0 0.0 0.2725550493113381" rpy="0 0 0"/>
            <geometry>
                <box size="0.5085479873596521 0.781435427714489 0.5451100986226762" />
            </geometry>
        </collision>
    </link>
    <joint name="0_2" type="revolute">
       <parent link="0"/>
       <child  link="2"/>
       <origin rpy="0 0 0" xyz="0.0 0.0 3.0" />
     <axis xyz="0 1 0"/>
       <limit effort="0.0" lower="-3.14159" upper="3.14159" velocity="0.0"/>
    </joint>
    <link name="2">
        <inertial>
            <origin xyz="0.0 0.0 -0.5365828423736867" rpy="0 0 0"/>
            <mass value="1" />
            <inertia ixx="100" ixy="0" ixz="0" iyy="100" iyz="0" izz="100" />
        </inertial>
        <visual>
            <origin xyz="0.0 0.0 -0.5365828423736867" rpy="0 0 0"/>
            <geometry>
                <box size="0.5748710863871203 0.9151088008644308 1.0731656847473734" />
            </geometry>
            <material name="Blue">
                <color rgba="0 0 1.0 1.0"/>
            </material>
        </visual>
        <collision>
            <origin xyz="0.0 0.0 -0.5365828423736867" rpy="0 0 0"/>
            <geometry>
                <box size="0.5748710863871203 0.9151088008644308 1.0731656847473734" />
            </geometry>
        </collision>
    </link>
    <joint name="2_3" type="revolute">
       <parent link="2"/>
       <child  link="3"/>
       <origin rpy="0 0 0" xyz="-0.28743554319356013 0.0 -0.5365828423736867" />
     <axis xyz="1 0 0"/>
       <limit effort="0.0" lower="-3.14159" upper="3.14159" velocity="0.0"/>
    </joint>
    <link name="3">
        <inertial>
            <origin xyz="-0.20012805799450933 0.0 0.0" rpy="0 0 0"/>
            <mass value="1" />
            <inertia ixx="100" ixy="0" ixz="0" iyy="100" iyz="0" izz="100" />
        </inertial>
        <visual>
            <origin xyz="-0.20012805799450933 0.0 0.0" rpy="0 0 0"/>
            <geometry>
                <box size="0.40025611598901867 0.5256579770397787 0.6787061270979742" />
            </geometry>
            <material name="Green">
                <color rgba="0 1.0 0 1.0"/>
            </material>
        </visual>
        <collision>
            <origin xyz="-0.20012805799450933 0.0 0.0" rpy="0 0 0"/>
            <geometry>
                <box size="0.40025611598901867 0.5256579770397787 0.6787061270979742" />
            </geometry>
        </collision>
    </link>
    <joint name="2_4" type="revolute">
       <parent link="2"/>
       <child  link="4"/>
       <origin rpy="0 0 0" xyz="0.0 0.0 -1.0731656847473734" />
     <axis xyz="0 1 0"/>
       <limit effort="0.0" lower="-3.14159" upper="3.14159" velocity="0.0"/>
    </joint>
    <link name="4">
        <inertial>
            <origin xyz="0.0 0.0 -0.4297813888533354" rpy="0 0 0"/>
            <mass value="1" />
            <inertia ixx="100" ixy="0" ixz="0" iyy="100" iyz="0" izz="100" />
        </inertial>
        <visual>
            <origin xyz="0.0 0.0 -0.4297813888533354" rpy="0 0 0"/>
            <geometry>
                <box size="0.8156628434919806 0.7433154176058252 0.8595627777066708" />
            </geometry>
            <material name="Green">
                <color rgba="0 1.0 0 1.0"/>
            </material>
        </visual>
        <collision>
            <origin xyz="0.0 0.0 -0.4297813888533354" rpy="0 0 0"/>
            <geometry>
                <box size="0.8156628434919806 0.7433154176058252 0.8595627777066708" />
            </geometry>
        </collision>
    </link>
    <joint name="1_7" type="revolute">
       <parent link="1"/>
       <child  link="7"/>
       <origin rpy="0 0 0" xyz="0.0 0.0 0.5451100986226762" />
     <axis xyz="1 0 0"/>
       <limit effort="0.0" lower="-3.14159" upper="3.14159" velocity="0.0"/>
    </joint>
    <link name="7">
        <inertial>
            <origin xyz="0.0 0.0 0.4884327093140538" rpy="0 0 0"/>
            <mass value="1" />
            <inertia ixx="100" ixy="0" ixz="0" iyy="100" iyz="0" izz="100" />
        </inertial>
        <visual>
            <origin xyz="0.0 0.0 0.4884327093140538" rpy="0 0 0"/>
            <geometry>
                <box size="0.6081021762610724 0.5111388325993059 0.9768654186281076" />
            </geometry>
            <material name="Blue">
                <color rgba="0 0 1.0 1.0"/>
            </material>
        </visual>
        <collision>
            <origin xyz="0.0 0.0 0.4884327093140538" rpy="0 0 0"/>
            <geometry>
                <box size="0.6081021762610724 0.5111388325993059 0.9768654186281076" />
            </geometry>
        </collision>
    </link>
    <joint name="0_5" type="revolute">
       <parent link="0"/>
       <child  link="5"/>
       <origin rpy="0 0 0" xyz="0.0 -0.23241425591158354 3.353954503378012" />
     <axis xyz="1 0 0"/>
       <limit effort="0.0" lower="-3.14159" upper="3.14159" velocity="0.0"/>
    </joint>
    <link name="5">
        <inertial>
            <origin xyz="0.0 -0.2207535041323928 0.0" rpy="0 0 0"/>
            <mass value="1" />
            <inertia ixx="100" ixy="0" ixz="0" iyy="100" iyz="0" izz="100" />
        </inertial>
        <visual>
            <origin xyz="0.0 -0.2207535041323928 0.0" rpy="0 0 0"/>
            <geometry>
                <box size="0.6749261354514551 0.4415070082647856 0.6782025487525435" />
            </geometry>
            <material name="Green">
                <color rgba="0 1.0 0 1.0"/>
            </material>
        </visual>
        <collision>
            <origin xyz="0.0 -0.2207535041323928 0.0" rpy="0 0 0"/>
            <geometry>
                <box size="0.6749261354514551 0.4415070082647856 0.6782025487525435" />
            </geometry>
        </collision>
    </link>
</robot>