<robot name = "robot">
    <link name="0">
        <inertial>
            <origin xyz="0 0 3.5092296066085336" rpy="0 0 0"/>
            <mass value="1" />
            <inertia ixx="100" ixy="0" ixz="0" iyy="100" iyz="0" izz="100" />
        </inertial>
        <visual>
            <origin xyz="0 0 3.5092296066085336" rpy="0 0 0"/>
            <geometry>
                <box size="0.8196334636687638 1.008199311435763 1.0184592132170676" />
            </geometry>
            <material name="Green">
                <color rgba="0 1.0 0 1.0"/>
            </material>
        </visual>
        <collision>
            <origin xyz="0 0 3.5092296066085336" rpy="0 0 0"/>
            <geometry>
                <box size="0.8196334636687638 1.008199311435763 1.0184592132170676" />
            </geometry>
        </collision>
    </link>
    <joint name="0_1" type="revolute">
       <parent link="0"/>
       <child  link="1"/>
       <origin rpy="0 0 0" xyz="0.4098167318343819 0.0 3.5092296066085336" />
     <axis xyz="1 0 0"/>
       <limit effort="0.0" lower="-3.14159" upper="3.14159" velocity="0.0"/>
    </joint>
    <link name="1">
        <inertial>
            <origin xyz="0.2990754774541771 0.0 0.0" rpy="0 0 0"/>
            <mass value="1" />
            <inertia ixx="100" ixy="0" ixz="0" iyy="100" iyz="0" izz="100" />
        </inertial>
        <visual>
            <origin xyz="0.2990754774541771 0.0 0.0" rpy="0 0 0"/>
            <geometry>
                <box size="0.5981509549083542 0.4175347329880824 0.5794922209350849" />
            </geometry>
            <material name="Blue">
                <color rgba="0 0 1.0 1.0"/>
            </material>
        </visual>
        <collision>
            <origin xyz="0.2990754774541771 0.0 0.0" rpy="0 0 0"/>
            <geometry>
                <box size="0.5981509549083542 0.4175347329880824 0.5794922209350849" />
            </geometry>
        </collision>
    </link>
    <joint name="1_5" type="revolute">
       <parent link="1"/>
       <child  link="5"/>
       <origin rpy="0 0 0" xyz="0.2990754774541771 0.2087673664940412 0.0" />
     <axis xyz="1 0 0"/>
       <limit effort="0.0" lower="-3.14159" upper="3.14159" velocity="0.0"/>
    </joint>
    <link name="5">
        <inertial>
            <origin xyz="0.0 0.3623665398211149 0.0" rpy="0 0 0"/>
            <mass value="1" />
            <inertia ixx="100" ixy="0" ixz="0" iyy="100" iyz="0" izz="100" />
        </inertial>
        <visual>
            <origin xyz="0.0 0.3623665398211149 0.0" rpy="0 0 0"/>
            <geometry>
                <box size="0.5649687019048366 0.7247330796422298 0.558319194001202" />
            </geometry>
            <material name="Green">
                <color rgba="0 1.0 0 1.0"/>
            </material>
        </visual>
        <collision>
            <origin xyz="0.0 0.3623665398211149 0.0" rpy="0 0 0"/>
            <geometry>
                <box size="0.5649687019048366 0.7247330796422298 0.558319194001202" />
            </geometry>
        </collision>
    </link>
    <joint name="5_9" type="revolute">
       <parent link="5"/>
       <child  link="9"/>
       <origin rpy="0 0 0" xyz="0.0 0.7247330796422298 0.0" />
     <axis xyz="1 0 0"/>
       <limit effort="0.0" lower="-3.14159" upper="3.14159" velocity="0.0"/>
    </joint>
    <link name="9">
        <inertial>
            <origin xyz="0.0 0.24843485050364056 0.0" rpy="0 0 0"/>
            <mass value="1" />
            <inertia ixx="100" ixy="0" ixz="0" iyy="100" iyz="0" izz="100" />
        </inertial>
        <visual>
            <origin xyz="0.0 0.24843485050364056 0.0" rpy="0 0 0"/>
            <geometry>
                <box size="1.0260945430261605 0.4968697010072811 0.8366696732128831" />
            </geometry>
            <material name="Green">
                <color rgba="0 1.0 0 1.0"/>
            </material>
        </visual>
        <collision>
            <origin xyz="0.0 0.24843485050364056 0.0" rpy="0 0 0"/>
            <geometry>
                <box size="1.0260945430261605 0.4968697010072811 0.8366696732128831" />
            </geometry>
        </collision>
    </link>
    <joint name="9_11" type="revolute">
       <parent link="9"/>
       <child  link="11"/>
       <origin rpy="0 0 0" xyz="0.0 0.24843485050364056 -0.41833483660644155" />
     <axis xyz="0 1 0"/>
       <limit effort="0.0" lower="-3.14159" upper="3.14159" velocity="0.0"/>
    </joint>
    <link name="11">
        <inertial>
            <origin xyz="0.0 0.0 -0.29976710818104085" rpy="0 0 0"/>
            <mass value="1" />
            <inertia ixx="100" ixy="0" ixz="0" iyy="100" iyz="0" izz="100" />
        </inertial>
        <visual>
            <origin xyz="0.0 0.0 -0.29976710818104085" rpy="0 0 0"/>
            <geometry>
                <box size="0.9047456668286598 0.5847551273826562 0.5995342163620817" />
            </geometry>
            <material name="Blue">
                <color rgba="0 0 1.0 1.0"/>
            </material>
        </visual>
        <collision>
            <origin xyz="0.0 0.0 -0.29976710818104085" rpy="0 0 0"/>
            <geometry>
                <box size="0.9047456668286598 0.5847551273826562 0.5995342163620817" />
            </geometry>
        </collision>
    </link>
    <joint name="9_2" type="revolute">
       <parent link="9"/>
       <child  link="2"/>
       <origin rpy="0 0 0" xyz="-0.5130472715130803 0.24843485050364056 0.0" />
     <axis xyz="1 0 0"/>
       <limit effort="0.0" lower="-3.14159" upper="3.14159" velocity="0.0"/>
    </joint>
    <link name="2">
        <inertial>
            <origin xyz="-0.3997509824744445 0.0 0.0" rpy="0 0 0"/>
            <mass value="1" />
            <inertia ixx="100" ixy="0" ixz="0" iyy="100" iyz="0" izz="100" />
        </inertial>
        <visual>
            <origin xyz="-0.3997509824744445 0.0 0.0" rpy="0 0 0"/>
            <geometry>
                <box size="0.799501964948889 0.8817669094747278 1.0669797386708826" />
            </geometry>
            <material name="Green">
                <color rgba="0 1.0 0 1.0"/>
            </material>
        </visual>
        <collision>
            <origin xyz="-0.3997509824744445 0.0 0.0" rpy="0 0 0"/>
            <geometry>
                <box size="0.799501964948889 0.8817669094747278 1.0669797386708826" />
            </geometry>
        </collision>
    </link>
    <joint name="5_3" type="revolute">
       <parent link="5"/>
       <child  link="3"/>
       <origin rpy="0 0 0" xyz="0.0 0.3623665398211149 0.279159597000601" />
     <axis xyz="0 1 0"/>
       <limit effort="0.0" lower="-3.14159" upper="3.14159" velocity="0.0"/>
    </joint>
    <link name="3">
        <inertial>
            <origin xyz="0.0 0.0 0.33137324524859385" rpy="0 0 0"/>
            <mass value="1" />
            <inertia ixx="100" ixy="0" ixz="0" iyy="100" iyz="0" izz="100" />
        </inertial>
        <visual>
            <origin xyz="0.0 0.0 0.33137324524859385" rpy="0 0 0"/>
            <geometry>
                <box size="0.4624989124055593 0.40716336148786214 0.6627464904971877" />
            </geometry>
            <material name="Green">
                <color rgba="0 1.0 0 1.0"/>
            </material>
        </visual>
        <collision>
            <origin xyz="0.0 0.0 0.33137324524859385" rpy="0 0 0"/>
            <geometry>
                <box size="0.4624989124055593 0.40716336148786214 0.6627464904971877" />
            </geometry>
        </collision>
    </link>
    <joint name="0_4" type="revolute">
       <parent link="0"/>
       <child  link="4"/>
       <origin rpy="0 0 0" xyz="0.0 0.0 4.018459213217067" />
     <axis xyz="0 1 0"/>
       <limit effort="0.0" lower="-3.14159" upper="3.14159" velocity="0.0"/>
    </joint>
    <link name="4">
        <inertial>
            <origin xyz="0.0 0.0 0.4572937916383969" rpy="0 0 0"/>
            <mass value="1" />
            <inertia ixx="100" ixy="0" ixz="0" iyy="100" iyz="0" izz="100" />
        </inertial>
        <visual>
            <origin xyz="0.0 0.0 0.4572937916383969" rpy="0 0 0"/>
            <geometry>
                <box size="1.072991592793053 0.3974359085066555 0.9145875832767938" />
            </geometry>
            <material name="Green">
                <color rgba="0 1.0 0 1.0"/>
            </material>
        </visual>
        <collision>
            <origin xyz="0.0 0.0 0.4572937916383969" rpy="0 0 0"/>
            <geometry>
                <box size="1.072991592793053 0.3974359085066555 0.9145875832767938" />
            </geometry>
        </collision>
    </link>
    <joint name="9_7" type="revolute">
       <parent link="9"/>
       <child  link="7"/>
       <origin rpy="0 0 0" xyz="0.5130472715130803 0.24843485050364056 0.0" />
     <axis xyz="1 0 0"/>
       <limit effort="0.0" lower="-3.14159" upper="3.14159" velocity="0.0"/>
    </joint>
    <link name="7">
        <inertial>
            <origin xyz="0.34485013629559946 0.0 0.0" rpy="0 0 0"/>
            <mass value="1" />
            <inertia ixx="100" ixy="0" ixz="0" iyy="100" iyz="0" izz="100" />
        </inertial>
        <visual>
            <origin xyz="0.34485013629559946 0.0 0.0" rpy="0 0 0"/>
            <geometry>
                <box size="0.6897002725911989 0.5244211098181344 0.8674538247824111" />
            </geometry>
            <material name="Green">
                <color rgba="0 1.0 0 1.0"/>
            </material>
        </visual>
        <collision>
            <origin xyz="0.34485013629559946 0.0 0.0" rpy="0 0 0"/>
            <geometry>
                <box size="0.6897002725911989 0.5244211098181344 0.8674538247824111" />
            </geometry>
        </collision>
    </link>
    <joint name="0_8" type="revolute">
       <parent link="0"/>
       <child  link="8"/>
       <origin rpy="0 0 0" xyz="0.0 0.0 3.0" />
     <axis xyz="0 1 0"/>
       <limit effort="0.0" lower="-3.14159" upper="3.14159" velocity="0.0"/>
    </joint>
    <link name="8">
        <inertial>
            <origin xyz="0.0 0.0 -0.5436735129722312" rpy="0 0 0"/>
            <mass value="1" />
            <inertia ixx="100" ixy="0" ixz="0" iyy="100" iyz="0" izz="100" />
        </inertial>
        <visual>
            <origin xyz="0.0 0.0 -0.5436735129722312" rpy="0 0 0"/>
            <geometry>
                <box size="0.4144944099684495 0.7514597799239419 1.0873470259444624" />
            </geometry>
            <material name="Blue">
                <color rgba="0 0 1.0 1.0"/>
            </material>
        </visual>
        <collision>
            <origin xyz="0.0 0.0 -0.5436735129722312" rpy="0 0 0"/>
            <geometry>
                <box size="0.4144944099684495 0.7514597799239419 1.0873470259444624" />
            </geometry>
        </collision>
    </link>
    <joint name="8_10" type="revolute">
       <parent link="8"/>
       <child  link="10"/>
       <origin rpy="0 0 0" xyz="0.0 0.0 -1.0873470259444624" />
     <axis xyz="0 1 0"/>
       <limit effort="0.0" lower="-3.14159" upper="3.14159" velocity="0.0"/>
    </joint>
    <link name="10">
        <inertial>
            <origin xyz="0.0 0.0 -0.3791452123542173" rpy="0 0 0"/>
            <mass value="1" />
            <inertia ixx="100" ixy="0" ixz="0" iyy="100" iyz="0" izz="100" />
        </inertial>
        <visual>
            <origin xyz="0.0 0.0 -0.3791452123542173" rpy="0 0 0"/>
            <geometry>
                <box size="0.7973616530351534 0.7451871072222402 0.7582904247084346" />
            </geometry>
            <material name="Green">
                <color rgba="0 1.0 0 1.0"/>
            </material>
        </visual>
        <collision>
            <origin xyz="0.0 0.0 -0.3791452123542173" rpy="0 0 0"/>
            <geometry>
                <box size="0.7973616530351534 0.7451871072222402 0.7582904247084346" />
            </geometry>
        </collision>
    </link>
    <joint name="4_12" type="revolute">
       <parent link="4"/>
       <child  link="12"/>
       <origin rpy="0 0 0" xyz="0.0 0.19871795425332775 0.4572937916383969" />
     <axis xyz="1 0 0"/>
       <limit effort="0.0" lower="-3.14159" upper="3.14159" velocity="0.0"/>
    </joint>
    <link name="12">
        <inertial>
            <origin xyz="0.0 0.3198886464178159 0.0" rpy="0 0 0"/>
            <mass value="1" />
            <inertia ixx="100" ixy="0" ixz="0" iyy="100" iyz="0" izz="100" />
        </inertial>
        <visual>
            <origin xyz="0.0 0.3198886464178159 0.0" rpy="0 0 0"/>
            <geometry>
                <box size="0.9343228005722461 0.6397772928356318 0.7007866884160425" />
            </geometry>
            <material name="Blue">
                <color rgba="0 0 1.0 1.0"/>
            </material>
        </visual>
        <collision>
            <origin xyz="0.0 0.3198886464178159 0.0" rpy="0 0 0"/>
            <geometry>
                <box size="0.9343228005722461 0.6397772928356318 0.7007866884160425" />
            </geometry>
        </collision>
    </link>
    <joint name="8_6" type="revolute">
       <parent link="8"/>
       <child  link="6"/>
       <origin rpy="0 0 0" xyz="-0.20724720498422475 0.0 -0.5436735129722312" />
     <axis xyz="1 0 0"/>
       <limit effort="0.0" lower="-3.14159" upper="3.14159" velocity="0.0"/>
    </joint>
    <link name="6">
        <inertial>
            <origin xyz="-0.3968848478403344 0.0 0.0" rpy="0 0 0"/>
            <mass value="1" />
            <inertia ixx="100" ixy="0" ixz="0" iyy="100" iyz="0" izz="100" />
        </inertial>
        <visual>
            <origin xyz="-0.3968848478403344 0.0 0.0" rpy="0 0 0"/>
            <geometry>
                <box size="0.7937696956806688 0.7627782440774222 0.7645801817699707" />
            </geometry>
            <material name="Green">
                <color rgba="0 1.0 0 1.0"/>
            </material>
        </visual>
        <collision>
            <origin xyz="-0.3968848478403344 0.0 0.0" rpy="0 0 0"/>
            <geometry>
                <box size="0.7937696956806688 0.7627782440774222 0.7645801817699707" />
            </geometry>
        </collision>
    </link>
</robot>