<robot name = "robot">
    <link name="0">
        <inertial>
            <origin xyz="0 0 3.5614194980761957" rpy="0 0 0"/>
            <mass value="1" />
            <inertia ixx="100" ixy="0" ixz="0" iyy="100" iyz="0" izz="100" />
        </inertial>
        <visual>
            <origin xyz="0 0 3.5614194980761957" rpy="0 0 0"/>
            <geometry>
                <box size="0.966437448373417 0.7515580444766163 1.1228389961523915" />
            </geometry>
            <material name="Green">
                <color rgba="0 1.0 0 1.0"/>
            </material>
        </visual>
        <collision>
            <origin xyz="0 0 3.5614194980761957" rpy="0 0 0"/>
            <geometry>
                <box size="0.966437448373417 0.7515580444766163 1.1228389961523915" />
            </geometry>
        </collision>
    </link>
    <joint name="0_1" type="revolute">
       <parent link="0"/>
       <child  link="1"/>
       <origin rpy="0 0 0" xyz="0.4832187241867085 0.0 3.5614194980761957" />
     <axis xyz="0 1 0"/>
       <limit effort="0.0" lower="-3.14159" upper="3.14159" velocity="0.0"/>
    </joint>
    <link name="1">
        <inertial>
            <origin xyz="0.49230657586431437 0.0 0.0" rpy="0 0 0"/>
            <mass value="1" />
            <inertia ixx="100" ixy="0" ixz="0" iyy="100" iyz="0" izz="100" />
        </inertial>
        <visual>
            <origin xyz="0.49230657586431437 0.0 0.0" rpy="0 0 0"/>
            <geometry>
                <box size="0.9846131517286287 0.5521007776891872 0.8676399706541806" />
            </geometry>
            <material name="Green">
                <color rgba="0 1.0 0 1.0"/>
            </material>
        </visual>
        <collision>
            <origin xyz="0.49230657586431437 0.0 0.0" rpy="0 0 0"/>
            <geometry>
                <box size="0.9846131517286287 0.5521007776891872 0.8676399706541806" />
            </geometry>
        </collision>
    </link>
    <joint name="1_2" type="revolute">
       <parent link="1"/>
       <child  link="2"/>
       <origin rpy="0 0 0" xyz="0.49230657586431437 0.2760503888445936 0.0" />
     <axis xyz="0 1 0"/>
       <limit effort="0.0" lower="-3.14159" upper="3.14159" velocity="0.0"/>
    </joint>
    <link name="2">
        <inertial>
            <origin xyz="0.0 0.3608850294517579 0.0" rpy="0 0 0"/>
            <mass value="1" />
            <inertia ixx="100" ixy="0" ixz="0" iyy="100" iyz="0" izz="100" />
        </inertial>
        <visual>
            <origin xyz="0.0 0.3608850294517579 0.0" rpy="0 0 0"/>
            <geometry>
                <box size="0.750454579458237 0.7217700589035158 0.37555791708255465" />
            </geometry>
            <material name="Green">
                <color rgba="0 1.0 0 1.0"/>
            </material>
        </visual>
        <collision>
            <origin xyz="0.0 0.3608850294517579 0.0" rpy="0 0 0"/>
            <geometry>
                <box size="0.750454579458237 0.7217700589035158 0.37555791708255465" />
            </geometry>
        </collision>
    </link>
    <joint name="2_3" type="revolute">
       <parent link="2"/>
       <child  link="3"/>
       <origin rpy="0 0 0" xyz="-0.3752272897291185 0.3608850294517579 0.0" />
     <axis xyz="0 1 0"/>
       <limit effort="0.0" lower="-3.14159" upper="3.14159" velocity="0.0"/>
    </joint>
    <link name="3">
        <inertial>
            <origin xyz="-0.20558691643636118 0.0 0.0" rpy="0 0 0"/>
            <mass value="1" />
            <inertia ixx="100" ixy="0" ixz="0" iyy="100" iyz="0" izz="100" />
        </inertial>
        <visual>
            <origin xyz="-0.20558691643636118 0.0 0.0" rpy="0 0 0"/>
            <geometry>
                <box size="0.41117383287272236 0.5063750844068624 0.7925815744997621" />
            </geometry>
            <material name="Blue">
                <color rgba="0 0 1.0 1.0"/>
            </material>
        </visual>
        <collision>
            <origin xyz="-0.20558691643636118 0.0 0.0" rpy="0 0 0"/>
            <geometry>
                <box size="0.41117383287272236 0.5063750844068624 0.7925815744997621" />
            </geometry>
        </collision>
    </link>
    <joint name="2_4" type="revolute">
       <parent link="2"/>
       <child  link="4"/>
       <origin rpy="0 0 0" xyz="0.0 0.3608850294517579 -0.18777895854127732" />
     <axis xyz="1 0 0"/>
       <limit effort="0.0" lower="-3.14159" upper="3.14159" velocity="0.0"/>
    </joint>
    <link name="4">
        <inertial>
            <origin xyz="0.0 0.0 -0.44759562474856085" rpy="0 0 0"/>
            <mass value="1" />
            <inertia ixx="100" ixy="0" ixz="0" iyy="100" iyz="0" izz="100" />
        </inertial>
        <visual>
            <origin xyz="0.0 0.0 -0.44759562474856085" rpy="0 0 0"/>
            <geometry>
                <box size="0.44007544657348097 0.6946312787091183 0.8951912494971217" />
            </geometry>
            <material name="Blue">
                <color rgba="0 0 1.0 1.0"/>
            </material>
        </visual>
        <collision>
            <origin xyz="0.0 0.0 -0.44759562474856085" rpy="0 0 0"/>
            <geometry>
                <box size="0.44007544657348097 0.6946312787091183 0.8951912494971217" />
            </geometry>
        </collision>
    </link>
    <joint name="1_5" type="revolute">
       <parent link="1"/>
       <child  link="5"/>
       <origin rpy="0 0 0" xyz="0.49230657586431437 0.0 -0.4338199853270903" />
     <axis xyz="0 1 0"/>
       <limit effort="0.0" lower="-3.14159" upper="3.14159" velocity="0.0"/>
    </joint>
    <link name="5">
        <inertial>
            <origin xyz="0.0 0.0 -0.19395258667110185" rpy="0 0 0"/>
            <mass value="1" />
            <inertia ixx="100" ixy="0" ixz="0" iyy="100" iyz="0" izz="100" />
        </inertial>
        <visual>
            <origin xyz="0.0 0.0 -0.19395258667110185" rpy="0 0 0"/>
            <geometry>
                <box size="0.5118746095674656 0.5704882255088851 0.3879051733422037" />
            </geometry>
            <material name="Green">
                <color rgba="0 1.0 0 1.0"/>
            </material>
        </visual>
        <collision>
            <origin xyz="0.0 0.0 -0.19395258667110185" rpy="0 0 0"/>
            <geometry>
                <box size="0.5118746095674656 0.5704882255088851 0.3879051733422037" />
            </geometry>
        </collision>
    </link>
    <joint name="1_6" type="revolute">
       <parent link="1"/>
       <child  link="6"/>
       <origin rpy="0 0 0" xyz="0.49230657586431437 -0.2760503888445936 0.0" />
     <axis xyz="1 0 0"/>
       <limit effort="0.0" lower="-3.14159" upper="3.14159" velocity="0.0"/>
    </joint>
    <link name="6">
        <inertial>
            <origin xyz="0.0 -0.25810965769702143 0.0" rpy="0 0 0"/>
            <mass value="1" />
            <inertia ixx="100" ixy="0" ixz="0" iyy="100" iyz="0" izz="100" />
        </inertial>
        <visual>
            <origin xyz="0.0 -0.25810965769702143 0.0" rpy="0 0 0"/>
            <geometry>
                <box size="0.7516378013596617 0.5162193153940429 0.642908734492694" />
            </geometry>
            <material name="Green">
                <color rgba="0 1.0 0 1.0"/>
            </material>
        </visual>
        <collision>
            <origin xyz="0.0 -0.25810965769702143 0.0" rpy="0 0 0"/>
            <geometry>
                <box size="0.7516378013596617 0.5162193153940429 0.642908734492694" />
            </geometry>
        </collision>
    </link>
    <joint name="5_7" type="revolute">
       <parent link="5"/>
       <child  link="7"/>
       <origin rpy="0 0 0" xyz="0.0 -0.28524411275444256 -0.19395258667110185" />
     <axis xyz="0 1 0"/>
       <limit effort="0.0" lower="-3.14159" upper="3.14159" velocity="0.0"/>
    </joint>
    <link name="7">
        <inertial>
            <origin xyz="0.0 -0.3860148955650671 0.0" rpy="0 0 0"/>
            <mass value="1" />
            <inertia ixx="100" ixy="0" ixz="0" iyy="100" iyz="0" izz="100" />
        </inertial>
        <visual>
            <origin xyz="0.0 -0.3860148955650671 0.0" rpy="0 0 0"/>
            <geometry>
                <box size="0.5313910806721036 0.7720297911301341 0.40577194111231996" />
            </geometry>
            <material name="Blue">
                <color rgba="0 0 1.0 1.0"/>
            </material>
        </visual>
        <collision>
            <origin xyz="0.0 -0.3860148955650671 0.0" rpy="0 0 0"/>
            <geometry>
                <box size="0.5313910806721036 0.7720297911301341 0.40577194111231996" />
            </geometry>
        </collision>
    </link>
</robot>