<robot name = "robot">
    <link name="0">
        <inertial>
            <origin xyz="0 0 3.547613477694342" rpy="0 0 0"/>
            <mass value="1" />
            <inertia ixx="100" ixy="0" ixz="0" iyy="100" iyz="0" izz="100" />
        </inertial>
        <visual>
            <origin xyz="0 0 3.547613477694342" rpy="0 0 0"/>
            <geometry>
                <box size="0.5274554337905112 0.9399803827284359 1.0952269553886842" />
            </geometry>
            <material name="Blue">
                <color rgba="0 0 1.0 1.0"/>
            </material>
        </visual>
        <collision>
            <origin xyz="0 0 3.547613477694342" rpy="0 0 0"/>
            <geometry>
                <box size="0.5274554337905112 0.9399803827284359 1.0952269553886842" />
            </geometry>
        </collision>
    </link>
    <joint name="0_1" type="revolute">
       <parent link="0"/>
       <child  link="1"/>
       <origin rpy="0 0 0" xyz="-0.2637277168952556 0.0 3.547613477694342" />
     <axis xyz="0 1 0"/>
       <limit effort="0.0" lower="-3.14159" upper="3.14159" velocity="0.0"/>
    </joint>
    <link name="1">
        <inertial>
            <origin xyz="-0.3304084627460355 0.0 0.0" rpy="0 0 0"/>
            <mass value="1" />
            <inertia ixx="100" ixy="0" ixz="0" iyy="100" iyz="0" izz="100" />
        </inertial>
        <visual>
            <origin xyz="-0.3304084627460355 0.0 0.0" rpy="0 0 0"/>
            <geometry>
                <box size="0.660816925492071 0.7942519181663595 0.7689482873325374" />
            </geometry>
            <material name="Green">
                <color rgba="0 1.0 0 1.0"/>
            </material>
        </visual>
        <collision>
            <origin xyz="-0.3304084627460355 0.0 0.0" rpy="0 0 0"/>
            <geometry>
                <box size="0.660816925492071 0.7942519181663595 0.7689482873325374" />
            </geometry>
        </collision>
    </link>
    <joint name="1_2" type="revolute">
       <parent link="1"/>
       <child  link="2"/>
       <origin rpy="0 0 0" xyz="-0.660816925492071 0.0 0.0" />
     <axis xyz="0 1 0"/>
       <limit effort="0.0" lower="-3.14159" upper="3.14159" velocity="0.0"/>
    </joint>
    <link name="2">
        <inertial>
            <origin xyz="-0.5600275596313148 0.0 0.0" rpy="0 0 0"/>
            <mass value="1" />
            <inertia ixx="100" ixy="0" ixz="0" iyy="100" iyz="0" izz="100" />
        </inertial>
        <visual>
            <origin xyz="-0.5600275596313148 0.0 0.0" rpy="0 0 0"/>
            <geometry>
                <box size="1.1200551192626296 0.847307004748046 0.5611494127104351" />
            </geometry>
            <material name="Green">
                <color rgba="0 1.0 0 1.0"/>
            </material>
        </visual>
        <collision>
            <origin xyz="-0.5600275596313148 0.0 0.0" rpy="0 0 0"/>
            <geometry>
                <box size="1.1200551192626296 0.847307004748046 0.5611494127104351" />
            </geometry>
        </collision>
    </link>
    <joint name="2_3" type="revolute">
       <parent link="2"/>
       <child  link="3"/>
       <origin rpy="0 0 0" xyz="-0.5600275596313148 0.423653502374023 0.0" />
     <axis xyz="1 0 0"/>
       <limit effort="0.0" lower="-3.14159" upper="3.14159" velocity="0.0"/>
    </joint>
    <link name="3">
        <inertial>
            <origin xyz="0.0 0.4717407060992296 0.0" rpy="0 0 0"/>
            <mass value="1" />
            <inertia ixx="100" ixy="0" ixz="0" iyy="100" iyz="0" izz="100" />
        </inertial>
        <visual>
            <origin xyz="0.0 0.4717407060992296 0.0" rpy="0 0 0"/>
            <geometry>
                <box size="0.668745263187647 0.9434814121984592 0.8530582985618121" />
            </geometry>
            <material name="Blue">
                <color rgba="0 0 1.0 1.0"/>
            </material>
        </visual>
        <collision>
            <origin xyz="0.0 0.4717407060992296 0.0" rpy="0 0 0"/>
            <geometry>
                <box size="0.668745263187647 0.9434814121984592 0.8530582985618121" />
            </geometry>
        </collision>
    </link>
    <joint name="1_6" type="revolute">
       <parent link="1"/>
       <child  link="6"/>
       <origin rpy="0 0 0" xyz="-0.3304084627460355 0.0 -0.3844741436662687" />
     <axis xyz="0 1 0"/>
       <limit effort="0.0" lower="-3.14159" upper="3.14159" velocity="0.0"/>
    </joint>
    <link name="6">
        <inertial>
            <origin xyz="0.0 0.0 -0.5256391498781255" rpy="0 0 0"/>
            <mass value="1" />
            <inertia ixx="100" ixy="0" ixz="0" iyy="100" iyz="0" izz="100" />
        </inertial>
        <visual>
            <origin xyz="0.0 0.0 -0.5256391498781255" rpy="0 0 0"/>
            <geometry>
                <box size="0.5291562312362381 0.40854452053519386 1.051278299756251" />
            </geometry>
            <material name="Green">
                <color rgba="0 1.0 0 1.0"/>
            </material>
        </visual>
        <collision>
            <origin xyz="0.0 0.0 -0.5256391498781255" rpy="0 0 0"/>
            <geometry>
                <box size="0.5291562312362381 0.40854452053519386 1.051278299756251" />
            </geometry>
        </collision>
    </link>
    <joint name="6_7" type="revolute">
       <parent link="6"/>
       <child  link="7"/>
       <origin rpy="0 0 0" xyz="0.0 0.20427226026759693 -0.5256391498781255" />
     <axis xyz="0 1 0"/>
       <limit effort="0.0" lower="-3.14159" upper="3.14159" velocity="0.0"/>
    </joint>
    <link name="7">
        <inertial>
            <origin xyz="0.0 0.22346112457594242 0.0" rpy="0 0 0"/>
            <mass value="1" />
            <inertia ixx="100" ixy="0" ixz="0" iyy="100" iyz="0" izz="100" />
        </inertial>
        <visual>
            <origin xyz="0.0 0.22346112457594242 0.0" rpy="0 0 0"/>
            <geometry>
                <box size="0.6902391030666293 0.44692224915188483 0.6470170657134362" />
            </geometry>
            <material name="Green">
                <color rgba="0 1.0 0 1.0"/>
            </material>
        </visual>
        <collision>
            <origin xyz="0.0 0.22346112457594242 0.0" rpy="0 0 0"/>
            <geometry>
                <box size="0.6902391030666293 0.44692224915188483 0.6470170657134362" />
            </geometry>
        </collision>
    </link>
    <joint name="2_4" type="revolute">
       <parent link="2"/>
       <child  link="4"/>
       <origin rpy="0 0 0" xyz="-0.5600275596313148 -0.423653502374023 0.0" />
     <axis xyz="1 0 0"/>
       <limit effort="0.0" lower="-3.14159" upper="3.14159" velocity="0.0"/>
    </joint>
    <link name="4">
        <inertial>
            <origin xyz="0.0 -0.45528876346033187 0.0" rpy="0 0 0"/>
            <mass value="1" />
            <inertia ixx="100" ixy="0" ixz="0" iyy="100" iyz="0" izz="100" />
        </inertial>
        <visual>
            <origin xyz="0.0 -0.45528876346033187 0.0" rpy="0 0 0"/>
            <geometry>
                <box size="1.0335279839026157 0.9105775269206637 0.9302482544828872" />
            </geometry>
            <material name="Green">
                <color rgba="0 1.0 0 1.0"/>
            </material>
        </visual>
        <collision>
            <origin xyz="0.0 -0.45528876346033187 0.0" rpy="0 0 0"/>
            <geometry>
                <box size="1.0335279839026157 0.9105775269206637 0.9302482544828872" />
            </geometry>
        </collision>
    </link>
    <joint name="7_5" type="revolute">
       <parent link="7"/>
       <child  link="5"/>
       <origin rpy="0 0 0" xyz="0.34511955153331464 0.22346112457594242 0.0" />
     <axis xyz="0 1 0"/>
       <limit effort="0.0" lower="-3.14159" upper="3.14159" velocity="0.0"/>
    </joint>
    <link name="5">
        <inertial>
            <origin xyz="0.23209760210553082 0.0 0.0" rpy="0 0 0"/>
            <mass value="1" />
            <inertia ixx="100" ixy="0" ixz="0" iyy="100" iyz="0" izz="100" />
        </inertial>
        <visual>
            <origin xyz="0.23209760210553082 0.0 0.0" rpy="0 0 0"/>
            <geometry>
                <box size="0.46419520421106164 0.8115629508686555 0.5093609529592295" />
            </geometry>
            <material name="Blue">
                <color rgba="0 0 1.0 1.0"/>
            </material>
        </visual>
        <collision>
            <origin xyz="0.23209760210553082 0.0 0.0" rpy="0 0 0"/>
            <geometry>
                <box size="0.46419520421106164 0.8115629508686555 0.5093609529592295" />
            </geometry>
        </collision>
    </link>
</robot>