<robot name = "robot">
    <link name="0">
        <inertial>
            <origin xyz="0 0 3.2510697753761963" rpy="0 0 0"/>
            <mass value="1" />
            <inertia ixx="100" ixy="0" ixz="0" iyy="100" iyz="0" izz="100" />
        </inertial>
        <visual>
            <origin xyz="0 0 3.2510697753761963" rpy="0 0 0"/>
            <geometry>
                <box size="0.9821764631359822 0.6103328568824526 0.5021395507523922" />
            </geometry>
            <material name="Blue">
                <color rgba="0 0 1.0 1.0"/>
            </material>
        </visual>
        <collision>
            <origin xyz="0 0 3.2510697753761963" rpy="0 0 0"/>
            <geometry>
                <box size="0.9821764631359822 0.6103328568824526 0.5021395507523922" />
            </geometry>
        </collision>
    </link>
    <joint name="0_1" type="revolute">
       <parent link="0"/>
       <child  link="1"/>
       <origin rpy="0 0 0" xyz="0.0 0.0 3.0" />
     <axis xyz="0 1 0"/>
       <limit effort="0.0" lower="-3.14159" upper="3.14159" velocity="0.0"/>
    </joint>
    <link name="1">
        <inertial>
            <origin xyz="0.0 0.0 -0.39909306460836314" rpy="0 0 0"/>
            <mass value="1" />
            <inertia ixx="100" ixy="0" ixz="0" iyy="100" iyz="0" izz="100" />
        </inertial>
        <visual>
            <origin xyz="0.0 0.0 -0.39909306460836314" rpy="0 0 0"/>
            <geometry>
                <box size="0.9241757655332982 0.6020417961940504 0.7981861292167263" />
            </geometry>
            <material name="Blue">
                <color rgba="0 0 1.0 1.0"/>
            </material>
        </visual>
        <collision>
            <origin xyz="0.0 0.0 -0.39909306460836314" rpy="0 0 0"/>
            <geometry>
                <box size="0.9241757655332982 0.6020417961940504 0.7981861292167263" />
            </geometry>
        </collision>
    </link>
    <joint name="1_2" type="revolute">
       <parent link="1"/>
       <child  link="2"/>
       <origin rpy="0 0 0" xyz="0.0 0.0 -0.7981861292167263" />
     <axis xyz="1 0 0"/>
       <limit effort="0.0" lower="-3.14159" upper="3.14159" velocity="0.0"/>
    </joint>
    <link name="2">
        <inertial>
            <origin xyz="0.0 0.0 -0.44439480634799833" rpy="0 0 0"/>
            <mass value="1" />
            <inertia ixx="100" ixy="0" ixz="0" iyy="100" iyz="0" izz="100" />
        </inertial>
        <visual>
            <origin xyz="0.0 0.0 -0.44439480634799833" rpy="0 0 0"/>
            <geometry>
                <box size="0.7461075913427629 0.8958187968838227 0.8887896126959967" />
            </geometry>
            <material name="Blue">
                <color rgba="0 0 1.0 1.0"/>
            </material>
        </visual>
        <collision>
            <origin xyz="0.0 0.0 -0.44439480634799833" rpy="0 0 0"/>
            <geometry>
                <box size="0.7461075913427629 0.8958187968838227 0.8887896126959967" />
            </geometry>
        </collision>
    </link>
    <joint name="2_3" type="revolute">
       <parent link="2"/>
       <child  link="3"/>
       <origin rpy="0 0 0" xyz="0.37305379567138147 0.0 -0.44439480634799833" />
     <axis xyz="1 0 0"/>
       <limit effort="0.0" lower="-3.14159" upper="3.14159" velocity="0.0"/>
    </joint>
    <link name="3">
        <inertial>
            <origin xyz="0.5187630078673087 0.0 0.0" rpy="0 0 0"/>
            <mass value="1" />
            <inertia ixx="100" ixy="0" ixz="0" iyy="100" iyz="0" izz="100" />
        </inertial>
        <visual>
            <origin xyz="0.5187630078673087 0.0 0.0" rpy="0 0 0"/>
            <geometry>
                <box size="1.0375260157346173 1.0164066957162428 0.6459462691871394" />
            </geometry>
            <material name="Green">
                <color rgba="0 1.0 0 1.0"/>
            </material>
        </visual>
        <collision>
            <origin xyz="0.5187630078673087 0.0 0.0" rpy="0 0 0"/>
            <geometry>
                <box size="1.0375260157346173 1.0164066957162428 0.6459462691871394" />
            </geometry>
        </collision>
    </link>
    <joint name="2_6" type="revolute">
       <parent link="2"/>
       <child  link="6"/>
       <origin rpy="0 0 0" xyz="0.0 0.0 -0.8887896126959967" />
     <axis xyz="1 0 0"/>
       <limit effort="0.0" lower="-3.14159" upper="3.14159" velocity="0.0"/>
    </joint>
    <link name="6">
        <inertial>
            <origin xyz="0.0 0.0 -0.40326999385209705" rpy="0 0 0"/>
            <mass value="1" />
            <inertia ixx="100" ixy="0" ixz="0" iyy="100" iyz="0" izz="100" />
        </inertial>
        <visual>
            <origin xyz="0.0 0.0 -0.40326999385209705" rpy="0 0 0"/>
            <geometry>
                <box size="0.7964066069780069 1.0725530419604206 0.8065399877041941" />
            </geometry>
            <material name="Blue">
                <color rgba="0 0 1.0 1.0"/>
            </material>
        </visual>
        <collision>
            <origin xyz="0.0 0.0 -0.40326999385209705" rpy="0 0 0"/>
            <geometry>
                <box size="0.7964066069780069 1.0725530419604206 0.8065399877041941" />
            </geometry>
        </collision>
    </link>
    <joint name="6_7" type="revolute">
       <parent link="6"/>
       <child  link="7"/>
       <origin rpy="0 0 0" xyz="-0.39820330348900346 0.0 -0.40326999385209705" />
     <axis xyz="1 0 0"/>
       <limit effort="0.0" lower="-3.14159" upper="3.14159" velocity="0.0"/>
    </joint>
    <link name="7">
        <inertial>
            <origin xyz="-0.2223850468960647 0.0 0.0" rpy="0 0 0"/>
            <mass value="1" />
            <inertia ixx="100" ixy="0" ixz="0" iyy="100" iyz="0" izz="100" />
        </inertial>
        <visual>
            <origin xyz="-0.2223850468960647 0.0 0.0" rpy="0 0 0"/>
            <geometry>
                <box size="0.4447700937921294 0.5546123519575306 0.6338984915289143" />
            </geometry>
            <material name="Blue">
                <color rgba="0 0 1.0 1.0"/>
            </material>
        </visual>
        <collision>
            <origin xyz="-0.2223850468960647 0.0 0.0" rpy="0 0 0"/>
            <geometry>
                <box size="0.4447700937921294 0.5546123519575306 0.6338984915289143" />
            </geometry>
        </collision>
    </link>
    <joint name="7_8" type="revolute">
       <parent link="7"/>
       <child  link="8"/>
       <origin rpy="0 0 0" xyz="-0.2223850468960647 0.0 -0.31694924576445715" />
     <axis xyz="0 1 0"/>
       <limit effort="0.0" lower="-3.14159" upper="3.14159" velocity="0.0"/>
    </joint>
    <link name="8">
        <inertial>
            <origin xyz="0.0 0.0 -0.4863776346258652" rpy="0 0 0"/>
            <mass value="1" />
            <inertia ixx="100" ixy="0" ixz="0" iyy="100" iyz="0" izz="100" />
        </inertial>
        <visual>
            <origin xyz="0.0 0.0 -0.4863776346258652" rpy="0 0 0"/>
            <geometry>
                <box size="0.4298493010844587 0.8860451573273093 0.9727552692517304" />
            </geometry>
            <material name="Blue">
                <color rgba="0 0 1.0 1.0"/>
            </material>
        </visual>
        <collision>
            <origin xyz="0.0 0.0 -0.4863776346258652" rpy="0 0 0"/>
            <geometry>
                <box size="0.4298493010844587 0.8860451573273093 0.9727552692517304" />
            </geometry>
        </collision>
    </link>
    <joint name="8_9" type="revolute">
       <parent link="8"/>
       <child  link="9"/>
       <origin rpy="0 0 0" xyz="-0.21492465054222934 0.0 -0.4863776346258652" />
     <axis xyz="1 0 0"/>
       <limit effort="0.0" lower="-3.14159" upper="3.14159" velocity="0.0"/>
    </joint>
    <link name="9">
        <inertial>
            <origin xyz="-0.2128793342377155 0.0 0.0" rpy="0 0 0"/>
            <mass value="1" />
            <inertia ixx="100" ixy="0" ixz="0" iyy="100" iyz="0" izz="100" />
        </inertial>
        <visual>
            <origin xyz="-0.2128793342377155 0.0 0.0" rpy="0 0 0"/>
            <geometry>
                <box size="0.425758668475431 0.3899417293106964 0.7131978353655279" />
            </geometry>
            <material name="Blue">
                <color rgba="0 0 1.0 1.0"/>
            </material>
        </visual>
        <collision>
            <origin xyz="-0.2128793342377155 0.0 0.0" rpy="0 0 0"/>
            <geometry>
                <box size="0.425758668475431 0.3899417293106964 0.7131978353655279" />
            </geometry>
        </collision>
    </link>
    <joint name="2_4" type="revolute">
       <parent link="2"/>
       <child  link="4"/>
       <origin rpy="0 0 0" xyz="0.0 0.44790939844191135 -0.44439480634799833" />
     <axis xyz="1 0 0"/>
       <limit effort="0.0" lower="-3.14159" upper="3.14159" velocity="0.0"/>
    </joint>
    <link name="4">
        <inertial>
            <origin xyz="0.0 0.20098969019167 0.0" rpy="0 0 0"/>
            <mass value="1" />
            <inertia ixx="100" ixy="0" ixz="0" iyy="100" iyz="0" izz="100" />
        </inertial>
        <visual>
            <origin xyz="0.0 0.20098969019167 0.0" rpy="0 0 0"/>
            <geometry>
                <box size="0.4342838159226124 0.40197938038334 0.4785763399247095" />
            </geometry>
            <material name="Blue">
                <color rgba="0 0 1.0 1.0"/>
            </material>
        </visual>
        <collision>
            <origin xyz="0.0 0.20098969019167 0.0" rpy="0 0 0"/>
            <geometry>
                <box size="0.4342838159226124 0.40197938038334 0.4785763399247095" />
            </geometry>
        </collision>
    </link>
</robot>