<robot name = "robot">
    <link name="0">
        <inertial>
            <origin xyz="0 0 3.5614194980761957" rpy="0 0 0"/>
            <mass value="1" />
            <inertia ixx="100" ixy="0" ixz="0" iyy="100" iyz="0" izz="100" />
        </inertial>
        <visual>
            <origin xyz="0 0 3.5614194980761957" rpy="0 0 0"/>
            <geometry>
                <box size="0.966437448373417 0.7515580444766163 1.1228389961523915" />
            </geometry>
            <material name="Green">
                <color rgba="0 1.0 0 1.0"/>
            </material>
        </visual>
        <collision>
            <origin xyz="0 0 3.5614194980761957" rpy="0 0 0"/>
            <geometry>
                <box size="0.966437448373417 0.7515580444766163 1.1228389961523915" />
            </geometry>
        </collision>
    </link>
    <joint name="0_1" type="revolute">
       <parent link="0"/>
       <child  link="1"/>
       <origin rpy="0 0 0" xyz="0.4832187241867085 0.0 3.5614194980761957" />
     <axis xyz="0 1 0"/>
       <limit effort="0.0" lower="-3.14159" upper="3.14159" velocity="0.0"/>
    </joint>
    <link name="1">
        <inertial>
            <origin xyz="0.49230657586431437 0.0 0.0" rpy="0 0 0"/>
            <mass value="1" />
            <inertia ixx="100" ixy="0" ixz="0" iyy="100" iyz="0" izz="100" />
        </inertial>
        <visual>
            <origin xyz="0.49230657586431437 0.0 0.0" rpy="0 0 0"/>
            <geometry>
                <box size="0.9846131517286287 0.5521007776891872 0.8676399706541806" />
            </geometry>
            <material name="Green">
                <color rgba="0 1.0 0 1.0"/>
            </material>
        </visual>
        <collision>
            <origin xyz="0.49230657586431437 0.0 0.0" rpy="0 0 0"/>
            <geometry>
                <box size="0.9846131517286287 0.5521007776891872 0.8676399706541806" />
            </geometry>
        </collision>
    </link>
    <joint name="1_5" type="revolute">
       <parent link="1"/>
       <child  link="5"/>
       <origin rpy="0 0 0" xyz="0.49230657586431437 0.0 -0.4338199853270903" />
     <axis xyz="0 1 0"/>
       <limit effort="0.0" lower="-3.14159" upper="3.14159" velocity="0.0"/>
    </joint>
    <link name="5">
        <inertial>
            <origin xyz="0.0 0.0 -0.19395258667110185" rpy="0 0 0"/>
            <mass value="1" />
            <inertia ixx="100" ixy="0" ixz="0" iyy="100" iyz="0" izz="100" />
        </inertial>
        <visual>
            <origin xyz="0.0 0.0 -0.19395258667110185" rpy="0 0 0"/>
            <geometry>
                <box size="0.5118746095674656 0.5704882255088851 0.3879051733422037" />
            </geometry>
            <material name="Green">
                <color rgba="0 1.0 0 1.0"/>
            </material>
        </visual>
        <collision>
            <origin xyz="0.0 0.0 -0.19395258667110185" rpy="0 0 0"/>
            <geometry>
                <box size="0.5118746095674656 0.5704882255088851 0.3879051733422037" />
            </geometry>
        </collision>
    </link>
    <joint name="1_6" type="revolute">
       <parent link="1"/>
       <child  link="6"/>
       <origin rpy="0 0 0" xyz="0.49230657586431437 -0.2760503888445936 0.0" />
     <axis xyz="1 0 0"/>
       <limit effort="0.0" lower="-3.14159" upper="3.14159" velocity="0.0"/>
    </joint>
    <link name="6">
        <inertial>
            <origin xyz="0.0 -0.25810965769702143 0.0" rpy="0 0 0"/>
            <mass value="1" />
            <inertia ixx="100" ixy="0" ixz="0" iyy="100" iyz="0" izz="100" />
        </inertial>
        <visual>
            <origin xyz="0.0 -0.25810965769702143 0.0" rpy="0 0 0"/>
            <geometry>
                <box size="0.7516378013596617 0.5162193153940429 0.642908734492694" />
            </geometry>
            <material name="Green">
                <color rgba="0 1.0 0 1.0"/>
            </material>
        </visual>
        <collision>
            <origin xyz="0.0 -0.25810965769702143 0.0" rpy="0 0 0"/>
            <geometry>
                <box size="0.7516378013596617 0.5162193153940429 0.642908734492694" />
            </geometry>
        </collision>
    </link>
    <joint name="5_7" type="revolute">
       <parent link="5"/>
       <child  link="7"/>
       <origin rpy="0 0 0" xyz="0.0 -0.28524411275444256 -0.19395258667110185" />
     <axis xyz="0 1 0"/>
       <limit effort="0.0" lower="-3.14159" upper="3.14159" velocity="0.0"/>
    </joint>
    <link name="7">
        <inertial>
            <origin xyz="0.0 -0.3860148955650671 0.0" rpy="0 0 0"/>
            <mass value="1" />
            <inertia ixx="100" ixy="0" ixz="0" iyy="100" iyz="0" izz="100" />
        </inertial>
        <visual>
            <origin xyz="0.0 -0.3860148955650671 0.0" rpy="0 0 0"/>
            <geometry>
                <box size="0.5313910806721036 0.7720297911301341 0.40577194111231996" />
            </geometry>
            <material name="Blue">
                <color rgba="0 0 1.0 1.0"/>
            </material>
        </visual>
        <collision>
            <origin xyz="0.0 -0.3860148955650671 0.0" rpy="0 0 0"/>
            <geometry>
                <box size="0.5313910806721036 0.7720297911301341 0.40577194111231996" />
            </geometry>
        </collision>
    </link>
    <joint name="0_2" type="revolute">
       <parent link="0"/>
       <child  link="2"/>
       <origin rpy="0 0 0" xyz="0.0 0.37577902223830817 3.5614194980761957" />
     <axis xyz="1 0 0"/>
       <limit effort="0.0" lower="-3.14159" upper="3.14159" velocity="0.0"/>
    </joint>
    <link name="2">
        <inertial>
            <origin xyz="0.0 0.4519046701220506 0.0" rpy="0 0 0"/>
            <mass value="1" />
            <inertia ixx="100" ixy="0" ixz="0" iyy="100" iyz="0" izz="100" />
        </inertial>
        <visual>
            <origin xyz="0.0 0.4519046701220506 0.0" rpy="0 0 0"/>
            <geometry>
                <box size="0.7981721426541668 0.9038093402441012 0.692159443803035" />
            </geometry>
            <material name="Blue">
                <color rgba="0 0 1.0 1.0"/>
            </material>
        </visual>
        <collision>
            <origin xyz="0.0 0.4519046701220506 0.0" rpy="0 0 0"/>
            <geometry>
                <box size="0.7981721426541668 0.9038093402441012 0.692159443803035" />
            </geometry>
        </collision>
    </link>
    <joint name="1_3" type="revolute">
       <parent link="1"/>
       <child  link="3"/>
       <origin rpy="0 0 0" xyz="0.49230657586431437 0.0 0.4338199853270903" />
     <axis xyz="0 1 0"/>
       <limit effort="0.0" lower="-3.14159" upper="3.14159" velocity="0.0"/>
    </joint>
    <link name="3">
        <inertial>
            <origin xyz="0.0 0.0 0.26725415163449634" rpy="0 0 0"/>
            <mass value="1" />
            <inertia ixx="100" ixy="0" ixz="0" iyy="100" iyz="0" izz="100" />
        </inertial>
        <visual>
            <origin xyz="0.0 0.0 0.26725415163449634" rpy="0 0 0"/>
            <geometry>
                <box size="0.5270876951154551 1.0304829093929095 0.5345083032689927" />
            </geometry>
            <material name="Blue">
                <color rgba="0 0 1.0 1.0"/>
            </material>
        </visual>
        <collision>
            <origin xyz="0.0 0.0 0.26725415163449634" rpy="0 0 0"/>
            <geometry>
                <box size="0.5270876951154551 1.0304829093929095 0.5345083032689927" />
            </geometry>
        </collision>
    </link>
    <joint name="0_4" type="revolute">
       <parent link="0"/>
       <child  link="4"/>
       <origin rpy="0 0 0" xyz="0.0 0.0 3.0" />
     <axis xyz="0 1 0"/>
       <limit effort="0.0" lower="-3.14159" upper="3.14159" velocity="0.0"/>
    </joint>
    <link name="4">
        <inertial>
            <origin xyz="0.0 0.0 -0.3515351980003395" rpy="0 0 0"/>
            <mass value="1" />
            <inertia ixx="100" ixy="0" ixz="0" iyy="100" iyz="0" izz="100" />
        </inertial>
        <visual>
            <origin xyz="0.0 0.0 -0.3515351980003395" rpy="0 0 0"/>
            <geometry>
                <box size="0.840802561540011 0.6836431957542498 0.703070396000679" />
            </geometry>
            <material name="Green">
                <color rgba="0 1.0 0 1.0"/>
            </material>
        </visual>
        <collision>
            <origin xyz="0.0 0.0 -0.3515351980003395" rpy="0 0 0"/>
            <geometry>
                <box size="0.840802561540011 0.6836431957542498 0.703070396000679" />
            </geometry>
        </collision>
    </link>
    <joint name="0_8" type="revolute">
       <parent link="0"/>
       <child  link="8"/>
       <origin rpy="0 0 0" xyz="0.0 -0.37577902223830817 3.5614194980761957" />
     <axis xyz="0 1 0"/>
       <limit effort="0.0" lower="-3.14159" upper="3.14159" velocity="0.0"/>
    </joint>
    <link name="8">
        <inertial>
            <origin xyz="0.0 -0.5111723877247929 0.0" rpy="0 0 0"/>
            <mass value="1" />
            <inertia ixx="100" ixy="0" ixz="0" iyy="100" iyz="0" izz="100" />
        </inertial>
        <visual>
            <origin xyz="0.0 -0.5111723877247929 0.0" rpy="0 0 0"/>
            <geometry>
                <box size="0.9515775149716679 1.0223447754495858 0.6134352460320198" />
            </geometry>
            <material name="Green">
                <color rgba="0 1.0 0 1.0"/>
            </material>
        </visual>
        <collision>
            <origin xyz="0.0 -0.5111723877247929 0.0" rpy="0 0 0"/>
            <geometry>
                <box size="0.9515775149716679 1.0223447754495858 0.6134352460320198" />
            </geometry>
        </collision>
    </link>
</robot>