<robot name = "robot">
    <link name="0">
        <inertial>
            <origin xyz="0 0 3.204516553531426" rpy="0 0 0"/>
            <mass value="1" />
            <inertia ixx="100" ixy="0" ixz="0" iyy="100" iyz="0" izz="100" />
        </inertial>
        <visual>
            <origin xyz="0 0 3.204516553531426" rpy="0 0 0"/>
            <geometry>
                <box size="0.8651932415594621 0.7091878026968175 0.4090331070628518" />
            </geometry>
            <material name="Green">
                <color rgba="0 1.0 0 1.0"/>
            </material>
        </visual>
        <collision>
            <origin xyz="0 0 3.204516553531426" rpy="0 0 0"/>
            <geometry>
                <box size="0.8651932415594621 0.7091878026968175 0.4090331070628518" />
            </geometry>
        </collision>
    </link>
    <joint name="0_1" type="revolute">
       <parent link="0"/>
       <child  link="1"/>
       <origin rpy="0 0 0" xyz="0.0 0.35459390134840874 3.204516553531426" />
     <axis xyz="0 1 0"/>
       <limit effort="0.0" lower="-3.14159" upper="3.14159" velocity="0.0"/>
    </joint>
    <link name="1">
        <inertial>
            <origin xyz="0.0 0.2381853700032932 0.0" rpy="0 0 0"/>
            <mass value="1" />
            <inertia ixx="100" ixy="0" ixz="0" iyy="100" iyz="0" izz="100" />
        </inertial>
        <visual>
            <origin xyz="0.0 0.2381853700032932 0.0" rpy="0 0 0"/>
            <geometry>
                <box size="1.1108952000730332 0.4763707400065864 1.057630469829547" />
            </geometry>
            <material name="Blue">
                <color rgba="0 0 1.0 1.0"/>
            </material>
        </visual>
        <collision>
            <origin xyz="0.0 0.2381853700032932 0.0" rpy="0 0 0"/>
            <geometry>
                <box size="1.1108952000730332 0.4763707400065864 1.057630469829547" />
            </geometry>
        </collision>
    </link>
    <joint name="1_2" type="revolute">
       <parent link="1"/>
       <child  link="2"/>
       <origin rpy="0 0 0" xyz="0.0 0.4763707400065864 0.0" />
     <axis xyz="1 0 0"/>
       <limit effort="0.0" lower="-3.14159" upper="3.14159" velocity="0.0"/>
    </joint>
    <link name="2">
        <inertial>
            <origin xyz="0.0 0.33579826949118746 0.0" rpy="0 0 0"/>
            <mass value="1" />
            <inertia ixx="100" ixy="0" ixz="0" iyy="100" iyz="0" izz="100" />
        </inertial>
        <visual>
            <origin xyz="0.0 0.33579826949118746 0.0" rpy="0 0 0"/>
            <geometry>
                <box size="0.6869152320933232 0.6715965389823749 0.5743465993144037" />
            </geometry>
            <material name="Green">
                <color rgba="0 1.0 0 1.0"/>
            </material>
        </visual>
        <collision>
            <origin xyz="0.0 0.33579826949118746 0.0" rpy="0 0 0"/>
            <geometry>
                <box size="0.6869152320933232 0.6715965389823749 0.5743465993144037" />
            </geometry>
        </collision>
    </link>
    <joint name="1_3" type="revolute">
       <parent link="1"/>
       <child  link="3"/>
       <origin rpy="0 0 0" xyz="0.0 0.2381853700032932 0.5288152349147734" />
     <axis xyz="0 1 0"/>
       <limit effort="0.0" lower="-3.14159" upper="3.14159" velocity="0.0"/>
    </joint>
    <link name="3">
        <inertial>
            <origin xyz="0.0 0.0 0.21015808465387795" rpy="0 0 0"/>
            <mass value="1" />
            <inertia ixx="100" ixy="0" ixz="0" iyy="100" iyz="0" izz="100" />
        </inertial>
        <visual>
            <origin xyz="0.0 0.0 0.21015808465387795" rpy="0 0 0"/>
            <geometry>
                <box size="0.856170571753276 0.9575464921923327 0.4203161693077559" />
            </geometry>
            <material name="Green">
                <color rgba="0 1.0 0 1.0"/>
            </material>
        </visual>
        <collision>
            <origin xyz="0.0 0.0 0.21015808465387795" rpy="0 0 0"/>
            <geometry>
                <box size="0.856170571753276 0.9575464921923327 0.4203161693077559" />
            </geometry>
        </collision>
    </link>
    <joint name="1_4" type="revolute">
       <parent link="1"/>
       <child  link="4"/>
       <origin rpy="0 0 0" xyz="-0.5554476000365166 0.2381853700032932 0.0" />
     <axis xyz="1 0 0"/>
       <limit effort="0.0" lower="-3.14159" upper="3.14159" velocity="0.0"/>
    </joint>
    <link name="4">
        <inertial>
            <origin xyz="-0.3677497001136769 0.0 0.0" rpy="0 0 0"/>
            <mass value="1" />
            <inertia ixx="100" ixy="0" ixz="0" iyy="100" iyz="0" izz="100" />
        </inertial>
        <visual>
            <origin xyz="-0.3677497001136769 0.0 0.0" rpy="0 0 0"/>
            <geometry>
                <box size="0.7354994002273538 1.0971251785612335 0.7558484350242644" />
            </geometry>
            <material name="Green">
                <color rgba="0 1.0 0 1.0"/>
            </material>
        </visual>
        <collision>
            <origin xyz="-0.3677497001136769 0.0 0.0" rpy="0 0 0"/>
            <geometry>
                <box size="0.7354994002273538 1.0971251785612335 0.7558484350242644" />
            </geometry>
        </collision>
    </link>
    <joint name="1_5" type="revolute">
       <parent link="1"/>
       <child  link="5"/>
       <origin rpy="0 0 0" xyz="0.5554476000365166 0.2381853700032932 0.0" />
     <axis xyz="0 1 0"/>
       <limit effort="0.0" lower="-3.14159" upper="3.14159" velocity="0.0"/>
    </joint>
    <link name="5">
        <inertial>
            <origin xyz="0.4988096009265932 0.0 0.0" rpy="0 0 0"/>
            <mass value="1" />
            <inertia ixx="100" ixy="0" ixz="0" iyy="100" iyz="0" izz="100" />
        </inertial>
        <visual>
            <origin xyz="0.4988096009265932 0.0 0.0" rpy="0 0 0"/>
            <geometry>
                <box size="0.9976192018531864 0.8051722409776397 0.971607532853126" />
            </geometry>
            <material name="Blue">
                <color rgba="0 0 1.0 1.0"/>
            </material>
        </visual>
        <collision>
            <origin xyz="0.4988096009265932 0.0 0.0" rpy="0 0 0"/>
            <geometry>
                <box size="0.9976192018531864 0.8051722409776397 0.971607532853126" />
            </geometry>
        </collision>
    </link>
    <joint name="0_6" type="revolute">
       <parent link="0"/>
       <child  link="6"/>
       <origin rpy="0 0 0" xyz="0.0 0.0 3.0" />
     <axis xyz="1 0 0"/>
       <limit effort="0.0" lower="-3.14159" upper="3.14159" velocity="0.0"/>
    </joint>
    <link name="6">
        <inertial>
            <origin xyz="0.0 0.0 -0.2087880834748747" rpy="0 0 0"/>
            <mass value="1" />
            <inertia ixx="100" ixy="0" ixz="0" iyy="100" iyz="0" izz="100" />
        </inertial>
        <visual>
            <origin xyz="0.0 0.0 -0.2087880834748747" rpy="0 0 0"/>
            <geometry>
                <box size="0.6346240925136946 0.6381461451708316 0.4175761669497494" />
            </geometry>
            <material name="Green">
                <color rgba="0 1.0 0 1.0"/>
            </material>
        </visual>
        <collision>
            <origin xyz="0.0 0.0 -0.2087880834748747" rpy="0 0 0"/>
            <geometry>
                <box size="0.6346240925136946 0.6381461451708316 0.4175761669497494" />
            </geometry>
        </collision>
    </link>
    <joint name="4_7" type="revolute">
       <parent link="4"/>
       <child  link="7"/>
       <origin rpy="0 0 0" xyz="-0.3677497001136769 0.0 -0.3779242175121322" />
     <axis xyz="0 1 0"/>
       <limit effort="0.0" lower="-3.14159" upper="3.14159" velocity="0.0"/>
    </joint>
    <link name="7">
        <inertial>
            <origin xyz="0.0 0.0 -0.23260553247417154" rpy="0 0 0"/>
            <mass value="1" />
            <inertia ixx="100" ixy="0" ixz="0" iyy="100" iyz="0" izz="100" />
        </inertial>
        <visual>
            <origin xyz="0.0 0.0 -0.23260553247417154" rpy="0 0 0"/>
            <geometry>
                <box size="0.6039699480249641 0.5479502660051454 0.4652110649483431" />
            </geometry>
            <material name="Green">
                <color rgba="0 1.0 0 1.0"/>
            </material>
        </visual>
        <collision>
            <origin xyz="0.0 0.0 -0.23260553247417154" rpy="0 0 0"/>
            <geometry>
                <box size="0.6039699480249641 0.5479502660051454 0.4652110649483431" />
            </geometry>
        </collision>
    </link>
    <joint name="1_8" type="revolute">
       <parent link="1"/>
       <child  link="8"/>
       <origin rpy="0 0 0" xyz="0.0 0.2381853700032932 -0.5288152349147734" />
     <axis xyz="0 1 0"/>
       <limit effort="0.0" lower="-3.14159" upper="3.14159" velocity="0.0"/>
    </joint>
    <link name="8">
        <inertial>
            <origin xyz="0.0 0.0 -0.34937173933164944" rpy="0 0 0"/>
            <mass value="1" />
            <inertia ixx="100" ixy="0" ixz="0" iyy="100" iyz="0" izz="100" />
        </inertial>
        <visual>
            <origin xyz="0.0 0.0 -0.34937173933164944" rpy="0 0 0"/>
            <geometry>
                <box size="1.0366064737952863 0.4106704184431601 0.6987434786632989" />
            </geometry>
            <material name="Green">
                <color rgba="0 1.0 0 1.0"/>
            </material>
        </visual>
        <collision>
            <origin xyz="0.0 0.0 -0.34937173933164944" rpy="0 0 0"/>
            <geometry>
                <box size="1.0366064737952863 0.4106704184431601 0.6987434786632989" />
            </geometry>
        </collision>
    </link>
</robot>