<robot name = "robot">
    <link name="0">
        <inertial>
            <origin xyz="0 0 3.276852715432205" rpy="0 0 0"/>
            <mass value="1" />
            <inertia ixx="100" ixy="0" ixz="0" iyy="100" iyz="0" izz="100" />
        </inertial>
        <visual>
            <origin xyz="0 0 3.276852715432205" rpy="0 0 0"/>
            <geometry>
                <box size="0.6167863470499653 1.1237096476288264 0.5537054308644094" />
            </geometry>
            <material name="Green">
                <color rgba="0 1.0 0 1.0"/>
            </material>
        </visual>
        <collision>
            <origin xyz="0 0 3.276852715432205" rpy="0 0 0"/>
            <geometry>
                <box size="0.6167863470499653 1.1237096476288264 0.5537054308644094" />
            </geometry>
        </collision>
    </link>
    <joint name="0_1" type="revolute">
       <parent link="0"/>
       <child  link="1"/>
       <origin rpy="0 0 0" xyz="0.0 0.0 3.0" />
     <axis xyz="0 1 0"/>
       <limit effort="0.0" lower="-3.14159" upper="3.14159" velocity="0.0"/>
    </joint>
    <link name="1">
        <inertial>
            <origin xyz="0.0 0.0 -0.4670824718742946" rpy="0 0 0"/>
            <mass value="1" />
            <inertia ixx="100" ixy="0" ixz="0" iyy="100" iyz="0" izz="100" />
        </inertial>
        <visual>
            <origin xyz="0.0 0.0 -0.4670824718742946" rpy="0 0 0"/>
            <geometry>
                <box size="0.46617119943876584 0.3791792379498493 0.9341649437485892" />
            </geometry>
            <material name="Blue">
                <color rgba="0 0 1.0 1.0"/>
            </material>
        </visual>
        <collision>
            <origin xyz="0.0 0.0 -0.4670824718742946" rpy="0 0 0"/>
            <geometry>
                <box size="0.46617119943876584 0.3791792379498493 0.9341649437485892" />
            </geometry>
        </collision>
    </link>
    <joint name="1_2" type="revolute">
       <parent link="1"/>
       <child  link="2"/>
       <origin rpy="0 0 0" xyz="-0.23308559971938292 0.0 -0.4670824718742946" />
     <axis xyz="1 0 0"/>
       <limit effort="0.0" lower="-3.14159" upper="3.14159" velocity="0.0"/>
    </joint>
    <link name="2">
        <inertial>
            <origin xyz="-0.40622417978795955 0.0 0.0" rpy="0 0 0"/>
            <mass value="1" />
            <inertia ixx="100" ixy="0" ixz="0" iyy="100" iyz="0" izz="100" />
        </inertial>
        <visual>
            <origin xyz="-0.40622417978795955 0.0 0.0" rpy="0 0 0"/>
            <geometry>
                <box size="0.8124483595759191 0.7171740275286824 0.7217532015087887" />
            </geometry>
            <material name="Blue">
                <color rgba="0 0 1.0 1.0"/>
            </material>
        </visual>
        <collision>
            <origin xyz="-0.40622417978795955 0.0 0.0" rpy="0 0 0"/>
            <geometry>
                <box size="0.8124483595759191 0.7171740275286824 0.7217532015087887" />
            </geometry>
        </collision>
    </link>
    <joint name="2_3" type="revolute">
       <parent link="2"/>
       <child  link="3"/>
       <origin rpy="0 0 0" xyz="-0.40622417978795955 0.0 0.36087660075439437" />
     <axis xyz="1 0 0"/>
       <limit effort="0.0" lower="-3.14159" upper="3.14159" velocity="0.0"/>
    </joint>
    <link name="3">
        <inertial>
            <origin xyz="0.0 0.0 0.4870172339260765" rpy="0 0 0"/>
            <mass value="1" />
            <inertia ixx="100" ixy="0" ixz="0" iyy="100" iyz="0" izz="100" />
        </inertial>
        <visual>
            <origin xyz="0.0 0.0 0.4870172339260765" rpy="0 0 0"/>
            <geometry>
                <box size="0.5517375225886644 1.0747389530849327 0.974034467852153" />
            </geometry>
            <material name="Green">
                <color rgba="0 1.0 0 1.0"/>
            </material>
        </visual>
        <collision>
            <origin xyz="0.0 0.0 0.4870172339260765" rpy="0 0 0"/>
            <geometry>
                <box size="0.5517375225886644 1.0747389530849327 0.974034467852153" />
            </geometry>
        </collision>
    </link>
    <joint name="3_4" type="revolute">
       <parent link="3"/>
       <child  link="4"/>
       <origin rpy="0 0 0" xyz="0.0 0.0 0.974034467852153" />
     <axis xyz="0 1 0"/>
       <limit effort="0.0" lower="-3.14159" upper="3.14159" velocity="0.0"/>
    </joint>
    <link name="4">
        <inertial>
            <origin xyz="0.0 0.0 0.4700087231133471" rpy="0 0 0"/>
            <mass value="1" />
            <inertia ixx="100" ixy="0" ixz="0" iyy="100" iyz="0" izz="100" />
        </inertial>
        <visual>
            <origin xyz="0.0 0.0 0.4700087231133471" rpy="0 0 0"/>
            <geometry>
                <box size="0.3937827367792702 0.9439235913156169 0.9400174462266943" />
            </geometry>
            <material name="Green">
                <color rgba="0 1.0 0 1.0"/>
            </material>
        </visual>
        <collision>
            <origin xyz="0.0 0.0 0.4700087231133471" rpy="0 0 0"/>
            <geometry>
                <box size="0.3937827367792702 0.9439235913156169 0.9400174462266943" />
            </geometry>
        </collision>
    </link>
    <joint name="1_5" type="revolute">
       <parent link="1"/>
       <child  link="5"/>
       <origin rpy="0 0 0" xyz="0.0 0.18958961897492466 -0.4670824718742946" />
     <axis xyz="1 0 0"/>
       <limit effort="0.0" lower="-3.14159" upper="3.14159" velocity="0.0"/>
    </joint>
    <link name="5">
        <inertial>
            <origin xyz="0.0 0.1882733398267716 0.0" rpy="0 0 0"/>
            <mass value="1" />
            <inertia ixx="100" ixy="0" ixz="0" iyy="100" iyz="0" izz="100" />
        </inertial>
        <visual>
            <origin xyz="0.0 0.1882733398267716 0.0" rpy="0 0 0"/>
            <geometry>
                <box size="0.38228954723728514 0.3765466796535432 0.4647115088377687" />
            </geometry>
            <material name="Blue">
                <color rgba="0 0 1.0 1.0"/>
            </material>
        </visual>
        <collision>
            <origin xyz="0.0 0.1882733398267716 0.0" rpy="0 0 0"/>
            <geometry>
                <box size="0.38228954723728514 0.3765466796535432 0.4647115088377687" />
            </geometry>
        </collision>
    </link>
    <joint name="3_7" type="revolute">
       <parent link="3"/>
       <child  link="7"/>
       <origin rpy="0 0 0" xyz="-0.2758687612943322 0.0 0.4870172339260765" />
     <axis xyz="0 1 0"/>
       <limit effort="0.0" lower="-3.14159" upper="3.14159" velocity="0.0"/>
    </joint>
    <link name="7">
        <inertial>
            <origin xyz="-0.5586861348975825 0.0 0.0" rpy="0 0 0"/>
            <mass value="1" />
            <inertia ixx="100" ixy="0" ixz="0" iyy="100" iyz="0" izz="100" />
        </inertial>
        <visual>
            <origin xyz="-0.5586861348975825 0.0 0.0" rpy="0 0 0"/>
            <geometry>
                <box size="1.117372269795165 0.9647056946605925 0.3985851082988898" />
            </geometry>
            <material name="Blue">
                <color rgba="0 0 1.0 1.0"/>
            </material>
        </visual>
        <collision>
            <origin xyz="-0.5586861348975825 0.0 0.0" rpy="0 0 0"/>
            <geometry>
                <box size="1.117372269795165 0.9647056946605925 0.3985851082988898" />
            </geometry>
        </collision>
    </link>
    <joint name="7_8" type="revolute">
       <parent link="7"/>
       <child  link="8"/>
       <origin rpy="0 0 0" xyz="-0.5586861348975825 -0.48235284733029626 0.0" />
     <axis xyz="0 1 0"/>
       <limit effort="0.0" lower="-3.14159" upper="3.14159" velocity="0.0"/>
    </joint>
    <link name="8">
        <inertial>
            <origin xyz="0.0 -0.31695582463656563 0.0" rpy="0 0 0"/>
            <mass value="1" />
            <inertia ixx="100" ixy="0" ixz="0" iyy="100" iyz="0" izz="100" />
        </inertial>
        <visual>
            <origin xyz="0.0 -0.31695582463656563 0.0" rpy="0 0 0"/>
            <geometry>
                <box size="0.5369371446071937 0.6339116492731313 0.4642109558332448" />
            </geometry>
            <material name="Blue">
                <color rgba="0 0 1.0 1.0"/>
            </material>
        </visual>
        <collision>
            <origin xyz="0.0 -0.31695582463656563 0.0" rpy="0 0 0"/>
            <geometry>
                <box size="0.5369371446071937 0.6339116492731313 0.4642109558332448" />
            </geometry>
        </collision>
    </link>
    <joint name="5_9" type="revolute">
       <parent link="5"/>
       <child  link="9"/>
       <origin rpy="0 0 0" xyz="0.19114477361864257 0.1882733398267716 0.0" />
     <axis xyz="0 1 0"/>
       <limit effort="0.0" lower="-3.14159" upper="3.14159" velocity="0.0"/>
    </joint>
    <link name="9">
        <inertial>
            <origin xyz="0.515880405238413 0.0 0.0" rpy="0 0 0"/>
            <mass value="1" />
            <inertia ixx="100" ixy="0" ixz="0" iyy="100" iyz="0" izz="100" />
        </inertial>
        <visual>
            <origin xyz="0.515880405238413 0.0 0.0" rpy="0 0 0"/>
            <geometry>
                <box size="1.031760810476826 0.3753513526844859 0.6824882470467313" />
            </geometry>
            <material name="Blue">
                <color rgba="0 0 1.0 1.0"/>
            </material>
        </visual>
        <collision>
            <origin xyz="0.515880405238413 0.0 0.0" rpy="0 0 0"/>
            <geometry>
                <box size="1.031760810476826 0.3753513526844859 0.6824882470467313" />
            </geometry>
        </collision>
    </link>
    <joint name="2_10" type="revolute">
       <parent link="2"/>
       <child  link="10"/>
       <origin rpy="0 0 0" xyz="-0.8124483595759191 0.0 0.0" />
     <axis xyz="1 0 0"/>
       <limit effort="0.0" lower="-3.14159" upper="3.14159" velocity="0.0"/>
    </joint>
    <link name="10">
        <inertial>
            <origin xyz="-0.3874568324857416 0.0 0.0" rpy="0 0 0"/>
            <mass value="1" />
            <inertia ixx="100" ixy="0" ixz="0" iyy="100" iyz="0" izz="100" />
        </inertial>
        <visual>
            <origin xyz="-0.3874568324857416 0.0 0.0" rpy="0 0 0"/>
            <geometry>
                <box size="0.7749136649714832 1.0924050429542262 1.0336351146995282" />
            </geometry>
            <material name="Green">
                <color rgba="0 1.0 0 1.0"/>
            </material>
        </visual>
        <collision>
            <origin xyz="-0.3874568324857416 0.0 0.0" rpy="0 0 0"/>
            <geometry>
                <box size="0.7749136649714832 1.0924050429542262 1.0336351146995282" />
            </geometry>
        </collision>
    </link>
    <joint name="8_6" type="revolute">
       <parent link="8"/>
       <child  link="6"/>
       <origin rpy="0 0 0" xyz="0.0 -0.31695582463656563 -0.2321054779166224" />
     <axis xyz="1 0 0"/>
       <limit effort="0.0" lower="-3.14159" upper="3.14159" velocity="0.0"/>
    </joint>
    <link name="6">
        <inertial>
            <origin xyz="0.0 0.0 -0.3382034138374176" rpy="0 0 0"/>
            <mass value="1" />
            <inertia ixx="100" ixy="0" ixz="0" iyy="100" iyz="0" izz="100" />
        </inertial>
        <visual>
            <origin xyz="0.0 0.0 -0.3382034138374176" rpy="0 0 0"/>
            <geometry>
                <box size="1.0024307585117587 0.5021208859619857 0.6764068276748352" />
            </geometry>
            <material name="Green">
                <color rgba="0 1.0 0 1.0"/>
            </material>
        </visual>
        <collision>
            <origin xyz="0.0 0.0 -0.3382034138374176" rpy="0 0 0"/>
            <geometry>
                <box size="1.0024307585117587 0.5021208859619857 0.6764068276748352" />
            </geometry>
        </collision>
    </link>
</robot>