<robot name = "robot">
    <link name="0">
        <inertial>
            <origin xyz="0 0 3.3371933314903233" rpy="0 0 0"/>
            <mass value="1" />
            <inertia ixx="100" ixy="0" ixz="0" iyy="100" iyz="0" izz="100" />
        </inertial>
        <visual>
            <origin xyz="0 0 3.3371933314903233" rpy="0 0 0"/>
            <geometry>
                <box size="0.5038537462701665 0.7347031756708593 0.674386662980647" />
            </geometry>
            <material name="Blue">
                <color rgba="0 0 1.0 1.0"/>
            </material>
        </visual>
        <collision>
            <origin xyz="0 0 3.3371933314903233" rpy="0 0 0"/>
            <geometry>
                <box size="0.5038537462701665 0.7347031756708593 0.674386662980647" />
            </geometry>
        </collision>
    </link>
    <joint name="0_1" type="revolute">
       <parent link="0"/>
       <child  link="1"/>
       <origin rpy="0 0 0" xyz="0.0 0.0 3.6743866629806465" />
     <axis xyz="1 0 0"/>
       <limit effort="0.0" lower="-3.14159" upper="3.14159" velocity="0.0"/>
    </joint>
    <link name="1">
        <inertial>
            <origin xyz="0.0 0.0 0.3965636529694795" rpy="0 0 0"/>
            <mass value="1" />
            <inertia ixx="100" ixy="0" ixz="0" iyy="100" iyz="0" izz="100" />
        </inertial>
        <visual>
            <origin xyz="0.0 0.0 0.3965636529694795" rpy="0 0 0"/>
            <geometry>
                <box size="0.6577623067672749 1.001515380146654 0.793127305938959" />
            </geometry>
            <material name="Blue">
                <color rgba="0 0 1.0 1.0"/>
            </material>
        </visual>
        <collision>
            <origin xyz="0.0 0.0 0.3965636529694795" rpy="0 0 0"/>
            <geometry>
                <box size="0.6577623067672749 1.001515380146654 0.793127305938959" />
            </geometry>
        </collision>
    </link>
    <joint name="0_2" type="revolute">
       <parent link="0"/>
       <child  link="2"/>
       <origin rpy="0 0 0" xyz="0.2519268731350833 0.0 3.3371933314903233" />
     <axis xyz="1 0 0"/>
       <limit effort="0.0" lower="-3.14159" upper="3.14159" velocity="0.0"/>
    </joint>
    <link name="2">
        <inertial>
            <origin xyz="0.4763145383781688 0.0 0.0" rpy="0 0 0"/>
            <mass value="1" />
            <inertia ixx="100" ixy="0" ixz="0" iyy="100" iyz="0" izz="100" />
        </inertial>
        <visual>
            <origin xyz="0.4763145383781688 0.0 0.0" rpy="0 0 0"/>
            <geometry>
                <box size="0.9526290767563376 0.8245976269045836 0.6292376103169206" />
            </geometry>
            <material name="Green">
                <color rgba="0 1.0 0 1.0"/>
            </material>
        </visual>
        <collision>
            <origin xyz="0.4763145383781688 0.0 0.0" rpy="0 0 0"/>
            <geometry>
                <box size="0.9526290767563376 0.8245976269045836 0.6292376103169206" />
            </geometry>
        </collision>
    </link>
    <joint name="0_4" type="revolute">
       <parent link="0"/>
       <child  link="4"/>
       <origin rpy="0 0 0" xyz="-0.2519268731350833 0.0 3.3371933314903233" />
     <axis xyz="1 0 0"/>
       <limit effort="0.0" lower="-3.14159" upper="3.14159" velocity="0.0"/>
    </joint>
    <link name="4">
        <inertial>
            <origin xyz="-0.25938464160999747 0.0 0.0" rpy="0 0 0"/>
            <mass value="1" />
            <inertia ixx="100" ixy="0" ixz="0" iyy="100" iyz="0" izz="100" />
        </inertial>
        <visual>
            <origin xyz="-0.25938464160999747 0.0 0.0" rpy="0 0 0"/>
            <geometry>
                <box size="0.5187692832199949 0.48737917697428956 0.5411948090170633" />
            </geometry>
            <material name="Blue">
                <color rgba="0 0 1.0 1.0"/>
            </material>
        </visual>
        <collision>
            <origin xyz="-0.25938464160999747 0.0 0.0" rpy="0 0 0"/>
            <geometry>
                <box size="0.5187692832199949 0.48737917697428956 0.5411948090170633" />
            </geometry>
        </collision>
    </link>
    <joint name="4_6" type="revolute">
       <parent link="4"/>
       <child  link="6"/>
       <origin rpy="0 0 0" xyz="-0.5187692832199949 0.0 0.0" />
     <axis xyz="1 0 0"/>
       <limit effort="0.0" lower="-3.14159" upper="3.14159" velocity="0.0"/>
    </joint>
    <link name="6">
        <inertial>
            <origin xyz="-0.3728714815057915 0.0 0.0" rpy="0 0 0"/>
            <mass value="1" />
            <inertia ixx="100" ixy="0" ixz="0" iyy="100" iyz="0" izz="100" />
        </inertial>
        <visual>
            <origin xyz="-0.3728714815057915 0.0 0.0" rpy="0 0 0"/>
            <geometry>
                <box size="0.745742963011583 0.6809457180960151 0.43023245156081696" />
            </geometry>
            <material name="Blue">
                <color rgba="0 0 1.0 1.0"/>
            </material>
        </visual>
        <collision>
            <origin xyz="-0.3728714815057915 0.0 0.0" rpy="0 0 0"/>
            <geometry>
                <box size="0.745742963011583 0.6809457180960151 0.43023245156081696" />
            </geometry>
        </collision>
    </link>
    <joint name="4_8" type="revolute">
       <parent link="4"/>
       <child  link="8"/>
       <origin rpy="0 0 0" xyz="-0.25938464160999747 0.24368958848714478 0.0" />
     <axis xyz="1 0 0"/>
       <limit effort="0.0" lower="-3.14159" upper="3.14159" velocity="0.0"/>
    </joint>
    <link name="8">
        <inertial>
            <origin xyz="0.0 0.31143835381084184 0.0" rpy="0 0 0"/>
            <mass value="1" />
            <inertia ixx="100" ixy="0" ixz="0" iyy="100" iyz="0" izz="100" />
        </inertial>
        <visual>
            <origin xyz="0.0 0.31143835381084184 0.0" rpy="0 0 0"/>
            <geometry>
                <box size="0.49804175630388353 0.6228767076216837 0.5319388678130338" />
            </geometry>
            <material name="Green">
                <color rgba="0 1.0 0 1.0"/>
            </material>
        </visual>
        <collision>
            <origin xyz="0.0 0.31143835381084184 0.0" rpy="0 0 0"/>
            <geometry>
                <box size="0.49804175630388353 0.6228767076216837 0.5319388678130338" />
            </geometry>
        </collision>
    </link>
    <joint name="1_3" type="revolute">
       <parent link="1"/>
       <child  link="3"/>
       <origin rpy="0 0 0" xyz="0.32888115338363744 0.0 0.3965636529694795" />
     <axis xyz="0 1 0"/>
       <limit effort="0.0" lower="-3.14159" upper="3.14159" velocity="0.0"/>
    </joint>
    <link name="3">
        <inertial>
            <origin xyz="0.26519389744144223 0.0 0.0" rpy="0 0 0"/>
            <mass value="1" />
            <inertia ixx="100" ixy="0" ixz="0" iyy="100" iyz="0" izz="100" />
        </inertial>
        <visual>
            <origin xyz="0.26519389744144223 0.0 0.0" rpy="0 0 0"/>
            <geometry>
                <box size="0.5303877948828845 0.5704988564188045 0.8229926670459866" />
            </geometry>
            <material name="Blue">
                <color rgba="0 0 1.0 1.0"/>
            </material>
        </visual>
        <collision>
            <origin xyz="0.26519389744144223 0.0 0.0" rpy="0 0 0"/>
            <geometry>
                <box size="0.5303877948828845 0.5704988564188045 0.8229926670459866" />
            </geometry>
        </collision>
    </link>
    <joint name="3_5" type="revolute">
       <parent link="3"/>
       <child  link="5"/>
       <origin rpy="0 0 0" xyz="0.26519389744144223 0.0 0.4114963335229933" />
     <axis xyz="1 0 0"/>
       <limit effort="0.0" lower="-3.14159" upper="3.14159" velocity="0.0"/>
    </joint>
    <link name="5">
        <inertial>
            <origin xyz="0.0 0.0 0.2794436867915374" rpy="0 0 0"/>
            <mass value="1" />
            <inertia ixx="100" ixy="0" ixz="0" iyy="100" iyz="0" izz="100" />
        </inertial>
        <visual>
            <origin xyz="0.0 0.0 0.2794436867915374" rpy="0 0 0"/>
            <geometry>
                <box size="0.5616452935587428 0.4263328706361187 0.5588873735830748" />
            </geometry>
            <material name="Green">
                <color rgba="0 1.0 0 1.0"/>
            </material>
        </visual>
        <collision>
            <origin xyz="0.0 0.0 0.2794436867915374" rpy="0 0 0"/>
            <geometry>
                <box size="0.5616452935587428 0.4263328706361187 0.5588873735830748" />
            </geometry>
        </collision>
    </link>
</robot>