<robot name = "robot">
    <link name="0">
        <inertial>
            <origin xyz="0 0 3.3806771703239766" rpy="0 0 0"/>
            <mass value="1" />
            <inertia ixx="100" ixy="0" ixz="0" iyy="100" iyz="0" izz="100" />
        </inertial>
        <visual>
            <origin xyz="0 0 3.3806771703239766" rpy="0 0 0"/>
            <geometry>
                <box size="1.086067816427028 0.9921634803573629 0.7613543406479528" />
            </geometry>
            <material name="Blue">
                <color rgba="0 0 1.0 1.0"/>
            </material>
        </visual>
        <collision>
            <origin xyz="0 0 3.3806771703239766" rpy="0 0 0"/>
            <geometry>
                <box size="1.086067816427028 0.9921634803573629 0.7613543406479528" />
            </geometry>
        </collision>
    </link>
    <joint name="0_1" type="revolute">
       <parent link="0"/>
       <child  link="1"/>
       <origin rpy="0 0 0" xyz="-0.543033908213514 0.0 3.3806771703239766" />
     <axis xyz="1 0 0"/>
       <limit effort="0.0" lower="-3.14159" upper="3.14159" velocity="0.0"/>
    </joint>
    <link name="1">
        <inertial>
            <origin xyz="-0.5435992315144611 0.0 0.0" rpy="0 0 0"/>
            <mass value="1" />
            <inertia ixx="100" ixy="0" ixz="0" iyy="100" iyz="0" izz="100" />
        </inertial>
        <visual>
            <origin xyz="-0.5435992315144611 0.0 0.0" rpy="0 0 0"/>
            <geometry>
                <box size="1.0871984630289222 0.5736994034563825 1.0097623206514978" />
            </geometry>
            <material name="Green">
                <color rgba="0 1.0 0 1.0"/>
            </material>
        </visual>
        <collision>
            <origin xyz="-0.5435992315144611 0.0 0.0" rpy="0 0 0"/>
            <geometry>
                <box size="1.0871984630289222 0.5736994034563825 1.0097623206514978" />
            </geometry>
        </collision>
    </link>
    <joint name="0_2" type="revolute">
       <parent link="0"/>
       <child  link="2"/>
       <origin rpy="0 0 0" xyz="0.543033908213514 0.0 3.3806771703239766" />
     <axis xyz="0 1 0"/>
       <limit effort="0.0" lower="-3.14159" upper="3.14159" velocity="0.0"/>
    </joint>
    <link name="2">
        <inertial>
            <origin xyz="0.39713457575325056 0.0 0.0" rpy="0 0 0"/>
            <mass value="1" />
            <inertia ixx="100" ixy="0" ixz="0" iyy="100" iyz="0" izz="100" />
        </inertial>
        <visual>
            <origin xyz="0.39713457575325056 0.0 0.0" rpy="0 0 0"/>
            <geometry>
                <box size="0.7942691515065011 0.5115641537738999 0.5259614534753576" />
            </geometry>
            <material name="Blue">
                <color rgba="0 0 1.0 1.0"/>
            </material>
        </visual>
        <collision>
            <origin xyz="0.39713457575325056 0.0 0.0" rpy="0 0 0"/>
            <geometry>
                <box size="0.7942691515065011 0.5115641537738999 0.5259614534753576" />
            </geometry>
        </collision>
    </link>
    <joint name="1_3" type="revolute">
       <parent link="1"/>
       <child  link="3"/>
       <origin rpy="0 0 0" xyz="-1.0871984630289222 0.0 0.0" />
     <axis xyz="1 0 0"/>
       <limit effort="0.0" lower="-3.14159" upper="3.14159" velocity="0.0"/>
    </joint>
    <link name="3">
        <inertial>
            <origin xyz="-0.4291387379697814 0.0 0.0" rpy="0 0 0"/>
            <mass value="1" />
            <inertia ixx="100" ixy="0" ixz="0" iyy="100" iyz="0" izz="100" />
        </inertial>
        <visual>
            <origin xyz="-0.4291387379697814 0.0 0.0" rpy="0 0 0"/>
            <geometry>
                <box size="0.8582774759395628 0.8270042375784442 0.8159738768967464" />
            </geometry>
            <material name="Blue">
                <color rgba="0 0 1.0 1.0"/>
            </material>
        </visual>
        <collision>
            <origin xyz="-0.4291387379697814 0.0 0.0" rpy="0 0 0"/>
            <geometry>
                <box size="0.8582774759395628 0.8270042375784442 0.8159738768967464" />
            </geometry>
        </collision>
    </link>
    <joint name="1_4" type="revolute">
       <parent link="1"/>
       <child  link="4"/>
       <origin rpy="0 0 0" xyz="-0.5435992315144611 0.0 0.5048811603257489" />
     <axis xyz="0 1 0"/>
       <limit effort="0.0" lower="-3.14159" upper="3.14159" velocity="0.0"/>
    </joint>
    <link name="4">
        <inertial>
            <origin xyz="0.0 0.0 0.4175368306289205" rpy="0 0 0"/>
            <mass value="1" />
            <inertia ixx="100" ixy="0" ixz="0" iyy="100" iyz="0" izz="100" />
        </inertial>
        <visual>
            <origin xyz="0.0 0.0 0.4175368306289205" rpy="0 0 0"/>
            <geometry>
                <box size="0.5526157614904191 0.6531409705634295 0.835073661257841" />
            </geometry>
            <material name="Blue">
                <color rgba="0 0 1.0 1.0"/>
            </material>
        </visual>
        <collision>
            <origin xyz="0.0 0.0 0.4175368306289205" rpy="0 0 0"/>
            <geometry>
                <box size="0.5526157614904191 0.6531409705634295 0.835073661257841" />
            </geometry>
        </collision>
    </link>
    <joint name="1_5" type="revolute">
       <parent link="1"/>
       <child  link="5"/>
       <origin rpy="0 0 0" xyz="-0.5435992315144611 0.28684970172819124 0.0" />
     <axis xyz="1 0 0"/>
       <limit effort="0.0" lower="-3.14159" upper="3.14159" velocity="0.0"/>
    </joint>
    <link name="5">
        <inertial>
            <origin xyz="0.0 0.4055531941047284 0.0" rpy="0 0 0"/>
            <mass value="1" />
            <inertia ixx="100" ixy="0" ixz="0" iyy="100" iyz="0" izz="100" />
        </inertial>
        <visual>
            <origin xyz="0.0 0.4055531941047284 0.0" rpy="0 0 0"/>
            <geometry>
                <box size="0.5680190195426984 0.8111063882094568 0.799990838901882" />
            </geometry>
            <material name="Blue">
                <color rgba="0 0 1.0 1.0"/>
            </material>
        </visual>
        <collision>
            <origin xyz="0.0 0.4055531941047284 0.0" rpy="0 0 0"/>
            <geometry>
                <box size="0.5680190195426984 0.8111063882094568 0.799990838901882" />
            </geometry>
        </collision>
    </link>
    <joint name="4_6" type="revolute">
       <parent link="4"/>
       <child  link="6"/>
       <origin rpy="0 0 0" xyz="0.0 0.32657048528171473 0.4175368306289205" />
     <axis xyz="1 0 0"/>
       <limit effort="0.0" lower="-3.14159" upper="3.14159" velocity="0.0"/>
    </joint>
    <link name="6">
        <inertial>
            <origin xyz="0.0 0.25456329485483825 0.0" rpy="0 0 0"/>
            <mass value="1" />
            <inertia ixx="100" ixy="0" ixz="0" iyy="100" iyz="0" izz="100" />
        </inertial>
        <visual>
            <origin xyz="0.0 0.25456329485483825 0.0" rpy="0 0 0"/>
            <geometry>
                <box size="0.6216700795936012 0.5091265897096765 0.9915411299794517" />
            </geometry>
            <material name="Green">
                <color rgba="0 1.0 0 1.0"/>
            </material>
        </visual>
        <collision>
            <origin xyz="0.0 0.25456329485483825 0.0" rpy="0 0 0"/>
            <geometry>
                <box size="0.6216700795936012 0.5091265897096765 0.9915411299794517" />
            </geometry>
        </collision>
    </link>
    <joint name="5_7" type="revolute">
       <parent link="5"/>
       <child  link="7"/>
       <origin rpy="0 0 0" xyz="-0.2840095097713492 0.4055531941047284 0.0" />
     <axis xyz="0 1 0"/>
       <limit effort="0.0" lower="-3.14159" upper="3.14159" velocity="0.0"/>
    </joint>
    <link name="7">
        <inertial>
            <origin xyz="-0.2672987662158975 0.0 0.0" rpy="0 0 0"/>
            <mass value="1" />
            <inertia ixx="100" ixy="0" ixz="0" iyy="100" iyz="0" izz="100" />
        </inertial>
        <visual>
            <origin xyz="-0.2672987662158975 0.0 0.0" rpy="0 0 0"/>
            <geometry>
                <box size="0.534597532431795 0.526672817023072 0.646620137924417" />
            </geometry>
            <material name="Green">
                <color rgba="0 1.0 0 1.0"/>
            </material>
        </visual>
        <collision>
            <origin xyz="-0.2672987662158975 0.0 0.0" rpy="0 0 0"/>
            <geometry>
                <box size="0.534597532431795 0.526672817023072 0.646620137924417" />
            </geometry>
        </collision>
    </link>
</robot>