<robot name = "robot">
    <link name="0">
        <inertial>
            <origin xyz="0 0 3.270314218148048" rpy="0 0 0"/>
            <mass value="1" />
            <inertia ixx="100" ixy="0" ixz="0" iyy="100" iyz="0" izz="100" />
        </inertial>
        <visual>
            <origin xyz="0 0 3.270314218148048" rpy="0 0 0"/>
            <geometry>
                <box size="0.9739392405743107 0.7825089229379271 0.5406284362960965" />
            </geometry>
            <material name="Green">
                <color rgba="0 1.0 0 1.0"/>
            </material>
        </visual>
        <collision>
            <origin xyz="0 0 3.270314218148048" rpy="0 0 0"/>
            <geometry>
                <box size="0.9739392405743107 0.7825089229379271 0.5406284362960965" />
            </geometry>
        </collision>
    </link>
    <joint name="0_1" type="revolute">
       <parent link="0"/>
       <child  link="1"/>
       <origin rpy="0 0 0" xyz="0.0 -0.39125446146896353 3.270314218148048" />
     <axis xyz="1 0 0"/>
       <limit effort="0.0" lower="-3.14159" upper="3.14159" velocity="0.0"/>
    </joint>
    <link name="1">
        <inertial>
            <origin xyz="0.0 -0.5302183039369245 0.0" rpy="0 0 0"/>
            <mass value="1" />
            <inertia ixx="100" ixy="0" ixz="0" iyy="100" iyz="0" izz="100" />
        </inertial>
        <visual>
            <origin xyz="0.0 -0.5302183039369245 0.0" rpy="0 0 0"/>
            <geometry>
                <box size="0.5728338969600149 1.060436607873849 0.6898015959801156" />
            </geometry>
            <material name="Green">
                <color rgba="0 1.0 0 1.0"/>
            </material>
        </visual>
        <collision>
            <origin xyz="0.0 -0.5302183039369245 0.0" rpy="0 0 0"/>
            <geometry>
                <box size="0.5728338969600149 1.060436607873849 0.6898015959801156" />
            </geometry>
        </collision>
    </link>
    <joint name="1_3" type="revolute">
       <parent link="1"/>
       <child  link="3"/>
       <origin rpy="0 0 0" xyz="0.0 -1.060436607873849 0.0" />
     <axis xyz="1 0 0"/>
       <limit effort="0.0" lower="-3.14159" upper="3.14159" velocity="0.0"/>
    </joint>
    <link name="3">
        <inertial>
            <origin xyz="0.0 -0.5385930161549537 0.0" rpy="0 0 0"/>
            <mass value="1" />
            <inertia ixx="100" ixy="0" ixz="0" iyy="100" iyz="0" izz="100" />
        </inertial>
        <visual>
            <origin xyz="0.0 -0.5385930161549537 0.0" rpy="0 0 0"/>
            <geometry>
                <box size="0.5830794120904681 1.0771860323099074 0.7228069553743106" />
            </geometry>
            <material name="Blue">
                <color rgba="0 0 1.0 1.0"/>
            </material>
        </visual>
        <collision>
            <origin xyz="0.0 -0.5385930161549537 0.0" rpy="0 0 0"/>
            <geometry>
                <box size="0.5830794120904681 1.0771860323099074 0.7228069553743106" />
            </geometry>
        </collision>
    </link>
    <joint name="3_4" type="revolute">
       <parent link="3"/>
       <child  link="4"/>
       <origin rpy="0 0 0" xyz="0.0 -0.5385930161549537 0.3614034776871553" />
     <axis xyz="1 0 0"/>
       <limit effort="0.0" lower="-3.14159" upper="3.14159" velocity="0.0"/>
    </joint>
    <link name="4">
        <inertial>
            <origin xyz="0.0 0.0 0.2232330195978014" rpy="0 0 0"/>
            <mass value="1" />
            <inertia ixx="100" ixy="0" ixz="0" iyy="100" iyz="0" izz="100" />
        </inertial>
        <visual>
            <origin xyz="0.0 0.0 0.2232330195978014" rpy="0 0 0"/>
            <geometry>
                <box size="0.5963792289148069 0.5154649085264233 0.4464660391956028" />
            </geometry>
            <material name="Green">
                <color rgba="0 1.0 0 1.0"/>
            </material>
        </visual>
        <collision>
            <origin xyz="0.0 0.0 0.2232330195978014" rpy="0 0 0"/>
            <geometry>
                <box size="0.5963792289148069 0.5154649085264233 0.4464660391956028" />
            </geometry>
        </collision>
    </link>
    <joint name="1_2" type="revolute">
       <parent link="1"/>
       <child  link="2"/>
       <origin rpy="0 0 0" xyz="0.0 -0.5302183039369245 -0.3449007979900578" />
     <axis xyz="1 0 0"/>
       <limit effort="0.0" lower="-3.14159" upper="3.14159" velocity="0.0"/>
    </joint>
    <link name="2">
        <inertial>
            <origin xyz="0.0 0.0 -0.37315844583264624" rpy="0 0 0"/>
            <mass value="1" />
            <inertia ixx="100" ixy="0" ixz="0" iyy="100" iyz="0" izz="100" />
        </inertial>
        <visual>
            <origin xyz="0.0 0.0 -0.37315844583264624" rpy="0 0 0"/>
            <geometry>
                <box size="0.8369534716408078 0.8150879257699005 0.7463168916652925" />
            </geometry>
            <material name="Green">
                <color rgba="0 1.0 0 1.0"/>
            </material>
        </visual>
        <collision>
            <origin xyz="0.0 0.0 -0.37315844583264624" rpy="0 0 0"/>
            <geometry>
                <box size="0.8369534716408078 0.8150879257699005 0.7463168916652925" />
            </geometry>
        </collision>
    </link>
    <joint name="1_5" type="revolute">
       <parent link="1"/>
       <child  link="5"/>
       <origin rpy="0 0 0" xyz="0.0 -0.5302183039369245 0.3449007979900578" />
     <axis xyz="1 0 0"/>
       <limit effort="0.0" lower="-3.14159" upper="3.14159" velocity="0.0"/>
    </joint>
    <link name="5">
        <inertial>
            <origin xyz="0.0 0.0 0.27972412823359205" rpy="0 0 0"/>
            <mass value="1" />
            <inertia ixx="100" ixy="0" ixz="0" iyy="100" iyz="0" izz="100" />
        </inertial>
        <visual>
            <origin xyz="0.0 0.0 0.27972412823359205" rpy="0 0 0"/>
            <geometry>
                <box size="0.4008245121368704 0.6052277451290169 0.5594482564671841" />
            </geometry>
            <material name="Green">
                <color rgba="0 1.0 0 1.0"/>
            </material>
        </visual>
        <collision>
            <origin xyz="0.0 0.0 0.27972412823359205" rpy="0 0 0"/>
            <geometry>
                <box size="0.4008245121368704 0.6052277451290169 0.5594482564671841" />
            </geometry>
        </collision>
    </link>
    <joint name="4_6" type="revolute">
       <parent link="4"/>
       <child  link="6"/>
       <origin rpy="0 0 0" xyz="0.29818961445740344 0.0 0.2232330195978014" />
     <axis xyz="1 0 0"/>
       <limit effort="0.0" lower="-3.14159" upper="3.14159" velocity="0.0"/>
    </joint>
    <link name="6">
        <inertial>
            <origin xyz="0.3249211021353607 0.0 0.0" rpy="0 0 0"/>
            <mass value="1" />
            <inertia ixx="100" ixy="0" ixz="0" iyy="100" iyz="0" izz="100" />
        </inertial>
        <visual>
            <origin xyz="0.3249211021353607 0.0 0.0" rpy="0 0 0"/>
            <geometry>
                <box size="0.6498422042707214 1.009234449731763 0.984589867904524" />
            </geometry>
            <material name="Green">
                <color rgba="0 1.0 0 1.0"/>
            </material>
        </visual>
        <collision>
            <origin xyz="0.3249211021353607 0.0 0.0" rpy="0 0 0"/>
            <geometry>
                <box size="0.6498422042707214 1.009234449731763 0.984589867904524" />
            </geometry>
        </collision>
    </link>
    <joint name="6_7" type="revolute">
       <parent link="6"/>
       <child  link="7"/>
       <origin rpy="0 0 0" xyz="0.3249211021353607 0.5046172248658815 0.0" />
     <axis xyz="1 0 0"/>
       <limit effort="0.0" lower="-3.14159" upper="3.14159" velocity="0.0"/>
    </joint>
    <link name="7">
        <inertial>
            <origin xyz="0.0 0.4036125978202278 0.0" rpy="0 0 0"/>
            <mass value="1" />
            <inertia ixx="100" ixy="0" ixz="0" iyy="100" iyz="0" izz="100" />
        </inertial>
        <visual>
            <origin xyz="0.0 0.4036125978202278 0.0" rpy="0 0 0"/>
            <geometry>
                <box size="0.49812838285334404 0.8072251956404556 0.5243981387714168" />
            </geometry>
            <material name="Blue">
                <color rgba="0 0 1.0 1.0"/>
            </material>
        </visual>
        <collision>
            <origin xyz="0.0 0.4036125978202278 0.0" rpy="0 0 0"/>
            <geometry>
                <box size="0.49812838285334404 0.8072251956404556 0.5243981387714168" />
            </geometry>
        </collision>
    </link>
</robot>