<robot name = "robot">
    <link name="0">
        <inertial>
            <origin xyz="0 0 3.2381179143814327" rpy="0 0 0"/>
            <mass value="1" />
            <inertia ixx="100" ixy="0" ixz="0" iyy="100" iyz="0" izz="100" />
        </inertial>
        <visual>
            <origin xyz="0 0 3.2381179143814327" rpy="0 0 0"/>
            <geometry>
                <box size="0.7452005662723925 0.6574447508474125 0.47623582876286497" />
            </geometry>
            <material name="Blue">
                <color rgba="0 0 1.0 1.0"/>
            </material>
        </visual>
        <collision>
            <origin xyz="0 0 3.2381179143814327" rpy="0 0 0"/>
            <geometry>
                <box size="0.7452005662723925 0.6574447508474125 0.47623582876286497" />
            </geometry>
        </collision>
    </link>
    <joint name="0_1" type="revolute">
       <parent link="0"/>
       <child  link="1"/>
       <origin rpy="0 0 0" xyz="0.0 -0.32872237542370625 3.2381179143814327" />
     <axis xyz="1 0 0"/>
       <limit effort="0.0" lower="-3.14159" upper="3.14159" velocity="0.0"/>
    </joint>
    <link name="1">
        <inertial>
            <origin xyz="0.0 -0.4762666034651703 0.0" rpy="0 0 0"/>
            <mass value="1" />
            <inertia ixx="100" ixy="0" ixz="0" iyy="100" iyz="0" izz="100" />
        </inertial>
        <visual>
            <origin xyz="0.0 -0.4762666034651703 0.0" rpy="0 0 0"/>
            <geometry>
                <box size="0.6723050676560848 0.9525332069303406 0.4150154894633996" />
            </geometry>
            <material name="Green">
                <color rgba="0 1.0 0 1.0"/>
            </material>
        </visual>
        <collision>
            <origin xyz="0.0 -0.4762666034651703 0.0" rpy="0 0 0"/>
            <geometry>
                <box size="0.6723050676560848 0.9525332069303406 0.4150154894633996" />
            </geometry>
        </collision>
    </link>
    <joint name="1_2" type="revolute">
       <parent link="1"/>
       <child  link="2"/>
       <origin rpy="0 0 0" xyz="-0.3361525338280424 -0.4762666034651703 0.0" />
     <axis xyz="0 1 0"/>
       <limit effort="0.0" lower="-3.14159" upper="3.14159" velocity="0.0"/>
    </joint>
    <link name="2">
        <inertial>
            <origin xyz="-0.3448076373106298 0.0 0.0" rpy="0 0 0"/>
            <mass value="1" />
            <inertia ixx="100" ixy="0" ixz="0" iyy="100" iyz="0" izz="100" />
        </inertial>
        <visual>
            <origin xyz="-0.3448076373106298 0.0 0.0" rpy="0 0 0"/>
            <geometry>
                <box size="0.6896152746212596 0.893798742311108 1.079432187260783" />
            </geometry>
            <material name="Blue">
                <color rgba="0 0 1.0 1.0"/>
            </material>
        </visual>
        <collision>
            <origin xyz="-0.3448076373106298 0.0 0.0" rpy="0 0 0"/>
            <geometry>
                <box size="0.6896152746212596 0.893798742311108 1.079432187260783" />
            </geometry>
        </collision>
    </link>
    <joint name="2_3" type="revolute">
       <parent link="2"/>
       <child  link="3"/>
       <origin rpy="0 0 0" xyz="-0.6896152746212596 0.0 0.0" />
     <axis xyz="0 1 0"/>
       <limit effort="0.0" lower="-3.14159" upper="3.14159" velocity="0.0"/>
    </joint>
    <link name="3">
        <inertial>
            <origin xyz="-0.5209971604913458 0.0 0.0" rpy="0 0 0"/>
            <mass value="1" />
            <inertia ixx="100" ixy="0" ixz="0" iyy="100" iyz="0" izz="100" />
        </inertial>
        <visual>
            <origin xyz="-0.5209971604913458 0.0 0.0" rpy="0 0 0"/>
            <geometry>
                <box size="1.0419943209826916 0.5845221891038924 0.3918213348482214" />
            </geometry>
            <material name="Green">
                <color rgba="0 1.0 0 1.0"/>
            </material>
        </visual>
        <collision>
            <origin xyz="-0.5209971604913458 0.0 0.0" rpy="0 0 0"/>
            <geometry>
                <box size="1.0419943209826916 0.5845221891038924 0.3918213348482214" />
            </geometry>
        </collision>
    </link>
    <joint name="3_4" type="revolute">
       <parent link="3"/>
       <child  link="4"/>
       <origin rpy="0 0 0" xyz="-1.0419943209826916 0.0 0.0" />
     <axis xyz="1 0 0"/>
       <limit effort="0.0" lower="-3.14159" upper="3.14159" velocity="0.0"/>
    </joint>
    <link name="4">
        <inertial>
            <origin xyz="-0.1990729270632966 0.0 0.0" rpy="0 0 0"/>
            <mass value="1" />
            <inertia ixx="100" ixy="0" ixz="0" iyy="100" iyz="0" izz="100" />
        </inertial>
        <visual>
            <origin xyz="-0.1990729270632966 0.0 0.0" rpy="0 0 0"/>
            <geometry>
                <box size="0.3981458541265932 0.8733677520753103 0.9698483928004266" />
            </geometry>
            <material name="Blue">
                <color rgba="0 0 1.0 1.0"/>
            </material>
        </visual>
        <collision>
            <origin xyz="-0.1990729270632966 0.0 0.0" rpy="0 0 0"/>
            <geometry>
                <box size="0.3981458541265932 0.8733677520753103 0.9698483928004266" />
            </geometry>
        </collision>
    </link>
    <joint name="2_5" type="revolute">
       <parent link="2"/>
       <child  link="5"/>
       <origin rpy="0 0 0" xyz="-0.3448076373106298 0.0 0.5397160936303915" />
     <axis xyz="0 1 0"/>
       <limit effort="0.0" lower="-3.14159" upper="3.14159" velocity="0.0"/>
    </joint>
    <link name="5">
        <inertial>
            <origin xyz="0.0 0.0 0.40311366391176384" rpy="0 0 0"/>
            <mass value="1" />
            <inertia ixx="100" ixy="0" ixz="0" iyy="100" iyz="0" izz="100" />
        </inertial>
        <visual>
            <origin xyz="0.0 0.0 0.40311366391176384" rpy="0 0 0"/>
            <geometry>
                <box size="0.8323583999799358 0.48036636148677625 0.8062273278235277" />
            </geometry>
            <material name="Blue">
                <color rgba="0 0 1.0 1.0"/>
            </material>
        </visual>
        <collision>
            <origin xyz="0.0 0.0 0.40311366391176384" rpy="0 0 0"/>
            <geometry>
                <box size="0.8323583999799358 0.48036636148677625 0.8062273278235277" />
            </geometry>
        </collision>
    </link>
    <joint name="3_6" type="revolute">
       <parent link="3"/>
       <child  link="6"/>
       <origin rpy="0 0 0" xyz="-0.5209971604913458 0.0 0.1959106674241107" />
     <axis xyz="0 1 0"/>
       <limit effort="0.0" lower="-3.14159" upper="3.14159" velocity="0.0"/>
    </joint>
    <link name="6">
        <inertial>
            <origin xyz="0.0 0.0 0.49193845723659524" rpy="0 0 0"/>
            <mass value="1" />
            <inertia ixx="100" ixy="0" ixz="0" iyy="100" iyz="0" izz="100" />
        </inertial>
        <visual>
            <origin xyz="0.0 0.0 0.49193845723659524" rpy="0 0 0"/>
            <geometry>
                <box size="0.4942340164095109 0.7030256444113381 0.9838769144731905" />
            </geometry>
            <material name="Blue">
                <color rgba="0 0 1.0 1.0"/>
            </material>
        </visual>
        <collision>
            <origin xyz="0.0 0.0 0.49193845723659524" rpy="0 0 0"/>
            <geometry>
                <box size="0.4942340164095109 0.7030256444113381 0.9838769144731905" />
            </geometry>
        </collision>
    </link>
    <joint name="1_7" type="revolute">
       <parent link="1"/>
       <child  link="7"/>
       <origin rpy="0 0 0" xyz="0.0 -0.4762666034651703 0.2075077447316998" />
     <axis xyz="1 0 0"/>
       <limit effort="0.0" lower="-3.14159" upper="3.14159" velocity="0.0"/>
    </joint>
    <link name="7">
        <inertial>
            <origin xyz="0.0 0.0 0.5382364397568895" rpy="0 0 0"/>
            <mass value="1" />
            <inertia ixx="100" ixy="0" ixz="0" iyy="100" iyz="0" izz="100" />
        </inertial>
        <visual>
            <origin xyz="0.0 0.0 0.5382364397568895" rpy="0 0 0"/>
            <geometry>
                <box size="0.46229065839541506 0.38933316087220826 1.076472879513779" />
            </geometry>
            <material name="Green">
                <color rgba="0 1.0 0 1.0"/>
            </material>
        </visual>
        <collision>
            <origin xyz="0.0 0.0 0.5382364397568895" rpy="0 0 0"/>
            <geometry>
                <box size="0.46229065839541506 0.38933316087220826 1.076472879513779" />
            </geometry>
        </collision>
    </link>
    <joint name="7_9" type="revolute">
       <parent link="7"/>
       <child  link="9"/>
       <origin rpy="0 0 0" xyz="0.23114532919770753 0.0 0.5382364397568895" />
     <axis xyz="0 1 0"/>
       <limit effort="0.0" lower="-3.14159" upper="3.14159" velocity="0.0"/>
    </joint>
    <link name="9">
        <inertial>
            <origin xyz="0.28950825604522884 0.0 0.0" rpy="0 0 0"/>
            <mass value="1" />
            <inertia ixx="100" ixy="0" ixz="0" iyy="100" iyz="0" izz="100" />
        </inertial>
        <visual>
            <origin xyz="0.28950825604522884 0.0 0.0" rpy="0 0 0"/>
            <geometry>
                <box size="0.5790165120904577 0.6970259612552545 1.0176057028937955" />
            </geometry>
            <material name="Green">
                <color rgba="0 1.0 0 1.0"/>
            </material>
        </visual>
        <collision>
            <origin xyz="0.28950825604522884 0.0 0.0" rpy="0 0 0"/>
            <geometry>
                <box size="0.5790165120904577 0.6970259612552545 1.0176057028937955" />
            </geometry>
        </collision>
    </link>
    <joint name="7_10" type="revolute">
       <parent link="7"/>
       <child  link="10"/>
       <origin rpy="0 0 0" xyz="0.0 0.19466658043610413 0.5382364397568895" />
     <axis xyz="1 0 0"/>
       <limit effort="0.0" lower="-3.14159" upper="3.14159" velocity="0.0"/>
    </joint>
    <link name="10">
        <inertial>
            <origin xyz="0.0 0.25499555693499 0.0" rpy="0 0 0"/>
            <mass value="1" />
            <inertia ixx="100" ixy="0" ixz="0" iyy="100" iyz="0" izz="100" />
        </inertial>
        <visual>
            <origin xyz="0.0 0.25499555693499 0.0" rpy="0 0 0"/>
            <geometry>
                <box size="0.4046822494595697 0.50999111386998 0.9415566857898386" />
            </geometry>
            <material name="Blue">
                <color rgba="0 0 1.0 1.0"/>
            </material>
        </visual>
        <collision>
            <origin xyz="0.0 0.25499555693499 0.0" rpy="0 0 0"/>
            <geometry>
                <box size="0.4046822494595697 0.50999111386998 0.9415566857898386" />
            </geometry>
        </collision>
    </link>
    <joint name="4_8" type="revolute">
       <parent link="4"/>
       <child  link="8"/>
       <origin rpy="0 0 0" xyz="-0.1990729270632966 -0.4366838760376551 0.0" />
     <axis xyz="0 1 0"/>
       <limit effort="0.0" lower="-3.14159" upper="3.14159" velocity="0.0"/>
    </joint>
    <link name="8">
        <inertial>
            <origin xyz="0.0 -0.5457755437072307 0.0" rpy="0 0 0"/>
            <mass value="1" />
            <inertia ixx="100" ixy="0" ixz="0" iyy="100" iyz="0" izz="100" />
        </inertial>
        <visual>
            <origin xyz="0.0 -0.5457755437072307 0.0" rpy="0 0 0"/>
            <geometry>
                <box size="0.9725240484978892 1.0915510874144614 0.8279164338120046" />
            </geometry>
            <material name="Blue">
                <color rgba="0 0 1.0 1.0"/>
            </material>
        </visual>
        <collision>
            <origin xyz="0.0 -0.5457755437072307 0.0" rpy="0 0 0"/>
            <geometry>
                <box size="0.9725240484978892 1.0915510874144614 0.8279164338120046" />
            </geometry>
        </collision>
    </link>
    <joint name="10_11" type="revolute">
       <parent link="10"/>
       <child  link="11"/>
       <origin rpy="0 0 0" xyz="0.0 0.25499555693499 0.4707783428949193" />
     <axis xyz="1 0 0"/>
       <limit effort="0.0" lower="-3.14159" upper="3.14159" velocity="0.0"/>
    </joint>
    <link name="11">
        <inertial>
            <origin xyz="0.0 0.0 0.35657934613287356" rpy="0 0 0"/>
            <mass value="1" />
            <inertia ixx="100" ixy="0" ixz="0" iyy="100" iyz="0" izz="100" />
        </inertial>
        <visual>
            <origin xyz="0.0 0.0 0.35657934613287356" rpy="0 0 0"/>
            <geometry>
                <box size="0.37684128660217603 0.4113598891259894 0.7131586922657471" />
            </geometry>
            <material name="Blue">
                <color rgba="0 0 1.0 1.0"/>
            </material>
        </visual>
        <collision>
            <origin xyz="0.0 0.0 0.35657934613287356" rpy="0 0 0"/>
            <geometry>
                <box size="0.37684128660217603 0.4113598891259894 0.7131586922657471" />
            </geometry>
        </collision>
    </link>
</robot>