<robot name = "robot">
    <link name="0">
        <inertial>
            <origin xyz="0 0 3.2357141036984025" rpy="0 0 0"/>
            <mass value="1" />
            <inertia ixx="100" ixy="0" ixz="0" iyy="100" iyz="0" izz="100" />
        </inertial>
        <visual>
            <origin xyz="0 0 3.2357141036984025" rpy="0 0 0"/>
            <geometry>
                <box size="0.47438971656396955 1.091412597109336 0.47142820739680535" />
            </geometry>
            <material name="Green">
                <color rgba="0 1.0 0 1.0"/>
            </material>
        </visual>
        <collision>
            <origin xyz="0 0 3.2357141036984025" rpy="0 0 0"/>
            <geometry>
                <box size="0.47438971656396955 1.091412597109336 0.47142820739680535" />
            </geometry>
        </collision>
    </link>
    <joint name="0_1" type="revolute">
       <parent link="0"/>
       <child  link="1"/>
       <origin rpy="0 0 0" xyz="-0.23719485828198478 0.0 3.2357141036984025" />
     <axis xyz="1 0 0"/>
       <limit effort="0.0" lower="-3.14159" upper="3.14159" velocity="0.0"/>
    </joint>
    <link name="1">
        <inertial>
            <origin xyz="-0.4215508965181459 0.0 0.0" rpy="0 0 0"/>
            <mass value="1" />
            <inertia ixx="100" ixy="0" ixz="0" iyy="100" iyz="0" izz="100" />
        </inertial>
        <visual>
            <origin xyz="-0.4215508965181459 0.0 0.0" rpy="0 0 0"/>
            <geometry>
                <box size="0.8431017930362918 1.082903139536298 0.827619170452326" />
            </geometry>
            <material name="Green">
                <color rgba="0 1.0 0 1.0"/>
            </material>
        </visual>
        <collision>
            <origin xyz="-0.4215508965181459 0.0 0.0" rpy="0 0 0"/>
            <geometry>
                <box size="0.8431017930362918 1.082903139536298 0.827619170452326" />
            </geometry>
        </collision>
    </link>
    <joint name="1_2" type="revolute">
       <parent link="1"/>
       <child  link="2"/>
       <origin rpy="0 0 0" xyz="-0.4215508965181459 0.0 -0.413809585226163" />
     <axis xyz="0 1 0"/>
       <limit effort="0.0" lower="-3.14159" upper="3.14159" velocity="0.0"/>
    </joint>
    <link name="2">
        <inertial>
            <origin xyz="0.0 0.0 -0.20358280004980153" rpy="0 0 0"/>
            <mass value="1" />
            <inertia ixx="100" ixy="0" ixz="0" iyy="100" iyz="0" izz="100" />
        </inertial>
        <visual>
            <origin xyz="0.0 0.0 -0.20358280004980153" rpy="0 0 0"/>
            <geometry>
                <box size="0.8597558300329938 1.0653248284735994 0.40716560009960306" />
            </geometry>
            <material name="Blue">
                <color rgba="0 0 1.0 1.0"/>
            </material>
        </visual>
        <collision>
            <origin xyz="0.0 0.0 -0.20358280004980153" rpy="0 0 0"/>
            <geometry>
                <box size="0.8597558300329938 1.0653248284735994 0.40716560009960306" />
            </geometry>
        </collision>
    </link>
    <joint name="2_3" type="revolute">
       <parent link="2"/>
       <child  link="3"/>
       <origin rpy="0 0 0" xyz="0.0 0.0 -0.40716560009960306" />
     <axis xyz="1 0 0"/>
       <limit effort="0.0" lower="-3.14159" upper="3.14159" velocity="0.0"/>
    </joint>
    <link name="3">
        <inertial>
            <origin xyz="0.0 0.0 -0.28771187190335823" rpy="0 0 0"/>
            <mass value="1" />
            <inertia ixx="100" ixy="0" ixz="0" iyy="100" iyz="0" izz="100" />
        </inertial>
        <visual>
            <origin xyz="0.0 0.0 -0.28771187190335823" rpy="0 0 0"/>
            <geometry>
                <box size="0.7784594190465647 0.5134594180248553 0.5754237438067165" />
            </geometry>
            <material name="Blue">
                <color rgba="0 0 1.0 1.0"/>
            </material>
        </visual>
        <collision>
            <origin xyz="0.0 0.0 -0.28771187190335823" rpy="0 0 0"/>
            <geometry>
                <box size="0.7784594190465647 0.5134594180248553 0.5754237438067165" />
            </geometry>
        </collision>
    </link>
    <joint name="3_4" type="revolute">
       <parent link="3"/>
       <child  link="4"/>
       <origin rpy="0 0 0" xyz="0.0 0.25672970901242764 -0.28771187190335823" />
     <axis xyz="1 0 0"/>
       <limit effort="0.0" lower="-3.14159" upper="3.14159" velocity="0.0"/>
    </joint>
    <link name="4">
        <inertial>
            <origin xyz="0.0 0.1945855863012877 0.0" rpy="0 0 0"/>
            <mass value="1" />
            <inertia ixx="100" ixy="0" ixz="0" iyy="100" iyz="0" izz="100" />
        </inertial>
        <visual>
            <origin xyz="0.0 0.1945855863012877 0.0" rpy="0 0 0"/>
            <geometry>
                <box size="0.4592801378543394 0.3891711726025754 0.4588283491015232" />
            </geometry>
            <material name="Green">
                <color rgba="0 1.0 0 1.0"/>
            </material>
        </visual>
        <collision>
            <origin xyz="0.0 0.1945855863012877 0.0" rpy="0 0 0"/>
            <geometry>
                <box size="0.4592801378543394 0.3891711726025754 0.4588283491015232" />
            </geometry>
        </collision>
    </link>
    <joint name="4_5" type="revolute">
       <parent link="4"/>
       <child  link="5"/>
       <origin rpy="0 0 0" xyz="0.0 0.3891711726025754 0.0" />
     <axis xyz="1 0 0"/>
       <limit effort="0.0" lower="-3.14159" upper="3.14159" velocity="0.0"/>
    </joint>
    <link name="5">
        <inertial>
            <origin xyz="0.0 0.4203900427924695 0.0" rpy="0 0 0"/>
            <mass value="1" />
            <inertia ixx="100" ixy="0" ixz="0" iyy="100" iyz="0" izz="100" />
        </inertial>
        <visual>
            <origin xyz="0.0 0.4203900427924695 0.0" rpy="0 0 0"/>
            <geometry>
                <box size="0.7646216484415008 0.840780085584939 0.9323536881617548" />
            </geometry>
            <material name="Green">
                <color rgba="0 1.0 0 1.0"/>
            </material>
        </visual>
        <collision>
            <origin xyz="0.0 0.4203900427924695 0.0" rpy="0 0 0"/>
            <geometry>
                <box size="0.7646216484415008 0.840780085584939 0.9323536881617548" />
            </geometry>
        </collision>
    </link>
    <joint name="2_6" type="revolute">
       <parent link="2"/>
       <child  link="6"/>
       <origin rpy="0 0 0" xyz="0.4298779150164969 0.0 -0.20358280004980153" />
     <axis xyz="0 1 0"/>
       <limit effort="0.0" lower="-3.14159" upper="3.14159" velocity="0.0"/>
    </joint>
    <link name="6">
        <inertial>
            <origin xyz="0.4912855661966202 0.0 0.0" rpy="0 0 0"/>
            <mass value="1" />
            <inertia ixx="100" ixy="0" ixz="0" iyy="100" iyz="0" izz="100" />
        </inertial>
        <visual>
            <origin xyz="0.4912855661966202 0.0 0.0" rpy="0 0 0"/>
            <geometry>
                <box size="0.9825711323932405 0.5119118231803013 0.5135751761055825" />
            </geometry>
            <material name="Green">
                <color rgba="0 1.0 0 1.0"/>
            </material>
        </visual>
        <collision>
            <origin xyz="0.4912855661966202 0.0 0.0" rpy="0 0 0"/>
            <geometry>
                <box size="0.9825711323932405 0.5119118231803013 0.5135751761055825" />
            </geometry>
        </collision>
    </link>
    <joint name="5_7" type="revolute">
       <parent link="5"/>
       <child  link="7"/>
       <origin rpy="0 0 0" xyz="-0.3823108242207504 0.4203900427924695 0.0" />
     <axis xyz="0 1 0"/>
       <limit effort="0.0" lower="-3.14159" upper="3.14159" velocity="0.0"/>
    </joint>
    <link name="7">
        <inertial>
            <origin xyz="-0.25791458968147196 0.0 0.0" rpy="0 0 0"/>
            <mass value="1" />
            <inertia ixx="100" ixy="0" ixz="0" iyy="100" iyz="0" izz="100" />
        </inertial>
        <visual>
            <origin xyz="-0.25791458968147196 0.0 0.0" rpy="0 0 0"/>
            <geometry>
                <box size="0.5158291793629439 1.0777981657686908 0.5629585571108298" />
            </geometry>
            <material name="Blue">
                <color rgba="0 0 1.0 1.0"/>
            </material>
        </visual>
        <collision>
            <origin xyz="-0.25791458968147196 0.0 0.0" rpy="0 0 0"/>
            <geometry>
                <box size="0.5158291793629439 1.0777981657686908 0.5629585571108298" />
            </geometry>
        </collision>
    </link>
    <joint name="5_8" type="revolute">
       <parent link="5"/>
       <child  link="8"/>
       <origin rpy="0 0 0" xyz="0.3823108242207504 0.4203900427924695 0.0" />
     <axis xyz="1 0 0"/>
       <limit effort="0.0" lower="-3.14159" upper="3.14159" velocity="0.0"/>
    </joint>
    <link name="8">
        <inertial>
            <origin xyz="0.44970960284167383 0.0 0.0" rpy="0 0 0"/>
            <mass value="1" />
            <inertia ixx="100" ixy="0" ixz="0" iyy="100" iyz="0" izz="100" />
        </inertial>
        <visual>
            <origin xyz="0.44970960284167383 0.0 0.0" rpy="0 0 0"/>
            <geometry>
                <box size="0.8994192056833477 0.6533027790862209 0.6130135303517638" />
            </geometry>
            <material name="Blue">
                <color rgba="0 0 1.0 1.0"/>
            </material>
        </visual>
        <collision>
            <origin xyz="0.44970960284167383 0.0 0.0" rpy="0 0 0"/>
            <geometry>
                <box size="0.8994192056833477 0.6533027790862209 0.6130135303517638" />
            </geometry>
        </collision>
    </link>
    <joint name="8_9" type="revolute">
       <parent link="8"/>
       <child  link="9"/>
       <origin rpy="0 0 0" xyz="0.44970960284167383 0.32665138954311046 0.0" />
     <axis xyz="1 0 0"/>
       <limit effort="0.0" lower="-3.14159" upper="3.14159" velocity="0.0"/>
    </joint>
    <link name="9">
        <inertial>
            <origin xyz="0.0 0.27638324940301606 0.0" rpy="0 0 0"/>
            <mass value="1" />
            <inertia ixx="100" ixy="0" ixz="0" iyy="100" iyz="0" izz="100" />
        </inertial>
        <visual>
            <origin xyz="0.0 0.27638324940301606 0.0" rpy="0 0 0"/>
            <geometry>
                <box size="0.5044710703259749 0.5527664988060321 0.6329287493971498" />
            </geometry>
            <material name="Green">
                <color rgba="0 1.0 0 1.0"/>
            </material>
        </visual>
        <collision>
            <origin xyz="0.0 0.27638324940301606 0.0" rpy="0 0 0"/>
            <geometry>
                <box size="0.5044710703259749 0.5527664988060321 0.6329287493971498" />
            </geometry>
        </collision>
    </link>
    <joint name="3_10" type="revolute">
       <parent link="3"/>
       <child  link="10"/>
       <origin rpy="0 0 0" xyz="0.0 0.0 -0.5754237438067165" />
     <axis xyz="0 1 0"/>
       <limit effort="0.0" lower="-3.14159" upper="3.14159" velocity="0.0"/>
    </joint>
    <link name="10">
        <inertial>
            <origin xyz="0.0 0.0 -0.3945403056851204" rpy="0 0 0"/>
            <mass value="1" />
            <inertia ixx="100" ixy="0" ixz="0" iyy="100" iyz="0" izz="100" />
        </inertial>
        <visual>
            <origin xyz="0.0 0.0 -0.3945403056851204" rpy="0 0 0"/>
            <geometry>
                <box size="0.7775129684444122 0.8048048351090704 0.7890806113702408" />
            </geometry>
            <material name="Green">
                <color rgba="0 1.0 0 1.0"/>
            </material>
        </visual>
        <collision>
            <origin xyz="0.0 0.0 -0.3945403056851204" rpy="0 0 0"/>
            <geometry>
                <box size="0.7775129684444122 0.8048048351090704 0.7890806113702408" />
            </geometry>
        </collision>
    </link>
    <joint name="0_11" type="revolute">
       <parent link="0"/>
       <child  link="11"/>
       <origin rpy="0 0 0" xyz="0.0 -0.545706298554668 3.2357141036984025" />
     <axis xyz="0 1 0"/>
       <limit effort="0.0" lower="-3.14159" upper="3.14159" velocity="0.0"/>
    </joint>
    <link name="11">
        <inertial>
            <origin xyz="0.0 -0.4328521156537116 0.0" rpy="0 0 0"/>
            <mass value="1" />
            <inertia ixx="100" ixy="0" ixz="0" iyy="100" iyz="0" izz="100" />
        </inertial>
        <visual>
            <origin xyz="0.0 -0.4328521156537116 0.0" rpy="0 0 0"/>
            <geometry>
                <box size="0.8611012118559995 0.8657042313074232 0.9874708233592792" />
            </geometry>
            <material name="Blue">
                <color rgba="0 0 1.0 1.0"/>
            </material>
        </visual>
        <collision>
            <origin xyz="0.0 -0.4328521156537116 0.0" rpy="0 0 0"/>
            <geometry>
                <box size="0.8611012118559995 0.8657042313074232 0.9874708233592792" />
            </geometry>
        </collision>
    </link>
    <joint name="1_12" type="revolute">
       <parent link="1"/>
       <child  link="12"/>
       <origin rpy="0 0 0" xyz="-0.4215508965181459 0.0 0.413809585226163" />
     <axis xyz="1 0 0"/>
       <limit effort="0.0" lower="-3.14159" upper="3.14159" velocity="0.0"/>
    </joint>
    <link name="12">
        <inertial>
            <origin xyz="0.0 0.0 0.22206593773162558" rpy="0 0 0"/>
            <mass value="1" />
            <inertia ixx="100" ixy="0" ixz="0" iyy="100" iyz="0" izz="100" />
        </inertial>
        <visual>
            <origin xyz="0.0 0.0 0.22206593773162558" rpy="0 0 0"/>
            <geometry>
                <box size="0.718868233323954 1.0086388523106584 0.44413187546325117" />
            </geometry>
            <material name="Blue">
                <color rgba="0 0 1.0 1.0"/>
            </material>
        </visual>
        <collision>
            <origin xyz="0.0 0.0 0.22206593773162558" rpy="0 0 0"/>
            <geometry>
                <box size="0.718868233323954 1.0086388523106584 0.44413187546325117" />
            </geometry>
        </collision>
    </link>
    <joint name="10_13" type="revolute">
       <parent link="10"/>
       <child  link="13"/>
       <origin rpy="0 0 0" xyz="-0.3887564842222061 0.0 -0.3945403056851204" />
     <axis xyz="1 0 0"/>
       <limit effort="0.0" lower="-3.14159" upper="3.14159" velocity="0.0"/>
    </joint>
    <link name="13">
        <inertial>
            <origin xyz="-0.28246857986871987 0.0 0.0" rpy="0 0 0"/>
            <mass value="1" />
            <inertia ixx="100" ixy="0" ixz="0" iyy="100" iyz="0" izz="100" />
        </inertial>
        <visual>
            <origin xyz="-0.28246857986871987 0.0 0.0" rpy="0 0 0"/>
            <geometry>
                <box size="0.5649371597374397 1.0648777329031627 0.5070422327058061" />
            </geometry>
            <material name="Green">
                <color rgba="0 1.0 0 1.0"/>
            </material>
        </visual>
        <collision>
            <origin xyz="-0.28246857986871987 0.0 0.0" rpy="0 0 0"/>
            <geometry>
                <box size="0.5649371597374397 1.0648777329031627 0.5070422327058061" />
            </geometry>
        </collision>
    </link>
</robot>