<robot name = "robot">
    <link name="0">
        <inertial>
            <origin xyz="0 0 3.4083502565203734" rpy="0 0 0"/>
            <mass value="1" />
            <inertia ixx="100" ixy="0" ixz="0" iyy="100" iyz="0" izz="100" />
        </inertial>
        <visual>
            <origin xyz="0 0 3.4083502565203734" rpy="0 0 0"/>
            <geometry>
                <box size="0.6442016253948498 0.4622974404814081 0.8167005130407471" />
            </geometry>
            <material name="Green">
                <color rgba="0 1.0 0 1.0"/>
            </material>
        </visual>
        <collision>
            <origin xyz="0 0 3.4083502565203734" rpy="0 0 0"/>
            <geometry>
                <box size="0.6442016253948498 0.4622974404814081 0.8167005130407471" />
            </geometry>
        </collision>
    </link>
    <joint name="0_1" type="revolute">
       <parent link="0"/>
       <child  link="1"/>
       <origin rpy="0 0 0" xyz="0.0 0.23114872024070404 3.4083502565203734" />
     <axis xyz="0 1 0"/>
       <limit effort="0.0" lower="-3.14159" upper="3.14159" velocity="0.0"/>
    </joint>
    <link name="1">
        <inertial>
            <origin xyz="0.0 0.21396153014726332 0.0" rpy="0 0 0"/>
            <mass value="1" />
            <inertia ixx="100" ixy="0" ixz="0" iyy="100" iyz="0" izz="100" />
        </inertial>
        <visual>
            <origin xyz="0.0 0.21396153014726332 0.0" rpy="0 0 0"/>
            <geometry>
                <box size="0.568348968148961 0.42792306029452665 0.7008397323522515" />
            </geometry>
            <material name="Green">
                <color rgba="0 1.0 0 1.0"/>
            </material>
        </visual>
        <collision>
            <origin xyz="0.0 0.21396153014726332 0.0" rpy="0 0 0"/>
            <geometry>
                <box size="0.568348968148961 0.42792306029452665 0.7008397323522515" />
            </geometry>
        </collision>
    </link>
    <joint name="1_2" type="revolute">
       <parent link="1"/>
       <child  link="2"/>
       <origin rpy="0 0 0" xyz="0.0 0.42792306029452665 0.0" />
     <axis xyz="0 1 0"/>
       <limit effort="0.0" lower="-3.14159" upper="3.14159" velocity="0.0"/>
    </joint>
    <link name="2">
        <inertial>
            <origin xyz="0.0 0.30432689632923904 0.0" rpy="0 0 0"/>
            <mass value="1" />
            <inertia ixx="100" ixy="0" ixz="0" iyy="100" iyz="0" izz="100" />
        </inertial>
        <visual>
            <origin xyz="0.0 0.30432689632923904 0.0" rpy="0 0 0"/>
            <geometry>
                <box size="1.0787210754195469 0.6086537926584781 0.7644739731858666" />
            </geometry>
            <material name="Blue">
                <color rgba="0 0 1.0 1.0"/>
            </material>
        </visual>
        <collision>
            <origin xyz="0.0 0.30432689632923904 0.0" rpy="0 0 0"/>
            <geometry>
                <box size="1.0787210754195469 0.6086537926584781 0.7644739731858666" />
            </geometry>
        </collision>
    </link>
    <joint name="1_4" type="revolute">
       <parent link="1"/>
       <child  link="4"/>
       <origin rpy="0 0 0" xyz="-0.2841744840744805 0.21396153014726332 0.0" />
     <axis xyz="0 1 0"/>
       <limit effort="0.0" lower="-3.14159" upper="3.14159" velocity="0.0"/>
    </joint>
    <link name="4">
        <inertial>
            <origin xyz="-0.30697214696084757 0.0 0.0" rpy="0 0 0"/>
            <mass value="1" />
            <inertia ixx="100" ixy="0" ixz="0" iyy="100" iyz="0" izz="100" />
        </inertial>
        <visual>
            <origin xyz="-0.30697214696084757 0.0 0.0" rpy="0 0 0"/>
            <geometry>
                <box size="0.6139442939216951 0.41818404031286993 0.5403144175258847" />
            </geometry>
            <material name="Green">
                <color rgba="0 1.0 0 1.0"/>
            </material>
        </visual>
        <collision>
            <origin xyz="-0.30697214696084757 0.0 0.0" rpy="0 0 0"/>
            <geometry>
                <box size="0.6139442939216951 0.41818404031286993 0.5403144175258847" />
            </geometry>
        </collision>
    </link>
    <joint name="0_5" type="revolute">
       <parent link="0"/>
       <child  link="5"/>
       <origin rpy="0 0 0" xyz="0.0 0.0 3.8167005130407468" />
     <axis xyz="1 0 0"/>
       <limit effort="0.0" lower="-3.14159" upper="3.14159" velocity="0.0"/>
    </joint>
    <link name="5">
        <inertial>
            <origin xyz="0.0 0.0 0.4717497392217538" rpy="0 0 0"/>
            <mass value="1" />
            <inertia ixx="100" ixy="0" ixz="0" iyy="100" iyz="0" izz="100" />
        </inertial>
        <visual>
            <origin xyz="0.0 0.0 0.4717497392217538" rpy="0 0 0"/>
            <geometry>
                <box size="1.0377511037810334 0.5926056305950456 0.9434994784435076" />
            </geometry>
            <material name="Green">
                <color rgba="0 1.0 0 1.0"/>
            </material>
        </visual>
        <collision>
            <origin xyz="0.0 0.0 0.4717497392217538" rpy="0 0 0"/>
            <geometry>
                <box size="1.0377511037810334 0.5926056305950456 0.9434994784435076" />
            </geometry>
        </collision>
    </link>
    <joint name="2_3" type="revolute">
       <parent link="2"/>
       <child  link="3"/>
       <origin rpy="0 0 0" xyz="-0.5393605377097734 0.30432689632923904 0.0" />
     <axis xyz="1 0 0"/>
       <limit effort="0.0" lower="-3.14159" upper="3.14159" velocity="0.0"/>
    </joint>
    <link name="3">
        <inertial>
            <origin xyz="-0.2972358076982432 0.0 0.0" rpy="0 0 0"/>
            <mass value="1" />
            <inertia ixx="100" ixy="0" ixz="0" iyy="100" iyz="0" izz="100" />
        </inertial>
        <visual>
            <origin xyz="-0.2972358076982432 0.0 0.0" rpy="0 0 0"/>
            <geometry>
                <box size="0.5944716153964864 0.5146763465464077 1.0835309561655464" />
            </geometry>
            <material name="Blue">
                <color rgba="0 0 1.0 1.0"/>
            </material>
        </visual>
        <collision>
            <origin xyz="-0.2972358076982432 0.0 0.0" rpy="0 0 0"/>
            <geometry>
                <box size="0.5944716153964864 0.5146763465464077 1.0835309561655464" />
            </geometry>
        </collision>
    </link>
    <joint name="0_6" type="revolute">
       <parent link="0"/>
       <child  link="6"/>
       <origin rpy="0 0 0" xyz="0.0 0.0 3.0" />
     <axis xyz="0 1 0"/>
       <limit effort="0.0" lower="-3.14159" upper="3.14159" velocity="0.0"/>
    </joint>
    <link name="6">
        <inertial>
            <origin xyz="0.0 0.0 -0.40078488698897585" rpy="0 0 0"/>
            <mass value="1" />
            <inertia ixx="100" ixy="0" ixz="0" iyy="100" iyz="0" izz="100" />
        </inertial>
        <visual>
            <origin xyz="0.0 0.0 -0.40078488698897585" rpy="0 0 0"/>
            <geometry>
                <box size="0.4828469171142219 0.7209782816679882 0.8015697739779517" />
            </geometry>
            <material name="Green">
                <color rgba="0 1.0 0 1.0"/>
            </material>
        </visual>
        <collision>
            <origin xyz="0.0 0.0 -0.40078488698897585" rpy="0 0 0"/>
            <geometry>
                <box size="0.4828469171142219 0.7209782816679882 0.8015697739779517" />
            </geometry>
        </collision>
    </link>
    <joint name="3_7" type="revolute">
       <parent link="3"/>
       <child  link="7"/>
       <origin rpy="0 0 0" xyz="-0.5944716153964864 0.0 0.0" />
     <axis xyz="0 1 0"/>
       <limit effort="0.0" lower="-3.14159" upper="3.14159" velocity="0.0"/>
    </joint>
    <link name="7">
        <inertial>
            <origin xyz="-0.4783451101802001 0.0 0.0" rpy="0 0 0"/>
            <mass value="1" />
            <inertia ixx="100" ixy="0" ixz="0" iyy="100" iyz="0" izz="100" />
        </inertial>
        <visual>
            <origin xyz="-0.4783451101802001 0.0 0.0" rpy="0 0 0"/>
            <geometry>
                <box size="0.9566902203604002 0.514674755268272 0.46540597678773926" />
            </geometry>
            <material name="Green">
                <color rgba="0 1.0 0 1.0"/>
            </material>
        </visual>
        <collision>
            <origin xyz="-0.4783451101802001 0.0 0.0" rpy="0 0 0"/>
            <geometry>
                <box size="0.9566902203604002 0.514674755268272 0.46540597678773926" />
            </geometry>
        </collision>
    </link>
    <joint name="7_8" type="revolute">
       <parent link="7"/>
       <child  link="8"/>
       <origin rpy="0 0 0" xyz="-0.4783451101802001 0.0 -0.23270298839386963" />
     <axis xyz="0 1 0"/>
       <limit effort="0.0" lower="-3.14159" upper="3.14159" velocity="0.0"/>
    </joint>
    <link name="8">
        <inertial>
            <origin xyz="0.0 0.0 -0.5484760085588058" rpy="0 0 0"/>
            <mass value="1" />
            <inertia ixx="100" ixy="0" ixz="0" iyy="100" iyz="0" izz="100" />
        </inertial>
        <visual>
            <origin xyz="0.0 0.0 -0.5484760085588058" rpy="0 0 0"/>
            <geometry>
                <box size="0.6400941600732524 0.5294472397526604 1.0969520171176117" />
            </geometry>
            <material name="Blue">
                <color rgba="0 0 1.0 1.0"/>
            </material>
        </visual>
        <collision>
            <origin xyz="0.0 0.0 -0.5484760085588058" rpy="0 0 0"/>
            <geometry>
                <box size="0.6400941600732524 0.5294472397526604 1.0969520171176117" />
            </geometry>
        </collision>
    </link>
    <joint name="8_9" type="revolute">
       <parent link="8"/>
       <child  link="9"/>
       <origin rpy="0 0 0" xyz="0.0 0.2647236198763302 -0.5484760085588058" />
     <axis xyz="1 0 0"/>
       <limit effort="0.0" lower="-3.14159" upper="3.14159" velocity="0.0"/>
    </joint>
    <link name="9">
        <inertial>
            <origin xyz="0.0 0.21833820344091778 0.0" rpy="0 0 0"/>
            <mass value="1" />
            <inertia ixx="100" ixy="0" ixz="0" iyy="100" iyz="0" izz="100" />
        </inertial>
        <visual>
            <origin xyz="0.0 0.21833820344091778 0.0" rpy="0 0 0"/>
            <geometry>
                <box size="0.9978689162279781 0.43667640688183557 0.6939413477594928" />
            </geometry>
            <material name="Green">
                <color rgba="0 1.0 0 1.0"/>
            </material>
        </visual>
        <collision>
            <origin xyz="0.0 0.21833820344091778 0.0" rpy="0 0 0"/>
            <geometry>
                <box size="0.9978689162279781 0.43667640688183557 0.6939413477594928" />
            </geometry>
        </collision>
    </link>
</robot>