<robot name = "robot">
    <link name="0">
        <inertial>
            <origin xyz="0 0 3.25347095427554" rpy="0 0 0"/>
            <mass value="1" />
            <inertia ixx="100" ixy="0" ixz="0" iyy="100" iyz="0" izz="100" />
        </inertial>
        <visual>
            <origin xyz="0 0 3.25347095427554" rpy="0 0 0"/>
            <geometry>
                <box size="0.9332767715503605 0.8276512336215387 0.5069419085510799" />
            </geometry>
            <material name="Blue">
                <color rgba="0 0 1.0 1.0"/>
            </material>
        </visual>
        <collision>
            <origin xyz="0 0 3.25347095427554" rpy="0 0 0"/>
            <geometry>
                <box size="0.9332767715503605 0.8276512336215387 0.5069419085510799" />
            </geometry>
        </collision>
    </link>
    <joint name="0_1" type="revolute">
       <parent link="0"/>
       <child  link="1"/>
       <origin rpy="0 0 0" xyz="0.46663838577518024 0.0 3.25347095427554" />
     <axis xyz="1 0 0"/>
       <limit effort="0.0" lower="-3.14159" upper="3.14159" velocity="0.0"/>
    </joint>
    <link name="1">
        <inertial>
            <origin xyz="0.44155185055902013 0.0 0.0" rpy="0 0 0"/>
            <mass value="1" />
            <inertia ixx="100" ixy="0" ixz="0" iyy="100" iyz="0" izz="100" />
        </inertial>
        <visual>
            <origin xyz="0.44155185055902013 0.0 0.0" rpy="0 0 0"/>
            <geometry>
                <box size="0.8831037011180403 0.5043225344733199 0.8818617979613139" />
            </geometry>
            <material name="Green">
                <color rgba="0 1.0 0 1.0"/>
            </material>
        </visual>
        <collision>
            <origin xyz="0.44155185055902013 0.0 0.0" rpy="0 0 0"/>
            <geometry>
                <box size="0.8831037011180403 0.5043225344733199 0.8818617979613139" />
            </geometry>
        </collision>
    </link>
    <joint name="1_2" type="revolute">
       <parent link="1"/>
       <child  link="2"/>
       <origin rpy="0 0 0" xyz="0.8831037011180403 0.0 0.0" />
     <axis xyz="0 1 0"/>
       <limit effort="0.0" lower="-3.14159" upper="3.14159" velocity="0.0"/>
    </joint>
    <link name="2">
        <inertial>
            <origin xyz="0.3353633252380709 0.0 0.0" rpy="0 0 0"/>
            <mass value="1" />
            <inertia ixx="100" ixy="0" ixz="0" iyy="100" iyz="0" izz="100" />
        </inertial>
        <visual>
            <origin xyz="0.3353633252380709 0.0 0.0" rpy="0 0 0"/>
            <geometry>
                <box size="0.6707266504761418 0.6345987825582782 0.8834514113098055" />
            </geometry>
            <material name="Blue">
                <color rgba="0 0 1.0 1.0"/>
            </material>
        </visual>
        <collision>
            <origin xyz="0.3353633252380709 0.0 0.0" rpy="0 0 0"/>
            <geometry>
                <box size="0.6707266504761418 0.6345987825582782 0.8834514113098055" />
            </geometry>
        </collision>
    </link>
    <joint name="2_3" type="revolute">
       <parent link="2"/>
       <child  link="3"/>
       <origin rpy="0 0 0" xyz="0.3353633252380709 -0.3172993912791391 0.0" />
     <axis xyz="1 0 0"/>
       <limit effort="0.0" lower="-3.14159" upper="3.14159" velocity="0.0"/>
    </joint>
    <link name="3">
        <inertial>
            <origin xyz="0.0 -0.42904661676130607 0.0" rpy="0 0 0"/>
            <mass value="1" />
            <inertia ixx="100" ixy="0" ixz="0" iyy="100" iyz="0" izz="100" />
        </inertial>
        <visual>
            <origin xyz="0.0 -0.42904661676130607 0.0" rpy="0 0 0"/>
            <geometry>
                <box size="0.5253488150566894 0.8580932335226121 0.8398358570595297" />
            </geometry>
            <material name="Blue">
                <color rgba="0 0 1.0 1.0"/>
            </material>
        </visual>
        <collision>
            <origin xyz="0.0 -0.42904661676130607 0.0" rpy="0 0 0"/>
            <geometry>
                <box size="0.5253488150566894 0.8580932335226121 0.8398358570595297" />
            </geometry>
        </collision>
    </link>
    <joint name="3_4" type="revolute">
       <parent link="3"/>
       <child  link="4"/>
       <origin rpy="0 0 0" xyz="-0.2626744075283447 -0.42904661676130607 0.0" />
     <axis xyz="1 0 0"/>
       <limit effort="0.0" lower="-3.14159" upper="3.14159" velocity="0.0"/>
    </joint>
    <link name="4">
        <inertial>
            <origin xyz="-0.4802318496061945 0.0 0.0" rpy="0 0 0"/>
            <mass value="1" />
            <inertia ixx="100" ixy="0" ixz="0" iyy="100" iyz="0" izz="100" />
        </inertial>
        <visual>
            <origin xyz="-0.4802318496061945 0.0 0.0" rpy="0 0 0"/>
            <geometry>
                <box size="0.960463699212389 0.5519704010854384 0.9023190072568918" />
            </geometry>
            <material name="Green">
                <color rgba="0 1.0 0 1.0"/>
            </material>
        </visual>
        <collision>
            <origin xyz="-0.4802318496061945 0.0 0.0" rpy="0 0 0"/>
            <geometry>
                <box size="0.960463699212389 0.5519704010854384 0.9023190072568918" />
            </geometry>
        </collision>
    </link>
    <joint name="2_5" type="revolute">
       <parent link="2"/>
       <child  link="5"/>
       <origin rpy="0 0 0" xyz="0.3353633252380709 0.3172993912791391 0.0" />
     <axis xyz="1 0 0"/>
       <limit effort="0.0" lower="-3.14159" upper="3.14159" velocity="0.0"/>
    </joint>
    <link name="5">
        <inertial>
            <origin xyz="0.0 0.3186029014846765 0.0" rpy="0 0 0"/>
            <mass value="1" />
            <inertia ixx="100" ixy="0" ixz="0" iyy="100" iyz="0" izz="100" />
        </inertial>
        <visual>
            <origin xyz="0.0 0.3186029014846765 0.0" rpy="0 0 0"/>
            <geometry>
                <box size="0.7807951561540821 0.637205802969353 0.6664965994926226" />
            </geometry>
            <material name="Green">
                <color rgba="0 1.0 0 1.0"/>
            </material>
        </visual>
        <collision>
            <origin xyz="0.0 0.3186029014846765 0.0" rpy="0 0 0"/>
            <geometry>
                <box size="0.7807951561540821 0.637205802969353 0.6664965994926226" />
            </geometry>
        </collision>
    </link>
    <joint name="1_6" type="revolute">
       <parent link="1"/>
       <child  link="6"/>
       <origin rpy="0 0 0" xyz="0.44155185055902013 0.25216126723665994 0.0" />
     <axis xyz="0 1 0"/>
       <limit effort="0.0" lower="-3.14159" upper="3.14159" velocity="0.0"/>
    </joint>
    <link name="6">
        <inertial>
            <origin xyz="0.0 0.2397608419948574 0.0" rpy="0 0 0"/>
            <mass value="1" />
            <inertia ixx="100" ixy="0" ixz="0" iyy="100" iyz="0" izz="100" />
        </inertial>
        <visual>
            <origin xyz="0.0 0.2397608419948574 0.0" rpy="0 0 0"/>
            <geometry>
                <box size="0.6323921754683927 0.4795216839897148 0.849707655184194" />
            </geometry>
            <material name="Blue">
                <color rgba="0 0 1.0 1.0"/>
            </material>
        </visual>
        <collision>
            <origin xyz="0.0 0.2397608419948574 0.0" rpy="0 0 0"/>
            <geometry>
                <box size="0.6323921754683927 0.4795216839897148 0.849707655184194" />
            </geometry>
        </collision>
    </link>
    <joint name="4_7" type="revolute">
       <parent link="4"/>
       <child  link="7"/>
       <origin rpy="0 0 0" xyz="-0.4802318496061945 0.0 -0.4511595036284459" />
     <axis xyz="0 1 0"/>
       <limit effort="0.0" lower="-3.14159" upper="3.14159" velocity="0.0"/>
    </joint>
    <link name="7">
        <inertial>
            <origin xyz="0.0 0.0 -0.30275722721234444" rpy="0 0 0"/>
            <mass value="1" />
            <inertia ixx="100" ixy="0" ixz="0" iyy="100" iyz="0" izz="100" />
        </inertial>
        <visual>
            <origin xyz="0.0 0.0 -0.30275722721234444" rpy="0 0 0"/>
            <geometry>
                <box size="1.1028655142803556 0.40022575640092145 0.6055144544246889" />
            </geometry>
            <material name="Green">
                <color rgba="0 1.0 0 1.0"/>
            </material>
        </visual>
        <collision>
            <origin xyz="0.0 0.0 -0.30275722721234444" rpy="0 0 0"/>
            <geometry>
                <box size="1.1028655142803556 0.40022575640092145 0.6055144544246889" />
            </geometry>
        </collision>
    </link>
    <joint name="3_8" type="revolute">
       <parent link="3"/>
       <child  link="8"/>
       <origin rpy="0 0 0" xyz="0.0 -0.8580932335226121 0.0" />
     <axis xyz="1 0 0"/>
       <limit effort="0.0" lower="-3.14159" upper="3.14159" velocity="0.0"/>
    </joint>
    <link name="8">
        <inertial>
            <origin xyz="0.0 -0.2813029424597724 0.0" rpy="0 0 0"/>
            <mass value="1" />
            <inertia ixx="100" ixy="0" ixz="0" iyy="100" iyz="0" izz="100" />
        </inertial>
        <visual>
            <origin xyz="0.0 -0.2813029424597724 0.0" rpy="0 0 0"/>
            <geometry>
                <box size="0.9448088187909737 0.5626058849195448 0.9586791815482969" />
            </geometry>
            <material name="Blue">
                <color rgba="0 0 1.0 1.0"/>
            </material>
        </visual>
        <collision>
            <origin xyz="0.0 -0.2813029424597724 0.0" rpy="0 0 0"/>
            <geometry>
                <box size="0.9448088187909737 0.5626058849195448 0.9586791815482969" />
            </geometry>
        </collision>
    </link>
    <joint name="3_9" type="revolute">
       <parent link="3"/>
       <child  link="9"/>
       <origin rpy="0 0 0" xyz="0.0 -0.42904661676130607 0.41991792852976484" />
     <axis xyz="1 0 0"/>
       <limit effort="0.0" lower="-3.14159" upper="3.14159" velocity="0.0"/>
    </joint>
    <link name="9">
        <inertial>
            <origin xyz="0.0 0.0 0.36153341768804154" rpy="0 0 0"/>
            <mass value="1" />
            <inertia ixx="100" ixy="0" ixz="0" iyy="100" iyz="0" izz="100" />
        </inertial>
        <visual>
            <origin xyz="0.0 0.0 0.36153341768804154" rpy="0 0 0"/>
            <geometry>
                <box size="0.4914466064272287 0.8559074170508644 0.7230668353760831" />
            </geometry>
            <material name="Blue">
                <color rgba="0 0 1.0 1.0"/>
            </material>
        </visual>
        <collision>
            <origin xyz="0.0 0.0 0.36153341768804154" rpy="0 0 0"/>
            <geometry>
                <box size="0.4914466064272287 0.8559074170508644 0.7230668353760831" />
            </geometry>
        </collision>
    </link>
    <joint name="9_10" type="revolute">
       <parent link="9"/>
       <child  link="10"/>
       <origin rpy="0 0 0" xyz="0.0 0.0 0.7230668353760831" />
     <axis xyz="0 1 0"/>
       <limit effort="0.0" lower="-3.14159" upper="3.14159" velocity="0.0"/>
    </joint>
    <link name="10">
        <inertial>
            <origin xyz="0.0 0.0 0.24987602732957762" rpy="0 0 0"/>
            <mass value="1" />
            <inertia ixx="100" ixy="0" ixz="0" iyy="100" iyz="0" izz="100" />
        </inertial>
        <visual>
            <origin xyz="0.0 0.0 0.24987602732957762" rpy="0 0 0"/>
            <geometry>
                <box size="0.5122365202034369 0.7703088601555035 0.49975205465915523" />
            </geometry>
            <material name="Green">
                <color rgba="0 1.0 0 1.0"/>
            </material>
        </visual>
        <collision>
            <origin xyz="0.0 0.0 0.24987602732957762" rpy="0 0 0"/>
            <geometry>
                <box size="0.5122365202034369 0.7703088601555035 0.49975205465915523" />
            </geometry>
        </collision>
    </link>
    <joint name="7_11" type="revolute">
       <parent link="7"/>
       <child  link="11"/>
       <origin rpy="0 0 0" xyz="-0.5514327571401778 0.0 -0.30275722721234444" />
     <axis xyz="0 1 0"/>
       <limit effort="0.0" lower="-3.14159" upper="3.14159" velocity="0.0"/>
    </joint>
    <link name="11">
        <inertial>
            <origin xyz="-0.29059676835188186 0.0 0.0" rpy="0 0 0"/>
            <mass value="1" />
            <inertia ixx="100" ixy="0" ixz="0" iyy="100" iyz="0" izz="100" />
        </inertial>
        <visual>
            <origin xyz="-0.29059676835188186 0.0 0.0" rpy="0 0 0"/>
            <geometry>
                <box size="0.5811935367037637 0.688904459050645 0.4791687969759997" />
            </geometry>
            <material name="Green">
                <color rgba="0 1.0 0 1.0"/>
            </material>
        </visual>
        <collision>
            <origin xyz="-0.29059676835188186 0.0 0.0" rpy="0 0 0"/>
            <geometry>
                <box size="0.5811935367037637 0.688904459050645 0.4791687969759997" />
            </geometry>
        </collision>
    </link>
    <joint name="3_12" type="revolute">
       <parent link="3"/>
       <child  link="12"/>
       <origin rpy="0 0 0" xyz="0.2626744075283447 -0.42904661676130607 0.0" />
     <axis xyz="1 0 0"/>
       <limit effort="0.0" lower="-3.14159" upper="3.14159" velocity="0.0"/>
    </joint>
    <link name="12">
        <inertial>
            <origin xyz="0.28801277123943625 0.0 0.0" rpy="0 0 0"/>
            <mass value="1" />
            <inertia ixx="100" ixy="0" ixz="0" iyy="100" iyz="0" izz="100" />
        </inertial>
        <visual>
            <origin xyz="0.28801277123943625 0.0 0.0" rpy="0 0 0"/>
            <geometry>
                <box size="0.5760255424788725 0.6786255545469286 0.47893648633059355" />
            </geometry>
            <material name="Blue">
                <color rgba="0 0 1.0 1.0"/>
            </material>
        </visual>
        <collision>
            <origin xyz="0.28801277123943625 0.0 0.0" rpy="0 0 0"/>
            <geometry>
                <box size="0.5760255424788725 0.6786255545469286 0.47893648633059355" />
            </geometry>
        </collision>
    </link>
</robot>