<robot name = "robot">
    <link name="0">
        <inertial>
            <origin xyz="0 0 3.474184161204177" rpy="0 0 0"/>
            <mass value="1" />
            <inertia ixx="100" ixy="0" ixz="0" iyy="100" iyz="0" izz="100" />
        </inertial>
        <visual>
            <origin xyz="0 0 3.474184161204177" rpy="0 0 0"/>
            <geometry>
                <box size="0.6438284462611172 0.9799250931957908 0.9483683224083536" />
            </geometry>
            <material name="Green">
                <color rgba="0 1.0 0 1.0"/>
            </material>
        </visual>
        <collision>
            <origin xyz="0 0 3.474184161204177" rpy="0 0 0"/>
            <geometry>
                <box size="0.6438284462611172 0.9799250931957908 0.9483683224083536" />
            </geometry>
        </collision>
    </link>
    <joint name="0_1" type="revolute">
       <parent link="0"/>
       <child  link="1"/>
       <origin rpy="0 0 0" xyz="-0.3219142231305586 0.0 3.474184161204177" />
     <axis xyz="1 0 0"/>
       <limit effort="0.0" lower="-3.14159" upper="3.14159" velocity="0.0"/>
    </joint>
    <link name="1">
        <inertial>
            <origin xyz="-0.5465415198097332 0.0 0.0" rpy="0 0 0"/>
            <mass value="1" />
            <inertia ixx="100" ixy="0" ixz="0" iyy="100" iyz="0" izz="100" />
        </inertial>
        <visual>
            <origin xyz="-0.5465415198097332 0.0 0.0" rpy="0 0 0"/>
            <geometry>
                <box size="1.0930830396194664 0.6254058160883192 0.9286894671365047" />
            </geometry>
            <material name="Green">
                <color rgba="0 1.0 0 1.0"/>
            </material>
        </visual>
        <collision>
            <origin xyz="-0.5465415198097332 0.0 0.0" rpy="0 0 0"/>
            <geometry>
                <box size="1.0930830396194664 0.6254058160883192 0.9286894671365047" />
            </geometry>
        </collision>
    </link>
    <joint name="1_2" type="revolute">
       <parent link="1"/>
       <child  link="2"/>
       <origin rpy="0 0 0" xyz="-0.5465415198097332 0.0 -0.46434473356825234" />
     <axis xyz="1 0 0"/>
       <limit effort="0.0" lower="-3.14159" upper="3.14159" velocity="0.0"/>
    </joint>
    <link name="2">
        <inertial>
            <origin xyz="0.0 0.0 -0.3605776092702377" rpy="0 0 0"/>
            <mass value="1" />
            <inertia ixx="100" ixy="0" ixz="0" iyy="100" iyz="0" izz="100" />
        </inertial>
        <visual>
            <origin xyz="0.0 0.0 -0.3605776092702377" rpy="0 0 0"/>
            <geometry>
                <box size="0.8337239975511108 0.6492526256828648 0.7211552185404754" />
            </geometry>
            <material name="Blue">
                <color rgba="0 0 1.0 1.0"/>
            </material>
        </visual>
        <collision>
            <origin xyz="0.0 0.0 -0.3605776092702377" rpy="0 0 0"/>
            <geometry>
                <box size="0.8337239975511108 0.6492526256828648 0.7211552185404754" />
            </geometry>
        </collision>
    </link>
    <joint name="1_3" type="revolute">
       <parent link="1"/>
       <child  link="3"/>
       <origin rpy="0 0 0" xyz="-0.5465415198097332 0.3127029080441596 0.0" />
     <axis xyz="0 1 0"/>
       <limit effort="0.0" lower="-3.14159" upper="3.14159" velocity="0.0"/>
    </joint>
    <link name="3">
        <inertial>
            <origin xyz="0.0 0.4649818191742105 0.0" rpy="0 0 0"/>
            <mass value="1" />
            <inertia ixx="100" ixy="0" ixz="0" iyy="100" iyz="0" izz="100" />
        </inertial>
        <visual>
            <origin xyz="0.0 0.4649818191742105 0.0" rpy="0 0 0"/>
            <geometry>
                <box size="0.8421255057397422 0.929963638348421 0.6889975726363806" />
            </geometry>
            <material name="Green">
                <color rgba="0 1.0 0 1.0"/>
            </material>
        </visual>
        <collision>
            <origin xyz="0.0 0.4649818191742105 0.0" rpy="0 0 0"/>
            <geometry>
                <box size="0.8421255057397422 0.929963638348421 0.6889975726363806" />
            </geometry>
        </collision>
    </link>
    <joint name="3_4" type="revolute">
       <parent link="3"/>
       <child  link="4"/>
       <origin rpy="0 0 0" xyz="0.0 0.929963638348421 0.0" />
     <axis xyz="0 1 0"/>
       <limit effort="0.0" lower="-3.14159" upper="3.14159" velocity="0.0"/>
    </joint>
    <link name="4">
        <inertial>
            <origin xyz="0.0 0.1965815011652966 0.0" rpy="0 0 0"/>
            <mass value="1" />
            <inertia ixx="100" ixy="0" ixz="0" iyy="100" iyz="0" izz="100" />
        </inertial>
        <visual>
            <origin xyz="0.0 0.1965815011652966 0.0" rpy="0 0 0"/>
            <geometry>
                <box size="0.6144071634908 0.3931630023305932 1.0211196801516587" />
            </geometry>
            <material name="Blue">
                <color rgba="0 0 1.0 1.0"/>
            </material>
        </visual>
        <collision>
            <origin xyz="0.0 0.1965815011652966 0.0" rpy="0 0 0"/>
            <geometry>
                <box size="0.6144071634908 0.3931630023305932 1.0211196801516587" />
            </geometry>
        </collision>
    </link>
    <joint name="4_5" type="revolute">
       <parent link="4"/>
       <child  link="5"/>
       <origin rpy="0 0 0" xyz="0.0 0.1965815011652966 -0.5105598400758293" />
     <axis xyz="1 0 0"/>
       <limit effort="0.0" lower="-3.14159" upper="3.14159" velocity="0.0"/>
    </joint>
    <link name="5">
        <inertial>
            <origin xyz="0.0 0.0 -0.22770420806935895" rpy="0 0 0"/>
            <mass value="1" />
            <inertia ixx="100" ixy="0" ixz="0" iyy="100" iyz="0" izz="100" />
        </inertial>
        <visual>
            <origin xyz="0.0 0.0 -0.22770420806935895" rpy="0 0 0"/>
            <geometry>
                <box size="0.4026930785065099 0.8208224455949118 0.4554084161387179" />
            </geometry>
            <material name="Green">
                <color rgba="0 1.0 0 1.0"/>
            </material>
        </visual>
        <collision>
            <origin xyz="0.0 0.0 -0.22770420806935895" rpy="0 0 0"/>
            <geometry>
                <box size="0.4026930785065099 0.8208224455949118 0.4554084161387179" />
            </geometry>
        </collision>
    </link>
    <joint name="2_6" type="revolute">
       <parent link="2"/>
       <child  link="6"/>
       <origin rpy="0 0 0" xyz="0.4168619987755554 0.0 -0.3605776092702377" />
     <axis xyz="1 0 0"/>
       <limit effort="0.0" lower="-3.14159" upper="3.14159" velocity="0.0"/>
    </joint>
    <link name="6">
        <inertial>
            <origin xyz="0.49042231894493454 0.0 0.0" rpy="0 0 0"/>
            <mass value="1" />
            <inertia ixx="100" ixy="0" ixz="0" iyy="100" iyz="0" izz="100" />
        </inertial>
        <visual>
            <origin xyz="0.49042231894493454 0.0 0.0" rpy="0 0 0"/>
            <geometry>
                <box size="0.9808446378898691 0.49741445649962407 0.638532205032342" />
            </geometry>
            <material name="Green">
                <color rgba="0 1.0 0 1.0"/>
            </material>
        </visual>
        <collision>
            <origin xyz="0.49042231894493454 0.0 0.0" rpy="0 0 0"/>
            <geometry>
                <box size="0.9808446378898691 0.49741445649962407 0.638532205032342" />
            </geometry>
        </collision>
    </link>
    <joint name="1_7" type="revolute">
       <parent link="1"/>
       <child  link="7"/>
       <origin rpy="0 0 0" xyz="-0.5465415198097332 0.0 0.46434473356825234" />
     <axis xyz="0 1 0"/>
       <limit effort="0.0" lower="-3.14159" upper="3.14159" velocity="0.0"/>
    </joint>
    <link name="7">
        <inertial>
            <origin xyz="0.0 0.0 0.32167096548593155" rpy="0 0 0"/>
            <mass value="1" />
            <inertia ixx="100" ixy="0" ixz="0" iyy="100" iyz="0" izz="100" />
        </inertial>
        <visual>
            <origin xyz="0.0 0.0 0.32167096548593155" rpy="0 0 0"/>
            <geometry>
                <box size="1.0920436980362154 1.0994481725244873 0.6433419309718631" />
            </geometry>
            <material name="Blue">
                <color rgba="0 0 1.0 1.0"/>
            </material>
        </visual>
        <collision>
            <origin xyz="0.0 0.0 0.32167096548593155" rpy="0 0 0"/>
            <geometry>
                <box size="1.0920436980362154 1.0994481725244873 0.6433419309718631" />
            </geometry>
        </collision>
    </link>
    <joint name="5_8" type="revolute">
       <parent link="5"/>
       <child  link="8"/>
       <origin rpy="0 0 0" xyz="0.0 0.4104112227974559 -0.22770420806935895" />
     <axis xyz="1 0 0"/>
       <limit effort="0.0" lower="-3.14159" upper="3.14159" velocity="0.0"/>
    </joint>
    <link name="8">
        <inertial>
            <origin xyz="0.0 0.3463701206867159 0.0" rpy="0 0 0"/>
            <mass value="1" />
            <inertia ixx="100" ixy="0" ixz="0" iyy="100" iyz="0" izz="100" />
        </inertial>
        <visual>
            <origin xyz="0.0 0.3463701206867159 0.0" rpy="0 0 0"/>
            <geometry>
                <box size="0.8892805466757208 0.6927402413734318 0.38437504608089273" />
            </geometry>
            <material name="Blue">
                <color rgba="0 0 1.0 1.0"/>
            </material>
        </visual>
        <collision>
            <origin xyz="0.0 0.3463701206867159 0.0" rpy="0 0 0"/>
            <geometry>
                <box size="0.8892805466757208 0.6927402413734318 0.38437504608089273" />
            </geometry>
        </collision>
    </link>
    <joint name="3_9" type="revolute">
       <parent link="3"/>
       <child  link="9"/>
       <origin rpy="0 0 0" xyz="0.4210627528698711 0.4649818191742105 0.0" />
     <axis xyz="1 0 0"/>
       <limit effort="0.0" lower="-3.14159" upper="3.14159" velocity="0.0"/>
    </joint>
    <link name="9">
        <inertial>
            <origin xyz="0.2809037238767837 0.0 0.0" rpy="0 0 0"/>
            <mass value="1" />
            <inertia ixx="100" ixy="0" ixz="0" iyy="100" iyz="0" izz="100" />
        </inertial>
        <visual>
            <origin xyz="0.2809037238767837 0.0 0.0" rpy="0 0 0"/>
            <geometry>
                <box size="0.5618074477535674 0.5631498677315929 0.4056973024103687" />
            </geometry>
            <material name="Green">
                <color rgba="0 1.0 0 1.0"/>
            </material>
        </visual>
        <collision>
            <origin xyz="0.2809037238767837 0.0 0.0" rpy="0 0 0"/>
            <geometry>
                <box size="0.5618074477535674 0.5631498677315929 0.4056973024103687" />
            </geometry>
        </collision>
    </link>
    <joint name="5_10" type="revolute">
       <parent link="5"/>
       <child  link="10"/>
       <origin rpy="0 0 0" xyz="0.0 -0.4104112227974559 -0.22770420806935895" />
     <axis xyz="0 1 0"/>
       <limit effort="0.0" lower="-3.14159" upper="3.14159" velocity="0.0"/>
    </joint>
    <link name="10">
        <inertial>
            <origin xyz="0.0 -0.3456596545374458 0.0" rpy="0 0 0"/>
            <mass value="1" />
            <inertia ixx="100" ixy="0" ixz="0" iyy="100" iyz="0" izz="100" />
        </inertial>
        <visual>
            <origin xyz="0.0 -0.3456596545374458 0.0" rpy="0 0 0"/>
            <geometry>
                <box size="1.025856216405604 0.6913193090748916 0.7290835437135553" />
            </geometry>
            <material name="Blue">
                <color rgba="0 0 1.0 1.0"/>
            </material>
        </visual>
        <collision>
            <origin xyz="0.0 -0.3456596545374458 0.0" rpy="0 0 0"/>
            <geometry>
                <box size="1.025856216405604 0.6913193090748916 0.7290835437135553" />
            </geometry>
        </collision>
    </link>
    <joint name="7_11" type="revolute">
       <parent link="7"/>
       <child  link="11"/>
       <origin rpy="0 0 0" xyz="0.0 -0.5497240862622437 0.32167096548593155" />
     <axis xyz="1 0 0"/>
       <limit effort="0.0" lower="-3.14159" upper="3.14159" velocity="0.0"/>
    </joint>
    <link name="11">
        <inertial>
            <origin xyz="0.0 -0.38555168624078273 0.0" rpy="0 0 0"/>
            <mass value="1" />
            <inertia ixx="100" ixy="0" ixz="0" iyy="100" iyz="0" izz="100" />
        </inertial>
        <visual>
            <origin xyz="0.0 -0.38555168624078273 0.0" rpy="0 0 0"/>
            <geometry>
                <box size="0.47087301489218925 0.7711033724815655 0.7570877962845748" />
            </geometry>
            <material name="Blue">
                <color rgba="0 0 1.0 1.0"/>
            </material>
        </visual>
        <collision>
            <origin xyz="0.0 -0.38555168624078273 0.0" rpy="0 0 0"/>
            <geometry>
                <box size="0.47087301489218925 0.7711033724815655 0.7570877962845748" />
            </geometry>
        </collision>
    </link>
    <joint name="7_12" type="revolute">
       <parent link="7"/>
       <child  link="12"/>
       <origin rpy="0 0 0" xyz="0.0 0.5497240862622437 0.32167096548593155" />
     <axis xyz="1 0 0"/>
       <limit effort="0.0" lower="-3.14159" upper="3.14159" velocity="0.0"/>
    </joint>
    <link name="12">
        <inertial>
            <origin xyz="0.0 0.27969123786332983 0.0" rpy="0 0 0"/>
            <mass value="1" />
            <inertia ixx="100" ixy="0" ixz="0" iyy="100" iyz="0" izz="100" />
        </inertial>
        <visual>
            <origin xyz="0.0 0.27969123786332983 0.0" rpy="0 0 0"/>
            <geometry>
                <box size="0.6015601448593274 0.5593824757266597 0.5441097944111155" />
            </geometry>
            <material name="Blue">
                <color rgba="0 0 1.0 1.0"/>
            </material>
        </visual>
        <collision>
            <origin xyz="0.0 0.27969123786332983 0.0" rpy="0 0 0"/>
            <geometry>
                <box size="0.6015601448593274 0.5593824757266597 0.5441097944111155" />
            </geometry>
        </collision>
    </link>
    <joint name="10_13" type="revolute">
       <parent link="10"/>
       <child  link="13"/>
       <origin rpy="0 0 0" xyz="-0.512928108202802 -0.3456596545374458 0.0" />
     <axis xyz="1 0 0"/>
       <limit effort="0.0" lower="-3.14159" upper="3.14159" velocity="0.0"/>
    </joint>
    <link name="13">
        <inertial>
            <origin xyz="-0.40999475646185557 0.0 0.0" rpy="0 0 0"/>
            <mass value="1" />
            <inertia ixx="100" ixy="0" ixz="0" iyy="100" iyz="0" izz="100" />
        </inertial>
        <visual>
            <origin xyz="-0.40999475646185557 0.0 0.0" rpy="0 0 0"/>
            <geometry>
                <box size="0.8199895129237111 0.3867746449480519 1.032384635648787" />
            </geometry>
            <material name="Green">
                <color rgba="0 1.0 0 1.0"/>
            </material>
        </visual>
        <collision>
            <origin xyz="-0.40999475646185557 0.0 0.0" rpy="0 0 0"/>
            <geometry>
                <box size="0.8199895129237111 0.3867746449480519 1.032384635648787" />
            </geometry>
        </collision>
    </link>
    <joint name="9_14" type="revolute">
       <parent link="9"/>
       <child  link="14"/>
       <origin rpy="0 0 0" xyz="0.5618074477535674 0.0 0.0" />
     <axis xyz="0 1 0"/>
       <limit effort="0.0" lower="-3.14159" upper="3.14159" velocity="0.0"/>
    </joint>
    <link name="14">
        <inertial>
            <origin xyz="0.2246321227106669 0.0 0.0" rpy="0 0 0"/>
            <mass value="1" />
            <inertia ixx="100" ixy="0" ixz="0" iyy="100" iyz="0" izz="100" />
        </inertial>
        <visual>
            <origin xyz="0.2246321227106669 0.0 0.0" rpy="0 0 0"/>
            <geometry>
                <box size="0.4492642454213338 0.46117780489325916 0.3787375415549692" />
            </geometry>
            <material name="Blue">
                <color rgba="0 0 1.0 1.0"/>
            </material>
        </visual>
        <collision>
            <origin xyz="0.2246321227106669 0.0 0.0" rpy="0 0 0"/>
            <geometry>
                <box size="0.4492642454213338 0.46117780489325916 0.3787375415549692" />
            </geometry>
        </collision>
    </link>
    <joint name="12_15" type="revolute">
       <parent link="12"/>
       <child  link="15"/>
       <origin rpy="0 0 0" xyz="0.3007800724296637 0.27969123786332983 0.0" />
     <axis xyz="0 1 0"/>
       <limit effort="0.0" lower="-3.14159" upper="3.14159" velocity="0.0"/>
    </joint>
    <link name="15">
        <inertial>
            <origin xyz="0.4099835172235626 0.0 0.0" rpy="0 0 0"/>
            <mass value="1" />
            <inertia ixx="100" ixy="0" ixz="0" iyy="100" iyz="0" izz="100" />
        </inertial>
        <visual>
            <origin xyz="0.4099835172235626 0.0 0.0" rpy="0 0 0"/>
            <geometry>
                <box size="0.8199670344471252 0.377340999689966 0.5121276656285177" />
            </geometry>
            <material name="Blue">
                <color rgba="0 0 1.0 1.0"/>
            </material>
        </visual>
        <collision>
            <origin xyz="0.4099835172235626 0.0 0.0" rpy="0 0 0"/>
            <geometry>
                <box size="0.8199670344471252 0.377340999689966 0.5121276656285177" />
            </geometry>
        </collision>
    </link>
    <joint name="8_16" type="revolute">
       <parent link="8"/>
       <child  link="16"/>
       <origin rpy="0 0 0" xyz="0.0 0.3463701206867159 -0.19218752304044637" />
     <axis xyz="0 1 0"/>
       <limit effort="0.0" lower="-3.14159" upper="3.14159" velocity="0.0"/>
    </joint>
    <link name="16">
        <inertial>
            <origin xyz="0.0 0.0 -0.22560688063859785" rpy="0 0 0"/>
            <mass value="1" />
            <inertia ixx="100" ixy="0" ixz="0" iyy="100" iyz="0" izz="100" />
        </inertial>
        <visual>
            <origin xyz="0.0 0.0 -0.22560688063859785" rpy="0 0 0"/>
            <geometry>
                <box size="1.1165483338685467 0.5311069236993601 0.4512137612771957" />
            </geometry>
            <material name="Blue">
                <color rgba="0 0 1.0 1.0"/>
            </material>
        </visual>
        <collision>
            <origin xyz="0.0 0.0 -0.22560688063859785" rpy="0 0 0"/>
            <geometry>
                <box size="1.1165483338685467 0.5311069236993601 0.4512137612771957" />
            </geometry>
        </collision>
    </link>
    <joint name="11_17" type="revolute">
       <parent link="11"/>
       <child  link="17"/>
       <origin rpy="0 0 0" xyz="-0.23543650744609462 -0.38555168624078273 0.0" />
     <axis xyz="1 0 0"/>
       <limit effort="0.0" lower="-3.14159" upper="3.14159" velocity="0.0"/>
    </joint>
    <link name="17">
        <inertial>
            <origin xyz="-0.4069451553041741 0.0 0.0" rpy="0 0 0"/>
            <mass value="1" />
            <inertia ixx="100" ixy="0" ixz="0" iyy="100" iyz="0" izz="100" />
        </inertial>
        <visual>
            <origin xyz="-0.4069451553041741 0.0 0.0" rpy="0 0 0"/>
            <geometry>
                <box size="0.8138903106083482 0.7653353124866416 0.8281504245365437" />
            </geometry>
            <material name="Green">
                <color rgba="0 1.0 0 1.0"/>
            </material>
        </visual>
        <collision>
            <origin xyz="-0.4069451553041741 0.0 0.0" rpy="0 0 0"/>
            <geometry>
                <box size="0.8138903106083482 0.7653353124866416 0.8281504245365437" />
            </geometry>
        </collision>
    </link>
</robot>